Workbook

Sheet Front Page
M6: Please contact this email for any model-specific questions:
M7: modelsupport@alpha-sense.com | N7: mailto:support@canalyst.com?subject=Canalyst%20Support:%20ASML%20Holdings%20N.V.%20ASML%20US&body=Model%20Version:%20Q2-2019.20 | O7: mailto:support@canalyst.com?subject=Canalyst%20Support:%20ASML%20Holdings%20N.V.%20ASML%20US&body=Model%20Version:%20Q2-2019.20
C9: Company Model: | H9: =Model!A1 -> ASML Holdings N.V.
C11: Updated: | H11: =OFFSET('Update Log'!$C$10,1,0,1,1) -> 46049
M12: Comments on Model:
C13: For: | H13: =OFFSET('Update Log'!$E$10,1,0,1,1) -> Initial (Press Release)
C15: Consensus Data and Real-Time Stock Price: | H15: Bloomberg
H16: =IF(FP.DataSourceName="Bloomberg",1,IF(FP.DataSourceName="Capital IQ",2,IF(FP.DataSourceName="FactSet",3,IF(FP.DataSourceName="Refinitiv",4)))) -> 1
C18: Real-Time Stock Price: | H18: OFF
C20: Stock Price Override: | F20: 46049 | H20: 1217.6
C22: DISCLAIMER Access to and use of this model, including the data contained herein (this "Model") is subject to Tegus, Inc.'s (a successor entity to Canalyst Financial Modeling Corporation) ("Company") Terms of Use that you accepted prior to accessing this Model, the applicable Service Agreement between the Company and you (or a corporate entity that has authorized you to access and use this Model on its behalf in accordance with the terms of such Service Agreement) or other similar agreement between you and the Company. BY CONTINUING TO ACCESS OR USE THIS MODEL, YOU EXPRESSLY AGREE TO THE TERMS AND CONDITIONS OF SUCH AGREEMENTS. The Company and certain of its licensors have exclusive proprietary rights in this Model. This Model is being provided for internal use only. Unless prior written consent by the Company and its licensors has been provided to you, you may not distribute or otherwise furnish this Model to any third party, nor use or permit anyone to use this Model for any unlawful or unauthorized purpose. IF YOU HAVE UNLAWFULLY OBTAINED, OR ARE NOT AUTHORIZED TO USE THIS MODEL, YOU ARE OBLIGATED TO PROMPTLY: (I) RETURN THIS MODEL (AND ANY DERIVATIVE WORKS ARISING FROM OR RELATING THERETO) TO THE AUTHORIZED USER OF THIS MODEL; (II) PROVIDE NOTICE TO THE COMPANY AT LEGAL@TEGUS.COM OF SUCH UNLAWFUL OR UNAUTHORIZED ACCESS AND USE; AND, (III) CERTIFY THAT YOU HAVE DESTROYED THIS MODEL (AND ANY DERIVATIVE WORKS ARISING FROM OR RELATING THERETO) AND ANY COPIES FROM YOUR SYSTEMS SO AS TO ENSURE THEY ARE INCAPABLE OF RETRIEVAL. A portion of the data contained in this Model may be powered by third party contributors and their respective licensors, or derived from data provided by such contributors, including (but not limited to): (i) QuoteMedia Inc.: A portion of the market data is powered by Quotemedia.com. All rights reserved. Data delayed 15 minutes unless otherwise indicated; (ii) S&P Global Market Intelligence LLC: Copyright (c) {{YEAR}} S&P Global Market Intelligence LLC (and its affiliates as applicable). All rights reserved. Reproduction of any information, opinions, views, data or material, including ratings ("Content") in any form is prohibited except with the prior written permission of the relevant party. Such party, its affiliates and suppliers ("Content Providers") do not guarantee the accuracy, adequacy, completeness, timeliness or availability of any Content and are not responsible for any errors or omissions (negligent or otherwise), regardless of the cause, or for the results obtained from the use of such Content. In no event shall Content Providers be liable for any damages, costs, expenses, legal fees, or losses (including lost income or lost profit and opportunity costs) in connection with any use of the Content. A reference to a particular investment or security, a rating or any observation concerning an investment that is part of the Content is not a recommendation to buy, sell or hold such investment or security, does not address the suitability of an investment or security and should not be relied on as investment advice. Credit ratings are statements of opinions and are not statements of fact; and, (iii) Refinitiv Canada Holdings Limited: A portion of the information may be provided by or derived from data provided by Refinitiv. By accessing or using this Model (including any portion of the data contained herein) you expressly represent that such access or use does not constitute a violation of any applicable law or regulation to which you or the securities are subject. This Model does not constitute investment advice by the Company or any of its licensors. Reference to a particular investment or security, credit rating or any observation concerning a security or investment in this Model is not a recommendation or solicitation to buy, sell or hold such investment or security or make any other investment decisions. For greater certainty, any forecasts or forward-looking information expressed herein are for illustrative purposes only and do not purport to express any view on what may transpire. Neither the Company nor any of its licensors have performed company-specific research on any projected information, as such, it is your responsibility to express your own views on projected results. This Model does not guarantee future performance and undue reliance should not be placed on such. You are solely responsible for evaluating the merits and risks of any investment based on your own business and financial expertise, the business and financial expertise of professional advisors with whom you have consulted, your financial situation and risk tolerance. Neither the Company, nor any of its licensors, undertake any liability with respect to your reliance on this Model. This Model is a quantitative tool with no investment views. The Company and its respective directors, officers, employees, agents, contractors, and affiliates may hold long or short positions in the security to which this Model relates, based on their personal views, and may initiate or close out any positions in such security at any time without any notice. THIS MODEL IS PROVIDED "AS IS" AND ON AN "AS AVAILABLE" BASIS ONLY, WITHOUT WARRANTIES OR CONDITIONS OF ANY KIND. NEITHER THE COMPANY NOR ANY OF ITS LICENSORS NOR THEIR RESPECTIVE AFFILIATES OR SUPPLIERS HAVE LIABILITY FOR THE ACCURACY, TIMELINESS OR COMPLETENESS OF THIS MODEL, OR FOR DELAYS, INTERRUPTIONS OR OMISSIONS HEREIN, NOR FOR ANY LOST PROFITS, INDIRECT, SPECIAL OR CONSEQUENTIAL DAMAGES. Access to data in this Model that is sourced from third party contributors is subject to termination in the event that any agreement between the Company and such third party contributors terminates for any reason. Copyright 2023 Tegus. All rights reserved.

Sheet Multiples Valuation
B1: ASML Holdings N.V. (ASML)
B2: Comprehensive Multiples-Based Valuation
B3: Stock Price Override: | C3: ='Front Page'!H20 -> 1217.6
B5: EPS DRIVERS — NON-GAAP INCOME STATEMENT WATERFALL
B6: ($ in millions, except per share & margins) | C6: FY2024 | D6: FY2025 | E6: FY2026E | F6: FY2027E
B7: Total Revenue | C7: =Model!C329 -> 1596.063 | D7: =Model!D329 -> 4507.938 | E7: =Model!E329 -> 5651.035 | F7: =Model!F329 -> 4731.555
B8: Y/Y Revenue Growth % | D8: =IFERROR(D7/C7-1,"-") -> 1.8244111 | E8: =IFERROR(E7/D7-1,"-") -> 0.25357425 | F8: =IFERROR(F7/E7-1,"-") -> -0.16271002
B9: Non-GAAP COGS | C9: =Model!C332 -> 1137.671 | D9: =Model!D332 -> 2552.768 | E9: =Model!E332 -> 3201.645 | F9: =Model!F332 -> 2726.298
B10: Non-GAAP Gross Profit | C10: =Model!C333 -> 458.392 | D10: =Model!D333 -> 1955.17 | E10: =Model!E333 -> 2449.39 | F10: =Model!F333 -> 2005.257
B11: Gross Margin % | C11: =IFERROR(C10/C7,"-") -> 0.2872017 | D11: =IFERROR(D10/D7,"-") -> 0.43371715 | E11: =IFERROR(E10/E7,"-") -> 0.43344095 | F11: =IFERROR(F10/F7,"-") -> 0.42380507
B12: Non-GAAP R&D Expense | C12: =Model!C335 -> 466.761 | D12: =Model!D335 -> 523.426 | E12: =Model!E335 -> 590.27 | F12: =Model!F335 -> 589.182
B13: R&D as % of Revenue | C13: =IFERROR(C12/C7,"-") -> 0.29244522 | D13: =IFERROR(D12/D7,"-") -> 0.11611207 | E13: =IFERROR(E12/E7,"-") -> 0.10445343 | F13: =IFERROR(F12/F7,"-") -> 0.12452185
B14: Non-GAAP SG&A Expense | C14: =Model!C336 -> 154.756 | D14: =Model!D336 -> 181.045 | E14: =Model!E336 -> 217.904 | F14: =Model!F336 -> 259.301
B15: SG&A as % of Revenue | C15: =IFERROR(C14/C7,"-") -> 0.096961085 | D15: =IFERROR(D14/D7,"-") -> 0.040161378 | E15: =IFERROR(E14/E7,"-") -> 0.038560016 | F15: =IFERROR(F14/F7,"-") -> 0.054802491
B16: Non-GAAP Other OPEX | C16: =Model!C337 -> 0 | D16: =Model!D337 -> 0 | E16: =Model!E337 -> 0 | F16: =Model!F337 -> 0
B17: Non-GAAP Operating Income (EBIT) | C17: =Model!C338 -> -163.125 | D17: =Model!D338 -> 1250.699 | E17: =Model!E338 -> 1641.216 | F17: =Model!F338 -> 1156.774
B18: EBIT Margin % | C18: =IFERROR(C17/C7,"-") -> -0.10220461 | D18: =IFERROR(D17/D7,"-") -> 0.2774437 | E18: =IFERROR(E17/E7,"-") -> 0.29042751 | F18: =IFERROR(F17/F7,"-") -> 0.24448073
B19: Non-GAAP Net Interest Expense | C19: =Model!C348 -> 8.425 | D19: =Model!D348 -> 8.176 | E19: =Model!E348 -> -7.419 | F19: =Model!F348 -> 6.196
B20: Other Non-Operating Items | C20: =Model!C349 -> 0 | D20: =Model!D349 -> 0 | E20: =Model!E349 -> 0 | F20: =Model!F349 -> 0
B21: Non-GAAP Earnings Before Taxes | C21: =C17+C19+C20 -> -154.7 | D21: =D17+D19+D20 -> 1258.875 | E21: =E17+E19+E20 -> 1633.797 | F21: =F17+F19+F20 -> 1162.97
B22: Non-GAAP Tax Provision | C22: =Model!C354 -> 28.798 | D22: =Model!D354 -> 192.65 | E22: =Model!E354 -> 118.425 | F22: =Model!F354 -> 76.636
B23: Tax Rate % | C23: =IFERROR(C22/C21,"-") -> -0.18615385 | D23: =IFERROR(D22/D21,"-") -> 0.15303346 | E23: =IFERROR(E22/E21,"-") -> 0.072484525 | F23: =IFERROR(F22/F21,"-") -> 0.065896799
B24: Non-GAAP Net Income | C24: =Model!C365 -> -150.925 | D24: =Model!D365 -> 1021.82 | E24: =Model!E365 -> 1466.96 | F24: =Model!F365 -> 1146.316
B25: Diluted Shares Outstanding (mm) | C25: =Model!C394 -> 433.63898 | D25: =Model!D394 -> 440.42097 | E25: =Model!E394 -> 417.10426 | F25: =Model!F394 -> 410.05522
B26: Non-GAAP EPS (Diluted) | C26: =IFERROR(C24/C25,"-") -> -0.34804298 | D26: =IFERROR(D24/D25,"-") -> 2.3200984 | E26: =IFERROR(E24/E25,"-") -> 3.5170104 | F26: =IFERROR(F24/F25,"-") -> 2.7955162
B27: Y/Y EPS Growth % | D27: =IFERROR(D26/C26-1,"-") -> -7.6661262 | E27: =IFERROR(E26/D26-1,"-") -> 0.51588844 | F27: =IFERROR(F26/E26-1,"-") -> -0.20514418
B29: EBITDA DRIVERS — NON-GAAP EBITDA BUILD
B30: ($ in millions) | C30: FY2024 | D30: FY2025 | E30: FY2026E | F30: FY2027E
B31: Company Reported Non-GAAP EBIT | C31: =Model!C338 -> -163.125 | D31: =Model!D338 -> 1250.699 | E31: =Model!E338 -> 1641.216 | F31: =Model!F338 -> 1156.774
B32: EBIT Margin % | C32: =IFERROR(C31/C7,"-") -> -0.10220461 | D32: =IFERROR(D31/D7,"-") -> 0.2774437 | E32: =IFERROR(E31/E7,"-") -> 0.29042751 | F32: =IFERROR(F31/F7,"-") -> 0.24448073
B33: Plus: Depreciation | C33: =Model!C107 -> 131.1 | D33: =Model!D107 -> 144.6 | E33: =Model!E107 -> 158 | F33: =Model!F107 -> 179.3
B34: Plus: Amortization | C34: =Model!C111 -> 8.8 | D34: =Model!D111 -> 5.5 | E34: =Model!E111 -> 5.3 | F34: =Model!F111 -> 6.1
B35: Total D&A | C35: =C33+C34 -> 139.9 | D35: =D33+D34 -> 150.1 | E35: =E33+E34 -> 163.3 | F35: =F33+F34 -> 185.4
B36: Non-GAAP EBITDA | C36: =Model!C344 -> -8.1 | D36: =Model!D344 -> 1414.252 | E36: =Model!E344 -> 1818.831 | F36: =Model!F344 -> 1362.108
B37: EBITDA Margin % | C37: =IFERROR(C36/C7,"-") -> -0.0050749876 | D37: =IFERROR(D36/D7,"-") -> 0.31372481 | E37: =IFERROR(E36/E7,"-") -> 0.32185803 | F37: =IFERROR(F36/F7,"-") -> 0.28787745
B38: Y/Y EBITDA Growth % | D38: =IFERROR(D36/C36-1,"-") -> -175.59901 | E38: =IFERROR(E36/D36-1,"-") -> 0.28607278 | F38: =IFERROR(F36/E36-1,"-") -> -0.25110799
B40: MEMO: KEY ADJUSTMENTS
B41: Stock-Based Compensation | C41: =Model!C343 -> 13.394 | D41: =Model!D343 -> 12.109 | E41: =Model!E343 -> 12.43 | F41: =Model!F343 -> 18.714
B42: SBC as % of Revenue | C42: =IFERROR(C41/C7,"-") -> 0.0083918993 | D42: =IFERROR(D41/D7,"-") -> 0.0026861505 | E42: =IFERROR(E41/E7,"-") -> 0.0021995971 | F42: =IFERROR(F41/F7,"-") -> 0.0039551479
B43: Capital Expenditures | C43: =Model!C403 -> -104.959 | D43: =Model!D403 -> -128.728 | E43: =Model!E403 -> -300.898 | F43: =Model!F403 -> -179.536
...

Sheet DCF
A1: ASML DCF Valuation Analysis
A4: Period | F4: FY2025 | G4: FY2026 | H4: FY2027 | I4: FY2028 | J4: FY2029
A6: REVENUE BUILD
A7: EUV Revenue | F7: =Model!L45 -> -0.14224467 | G7: =Model!Q45 -> 2.2971083 | H7: =Model!V45 -> 0.08721936 | I7: =Model!AA45 -> 0.79897348 | J7: =Model!AF45 -> 0.30432715
A8: ArFi Revenue | F8: =Model!L48 -> 0 | G8: =Model!Q48 -> 0 | H8: =Model!V48 -> 0 | I8: =Model!AA48 -> 1.7430556 | J8: =Model!AF48 -> 0.22640145
A9: ArF Revenue | F9: =Model!L51 -> 0.11647532 | G9: =Model!Q51 -> 0.07361298 | H9: =Model!V51 -> 0.080705382 | I9: =Model!AA51 -> 0.33231295 | J9: =Model!AF51 -> 0.20890774
A10: KrF Revenue | F10: =Model!L54 -> 0.81967715 | G10: =Model!Q54 -> 0.76429364 | H10: =Model!V54 -> 0.7531464 | I10: =Model!AA54 -> 0.63030893 | J10: =Model!AF54 -> 0.58201257
A11: i-line Revenue | F11: =Model!L57 -> 0.012062817 | G11: =Model!Q57 -> 0.017227483 | H11: =Model!V57 -> 0.016695205 | I11: =Model!AA57 -> 0.013288984 | J11: =Model!AF57 -> 0.011938347
A12: Metrology Revenue | F12: =Model!L60 -> 0 | G12: =Model!Q60 -> 0 | H12: =Model!V60 -> 0 | I12: =Model!AA60 -> 0 | J12: =Model!AF60 -> 0
A13: Total Revenue | F13: =SUM(F7:F12) -> 0.80597061 | G13: =SUM(G7:G12) -> 3.1522424 | H13: =SUM(H7:H12) -> 0.93776635 | I13: =SUM(I7:I12) -> 3.5179399 | J13: =SUM(J7:J12) -> 1.3335873
A14: Y/Y Growth % | G14: =G13/F13 - 1 -> 2.9111134 | H14: =H13/G13 - 1 -> -0.70250818 | I14: =I13/H13 - 1 -> 2.7514034 | J14: =J13/I13 - 1 -> -0.62091812
A16: OPERATING MARGINS
A17: Gross Margin % | F17: =Model!L74 -> 0.44334891 | G17: =Model!Q74 -> 0.46056486 | H17: =Model!V74 -> 0.44806322 | I17: =Model!AA74 -> 0.45032476 | J17: =Model!AF74 -> 0.45953947
A18: Operating Margin % | F18: =Model!L89/Model!L67 -> #DIV/0! | G18: =Model!Q89/Model!Q67 -> #DIV/0! | H18: =Model!V89/Model!V67 -> #DIV/0! | I18: =Model!AA89/Model!AA67 -> #DIV/0! | J18: =Model!AF89/Model!AF67 -> #DIV/0!
A21: UFCF BUILD
A22: Revenue | F22: =F13 -> 0.80597061 | G22: =G13 -> 3.1522424 | H22: =H13 -> 0.93776635 | I22: =I13 -> 3.5179399 | J22: =J13 -> 1.3335873
A23: EBIT | F23: =Model!L89 -> 1282.235 | G23: =Model!Q89 -> 1565.135 | H23: =Model!V89 -> 1657.7 | I23: =Model!AA89 -> 2496.2 | J23: =Model!AF89 -> 2965.3
A24: Tax Rate % | F24: 0.14 | G24: 0.14 | H24: 0.14 | I24: 0.14 | J24: 0.14
A25: NOPAT | F25: =F23 * (1 - F24) -> 1102.7221 | G25: =G23 * (1 - G24) -> 1346.0161 | H25: =H23 * (1 - H24) -> 1425.622 | I25: =I23 * (1 - I24) -> 2146.732 | J25: =J23 * (1 - J24) -> 2550.158
A26: D&A | F26: =Model!L113 -> 254.644 | G26: =Model!Q113 -> 296.884 | H26: =Model!V113 -> 356.9 | I26: =Model!AA113 -> 417.5 | J26: =Model!AF113 -> 422.7
A27: CapEx | F27: =F22 * 0.03 -> 0.024179118 | G27: =G22 * 0.03 -> 0.094567273 | H27: =H22 * 0.03 -> 0.028132991 | I27: =I22 * 0.03 -> 0.1055382 | J27: =J22 * 0.03 -> 0.040007618
A28: Change in Working Capital | F28: =F22 * 0.05 -> 0.040298531 | G28: =G22 * 0.05 -> 0.15761212 | H28: =H22 * 0.05 -> 0.046888318 | I28: =I22 * 0.05 -> 0.17589699 | J28: =J22 * 0.05 -> 0.066679363
A29: Unlevered FCF | F29: =F25 + F26 - F27 - F28 -> 1357.3016 | G29: =G25 + G26 - G27 - G28 -> 1642.6479 | H29: =H25 + H26 - H27 - H28 -> 1782.447 | I29: =I25 + I26 - I27 - I28 -> 2563.9506 | J29: =J25 + J26 - J27 - J28 -> 2972.7513
A31: DISCOUNTING
A32: WACC % | F32: 0.085 | G32: 0.085 | H32: 0.085 | I32: 0.085 | J32: 0.085
A33: Discount Factor | F33: =1 / (1 + F32)^1 -> 0.92165899 | G33: =1 / (1 + G32)^2 -> 0.84945529 | H33: =1 / (1 + H32)^3 -> 0.7829081 | I33: =1 / (1 + I32)^4 -> 0.72157428 | J33: =1 / (1 + J32)^5 -> 0.66504542
A34: PV of UFCF | F34: =F29 * F33 -> 1250.9692 | G34: =G29 * G33 -> 1395.356 | H34: =H29 * H33 -> 1395.4922 | I34: =I29 * I33 -> 1850.0808 | J34: =J29 * J33 -> 1977.0147
A36: TERMINAL VALUE
A37: Terminal Growth % | F37: 0.02
A38: Terminal Value | F38: =F29 * (1 + F37) / (F32 - F37) -> 21299.195
A39: PV of TV | F39: =F38 * F33 -> 19630.594
A41: VALUATION
A42: Sum PV UFCF | F42: =SUM(F34:J34) -> 7868.9128
A43: PV Terminal Value | F43: =F39 -> 19630.594
A44: Enterprise Value | F44: =F42 + F43 -> 27499.507
A45: Less: Net Debt | F45: =Model!L700 - Model!L650 -> 0
A46: Equity Value | F46: =F44 - F45 -> 27499.507
A47: Shares Outstanding (mm) | F47: =Model!L750 -> 0
A48: Implied Price | F48: =F46 / F47 -> #DIV/0!
A49: Current Price | F49: ='Front Page'!H20 -> 1217.6
...

Sheet Model
A1: ASML Holdings N.V.
A2: =CHOOSE(MO.DataSourceIndex,MO.Ticker.Bloomberg,MO.Ticker.CapIQ,MO.Ticker.FactSet,MO.Ticker.Thomson) -> ASML NA | C2: =EOMONTH(C4,-12) -> 39813 | BN2: Partial | BO2: Partial
A3: =HP.TradeCurrency -> EUR | B3: =IF(MO.RealTime="OFF",MO.LastPriceHardcoded,MO.LastPriceFormula) -> 1217.6 | C3: =C4-C2 -> 365 | D3: =D4-C4 -> 365 | E3: =E4-D4 -> 365 | F3: =F4-E4 -> 366 | G3: =G4-F4 -> 365 | H3: =H4-G4 -> 89 | I3: =I4-H4 -> 91 | J3: =J4-I4 -> 91 | K3: =K4-J4 -> 94 | L3: =L4-G4 -> 365 | M3: =M4-L4 -> 88 | N3: =N4-M4 -> 91 | O3: =O4-N4 -> 91 | P3: =P4-O4 -> 95 | Q3: =Q4-L4 -> 365 | R3: =R4-Q4 -> 94 | S3: =S4-R4 -> 91 | T3: =T4-S4 -> 91 | U3: =U4-T4 -> 90 | V3: =V4-Q4 -> 366 | W3: =W4-V4 -> 92 | X3: =X4-W4 -> 91 | Y3: =Y4-X4 -> 91 | Z3: =Z4-Y4 -> 91 | AA3: =AA4-V4 -> 365 | AB3: =AB4-AA4 -> 91 | AC3: =AC4-AB4 -> 91 | AD3: =AD4-AC4 -> 91 | AE3: =AE4-AD4 -> 92 | AF3: =AF4-AA4 -> 365 | AG3: =AG4-AF4 -> 90 | AH3: =AH4-AG4 -> 91 | AI3: =AI4-AH4 -> 91 | AJ3: =AJ4-AI4 -> 93 | AK3: =AK4-AF4 -> 365 | AL3: =AL4-AK4 -> 89 | AM3: =AM4-AL4 -> 91 | AN3: =AN4-AM4 -> 91 | AO3: =AO4-AN4 -> 95 | AP3: =AP4-AK4 -> 366 | AQ3: =AQ4-AP4 -> 94 | AR3: =AR4-AQ4 -> 91 | AS3: =AS4-AR4 -> 91 | AT3: =AT4-AS4 -> 89 | AU3: =AU4-AP4 -> 365 | AV3: =AV4-AU4 -> 93 | AW3: =AW4-AV4 -> 91 | AX3: =AX4-AW4 -> 91 | AY3: =AY4-AX4 -> 90 | AZ3: =AZ4-AU4 -> 365 | BA3: =BA4-AZ4 -> 92 | BB3: =BB4-BA4 -> 91 | BC3: =BC4-BB4 -> 91 | BD3: =BD4-BC4 -> 91 | BE3: =BE4-AZ4 -> 365 | BF3: =BF4-BE4 -> 91 | BG3: =BG4-BF4 -> 91 | BH3: =BH4-BG4 -> 91 | BI3: =BI4-BH4 -> 93 | BJ3: =BJ4-BE4 -> 366 | BK3: =BK4-BJ4 -> 89 | BL3: =BL4-BK4 -> 91 | BM3: =BM4-BL4 -> 91 | BN3: =BN4-BM4 -> 94 | BO3: =BO4-BJ4 -> 365 | BP3: =BP4-BO4 -> 90 | BQ3: =BQ4-BP4 -> 91 | BR3: =BR4-BQ4 -> 92 | BS3: =BS4-BR4 -> 92 | BT3: =BT4-BO4 -> 365 | BU3: =BU4-BT4 -> 90 | BV3: =BV4-BU4 -> 91 | BW3: =BW4-BV4 -> 92 | BX3: =BX4-BW4 -> 92 | BY3: =BY4-BT4 -> 365 | BZ3: =BZ4-BY4 -> 366 | CA3: =CA4-BZ4 -> 365 | CB3: =CB4-CA4 -> 365
A4: =FP.DataSourceName -> Bloomberg | B4: =IF(AND(MO.RealTimeStockPriceToggle,MO.LastPriceFormula<>"N/A"),"ON","OFF") -> OFF | C4: 40178 | D4: 40543 | E4: 40908 | F4: 41274 | G4: 41639 | H4: 41728 | I4: 41819 | J4: 41910 | K4: =L4 -> 42004 | L4: 42004 | M4: 42092 | N4: 42183 | O4: 42274 | P4: =Q4 -> 42369 | Q4: 42369 | R4: 42463 | S4: 42554 | T4: 42645 | U4: =V4 -> 42735 | V4: 42735 | W4: 42827 | X4: 42918 | Y4: 43009 | Z4: =AA4 -> 43100 | AA4: 43100 | AB4: 43191 | AC4: 43282 | AD4: 43373 | AE4: =AF4 -> 43465 | AF4: 43465 | AG4: 43555 | AH4: 43646 | AI4: 43737 | AJ4: =AK4 -> 43830 | AK4: 43830 | AL4: 43919 | AM4: 44010 | AN4: 44101 | AO4: =AP4 -> 44196 | AP4: 44196 | AQ4: 44290 | AR4: 44381 | AS4: 44472 | AT4: =AU4 -> 44561 | AU4: 44561 | AV4: 44654 | AW4: 44745 | AX4: 44836 | AY4: =AZ4 -> 44926 | AZ4: 44926 | BA4: 45018 | BB4: 45109 | BC4: 45200 | BD4: =BE4 -> 45291 | BE4: 45291 | BF4: 45382 | BG4: 45473 | BH4: 45564 | BI4: =BJ4 -> 45657 | BJ4: 45657 | BK4: 45746 | BL4: 45837 | BM4: 45928 | BN4: =BO4 -> 46022 | BO4: 46022 | BP4: =+EDATE(BO4,3) -> 46112 | BQ4: =+EDATE(BP4,3) -> 46203 | BR4: =+EDATE(BQ4,3) -> 46295 | BS4: =DATE(YEAR(BR4),12,31) -> 46387 | BT4: =BS4 -> 46387 | BU4: =+EDATE(BT4,3) -> 46477 | BV4: =+EDATE(BU4,3) -> 46568 | BW4: =+EDATE(BV4,3) -> 46660 | BX4: =DATE(YEAR(BW4),12,31) -> 46752 | BY4: =BX4 -> 46752 | BZ4: =EOMONTH(BY4,12) -> 47118 | CA4: =EOMONTH(BZ4,12) -> 47483 | CB4: =EOMONTH(CA4,12) -> 47848
A5: =MO.ReportCurrency -> EUR | C5: FY2009 | D5: =CONCATENATE("FY",RIGHT(C5,4)+1) -> FY2010 | E5: =CONCATENATE("FY",RIGHT(D5,4)+1) -> FY2011 | F5: =CONCATENATE("FY",RIGHT(E5,4)+1) -> FY2012 | G5: =CONCATENATE("FY",RIGHT(F5,4)+1) -> FY2013 | H5: =CONCATENATE("Q1","-",RIGHT(G5,4)+1) -> Q1-2014 | I5: =CONCATENATE("Q2","-",RIGHT(H5,4)) -> Q2-2014 | J5: =CONCATENATE("Q3","-",RIGHT(I5,4)) -> Q3-2014 | K5: =CONCATENATE("Q4","-",RIGHT(J5,4)) -> Q4-2014 | L5: =CONCATENATE("FY",RIGHT(G5,4)+1) -> FY2014 | M5: =CONCATENATE("Q1","-",RIGHT(L5,4)+1) -> Q1-2015 | N5: =CONCATENATE("Q2","-",RIGHT(M5,4)) -> Q2-2015 | O5: =CONCATENATE("Q3","-",RIGHT(N5,4)) -> Q3-2015 | P5: =CONCATENATE("Q4","-",RIGHT(O5,4)) -> Q4-2015 | Q5: =CONCATENATE("FY",RIGHT(L5,4)+1) -> FY2015 | R5: =CONCATENATE("Q1","-",RIGHT(Q5,4)+1) -> Q1-2016 | S5: =CONCATENATE("Q2","-",RIGHT(R5,4)) -> Q2-2016 | T5: =CONCATENATE("Q3","-",RIGHT(S5,4)) -> Q3-2016 | U5: =CONCATENATE("Q4","-",RIGHT(T5,4)) -> Q4-2016 | V5: =CONCATENATE("FY",RIGHT(Q5,4)+1) -> FY2016 | W5: =CONCATENATE("Q1","-",RIGHT(V5,4)+1) -> Q1-2017 | X5: =CONCATENATE("Q2","-",RIGHT(W5,4)) -> Q2-2017 | Y5: =CONCATENATE("Q3","-",RIGHT(X5,4)) -> Q3-2017 | Z5: =CONCATENATE("Q4","-",RIGHT(Y5,4)) -> Q4-2017 | AA5: =CONCATENATE("FY",RIGHT(V5,4)+1) -> FY2017 | AB5: =CONCATENATE("Q1","-",RIGHT(AA5,4)+1) -> Q1-2018 | AC5: =CONCATENATE("Q2","-",RIGHT(AB5,4)) -> Q2-2018 | AD5: =CONCATENATE("Q3","-",RIGHT(AC5,4)) -> Q3-2018 | AE5: =CONCATENATE("Q4","-",RIGHT(AD5,4)) -> Q4-2018 | AF5: =CONCATENATE("FY",RIGHT(AA5,4)+1) -> FY2018 | AG5: =CONCATENATE("Q1","-",RIGHT(AF5,4)+1) -> Q1-2019 | AH5: =CONCATENATE("Q2","-",RIGHT(AG5,4)) -> Q2-2019 | AI5: =CONCATENATE("Q3","-",RIGHT(AH5,4)) -> Q3-2019 | AJ5: =CONCATENATE("Q4","-",RIGHT(AI5,4)) -> Q4-2019 | AK5: =CONCATENATE("FY",RIGHT(AF5,4)+1) -> FY2019 | AL5: =CONCATENATE("Q1","-",RIGHT(AK5,4)+1) -> Q1-2020 | AM5: =CONCATENATE("Q2","-",RIGHT(AL5,4)) -> Q2-2020 | AN5: =CONCATENATE("Q3","-",RIGHT(AM5,4)) -> Q3-2020 | AO5: =CONCATENATE("Q4","-",RIGHT(AN5,4)) -> Q4-2020 | AP5: =CONCATENATE("FY",RIGHT(AK5,4)+1) -> FY2020 | AQ5: =CONCATENATE("Q1","-",RIGHT(AP5,4)+1) -> Q1-2021 | AR5: =CONCATENATE("Q2","-",RIGHT(AQ5,4)) -> Q2-2021 | AS5: =CONCATENATE("Q3","-",RIGHT(AR5,4)) -> Q3-2021 | AT5: =CONCATENATE("Q4","-",RIGHT(AS5,4)) -> Q4-2021 | AU5: =CONCATENATE("FY",RIGHT(AP5,4)+1) -> FY2021 | AV5: =CONCATENATE("Q1","-",RIGHT(AU5,4)+1) -> Q1-2022 | AW5: =CONCATENATE("Q2","-",RIGHT(AV5,4)) -> Q2-2022 | AX5: =CONCATENATE("Q3","-",RIGHT(AW5,4)) -> Q3-2022 | AY5: =CONCATENATE("Q4","-",RIGHT(AX5,4)) -> Q4-2022 | AZ5: =CONCATENATE("FY",RIGHT(AU5,4)+1) -> FY2022 | BA5: =CONCATENATE("Q1","-",RIGHT(AZ5,4)+1) -> Q1-2023 | BB5: =CONCATENATE("Q2","-",RIGHT(BA5,4)) -> Q2-2023 | BC5: =CONCATENATE("Q3","-",RIGHT(BB5,4)) -> Q3-2023 | BD5: =CONCATENATE("Q4","-",RIGHT(BC5,4)) -> Q4-2023 | BE5: =CONCATENATE("FY",RIGHT(AZ5,4)+1) -> FY2023 | BF5: =CONCATENATE("Q1","-",RIGHT(BE5,4)+1) -> Q1-2024 | BG5: =CONCATENATE("Q2","-",RIGHT(BF5,4)) -> Q2-2024 | BH5: =CONCATENATE("Q3","-",RIGHT(BG5,4)) -> Q3-2024 | BI5: =CONCATENATE("Q4","-",RIGHT(BH5,4)) -> Q4-2024 | BJ5: =CONCATENATE("FY",RIGHT(BE5,4)+1) -> FY2024 | BK5: =CONCATENATE("Q1","-",RIGHT(BJ5,4)+1) -> Q1-2025 | BL5: =CONCATENATE("Q2","-",RIGHT(BK5,4)) -> Q2-2025 | BM5: =CONCATENATE("Q3","-",RIGHT(BL5,4)) -> Q3-2025 | BN5: =CONCATENATE("Q4","-",RIGHT(BM5,4)) -> Q4-2025 | BO5: =CONCATENATE("FY",RIGHT(BJ5,4)+1) -> FY2025 | BP5: =CONCATENATE("Q1","-",RIGHT(BO5,4)+1) -> Q1-2026 | BQ5: =CONCATENATE("Q2","-",RIGHT(BP5,4)) -> Q2-2026 | BR5: =CONCATENATE("Q3","-",RIGHT(BQ5,4)) -> Q3-2026 | BS5: =CONCATENATE("Q4","-",RIGHT(BR5,4)) -> Q4-2026 | BT5: =CONCATENATE("FY",RIGHT(BO5,4)+1) -> FY2026 | BU5: =CONCATENATE("Q1","-",RIGHT(BT5,4)+1) -> Q1-2027 | BV5: =CONCATENATE("Q2","-",RIGHT(BU5,4)) -> Q2-2027 | BW5: =CONCATENATE("Q3","-",RIGHT(BV5,4)) -> Q3-2027 | BX5: =CONCATENATE("Q4","-",RIGHT(BW5,4)) -> Q4-2027 | BY5: =CONCATENATE("FY",RIGHT(BT5,4)+1) -> FY2027 | BZ5: =CONCATENATE("FY",RIGHT(BY5,4)+1) -> FY2028 | CA5: =CONCATENATE("FY",RIGHT(BZ5,4)+1) -> FY2029 | CB5: =CONCATENATE("FY",RIGHT(CA5,4)+1) -> FY2030
A6: Revenue Build
A7: EUV 3400C units sold, # of units | AI7: 3 | AJ7: 6 | AK7: 9
A8: EUV 3400B units sold, # of units | AG8: 4 | AH8: 7 | AI8: =AI11-AI7 -> 4 | AJ8: =+AJ11-AJ7 -> 2 | AK8: =+AK11-AK7 -> 17
A9: High NA EUV, # of units | BI9: 2 | BJ9: 2 | BK9: 3 | BN9: 2 | BO9: =SUM(BK9,BL9,BM9,BN9) -> 5
A10: Low NA EUV, # of units | BH10: =BH11-BH9 -> 11 | BI10: =BI11-BI9 -> 12 | BJ10: =BJ11-BJ9 -> 42 | BK10: =BK11-BK9 -> 11 | BN10: =BN11-BN9 -> 12 | BO10: =BO11-BO9 -> 43
A11: EUV units sold, # of units | E11: 3 | F11: 1 | G11: 1 | H11: 1 | I11: 1 | J11: 2 | K11: 1 | L11: 5 | M11: 0 | N11: 1 | O11: 0 | P11: 0 | Q11: 1 | R11: 0 | S11: 2 | T11: 1 | U11: 1 | V11: 4 | W11: 0 | X11: 2 | Y11: 4 | Z11: 5 | AA11: 11 | AB11: 1 | AC11: 7 | AD11: 5 | AE11: 5 | AF11: 18 | AG11: =SUM(AG7:AG8) -> 4 | AH11: =SUM(AH7:AH8) -> 7 | AI11: 7 | AJ11: 8 | AK11: 26 | AL11: 2 | AM11: 7 | AN11: 14 | AO11: 8 | AP11: 31 | AQ11: 7 | AR11: 9 | AS11: 15 | AT11: 11 | AU11: 42 | AV11: 3 | AW11: 12 | AX11: 12 | AY11: 13 | AZ11: 40 | BA11: 17 | BB11: 12 | BC11: 11 | BD11: 13 | BE11: 53 | BF11: 11 | BG11: 8 | BH11: 11 | BI11: 14 | BJ11: 44 | BK11: 14 | BL11: 11 | BM11: 9 | BN11: 14 | BO11: 48 | BP11: 13 | BQ11: 13 | BR11: 15 | BS11: 15 | BT11: =SUM(BP11,BQ11,BR11,BS11) -> 56 | BU11: 13 | BV11: 13 | BW11: 15 | BX11: 15 | BY11: =SUM(BU11,BV11,BW11,BX11) -> 56 | BZ11: 65 | CA11: 65 | CB11: 65
A12: ArFi units sold, # of units | E12: 101 | F12: 72 | G12: 77 | H12: 19 | I12: 24 | J12: 13 | K12: 20 | L12: 76 | M12: 23 | N12: 19 | O12: 14 | P12: 11 | Q12: 67 | R12: 15 | S12: 19 | T12: 19 | U12: 17 | V12: 70 | W12: 18 | X12: 16 | Y12: 22 | Z12: 20 | AA12: 76 | AB12: 21 | AC12: 19 | AD12: 22 | AE12: 24 | AF12: 86 | AG12: 17 | AH12: 13 | AI12: 21 | AJ12: 31 | AK12: 82 | AL12: 16 | AM12: 17 | AN12: 11 | AO12: 24 | AP12: 68 | AQ12: 24 | AR12: 16 | AS12: 21 | AT12: 20 | AU12: 81 | AV12: 18 | AW12: 21 | AX12: 20 | AY12: 22 | AZ12: 81 | BA12: 25 | BB12: 39 | BC12: 32 | BD12: 29 | BE12: 125 | BF12: 20 | BG12: 32 | BH12: 38 | BI12: 39 | BJ12: 129 | BK12: 25 | BL12: 31 | BM12: 38 | BN12: 37 | BO12: 131 | BP12: 20 | BQ12: 20 | BR12: 21 | BS12: 20 | BT12: =SUM(BP12,BQ12,BR12,BS12) -> 81 | BU12: 20 | BV12: 20 | BW12: 21 | BX12: 20 | BY12: =SUM(BU12,BV12,BW12,BX12) -> 81 | BZ12: 80 | CA12: 80 | CB12: 80
A13: ArF units sold, # of units | E13: 11 | F13: 4 | G13: 2 | H13: 0 | I13: 2 | J13: 0 | K13: 1 | L13: 3 | M13: 2 | N13: 2 | O13: 2 | P13: 3 | Q13: 9 | R13: 2 | S13: 2 | T13: 1 | U13: 1 | V13: 6 | W13: 4 | X13: 3 | Y13: 2 | Z13: 5 | AA13: 14 | AB13: 3 | AC13: 5 | AD13: 3 | AE13: 5 | AF13: 16 | AG13: 4 | AH13: 3 | AI13: 9 | AJ13: 6 | AK13: 22 | AL13: 6 | AM13: 7 | AN13: 2 | AO13: 7 | AP13: 22 | AQ13: 4 | AR13: 7 | AS13: 6 | AT13: 5 | AU13: 22 | AV13: 6 | AW13: 8 | AX13: 6 | AY13: 8 | AZ13: 28 | BA13: 7 | BB13: 6 | BC13: 9 | BD13: 10 | BE13: 32 | BF13: 4 | BG13: 11 | BH13: 7 | BI13: 6 | BJ13: 28 | BK13: 3 | BL13: 4 | BM13: 4 | BN13: 5 | BO13: 16 | BP13: 8 | BQ13: 8 | BR13: 8 | BS13: 8 | BT13: =SUM(BP13,BQ13,BR13,BS13) -> 32 | BU13: 8 | BV13: 8 | BW13: 8 | BX13: 8 | BY13: =SUM(BU13,BV13,BW13,BX13) -> 32 | BZ13: 32 | CA13: 32 | CB13: 32
A14: KrF units sold, # of units | E14: 87 | F14: 78 | G14: 64 | H14: 17 | I14: 2 | J14: 10 | K14: 10 | L14: 38 | M14: 16 | N14: 14 | O14: 24 | P14: 20 | Q14: 74 | R14: 12 | S14: 16 | T14: 14 | U14: 15 | V14: 57 | W14: 19 | X14: 14 | Y14: 18 | Z14: 20 | AA14: 71 | AB14: 19 | AC14: 19 | AD14: 18 | AE14: 22 | AF14: 78 | AG14: 14 | AH14: 19 | AI14: 14 | AJ14: 18 | AK14: 65 | AL14: 22 | AM14: 23 | AN14: 23 | AO14: 35 | AP14: 103 | AQ14: 35 | AR14: 31 | AS14: 30 | AT14: 35 | AU14: 131 | AV14: 26 | AW14: 38 | AX14: 38 | AY14: 49 | AZ14: 151 | BA14: 43 | BB14: 43 | BC14: 44 | BD14: 54 | BE14: 184 | BF14: 25 | BG14: 33 | BH14: 42 | BI14: 52 | BJ14: 152 | BK14: 22 | BL14: 16 | BM14: 11 | BN14: 29 | BO14: 78 | BP14: 40 | BQ14: 40 | BR14: 40 | BS14: 40 | BT14: =SUM(BP14,BQ14,BR14,BS14) -> 160 | BU14: 40 | BV14: 40 | BW14: 40 | BX14: 40 | BY14: =SUM(BU14,BV14,BW14,BX14) -> 160 | BZ14: 160 | CA14: 160 | CB14: 160
A15: i-line units sold, # of units | E15: 20 | F15: 15 | G15: 13 | H15: 3 | I15: 2 | J15: 5 | K15: 3 | L15: 14 | M15: 6 | N15: 5 | O15: 4 | P15: 3 | Q15: 18 | R15: 4 | S15: 7 | T15: 5 | U15: 4 | V15: 20 | W15: 3 | X15: 7 | Y15: 9 | Z15: 7 | AA15: 26 | AB15: 5 | AC15: 8 | AD15: 5 | AE15: 8 | AF15: 26 | AG15: 9 | AH15: 6 | AI15: 6 | AJ15: 13 | AK15: 34 | AL15: 11 | AM15: 7 | AN15: 10 | AO15: 6 | AP15: 34 | AQ15: 6 | AR15: 9 | AS15: 7 | AT15: 11 | AU15: 33 | AV15: 9 | AW15: 12 | AX15: 10 | AY15: 14 | AZ15: 45 | BA15: 8 | BB15: 13 | BC15: 16 | BD15: 18 | BE15: 55 | BF15: 10 | BG15: 16 | BH15: 18 | BI15: 21 | BJ15: 65 | BK15: 13 | BL15: 14 | BM15: 10 | BN15: 17 | BO15: 54 | BP15: 8 | BQ15: 8 | BR15: 8 | BS15: 8 | BT15: =SUM(BP15,BQ15,BR15,BS15) -> 32 | BU15: 8 | BV15: 8 | BW15: 8 | BX15: 8 | BY15: =SUM(BU15,BV15,BW15,BX15) -> 32 | BZ15: 32 | CA15: 32 | CB15: 32
A16: Total net lithography systems sold, # of units | C16: 70 | D16: 197 | E16: =SUM(E11:E15) -> 222 | F16: =SUM(F11:F15) -> 170 | G16: =SUM(G11:G15) -> 157 | H16: =SUM(H11:H15) -> 40 | I16: =SUM(I11:I15) -> 31 | J16: =SUM(J11:J15) -> 30 | K16: =SUM(K11:K15) -> 35 | L16: =SUM(L11:L15) -> 136 | ... CB16: =SUM(CB11:CB15) -> 369
A17: Metrology & Inspection units sold, # of units | Q17: 45 | V17: 55 | AA17: 95 | AF17: 114 | AK17: 115 | AP17: 137 | AU17: 196 | AZ17: 216 | BA17: 37 | BB17: 37 | BC17: 37 | BD17: =BE17-SUM(BA17,BB17,BC17) -> 40 | BE17: 151 | BF17: 40 | BG17: 40 | BH17: 40 | BI17: =BJ17-SUM(BF17,BG17,BH17) -> 45 | BJ17: 165 | BK17: 45 | BL17: 45 | BM17: 45 | BN17: =BO17-SUM(BK17,BL17,BM17) -> 45 | BO17: 180 | BP17: 50 | BQ17: 50 | BR17: 50 | BS17: 50 | BT17: =IF(OR(ISBLANK(BP17),ISBLANK(BQ17),ISBLANK(BR17),ISBLANK(BS17)),"n/a",SUM(BP17,BQ17,BR17,BS17)) -> 200 | BU17: 50 | BV17: 50 | BW17: 50 | BX17: 50 | BY17: =IF(OR(ISBLANK(BU17),ISBLANK(BV17),ISBLANK(BW17),ISBLANK(BX17)),"n/a",SUM(BU17,BV17,BW17,BX17)) -> 200 | BZ17: 200 | CA17: 200 | CB17: 200
A18: Total net system sold, # of units | Q18: =Q16+Q17 -> 214 | V18: =V16+V17 -> 212 | AA18: =AA16+AA17 -> 293 | AF18: =AF16+AF17 -> 338 | AK18: =AK16+AK17 -> 344 | AP18: =AP16+AP17 -> 395 | AU18: =AU16+AU17 -> 505 | AZ18: =AZ16+AZ17 -> 561 | BA18: =BA16+BA17 -> 137 | BB18: =BB16+BB17 -> 150 | BC18: =BC16+BC17 -> 149 | BD18: =BD16+BD17 -> 164 | BE18: =BE16+BE17 -> 600 | BF18: =BF16+BF17 -> 110 | BG18: =BG16+BG17 -> 140 | ... CB18: =CB16+CB17 -> 569
A20: EUV unit price, 000 EUR/unit | E20: =IFERROR(+E33*1000/E11,"n/a") -> 39766.667 | F20: =IFERROR(+F33*1000/F11,"n/a") -> 43700 | G20: =IFERROR(+G33*1000/G11,"n/a") -> 60100 | H20: =IFERROR(+H33*1000/H11,"n/a") -> 61800 | I20: =IFERROR(+I33*1000/I11,"n/a") -> 62150 | J20: =IFERROR(+J33*1000/J11,"n/a") -> 61915 | K20: =IFERROR(+K33*1000/K11,"n/a") -> 65118 | L20: =IFERROR(+L33*1000/L11,"n/a") -> 59969 | ... BO20: =IFERROR(+BO33*1000/BO11,"n/a") -> 242739.92 | BP20: =BK20*(1+BP21) -> 252577.6 | BQ20: =BL20*(1+BQ21) -> 293032.15 | BR20: =BM20*(1+BR21) -> 281392.53 | BS20: =BN20*(1+BS21) -> 312027.43 | BT20: =IFERROR(+BT33*1000/BT11,"n/a") -> 285611.18 | BU20: =BP20*(1+BU21) -> 290464.24 | BV20: =BQ20*(1+BV21) -> 322335.36 | BW20: =BR20*(1+BW21) -> 309531.79 | BX20: =BS20*(1+BX21) -> 343230.17 | BY20: =IFERROR(+BY33*1000/BY11,"n/a") -> 317104 | BZ20: =BY20*(1+BZ21) -> 380524.8 | CA20: =BZ20*(1+CA21) -> 399551.04 | CB20: =CA20*(1+CB21) -> 419528.6
A21: Y/Y EUV unit price growth, % | F21: =F20/E20-1 -> 0.09891031 | G21: =G20/F20-1 -> 0.37528604 | L21: =L20/G20-1 -> -0.0021797005 | N21: =N20/I20-1 -> 0.095253419 | Q21: =Q20/L20-1 -> 0.17515716 | S21: =S20/N20-1 -> -0.25641252 | V21: =V20/Q20-1 -> 0.15256907 | X21: =X20/S20-1 -> 1.1876087 | Y21: =Y20/T20-1 -> 0.084658504 | Z21: =Z20/U20-1 -> -0.31068892 | AA21: =AA20/V20-1 -> 0.23282688 | AC21: =AC20/X20-1 -> -0.13858412 | AD21: =AD20/Y20-1 -> 0.089407779 | AE21: =AE20/Z20-1 -> 0.19051 | AF21: =AF20/AA20-1 -> 0.043077621 | AG21: =AG20/AB20-1 -> -0.20425051 | AH21: =AH20/AC20-1 -> 0.1365145 | AI21: =AI20/AD20-1 -> 0.021946966 | AJ21: =AJ20/AE20-1 -> -0.024705585 | ... BO21: =BO20/BJ20-1 -> 0.28350474 | BP21: 0.1 | BQ21: 0.2 | BR21: 0.2 | BS21: 0.2 | BT21: =BT20/BO20-1 -> 0.17661399 | BU21: 0.15 | BV21: 0.1 | BW21: 0.1 | BX21: 0.1 | BY21: =BY20/BT20-1 -> 0.11026467 | BZ21: 0.2 | CA21: 0.05 | CB21: 0.05
A22: ArFi unit price, 000 EUR/unit | E22: =IFERROR(+E34*1000/E12,"n/a") -> 35139.822 | F22: =IFERROR(+F34*1000/F12,"n/a") -> 37711.403 | G22: =IFERROR(+G34*1000/G12,"n/a") -> 40528.818 | H22: =IFERROR(+H34*1000/H12,"n/a") -> 41200 | I22: =IFERROR(+I34*1000/I12,"n/a") -> 47130.417 | J22: =IFERROR(+J34*1000/J12,"n/a") -> 48987.692 | K22: =IFERROR(+K34*1000/K12,"n/a") -> 45039.95 | L22: =IFERROR(+L34*1000/L12,"n/a") -> 45759.447 | ... BO22: =IFERROR(+BO34*1000/BO12,"n/a") -> 78032.298 | BP22: =BK22*(1+BP23) -> 87139.272 | BQ22: =BL22*(1+BQ23) -> 89266.821 | BR22: =BM22*(1+BR23) -> 87399.274 | BS22: =BN22*(1+BS23) -> 94287.568 | BT22: =IFERROR(+BT34*1000/BT12,"n/a") -> 89497.012 | BU22: =BP22*(1+BU23) -> 78425.345 | BV22: =BQ22*(1+BV23) -> 80340.139 | BW22: =BR22*(1+BW23) -> 94391.216 | BX22: =BS22*(1+BX23) -> 101830.57 | BY22: =IFERROR(+BY34*1000/BY12,"n/a") -> 88816.502 | BZ22: =BY22*(1+BZ23) -> 96272.405 | CA22: =BZ22*(1+CA23) -> 104354.21 | CB22: =CA22*(1+CB23) -> 113114.46
A23: Y/Y ArFi unit price growth, % | F23: =F22/E22-1 -> 0.07318139 | G23: =G22/F22-1 -> 0.074709907 | L23: =L22/G22-1 -> 0.1290595 | M23: =M22/H22-1 -> 0.091805614 | N23: =N22/I22-1 -> 0.00086778615 | O23: =O22/J22-1 -> -0.032987429 | P23: =P22/K22-1 -> 0.28017258 | Q23: =Q22/L22-1 -> 0.056286893 | R23: =R22/M22-1 -> 0.0066783621 | S23: =S22/N22-1 -> 0.073024976 | ... BO23: =BO22/BJ22-1 -> 0.041291652 | BP23: 0.15 | BQ23: 0.15 | BR23: 0.15 | BS23: 0.15 | BT23: =BT22/BO22-1 -> 0.14692268 | BU23: -0.1 | BV23: -0.1 | BW23: 0.08 | BX23: 0.08 | BY23: =BY22/BT22-1 -> -0.0076037159 | BZ23: 0.083947268 | CA23: 0.083947268 | CB23: 0.083947268
A24: ArF unit price, 000 EUR/unit | E24: =IFERROR(+E35*1000/E13,"n/a") -> 20809.909 | F24: =IFERROR(+F35*1000/F13,"n/a") -> 20357 | G24: =IFERROR(+G35*1000/G13,"n/a") -> 19009.5 | H24: =IFERROR(+H35*1000/H13,"n/a") -> n/a | I24: =IFERROR(+I35*1000/I13,"n/a") -> 6215 | J24: =IFERROR(+J35*1000/J13,"n/a") -> n/a | K24: =IFERROR(+K35*1000/K13,"n/a") -> 10853 | L24: =IFERROR(+L35*1000/L13,"n/a") -> 10870.333 | ... BO24: =IFERROR(+BO35*1000/BO13,"n/a") -> 30592.875 | BP24: =BK24*(1+BP25) -> 42096.267 | BQ24: =BL24*(1+BQ25) -> 32177.575 | BR24: =BM24*(1+BR25) -> 31934.35 | BS24: =BN24*(1+BS25) -> 34886.4 | BT24: =IFERROR(+BT35*1000/BT13,"n/a") -> 35273.648 | BU24: =BP24*(1+BU25) -> 42306.748 | BV24: =BQ24*(1+BV25) -> 32338.463 | BW24: =BR24*(1+BW25) -> 32094.022 | BX24: =BS24*(1+BX25) -> 35060.832 | BY24: =IFERROR(+BY35*1000/BY13,"n/a") -> 35450.016 | BZ24: =BY24*(1+BZ25) -> 35661.364 | CA24: =BZ24*(1+CA25) -> 35873.973 | CB24: =CA24*(1+CB25) -> 36087.848
A25: Y/Y ArF unit price growth, % | F25: =F24/E24-1 -> -0.021764107 | G25: =G24/F24-1 -> -0.066193447 | L25: =L24/G24-1 -> -0.42816311 | N25: =N24/I24-1 -> -0.087288817 | P25: =P24/K24-1 -> -0.18833502 | Q25: =Q24/L24-1 -> 0.099036113 | R25: =R24/M24-1 -> 0.14961893 | S25: =S24/N24-1 -> 2.3461437 | T25: =T24/O24-1 -> 0.71940258 | U25: =U24/P24-1 -> 1.9267794 | V25: =V24/Q24-1 -> 0.63082904 | W25: =W24/R24-1 -> -0.29297511 | ... BO25: =BO24/BJ24-1 -> 0.10614734 | BP25: 0.1 | BQ25: 0.15 | BR25: 0.15 | BS25: 0.15 | BT25: =BT24/BO24-1 -> 0.15300206 | BU25: 0.005 | BV25: 0.005 | BW25: 0.005 | BX25: 0.005 | BY25: =BY24/BT24-1 -> 0.005 | BZ25: 0.005961866 | CA25: 0.005961866 | CB25: 0.005961866
A26: KrF unit price, 000 EUR/unit | E26: =IFERROR(+E36*1000/E14,"n/a") -> 10650.253 | F26: =IFERROR(+F36*1000/F14,"n/a") -> 11644.154 | G26: =IFERROR(+G36*1000/G14,"n/a") -> 11250.828 | H26: =IFERROR(+H36*1000/H14,"n/a") -> 10300 | I26: =IFERROR(+I36*1000/I14,"n/a") -> 12430 | J26: =IFERROR(+J36*1000/J14,"n/a") -> 10614 | K26: =IFERROR(+K36*1000/K14,"n/a") -> 9767.7 | L26: =IFERROR(+L36*1000/L14,"n/a") -> 10037.789 | ... BO26: =IFERROR(+BO36*1000/BO14,"n/a") -> 13547.154 | BP26: =BK26*(1+BP27) -> 14351 | BQ26: =BL26*(1+BQ27) -> 16088.788 | BR26: =BM26*(1+BR27) -> 17418.736 | BS26: =BN26*(1+BS27) -> 15037.241 | BT26: =IFERROR(+BT36*1000/BT14,"n/a") -> 15723.941 | BU26: =BP26*(1+BU27) -> 12915.9 | BV26: =BQ26*(1+BV27) -> 14479.909 | BW26: =BR26*(1+BW27) -> 16547.8 | BX26: =BS26*(1+BX27) -> 14285.379 | BY26: =IFERROR(+BY36*1000/BY14,"n/a") -> 14557.247 | BZ26: =BY26*(1+BZ27) -> 15744.006 | CA26: =BZ26*(1+CA27) -> 17027.515 | CB26: =CA26*(1+CB27) -> 18415.659
A27: Y/Y KrF unit price growth, % | F27: =F26/E26-1 -> 0.093321819 | G27: =G26/F26-1 -> -0.033778815 | L27: =L26/G26-1 -> -0.10781772 | M27: =M26/H26-1 -> -0.092354369 | N27: =N26/I26-1 -> -0.21767613 | O27: =O26/J26-1 -> 0.033740814 | P27: =P26/K26-1 -> 0.037127471 | Q27: =Q26/L26-1 -> 0.0066553618 | R27: =R26/M26-1 -> 0.072977671 | S27: =S26/N26-1 -> -0.10537131 | ... BO27: =BO26/BJ26-1 -> 0.034133881 | BP27: 0.1 | BQ27: 0.15 | BR27: 0.15 | BS27: 0.15 | BT27: =BT26/BO26-1 -> 0.16068227 | BU27: -0.1 | BV27: -0.1 | BW27: -0.05 | BX27: -0.05 | BY27: =BY26/BT26-1 -> -0.074198599 | BZ27: 0.081523618 | CA27: 0.081523618 | CB27: 0.081523618
A28: i-line unit price, 000 EUR/unit | E28: =IFERROR(+E37*1000/E15,"n/a") -> 3000.5 | F28: =IFERROR(+F37*1000/F15,"n/a") -> 3535.9333 | G28: =IFERROR(+G37*1000/G15,"n/a") -> 4172.1538 | H28: =IFERROR(+H37*1000/H15,"n/a") -> 3433.3333 | I28: =IFERROR(+I37*1000/I15,"n/a") -> 6215 | J28: =IFERROR(+J37*1000/J15,"n/a") -> 3538 | K28: =IFERROR(+K37*1000/K15,"n/a") -> 3617.6667 | L28: =IFERROR(+L37*1000/L15,"n/a") -> 3655.7143 | ... BO28: =IFERROR(+BO37*1000/BO15,"n/a") -> 4532.2778 | BP28: =BK28*(1+BP29) -> 5078.0462 | BQ28: =BL28*(1+BQ29) -> 4596.7964 | BR28: =BM28*(1+BR29) -> 6386.87 | BS28: =BN28*(1+BS29) -> 5130.3529 | BT28: =IFERROR(+BT37*1000/BT15,"n/a") -> 5298.0164 | BU28: =BP28*(1+BU29) -> 5839.7531 | BV28: =BQ28*(1+BV29) -> 5286.3159 | BW28: =BR28*(1+BW29) -> 7344.9005 | BX28: =BS28*(1+BX29) -> 5899.9059 | BY28: =IFERROR(+BY37*1000/BY15,"n/a") -> 6092.7188 | BZ28: =BY28*(1+BZ29) -> 7006.6267 | CA28: =BZ28*(1+CA29) -> 8057.6207 | CB28: =CA28*(1+CB29) -> 9266.2638
A29: Y/Y i-line unit price growth, % | F29: =F28/E28-1 -> 0.17844804 | G29: =G28/F28-1 -> 0.17993001 | L29: =L28/G28-1 -> -0.12378248 | M29: =M28/H28-1 -> 0.21019417 | N29: =N28/I28-1 -> -0.26983105 | O29: =O28/J28-1 -> 0.37832109 | P29: =P28/K28-1 -> 0.62332995 | Q29: =Q28/L28-1 -> 0.10931353 | R29: =R28/M28-1 -> 0.03465704 | S29: =S28/N28-1 -> -0.20329912 | ... BO29: =BO28/BJ28-1 -> -0.20206377 | BP29: 0.15 | BQ29: 0.15 | BR29: 0.15 | BS29: 0.15 | BT29: =BT28/BO28-1 -> 0.16895227 | BU29: 0.15 | BV29: 0.15 | BW29: 0.15 | BX29: 0.15 | BY29: =BY28/BT28-1 -> 0.15 | BZ29: 0.15 | CA29: 0.15 | CB29: 0.15
A30: Metrology & Inspection unit price, 000 EUR/unit | V30: =IFERROR(+V38/V17*1000,"n/a") -> 1832.7273 | AA30: =IFERROR(+AA38/AA17*1000,"n/a") -> 2910.5263 | AF30: =IFERROR(+AF38/AF17*1000,"n/a") -> 2974.5614 | AK30: =IFERROR(+AK38/AK17*1000,"n/a") -> 2386.087 | AP30: =IFERROR(+AP38/AP17*1000,"n/a") -> 2555.4745 | AU30: =IFERROR(+AU38/AU17*1000,"n/a") -> 2620.9184 | AZ30: =IFERROR(+AZ38/AZ17*1000,"n/a") -> 3053.7037 | BA30: =BA38/BA17*1000 -> 4331.1892 | BB30: =BB38/BB17*1000 -> 3030.3243 | BC30: =BC38/BC17*1000 -> 2869.2973 | BD30: =BD38/BD17*1000 -> 4261.875 | BE30: =IFERROR(+BE38/BE17*1000,"n/a") -> 3550.3311 | BF30: =BF38/BF17*1000 -> 2974.425 | BG30: =BG38/BG17*1000 -> 1190.225 | BH30: =BH38/BH17*1000 -> 2963 | BI30: =BI38/BI17*1000 -> 6325.2444 | BJ30: =IFERROR(+BJ38/BJ17*1000,"n/a") -> 3912.1212 | BK30: =BK38/BK17*1000 -> 3826.9333 | BL30: =BL38/BL17*1000 -> 2487.1556 | BM30: =BM38/BM17*1000 -> 4936.7111 | BN30: =BN38/BN17*1000 -> 6741.3333 | BO30: =IFERROR(+BO38/BO17*1000,"n/a") -> 4498.0333 | BP30: =BK30*(1+BP31) -> 4209.6267 | BQ30: =BL30*(1+BQ31) -> 2611.5133 | BR30: =BM30*(1+BR31) -> 5183.5467 | BS30: =BN30*(1+BS31) -> 7078.4 | BT30: =IFERROR(+BT38/BT17*1000,"n/a") -> 4770.7717 | BU30: =BP30*(1+BU31) -> 4420.108 | BV30: =BQ30*(1+BV31) -> 2742.089 | BW30: =BR30*(1+BW31) -> 5442.724 | BX30: =BS30*(1+BX31) -> 7432.32 | BY30: =IFERROR(+BY38/BY17*1000,"n/a") -> 5009.3103 | BZ30: =BY30*(1+BZ31) -> 5259.7758 | CA30: =BZ30*(1+CA31) -> 5522.7646 | CB30: =CA30*(1+CB31) -> 5798.9028
A31: Metrology & Inspection unit price growth, % | AA31: =AA30/V30-1 -> 0.5880848 | AF31: =AF30/AA30-1 -> 0.022001206 | AK31: =AK30/AF30-1 -> -0.1978357 | AP31: =AP30/AK30-1 -> 0.070989658 | AU31: =AU30/AP30-1 -> 0.025609301 | AZ31: =AZ30/AU30-1 -> 0.16512736 | BE31: =BE30/AZ30-1 -> 0.16263118 | BF31: =BF30/BA30-1 -> -0.31325443 | BG31: =BG30/BB30-1 -> -0.60722851 | BH31: =BH30/BC30-1 -> 0.032657021 | BI31: =BI30/BD30-1 -> 0.48414593 | BJ31: =BJ30/BE30-1 -> 0.1019032 | BK31: =BK30/BF30-1 -> 0.28661282 | BL31: =BL30/BG30-1 -> 1.0896516 | ... BO31: =BO30/BJ30-1 -> 0.1497684 | BP31: 0.1 | BQ31: 0.05 | BR31: 0.05 | BS31: 0.05 | BT31: =BT30/BO30-1 -> 0.060635018 | BU31: 0.05 | BV31: 0.05 | BW31: 0.05 | BX31: 0.05 | BY31: =BY30/BT30-1 -> 0.05 | BZ31: 0.05 | CA31: 0.05 | CB31: 0.05
A33: EUV sales, mm | E33: 119.3 | F33: 43.7 | G33: 60.1 | H33: =H53*H$39 -> 61.8 | I33: =I53*I$39 -> 62.15 | J33: =J53*J$39 -> 123.83 | K33: =K53*K$39 -> 65.118 | L33: 299.845 | M33: =M53*M$39 -> 0 | N33: =N53*N$39 -> 68.07 | O33: =O53*O$39 -> 0 | P33: =P53*P$39 -> 0 | Q33: 70.473 | R33: =R53*R$39 -> 0 | S33: =S53*S$39 -> 101.232 | T33: =T53*T$39 -> 88.039 | U33: =U53*U$39 -> 141.801 | V33: 324.9 | W33: =W53*W$39 -> 0 | X33: =X53*X$39 -> 221.456 | Y33: =Y53*Y$39 -> 381.969 | Z33: =Z53*Z$39 -> 488.725 | AA33: 1101.5 | AB33: =AB53*AB$39 -> 116.739 | AC33: =AC53*AC$39 -> 667.68 | AD33: =AD53*AD$39 -> 520.15 | AE33: =AE53*AE$39 -> 581.832 | AF33: 1880.1 | AG33: =AG53*AG$39 -> 371.58 | AH33: =AH53*AH$39 -> 758.828 | AI33: =AI53*AI$39 -> 744.192 | AJ33: =AJ53*AJ$39 -> 907.932 | AK33: 2799.7 | AL33: =AL53*AL$39 -> 348.48 | AM33: =AM53*AM$39 -> 951.054 | AN33: =AN53*AN$39 -> 2043.096 | AO33: =AO53*AO$39 -> 1151.424 | AP33: 4463.8 | AQ33: =AQ53*AQ$39 -> 1126.368 | AR33: =AR53*AR$39 -> 1327.32 | AS33: =AS53*AS$39 -> 2219.994 | AT33: =AT53*AT$39 -> 1593.118 | AU33: 6284 | AV33: =AV53*AV$39 -> 594.672 | AW33: =AW53*AW$39 -> 1987.44 | AX33: =AX53*AX$39 -> 2169.897 | AY33: =AY53*AY$39 -> 2326.471 | AZ33: 7045.3 | BA33: =BA53*BA$39 -> 2884.572 | BB33: =BB53*BB$39 -> 2074.257 | BC33: =BC53*BC$39 -> 1857.87 | BD33: =BD53*BD$39 -> 2273 | BE33: 9124 | BF33: =BF53*BF$39 -> 1824.314 | BG33: =BG53*BG$39 -> 1475.879 | BH33: =BH53*BH$39 -> 2074.1 | BI33: =BI53*BI$39 -> 2988.678 | BJ33: =7856.4+465 -> 8321.4 | BK33: =BK53*BK$39 -> 3214.624 | BL33: =BL53*BL$39 -> 2686.128 | BM33: =BM53*BM$39 -> 2110.444 | BN33: =BN53*BN$39 -> 3640.32 | BO33: =SUM(BK33,BL33,BM33,BN33) -> 11651.516 | BP33: =BP11*BP20/1000 -> 3283.5088 | BQ33: =BQ11*BQ20/1000 -> 3809.4179 | BR33: =BR11*BR20/1000 -> 4220.888 | BS33: =BS11*BS20/1000 -> 4680.4114 | BT33: =SUM(BP33,BQ33,BR33,BS33) -> 15994.226 | BU33: =BU11*BU20/1000 -> 3776.0351 | BV33: =BV11*BV20/1000 -> 4190.3597 | BW33: =BW11*BW20/1000 -> 4642.9768 | BX33: =BX11*BX20/1000 -> 5148.4526 | BY33: =SUM(BU33,BV33,BW33,BX33) -> 17757.824 | BZ33: =BZ11*BZ20/1000 -> 24734.112 | CA33: =CA11*CA20/1000 -> 25970.818 | CB33: =CB11*CB20/1000 -> 27269.359
A34: ArFi sales, mm | E34: 3549.122 | F34: 2715.221 | G34: 3120.719 | H34: =H54*H$39 -> 782.8 | I34: =I54*I$39 -> 1131.13 | J34: =J54*J$39 -> 636.84 | K34: =K54*K$39 -> 900.799 | L34: 3477.718 | M34: =M54*M$39 -> 1034.595 | N34: =N54*N$39 -> 896.255 | O34: =O54*O$39 -> 663.204 | P34: =P54*P$39 -> 634.248 | Q34: 3238.452 | R34: =R54*R$39 -> 679.242 | S34: =S54*S$39 -> 961.704 | T34: =T54*T$39 -> 968.429 | U34: =U54*U$39 -> 915.261 | V34: 3518.7 | W34: =W54*W$39 -> 899.692 | X34: =X54*X$39 -> 885.824 | Y34: =Y54*Y$39 -> 1145.907 | Z34: =Z54*Z$39 -> 1094.744 | AA34: 4017.4 | AB34: =AB54*AB$39 -> 1200.744 | AC34: =AC54*AC$39 -> 1022.385 | AD34: =AD54*AD$39 -> 1206.748 | AE34: =AE54*AE$39 -> 1381.851 | AF34: 4806.9 | AG34: =AG54*AG$39 -> 1013.4 | AH34: =AH54*AH$39 -> 758.828 | AI34: =AI54*AI$39 -> 1186.056 | AJ34: =AJ54*AJ$39 -> 1753.248 | AK34: 4707.7 | AL34: =AL54*AL$39 -> 823.68 | AM34: =AM54*AM$39 -> 999.826 | AN34: =AN54*AN$39 -> 650.076 | AO34: =AO54*AO$39 -> 1439.28 | AP34: 3917 | AQ34: =AQ54*AQ$39 -> 1470.536 | AR34: =AR54*AR$39 -> 1002.864 | AS34: =AS54*AS$39 -> 1315.552 | AT34: =AT54*AT$39 -> 1212.155 | AU34: 4959.6 | AV34: =AV54*AV$39 -> 1074.984 | AW34: =AW54*AW$39 -> 1366.365 | AX34: =AX54*AX$39 -> 1318.957 | AY34: =AY54*AY$39 -> 1471.849 | AZ34: 5236.5 | BA34: =BA54*BA$39 -> 1602.54 | BB34: =BB54*BB$39 -> 2746.989 | BC34: =BC54*BC$39 -> 2547.936 | BD34: =BD54*BD$39 -> 2159.35 | BE34: 9017.4 | BF34: =BF54*BF$39 -> 1546.701 | BG34: =BG54*BG$39 -> 2380.45 | BH34: =BH54*BH$39 -> 2844.48 | BI34: =BI54*BI$39 -> 2917.519 | BJ34: 9667 | BK34: =BK54*BK$39 -> 1894.332 | BL34: =BL54*BL$39 -> 2406.323 | BM34: =BM54*BM$39 -> 2887.976 | BN34: =BN54*BN$39 -> 3033.6 | BO34: =SUM(BK34,BL34,BM34,BN34) -> 10222.231 | BP34: =BP12*BP22/1000 -> 1742.7854 | BQ34: =BQ12*BQ22/1000 -> 1785.3364 | BR34: =BR12*BR22/1000 -> 1835.3847 | BS34: =BS12*BS22/1000 -> 1885.7514 | BT34: =SUM(BP34,BQ34,BR34,BS34) -> 7249.258 | BU34: =BU12*BU22/1000 -> 1568.5069 | BV34: =BV12*BV22/1000 -> 1606.8028 | BW34: =BW12*BW22/1000 -> 1982.2155 | BX34: =BX12*BX22/1000 -> 2036.6115 | BY34: =SUM(BU34,BV34,BW34,BX34) -> 7194.1367 | BZ34: =BZ12*BZ22/1000 -> 7701.7924 | CA34: =CA12*CA22/1000 -> 8348.3368 | CB34: =CB12*CB22/1000 -> 9049.1569
A35: ArF sales, mm | E35: 228.909 | F35: 81.428 | G35: 38.019 | H35: =H55*H$39 -> 0 | I35: =I55*I$39 -> 12.43 | J35: =J55*J$39 -> 0 | K35: =K55*K$39 -> 10.853 | L35: 32.611 | M35: =M55*M$39 -> 37.395 | N35: =N55*N$39 -> 11.345 | O35: =O55*O$39 -> 29.259 | P35: =P55*P$39 -> 26.427 | Q35: 107.522 | R35: =R55*R$39 -> 42.99 | S35: =S55*S$39 -> 37.962 | T35: =T55*T$39 -> 25.154 | U35: =U55*U$39 -> 25.782 | V35: 116.9 | W35: =W55*W$39 -> 60.79 | X35: =X55*X$39 -> 41.523 | Y35: =Y55*Y$39 -> 36.378 | Z35: =Z55*Z$39 -> 78.196 | AA35: 210.3 | AB35: =AB55*AB$39 -> 66.708 | AC35: =AC55*AC$39 -> 83.46 | AD35: =AD55*AD$39 -> 62.418 | AE35: =AE55*AE$39 -> 72.729 | AF35: 274.3 | AG35: =AG55*AG$39 -> 67.56 | AH35: =AH55*AH$39 -> 37.016 | AI35: =AI55*AI$39 -> 162.792 | AJ35: =AJ55*AJ$39 -> 125.232 | AK35: 401.2 | AL35: =AL55*AL$39 -> 110.88 | AM35: =AM55*AM$39 -> 121.93 | AN35: =AN55*AN$39 -> 30.956 | AO35: =AO55*AO$39 -> 127.936 | AP35: 427 | AQ35: =AQ55*AQ$39 -> 62.576 | AR35: =AR55*AR$39 -> 147.48 | AS35: =AS55*AS$39 -> 123.333 | AT35: =AT55*AT$39 -> 103.899 | AU35: 431.9 | AV35: =AV55*AV$39 -> 137.232 | AW35: =AW55*AW$39 -> 165.62 | AX35: =AX55*AX$39 -> 127.641 | AY35: =AY55*AY$39 -> 189.916 | AZ35: 623.7 | BA35: =BA55*BA$39 -> 160.254 | BB35: =BB55*BB$39 -> 112.122 | BC35: =BC55*BC$39 -> 212.328 | BD35: =BD55*BD$39 -> 284.125 | BE35: 780.2 | BF35: =BF55*BF$39 -> 118.977 | BG35: =BG55*BG$39 -> 333.263 | BH35: =BH55*BH$39 -> 177.78 | BI35: =BI55*BI$39 -> 142.318 | BJ35: 774.4 | BK35: =BK55*BK$39 -> 114.808 | BL35: =BL55*BL$39 -> 111.922 | BM35: =BM55*BM$39 -> 111.076 | BN35: =BN55*BN$39 -> 151.68 | BO35: =SUM(BK35,BL35,BM35,BN35) -> 489.486 | BP35: =BP13*BP24/1000 -> 336.77013 | BQ35: =BQ13*BQ24/1000 -> 257.4206 | BR35: =BR13*BR24/1000 -> 255.4748 | BS35: =BS13*BS24/1000 -> 279.0912 | BT35: =SUM(BP35,BQ35,BR35,BS35) -> 1128.7567 | BU35: =BU13*BU24/1000 -> 338.45398 | BV35: =BV13*BV24/1000 -> 258.7077 | BW35: =BW13*BW24/1000 -> 256.75217 | BX35: =BX13*BX24/1000 -> 280.48666 | BY35: =SUM(BU35,BV35,BW35,BX35) -> 1134.4005 | BZ35: =BZ13*BZ24/1000 -> 1141.1637 | CA35: =CA13*CA24/1000 -> 1147.9671 | CB35: =CB13*CB24/1000 -> 1154.8112
A36: KrF sales, mm | E36: 926.572 | F36: 908.244 | G36: 720.053 | H36: =H56*H$39 -> 175.1 | I36: =I56*I$39 -> 24.86 | J36: =J56*J$39 -> 106.14 | K36: =K56*K$39 -> 97.677 | L36: 381.436 | M36: =M56*M$39 -> 149.58 | N36: =N56*N$39 -> 136.14 | O36: =O56*O$39 -> 263.331 | P36: =P56*P$39 -> 202.607 | Q36: 747.74 | R36: =R56*R$39 -> 120.372 | S36: =S56*S$39 -> 139.194 | T36: =T56*T$39 -> 150.924 | U36: =U56*U$39 -> 128.91 | V36: 532.7 | W36: =W56*W$39 -> 182.37 | X36: =X56*X$39 -> 124.569 | Y36: =Y56*Y$39 -> 181.89 | Z36: =Z56*Z$39 -> 195.49 | AA36: 683.3 | AB36: =AB56*AB$39 -> 233.478 | AC36: =AC56*AC$39 -> 208.65 | AD36: =AD56*AD$39 -> 187.254 | AE36: =AE56*AE$39 -> 242.43 | AF36: 860.1 | AG36: =AG56*AG$39 -> 152.01 | AH36: =AH56*AH$39 -> 203.588 | AI36: =AI56*AI$39 -> 139.536 | AJ36: =AJ56*AJ$39 -> 187.848 | AK36: 679.7 | AL36: =AL56*AL$39 -> 205.92 | AM36: =AM56*AM$39 -> 243.86 | AN36: =AN56*AN$39 -> 247.648 | AO36: =AO56*AO$39 -> 351.824 | AP36: 1012.3 | AQ36: =AQ56*AQ$39 -> 344.168 | AR36: =AR56*AR$39 -> 324.456 | AS36: =AS56*AS$39 -> 287.777 | AT36: =AT56*AT$39 -> 346.33 | AU36: 1321.3 | AV36: =AV56*AV$39 -> 274.464 | AW36: =AW56*AW$39 -> 414.05 | AX36: =AX56*AX$39 -> 425.47 | AY36: =AY56*AY$39 -> 569.748 | AZ36: 1653.7 | BA36: =BA56*BA$39 -> 480.762 | BB36: =BB56*BB$39 -> 504.549 | BC36: =BC56*BC$39 -> 530.82 | BD36: =BD56*BD$39 -> 681.9 | BE36: 2202.5 | BF36: =BF56*BF$39 -> 317.272 | BG36: =BG56*BG$39 -> 428.481 | BH36: =BH56*BH$39 -> 592.6 | BI36: =BI56*BI$39 -> 640.431 | BJ36: 1991.2 | BK36: =BK56*BK$39 -> 287.02 | BL36: =BL56*BL$39 -> 223.844 | BM36: =BM56*BM$39 -> 166.614 | BN36: =BN56*BN$39 -> 379.2 | BO36: =SUM(BK36,BL36,BM36,BN36) -> 1056.678 | BP36: =BP14*BP26/1000 -> 574.04 | BQ36: =BQ14*BQ26/1000 -> 643.5515 | BR36: =BR14*BR26/1000 -> 696.74945 | BS36: =BS14*BS26/1000 -> 601.48966 | BT36: =SUM(BP36,BQ36,BR36,BS36) -> 2515.8306 | BU36: =BU14*BU26/1000 -> 516.636 | BV36: =BV14*BV26/1000 -> 579.19635 | BW36: =BW14*BW26/1000 -> 661.91198 | BX36: =BX14*BX26/1000 -> 571.41517 | BY36: =SUM(BU36,BV36,BW36,BX36) -> 2329.1595 | BZ36: =BZ14*BZ26/1000 -> 2519.041 | CA36: =CA14*CA26/1000 -> 2724.4024 | CB36: =CB14*CB26/1000 -> 2946.5055
A37: i-line sales, mm | E37: 60.01 | F37: 53.039 | G37: 54.238 | H37: =H57*H$39 -> 10.3 | I37: =I57*I$39 -> 12.43 | J37: =J57*J$39 -> 17.69 | K37: =K57*K$39 -> 10.853 | L37: 51.18 | M37: =M57*M$39 -> 24.93 | N37: =N57*N$39 -> 22.69 | O37: =O57*O$39 -> 19.506 | P37: =P57*P$39 -> 17.618 | Q37: 72.996 | R37: =R57*R$39 -> 17.196 | S37: =S57*S$39 -> 25.308 | T37: =T57*T$39 -> 25.154 | U37: =U57*U$39 -> 12.891 | V37: 78 | W37: =W57*W$39 -> 12.158 | X37: =X57*X$39 -> 27.682 | Y37: =Y57*Y$39 -> 18.189 | Z37: =Z57*Z$39 -> 19.549 | AA37: 84.7 | AB37: =AB57*AB$39 -> 16.677 | AC37: =AC57*AC$39 -> 20.865 | AD37: =AD57*AD$39 -> 20.806 | AE37: =AE57*AE$39 -> 24.243 | AF37: 98.6 | AG37: =AG57*AG$39 -> 33.78 | AH37: =AH57*AH$39 -> 18.508 | AI37: =AI57*AI$39 -> 23.256 | AJ37: =AJ57*AJ$39 -> 62.616 | AK37: 133.5 | AL37: =AL57*AL$39 -> 47.52 | AM37: =AM57*AM$39 -> 24.386 | AN37: =AN57*AN$39 -> 30.956 | AO37: =AO57*AO$39 -> 31.984 | AP37: 146.4 | AQ37: =AQ57*AQ$39 -> 31.288 | AR37: =AR57*AR$39 -> 29.496 | AS37: =AS57*AS$39 -> 41.111 | AT37: =AT57*AT$39 -> 34.633 | AU37: 142.3 | AV37: =AV57*AV$39 -> 45.744 | AW37: =AW57*AW$39 -> 41.405 | AX37: =AX57*AX$39 -> 42.547 | AY37: =AY57*AY$39 -> 47.479 | AZ37: 211.5 | BA37: =BA57*BA$39 -> 53.418 | BB37: =BB57*BB$39 -> 56.061 | BC37: =BC57*BC$39 -> 53.082 | BD37: =BD57*BD$39 -> 113.65 | BE37: 278.4 | BF37: =BF57*BF$39 -> 39.659 | BG37: =BG57*BG$39 -> 95.218 | BH37: =BH57*BH$39 -> 118.52 | BI37: =BI57*BI$39 -> 142.318 | BJ37: 369.2 | BK37: =BK57*BK$39 -> 57.404 | BL37: =BL57*BL$39 -> 55.961 | BM37: =BM57*BM$39 -> 55.538 | BN37: =BN57*BN$39 -> 75.84 | BO37: =SUM(BK37,BL37,BM37,BN37) -> 244.743 | BP37: =BP15*BP28/1000 -> 40.624369 | BQ37: =BQ15*BQ28/1000 -> 36.774371 | BR37: =BR15*BR28/1000 -> 51.09496 | BS37: =BS15*BS28/1000 -> 41.042824 | BT37: =SUM(BP37,BQ37,BR37,BS37) -> 169.53652 | BU37: =BU15*BU28/1000 -> 46.718025 | BV37: =BV15*BV28/1000 -> 42.290527 | BW37: =BW15*BW28/1000 -> 58.759204 | BX37: =BX15*BX28/1000 -> 47.199247 | BY37: =SUM(BU37,BV37,BW37,BX37) -> 194.967 | BZ37: =BZ15*BZ28/1000 -> 224.21205 | CA37: =CA15*CA28/1000 -> 257.84386 | CB37: =CB15*CB28/1000 -> 296.52044
A38: Metrology & Inspection sales, mm | U38: =U58*U$39 -> 0 | V38: 100.8 | W38: =W58*W$39 -> 60.79 | X38: =X58*X$39 -> 83.046 | Y38: =Y58*Y$39 -> 54.567 | Z38: =Z58*Z$39 -> 78.196 | AA38: 276.5 | AB38: =AB58*AB$39 -> 33.354 | AC38: =AC58*AC$39 -> 83.46 | AD38: =AD58*AD$39 -> 83.224 | AE38: =AE58*AE$39 -> 121.215 | AF38: 339.1 | AG38: =AG58*AG$39 -> 50.67 | AH38: =AH58*AH$39 -> 74.032 | AI38: =AI58*AI$39 -> 69.768 | AJ38: =AJ58*AJ$39 -> 93.924 | AK38: 274.4 | AL38: =AL58*AL$39 -> 47.52 | AM38: =AM58*AM$39 -> 97.544 | AN38: =AN58*AN$39 -> 92.868 | AO38: =AO58*AO$39 -> 95.952 | AP38: 350.1 | AQ38: =AQ58*AQ$39 -> 93.864 | AR38: =AR58*AR$39 -> 117.984 | AS38: =AS58*AS$39 -> 123.333 | AT38: =AT58*AT$39 -> 173.165 | AU38: 513.7 | AV38: =AV58*AV$39 -> 160.104 | AW38: =AW58*AW$39 -> 165.62 | AX38: =AX58*AX$39 -> 170.188 | AY38: =AY58*AY$39 -> 142.437 | AZ38: 659.6 | BA38: =BA58*BA$39 -> 160.254 | BB38: =BB58*BB$39 -> 112.122 | BC38: =BC58*BC$39 -> 106.164 | BD38: =BD58*BD$39 -> 170.475 | BE38: 536.1 | BF38: =BF58*BF$39 -> 118.977 | BG38: =BG58*BG$39 -> 47.609 | BH38: =BH58*BH$39 -> 118.52 | BI38: =BI58*BI$39 -> 284.636 | BJ38: 645.5 | BK38: =BK58*BK$39 -> 172.212 | BL38: =BL58*BL$39 -> 111.922 | BM38: =BM58*BM$39 -> 222.152 | BN38: =BN58*BN$39 -> 303.36 | BO38: =SUM(BK38,BL38,BM38,BN38) -> 809.646 | BP38: =BP17*BP30/1000 -> 210.48133 | BQ38: =BQ17*BQ30/1000 -> 130.57567 | BR38: =BR17*BR30/1000 -> 259.17733 | BS38: =BS17*BS30/1000 -> 353.92 | BT38: =SUM(BP38,BQ38,BR38,BS38) -> 954.15433 | BU38: =BU17*BU30/1000 -> 221.0054 | BV38: =BV17*BV30/1000 -> 137.10445 | BW38: =BW17*BW30/1000 -> 272.1362 | BX38: =BX17*BX30/1000 -> 371.616 | BY38: =SUM(BU38,BV38,BW38,BX38) -> 1001.862 | BZ38: =BZ17*BZ30/1000 -> 1051.9552 | CA38: =CA17*CA30/1000 -> 1104.5529 | CB38: =CB17*CB30/1000 -> 1159.7806
A39: Total net system sales, mm | C39: =C298 -> 1174.858 | D39: =D298 -> 3894.742 | E39: =E33+E34+E35+E36+E37+E38 -> 4883.913 | F39: =F33+F34+F35+F36+F37+F38 -> 3801.632 | G39: =G33+G34+G35+G36+G37+G38 -> 3993.129 | H39: =H298 -> 1030 | I39: =I298 -> 1243 | J39: =J298 -> 884.5 | K39: =K298 -> 1085.3 | L39: =L33+L34+L35+L36+L37+L38 -> 4242.79 | M39: =M298 -> 1246.5 | N39: =N298 -> 1134.5 | O39: =O298 -> 975.3 | P39: =P298 -> 880.9 | Q39: =Q33+Q34+Q35+Q36+Q37+Q38 -> 4237.183 | R39: =R298 -> 859.8 | S39: =S298 -> 1265.4 | T39: =T298 -> 1257.7 | U39: =U298 -> 1289.1 | V39: =V33+V34+V35+V36+V37+V38 -> 4672 | W39: =W298 -> 1215.8 | X39: =X298 -> 1384.1 | Y39: =Y298 -> 1818.9 | Z39: =Z298 -> 1954.9 | AA39: =AA33+AA34+AA35+AA36+AA37+AA38 -> 6373.7 | AB39: =AB298 -> 1667.7 | AC39: =AC298 -> 2086.5 | AD39: =AD298 -> 2080.6 | AE39: =AE298 -> 2424.3 | AF39: =AF33+AF34+AF35+AF36+AF37+AF38 -> 8259.1 | AG39: =AG298 -> 1689 | AH39: =AH298 -> 1850.8 | AI39: =AI298 -> 2325.6 | AJ39: =AJ298 -> 3130.8 | AK39: =AK33+AK34+AK35+AK36+AK37+AK38 -> 8996.2 | AL39: =AL298 -> 1584 | AM39: =AM298 -> 2438.6 | AN39: =AN298 -> 3095.6 | AO39: =AO298 -> 3198.4 | AP39: =AP33+AP34+AP35+AP36+AP37+AP38 -> 10316.6 | AQ39: =AQ298 -> 3128.8 | AR39: =AR298 -> 2949.6 | AS39: =AS298 -> 4111.1 | AT39: =AT298 -> 3463.3 | AU39: =AU33+AU34+AU35+AU36+AU37+AU38 -> 13652.8 | AV39: =AV298 -> 2287.2 | AW39: =AW298 -> 4140.5 | AX39: =AX298 -> 4254.7 | AY39: =AY298 -> 4747.9 | AZ39: =AZ33+AZ34+AZ35+AZ36+AZ37+AZ38 -> 15430.3 | BA39: =BA298 -> 5341.8 | BB39: =BB298 -> 5606.1 | BC39: =BC298 -> 5308.2 | BD39: =BD298 -> 5682.5 | BE39: =BE33+BE34+BE35+BE36+BE37+BE38 -> 21938.6 | BF39: =BF298 -> 3965.9 | BG39: =BG298 -> 4760.9 | BH39: =BH298 -> 5926 | BI39: =BI298 -> 7115.9 | BJ39: =BJ33+BJ34+BJ35+BJ36+BJ37+BJ38 -> 21768.7 | BK39: =BK298 -> 5740.4 | BL39: =BL298 -> 5596.1 | BM39: =BM298 -> 5553.8 | BN39: =BN298 -> 7584 | BO39: =BO33+BO34+BO35+BO36+BO37+BO38 -> 24474.3 | BP39: =BP33+BP34+BP35+BP36+BP37+BP38 -> 6188.2101 | BQ39: =BQ33+BQ34+BQ35+BQ36+BQ37+BQ38 -> 6663.0764 | BR39: =BR33+BR34+BR35+BR36+BR37+BR38 -> 7318.7693 | BS39: =BS33+BS34+BS35+BS36+BS37+BS38 -> 7841.7065 | BT39: =BT33+BT34+BT35+BT36+BT37+BT38 -> 28011.762 | BU39: =BU33+BU34+BU35+BU36+BU37+BU38 -> 6467.3554 | BV39: =BV33+BV34+BV35+BV36+BV37+BV38 -> 6814.4615 | ... CB39: =CB33+CB34+CB35+CB36+CB37+CB38 -> 41876.133
A40: Net service and field option sales, mm | C40: =C299 -> 421.205 | D40: =D299 -> 613.196 | E40: =E299 -> 767.122 | F40: =F299 -> 929.923 | G40: =G299 -> 1252.197 | H40: =H299 -> 366.5 | I40: =I299 -> 400.6 | J40: =J299 -> 437.7 | ... BO40: =BO299 -> 8193 | BP40: =BK40*(1+BP50) -> 2401.32 | BQ40: =BL40*(1+BQ50) -> 2200.38 | BR40: =BM40*(1+BR50) -> 2060.31 | BS40: =BN40*(1+BS50) -> 2240.805 | BT40: =SUM(BP40,BQ40,BR40,BS40) -> 8902.815 | BU40: =BP40*(1+BU50) -> 2425.3332 | BV40: =BQ40*(1+BV50) -> 2222.3838 | BW40: =BR40*(1+BW50) -> 2080.9131 | BX40: =BS40*(1+BX50) -> 2263.213 | BY40: =SUM(BU40,BV40,BW40,BX40) -> 8991.8432 | BZ40: =BY40*(1+BZ50) -> 9171.68 | CA40: =BZ40*(1+CA50) -> 9355.1136 | CB40: =CA40*(1+CB50) -> 9542.2159
A41: Total revenue, mm | C41: =C39+C40 -> 1596.063 | D41: =D39+D40 -> 4507.938 | E41: =E39+E40 -> 5651.035 | F41: =F39+F40 -> 4731.555 | G41: =G39+G40 -> 5245.326 | H41: =H39+H40 -> 1396.5 | I41: =I39+I40 -> 1643.6 | J41: =J39+J40 -> 1322.2 | ... CB41: =CB39+CB40 -> 51418.349
A43: Y/Y EUV sales growth, % | F43: =IFERROR(F33/E33-1,"n/a") -> -0.63369656 | G43: =IFERROR(G33/F33-1,"n/a") -> 0.37528604 | L43: =IFERROR(L33/G33-1,"n/a") -> 3.9891015 | M43: =IFERROR(M33/H33-1,"n/a") -> -1 | N43: =IFERROR(N33/I33-1,"n/a") -> 0.095253419 | O43: =IFERROR(O33/J33-1,"n/a") -> -1 | P43: =IFERROR(P33/K33-1,"n/a") -> -1 | Q43: =IFERROR(Q33/L33-1,"n/a") -> -0.76496857 | R43: =IFERROR(R33/M33-1,"n/a") -> n/a | S43: =IFERROR(S33/N33-1,"n/a") -> 0.48717497 | ... BY43: =IFERROR(BY33/BT33-1,"n/a") -> 0.11026467 | BZ43: =IFERROR(BZ33/BY33-1,"n/a") -> 0.39285714 | CA43: =IFERROR(CA33/BZ33-1,"n/a") -> 0.05 | CB43: =IFERROR(CB33/CA33-1,"n/a") -> 0.05
...

Sheet Guidance
B1: =MO.CompanyName -> ASML Holdings N.V.
B2: Most Recent Period: | F2: =UL.MRQ -> FY2025
I4: Guidance | M4: Model | P4: Difference vs. Mid | S4: Update Log
B5: Type | D5: Item | E5: Item Name | F5: Fiscal Period | G5: Base Period | I5: Low | J5: High | K5: Mid | M5: Type | N5: Output | P5: Absolute | Q5: Relative | S5: Date | T5: Link
A6: 288 | B6: =IF(INDEX(MO_SNA_IsHistoricalPeriod,,MATCH(F6,MO_Common_ColumnHeader,0)),"Historical","Forward") -> Forward | D6: =INDEX(INDIRECT(E6),0,COLUMN(MO_Common_Column_A)) -> Net Revenue | E6: MO_RIS_REV | F6: FY2026 | I6: 34000 | J6: 39000 | K6: =AVERAGE(I6:J6) -> 36500 | M6: =IF(INDEX(MO_SNA_IsHistoricalPeriod,,MATCH(F6,MO_Common_ColumnHeader,0)),"Actual","Estimate") -> Estimate | N6: =IFERROR(INDEX(INDIRECT(E6),0,MATCH(F6,MO_Common_ColumnHeader,0)),"N/A") -> 36914.577 | P6: =IF(ISNUMBER(N6),N6-K6,"N/A") -> 414.57728 | Q6: =IFERROR(IF(ISNUMBER(N6),(N6-K6)/ABS(K6),"N/A"),"N/A") -> 0.011358282 | S6: 46050 | T6: Investor Presentation
A7: 287 | B7: =IF(INDEX(MO_SNA_IsHistoricalPeriod,,MATCH(F7,MO_Common_ColumnHeader,0)),"Historical","Forward") -> Forward | D7: =INDEX(INDIRECT(E7),0,COLUMN(MO_Common_Column_A)) -> Gross Margin, % | E7: MO_MA_GM | F7: FY2026 | I7: 0.51 | J7: 0.53 | K7: =AVERAGE(I7:J7) -> 0.52 | M7: =IF(INDEX(MO_SNA_IsHistoricalPeriod,,MATCH(F7,MO_Common_ColumnHeader,0)),"Actual","Estimate") -> Estimate | N7: =IFERROR(INDEX(INDIRECT(E7),0,MATCH(F7,MO_Common_ColumnHeader,0)),"N/A") -> 0.52504252 | P7: =IF(ISNUMBER(N7),N7-K7,"N/A") -> 0.0050425246 | Q7: =IFERROR(IF(ISNUMBER(N7),(N7-K7)/ABS(K7),"N/A"),"N/A") -> 0.0096971626 | S7: 46050 | T7: Investor Presentation
