Workbook
Name AA.AlternatePriceSourceStartPeriod: "Q1-2018"
Name AA.CIK: "813672"
Name AA.CompareQuarters.LatestMRQ: "Q3-2019"
Name AA.CSIN: "9SC16I0108"
Name AA.CurationVersion: "2023.11.1.0"
Name AA.DBMacroVersion: "1.0.13.0"
Name AA.FreeCashFlow: "TRUE"
Name AA.GuidanceAnalysisNonGaapEbitVersion: "1.0.0.0"
Name AA.GuidanceAnalysisRevenueVersion: "1.0.0.0"
Name AA.GuidanceAnalysisWadAdjustedEps: "1.0.0.0"
Name AA.HardcodeChecker.LatestMRQ: "Q3-2019"
Name AA.ModelChecks.LatestMRQ: "Q3-2021"
Name AA.ModelChecks.LatestVersionNumber: "2.38.4.0"
Name AA.ModelVersion: "Q3-2025.24"
Name AA.NonLibraryWideCurationVersion: "4"
Name AA.PartialUpdate.BsAvailable: "TRUE"
Name AA.PartialUpdate.CfsAvailable: "TRUE"
Name AA.PartialUpdate.IsAvailable: "TRUE"
Name AA.PeriodLayout: "QFY"
Name AA.PersonalMacro.VersionNumber: ""
Name AA.RowNameEnforcerVersion: "2023.11.1.0"
Name AA.SessionToUploadId: ""
Name AA.StartWorkModelVersion: "Q3-2025.23"
Name AA.StartWorkType: ""
Name AA.SubyearType: "Q"
Name AA.TemplateUpgradeAttempted: "TRUE"
Name AA.TemplateVersion: "7.5.4.0"
Name AA.UpdateType: "Regular"
Name AA.VerifyUnitsAtModelVersion: "Q1-2018.22"
Name EC_CEO_BasePay: 'Exec Comp'!$20:$20
Name EC_CEO_EquityComp_Percent: 'Exec Comp'!$26:$26
Name EC_CEO_SharesOwned: 'Exec Comp'!$67:$67
Name EC_CEO_TotalComp: 'Exec Comp'!$25:$25
Name EC_CFO_BasePay: 'Exec Comp'!$69:$69
Name EC_CFO_EquityComp_Percent: 'Exec Comp'!$75:$75
Name EC_CFO_SharesOwned: 'Exec Comp'!$105:$105
Name EC_CFO_TotalComp: 'Exec Comp'!$74:$74
Name EC_CLO_BasePay: 'Exec Comp'!$145:$145
Name EC_CLO_EquityComp_Percent: 'Exec Comp'!$151:$151
Name EC_CLO_SharesOwned: 'Exec Comp'!$156:$156
Name EC_CLO_TotalComp: 'Exec Comp'!$150:$150
Name EC_CRO_BasePay: 'Exec Comp'!$107:$107
Name EC_CRO_EquityComp_Percent: 'Exec Comp'!$113:$113
Name EC_CRO_SharesOwned: 'Exec Comp'!$143:$143
Name EC_CRO_TotalComp: 'Exec Comp'!$112:$112
Name EC_Director_Compensation_Cash: 'Exec Comp'!$178:$178
Name EC_Director_Compensation_Total: 'Exec Comp'!$201:$201
Name EC_Directors_Current: 'Exec Comp'!$159:$159
Name EC_Directors_Current_Diverse: 'Exec Comp'!$162:$162
Name EC_Directors_Current_Female: 'Exec Comp'!$161:$161
Name EC_Directors_Current_Independent: 'Exec Comp'!$160:$160
Name EC_Directors_Nominees: 'Exec Comp'!$164:$164
Name EC_Directors_Nominees_Independent: 'Exec Comp'!$165:$165
Name FP.DataSource: 'Front Page'!$H$16
Name FP.DataSourceName: 'Front Page'!$H$15
Name FP.Disclaimer: 'Front Page'!$C$22
Name FP.LastPrice: 'Front Page'!$H$20
Name FP.LastPriceDate: 'Front Page'!$F$20
Name FP.RealTimeToggle: 'Front Page'!$H$18
Name FP.UpdateDate: 'Front Page'!$H$11

Sheet Front Page
M6: Please contact this email for any model-specific questions:
M7: modelsupport@alpha-sense.com | N7: mailto:support@canalyst.com?subject=Canalyst%20Support:%20Cadence%20Design%20Systems,%20Inc.%20CDNS%20US&body=Model%20Version:%20Q1-2019.21 | O7: mailto:support@canalyst.com?subject=Canalyst%20Support:%20Cadence%20Design%20Systems,%20Inc.%20CDNS%20US&body=Model%20Version:%20Q1-2019.21
C9: Company Model: | H9: =Model!A1
C11: Updated: | H11: =OFFSET('Update Log'!$C$10,1,0,1,1)
M12: Comments on Model:
C13: For: | H13: =OFFSET('Update Log'!$E$10,1,0,1,1)
C15: Consensus Data and Real-Time Stock Price: | H15: Bloomberg
H16: =IF(FP.DataSourceName="Bloomberg",1,IF(FP.DataSourceName="Capital IQ",2,IF(FP.DataSourceName="FactSet",3,IF(FP.DataSourceName="Refinitiv",4))))
C18: Real-Time Stock Price: | H18: OFF
C20: Stock Price Override: | F20: 45961 | H20: 338.69
C22: DISCLAIMER Access to and use of this model, including the data contained herein (this "Model") is subject to Tegus, Inc.'s (a successor entity to Canalyst Financial Modeling Corporation) ("Company") Terms of Use that you accepted prior to accessing this Model, the applicable Service Agreement between the Company and you (or a corporate entity that has authorized you to access and use this Model on its behalf in accordance with the terms of such Service Agreement) or other similar agreement between you and the Company. BY CONTINUING TO ACCESS OR USE THIS MODEL, YOU EXPRESSLY AGREE TO THE TERMS AND CONDITIONS OF SUCH AGREEMENTS. The Company and certain of its licensors have exclusive proprietary rights in this Model. This Model is being provided for internal use only. Unless prior written consent by the Company and its licensors has been provided to you, you may not distribute or otherwise furnish this Model to any third party, nor use or permit anyone to use this Model for any unlawful or unauthorized purpose. IF YOU HAVE UNLAWFULLY OBTAINED, OR ARE NOT AUTHORIZED TO USE THIS MODEL, YOU ARE OBLIGATED TO PROMPTLY: (I) RETURN THIS MODEL (AND ANY DERIVATIVE WORKS ARISING FROM OR RELATING THERETO) TO THE AUTHORIZED USER OF THIS MODEL; (II) PROVIDE NOTICE TO THE COMPANY AT LEGAL@TEGUS.COM OF SUCH UNLAWFUL OR UNAUTHORIZED ACCESS AND USE; AND, (III) CERTIFY THAT YOU HAVE DESTROYED THIS MODEL (AND ANY DERIVATIVE WORKS ARISING FROM OR RELATING THERETO) AND ANY COPIES FROM YOUR SYSTEMS SO AS TO ENSURE THEY ARE INCAPABLE OF RETRIEVAL. A portion of the data contained in this Model may be powered by third party contributors and their respective licensors, or derived from data provided by such contributors, including (but not limited to): (i) QuoteMedia Inc.: A portion of the market data is powered by Quotemedia.com. All rights reserved. Data delayed 15 minutes unless otherwise indicated; (ii) S&P Global Market Intelligence LLC: Copyright (c) {{YEAR}} S&P Global Market Intelligence LLC (and its affiliates as applicable). All rights reserved. Reproduction of any information, opinions, views, data or material, including ratings ("Content") in any form is prohibited except with the prior written permission of the relevant party. Such party, its affiliates and suppliers ("Content Providers") do not guarantee the accuracy, adequacy, completeness, timeliness or availability of any Content and are not responsible for any errors or omissions (negligent or otherwise), regardless of the cause, or for the results obtained from the use of such Content. In no event shall Content Providers be liable for any damages, costs, expenses, legal fees, or losses (including lost income or lost profit and opportunity costs) in connection with any use of the Content. A reference to a particular investment or security, a rating or any observation concerning an investment that is part of the Content is not a recommendation to buy, sell or hold such investment or security, does not address the suitability of an investment or security and should not be relied on as investment advice. Credit ratings are statements of opinions and are not statements of fact; and, (iii) Refinitiv Canada Holdings Limited: A portion of the information may be provided by or derived from data provided by Refinitiv. By accessing or using this Model (including any portion of the data contained herein) you expressly represent that such access or use does not constitute a violation of any applicable law or regulation to which you or the securities are subject. This Model does not constitute investment advice by the Company or any of its licensors. Reference to a particular investment or security, credit rating or any observation concerning a security or investment in this Model is not a recommendation or solicitation to buy, sell or hold such investment or security or make any other investment decisions. For greater certainty, any forecasts or forward-looking information expressed herein are for illustrative purposes only and do not purport to express any view on what may transpire. Neither the Company nor any of its licensors have performed company-specific research on any projected information, as such, it is your responsibility to express your own views on projected results. This Model does not guarantee future performance and undue reliance should not be placed on such. You are solely responsible for evaluating the merits and risks of any investment based on your own business and financial expertise, the business and financial expertise of professional advisors with whom you have consulted, your financial situation and risk tolerance. Neither the Company, nor any of its licensors, undertake any liability with respect to your reliance on this Model. This Model is a quantitative tool with no investment views. The Company and its respective directors, officers, employees, agents, contractors, and affiliates may hold long or short positions in the security to which this Model relates, based on their personal views, and may initiate or close out any positions in such security at any time without any notice. THIS MODEL IS PROVIDED "AS IS" AND ON AN "AS AVAILABLE" BASIS ONLY, WITHOUT WARRANTIES OR CONDITIONS OF ANY KIND. NEITHER THE COMPANY NOR ANY OF ITS LICENSORS NOR THEIR RESPECTIVE AFFILIATES OR SUPPLIERS HAVE LIABILITY FOR THE ACCURACY, TIMELINESS OR COMPLETENESS OF THIS MODEL, OR FOR DELAYS, INTERRUPTIONS OR OMISSIONS HEREIN, NOR FOR ANY LOST PROFITS, INDIRECT, SPECIAL OR CONSEQUENTIAL DAMAGES. Access to data in this Model that is sourced from third party contributors is subject to termination in the event that any agreement between the Company and such third party contributors terminates for any reason. Copyright 2023 Tegus. All rights reserved.

Sheet DCF
B1: Cadence Design Systems
B2: Discounted Cash Flow Valuation Analysis
F5: Historical | G5: Projected | L5: Assumptions | Q5: Notes
L6: Risk Free Rate: | O6: 0.0425 | Q6: 10-Year US Treasury yield
B7: ($ in millions) | F7: FY2025 | G7: FY2026 | H7: FY2027 | I7: FY2028 | J7: FY2029 | L7: Market Risk Premium: | O7: 0.055 | Q7: Damodaran equity risk premium
L8: Unlevered Beta: | O8: 1.15 | Q8: EDA software industry avg
B9: Revenue Build by Segment | L9: Projected Equity to Value: | O9: 0.92 | Q9: CDNS moderate leverage
B10: Core EDA Revenue | F10: =Model!BS13 | G10: =Model!BX13 | H10: =Model!BY13 | I10: =Model!BZ13 | J10: =Model!CA13 | L10: Levered Beta: | O10: =(1+(1-O12)*(1-O9)/O9)*O8 | Q10: Hamada equation
B11: Y/Y Growth | F11: =Model!BS14 | G11: =Model!BX14 | H11: =Model!BY14 | I11: =Model!BZ14 | J11: =Model!CA14 | L11: Cost of Equity: | O11: =O6+O7*O10 | Q11: CAPM: Rf + B(Rm-Rf)
B12: System Interconnect & Analysis Revenue | F12: =Model!BS16 | G12: =Model!BX16 | H12: =Model!BY16 | I12: =Model!BZ16 | J12: =Model!CA16 | L12: Tax Rate: | O12: 0.18 | Q12: Long-term effective tax rate
B13: Y/Y Growth | F13: =Model!BS17 | G13: =Model!BX17 | H13: =Model!BY17 | I13: =Model!BZ17 | J13: =Model!CA17 | L13: Cost of Debt: | O13: 0.04 | Q13: Based on outstanding senior notes
B14: IP Revenue | F14: =Model!BS18 | G14: =Model!BX18 | H14: =Model!BY18 | I14: =Model!BZ18 | J14: =Model!CA18 | L14: WACC: | O14: =O11*O9+O13*(1-O12)*(1-O9) | Q14: Rd*(1-T)*(D/V) + Re*(E/V)
B15: Y/Y Growth | F15: =Model!BS19 | G15: =Model!BX19 | H15: =Model!BY19 | I15: =Model!BZ19 | J15: =Model!CA19 | L15: Terminal Growth Rate: | O15: 0.03 | Q15: Long-term nominal GDP growth
B16: Total Revenue | F16: =Model!BS20 | G16: =Model!BX20 | H16: =Model!BY20 | I16: =Model!BZ20 | J16: =Model!CA20 | L16: Implied TV/EBITDA: | O16: =F44/(Model!CA99+Model!CA170) | Q16: Terminal value / FY2029 EBITDA
B17: Y/Y Total Revenue Growth | G17: =G16/F16-1 | H17: =H16/G16-1 | I17: =I16/H16-1 | J17: =J16/I16-1
B19: Operating Margin Drivers
B20: Non-GAAP Gross Margin % | F20: =Model!BS47 | G20: =Model!BX47 | H20: =Model!BY47 | I20: =Model!BZ47 | J20: =Model!CA47
B21: Gross Margin Improvement (bps) | F21: =Model!BS49 | G21: =Model!BX49 | H21: =Model!BY49 | I21: =Model!BZ49 | J21: =Model!CA49
B22: Non-GAAP R&D Margin % | F22: =Model!BS61 | G22: =Model!BX61 | H22: =Model!BY61 | I22: =Model!BZ61 | J22: =Model!CA61
B23: R&D Margin Improvement (bps) | F23: =Model!BS62 | G23: =Model!BX62 | H23: =Model!BY62 | I23: =Model!BZ62 | J23: =Model!CA62
B24: Non-GAAP G&A Margin % | F24: =Model!BS74 | G24: =Model!BX74 | H24: =Model!BY74 | I24: =Model!BZ74 | J24: =Model!CA74
B25: G&A Margin Improvement (bps) | F25: =Model!BS75 | G25: =Model!BX75 | H25: =Model!BY75 | I25: =Model!BZ75 | J25: =Model!CA75
B26: Non-GAAP S&M Margin % | F26: =Model!BS87 | G26: =Model!BX87 | H26: =Model!BY87 | I26: =Model!BZ87 | J26: =Model!CA87
B27: S&M Margin Improvement (bps) | F27: =Model!BS88 | G27: =Model!BX88 | H27: =Model!BY88 | I27: =Model!BZ88 | J27: =Model!CA88
B28: Non-GAAP EBIT Margin % | F28: =Model!BS102 | G28: =Model!BX102 | H28: =Model!BY102 | I28: =Model!BZ102 | J28: =Model!CA102
B29: Non-GAAP Operating Income (EBIT) | F29: =Model!BS99 | G29: =Model!BX99 | H29: =Model!BY99 | I29: =Model!BZ99 | J29: =Model!CA99
B31: Unlevered Free Cash Flow Build
B32: Non-GAAP EBIT | G32: =G29 | H32: =H29 | I32: =I29 | J32: =J29
B33: Less: Taxes on EBIT | G33: =-G32*$O$12 | H33: =-H32*$O$12 | I33: =-I32*$O$12 | J33: =-J32*$O$12
B34: NOPAT | G34: =G32+G33 | H34: =H32+H33 | I34: =I32+I33 | J34: =J32+J33
B35: Plus: Depreciation & Amortization | G35: =Model!BX170 | H35: =Model!BY170 | I35: =Model!BZ170 | J35: =Model!CA170
B36: Less: Capital Expenditures | G36: =-Model!BX938 | H36: =-Model!BY938 | I36: =-Model!BZ938 | J36: =-Model!CA938
B37: Less: Increase in Net Working Capital | G37: =-Model!BX933 | H37: =-Model!BY933 | I37: =-Model!BZ933 | J37: =-Model!CA933
B38: Unlevered Free Cash Flow | G38: =SUM(G34:G37) | H38: =SUM(H34:H37) | I38: =SUM(I34:I37) | J38: =SUM(J34:J37)
B40: Times: Discount Factor | G40: =1/(1+$O$14)^1 | H40: =1/(1+$O$14)^2 | I40: =1/(1+$O$14)^3 | J40: =1/(1+$O$14)^4
B41: Discounted Cash Flows | G41: =G38*G40 | H41: =H38*H40 | I41: =I38*I40 | J41: =J38*J40
B43: Sum of Discounted Cash Flows | F43: =SUM(G41:J41)
B44: Terminal Value: | F44: =(J38*(1+$O$15))/($O$14-$O$15)
B45: Times: Discount Factor | F45: =J40
B46: PV of Terminal Value | F46: =F44*F45
...

Sheet Model
A1: Cadence Design Systems, Inc.
A2: =CHOOSE(MO.DataSourceIndex,MO.Ticker.Bloomberg,MO.Ticker.CapIQ,MO.Ticker.FactSet,MO.Ticker.Thomson) | C2: =EOMONTH(C4,-12)
A3: =HP.TradeCurrency | B3: =IF(MO.RealTime="OFF",MO.LastPriceHardcoded,MO.LastPriceFormula) | C3: =C4-C2 | D3: =D4-C4 | E3: =E4-D4 | F3: =F4-E4 | G3: =G4-F4 | H3: =H4-G4 | I3: =I4-H4 | J3: =J4-I4 | K3: =K4-F4 | L3: =L4-K4 | M3: =M4-L4 | N3: =N4-M4 | O3: =O4-N4 | P3: =P4-K4 | Q3: =Q4-P4 | R3: =R4-Q4 | S3: =S4-R4 | T3: =T4-S4 | U3: =U4-P4 | V3: =V4-U4 | W3: =W4-V4 | X3: =X4-W4 | Y3: =Y4-X4 | Z3: =Z4-U4 | AA3: =AA4-Z4 | AB3: =AB4-AA4 | AC3: =AC4-AB4 | AD3: =AD4-AC4 | AE3: =AE4-Z4 | AF3: =AF4-AE4 | AG3: =AG4-AF4 | AH3: =AH4-AG4 | AI3: =AI4-AH4 | AJ3: =AJ4-AE4 | AK3: =AK4-AJ4 | AL3: =AL4-AK4 | AM3: =AM4-AL4 | AN3: =AN4-AM4 | AO3: =AO4-AJ4 | AP3: =AP4-AO4 | AQ3: =AQ4-AP4 | AR3: =AR4-AQ4 | AS3: =AS4-AR4 | AT3: =AT4-AO4 | AU3: =AU4-AT4 | AV3: =AV4-AU4 | AW3: =AW4-AV4 | AX3: =AX4-AW4 | AY3: =AY4-AT4 | AZ3: =AZ4-AY4 | BA3: =BA4-AZ4 | BB3: =BB4-BA4 | BC3: =BC4-BB4 | BD3: =BD4-AY4 | BE3: =BE4-BD4 | BF3: =BF4-BE4 | BG3: =BG4-BF4 | BH3: =BH4-BG4 | BI3: =BI4-BD4 | BJ3: =BJ4-BI4 | BK3: =BK4-BJ4 | BL3: =BL4-BK4 | BM3: =BM4-BL4 | BN3: =BN4-BI4 | BO3: =BO4-BN4 | BP3: =BP4-BO4 | BQ3: =BQ4-BP4 | BR3: =BR4-BQ4 | BS3: =BS4-BN4 | BT3: =BT4-BS4 | BU3: =BU4-BT4 | BV3: =BV4-BU4 | BW3: =BW4-BV4 | BX3: =BX4-BS4 | BY3: =BY4-BX4 | BZ3: =BZ4-BY4 | CA3: =CA4-BZ4
A4: =FP.DataSourceName | B4: =IF(AND(MO.RealTimeStockPriceToggle,MO.LastPriceFormula<>"N/A"),"ON","OFF") | C4: 40180 | D4: 40544 | E4: 40908 | F4: 41272 | G4: 41363 | H4: 41454 | I4: 41545 | J4: =K4 | K4: 41636 | L4: 41727 | M4: 41818 | N4: 41909 | O4: =P4 | P4: 42007 | Q4: 42098 | R4: 42189 | S4: 42280 | T4: =U4 | U4: 42371 | V4: 42462 | W4: 42553 | X4: 42644 | Y4: =Z4 | Z4: 42735 | AA4: 42826 | AB4: 42917 | AC4: 43008 | AD4: =AE4 | AE4: 43099 | AF4: 43190 | AG4: 43281 | AH4: 43372 | AI4: =AJ4 | AJ4: 43463 | AK4: 43554 | AL4: 43645 | AM4: 43736 | AN4: =AO4 | AO4: 43827 | AP4: 43918 | AQ4: 44009 | AR4: 44100 | AS4: =AT4 | AT4: 44198 | AU4: 44289 | AV4: 44380 | AW4: 44471 | AX4: =AY4 | AY4: 44562 | AZ4: 44653 | BA4: 44744 | BB4: 44835 | BC4: =BD4 | BD4: 44926 | BE4: 45016 | BF4: 45107 | BG4: 45199 | BH4: =BI4 | BI4: 45291 | BJ4: 45382 | BK4: 45473 | BL4: 45565 | BM4: =BN4 | BN4: 45657 | BO4: 45747 | BP4: 45838 | BQ4: 45930 | BR4: =DATE(YEAR(BQ4),12,31) | BS4: =BR4 | BT4: =+EDATE(BS4,3) | BU4: =+EDATE(BT4,3) | BV4: =+EDATE(BU4,3) | BW4: =DATE(YEAR(BV4),12,31) | BX4: =BW4 | BY4: =EOMONTH(BX4,12) | BZ4: =EOMONTH(BY4,12) | CA4: =EOMONTH(BZ4,12)
A5: =MO.ReportCurrency | C5: FY2009 | D5: =CONCATENATE("FY",RIGHT(C5,4)+1) | E5: =CONCATENATE("FY",RIGHT(D5,4)+1) | F5: =CONCATENATE("FY",RIGHT(E5,4)+1) | G5: =CONCATENATE("Q1","-",RIGHT(F5,4)+1) | H5: =CONCATENATE("Q2","-",RIGHT(G5,4)) | I5: =CONCATENATE("Q3","-",RIGHT(H5,4)) | J5: =CONCATENATE("Q4","-",RIGHT(I5,4)) | K5: =CONCATENATE("FY",RIGHT(F5,4)+1) | L5: =CONCATENATE("Q1","-",RIGHT(K5,4)+1) | M5: =CONCATENATE("Q2","-",RIGHT(L5,4)) | N5: =CONCATENATE("Q3","-",RIGHT(M5,4)) | O5: =CONCATENATE("Q4","-",RIGHT(N5,4)) | P5: =CONCATENATE("FY",RIGHT(K5,4)+1) | Q5: =CONCATENATE("Q1","-",RIGHT(P5,4)+1) | R5: =CONCATENATE("Q2","-",RIGHT(Q5,4)) | S5: =CONCATENATE("Q3","-",RIGHT(R5,4)) | T5: =CONCATENATE("Q4","-",RIGHT(S5,4)) | U5: =CONCATENATE("FY",RIGHT(P5,4)+1) | V5: =CONCATENATE("Q1","-",RIGHT(U5,4)+1) | W5: =CONCATENATE("Q2","-",RIGHT(V5,4)) | X5: =CONCATENATE("Q3","-",RIGHT(W5,4)) | Y5: =CONCATENATE("Q4","-",RIGHT(X5,4)) | Z5: =CONCATENATE("FY",RIGHT(U5,4)+1) | AA5: =CONCATENATE("Q1","-",RIGHT(Z5,4)+1) | AB5: =CONCATENATE("Q2","-",RIGHT(AA5,4)) | AC5: =CONCATENATE("Q3","-",RIGHT(AB5,4)) | AD5: =CONCATENATE("Q4","-",RIGHT(AC5,4)) | AE5: =CONCATENATE("FY",RIGHT(Z5,4)+1) | AF5: =CONCATENATE("Q1","-",RIGHT(AE5,4)+1) | AG5: =CONCATENATE("Q2","-",RIGHT(AF5,4)) | AH5: =CONCATENATE("Q3","-",RIGHT(AG5,4)) | AI5: =CONCATENATE("Q4","-",RIGHT(AH5,4)) | AJ5: =CONCATENATE("FY",RIGHT(AE5,4)+1) | AK5: =CONCATENATE("Q1","-",RIGHT(AJ5,4)+1) | AL5: =CONCATENATE("Q2","-",RIGHT(AK5,4)) | AM5: =CONCATENATE("Q3","-",RIGHT(AL5,4)) | AN5: =CONCATENATE("Q4","-",RIGHT(AM5,4)) | AO5: =CONCATENATE("FY",RIGHT(AJ5,4)+1) | AP5: =CONCATENATE("Q1","-",RIGHT(AO5,4)+1) | AQ5: =CONCATENATE("Q2","-",RIGHT(AP5,4)) | AR5: =CONCATENATE("Q3","-",RIGHT(AQ5,4)) | AS5: =CONCATENATE("Q4","-",RIGHT(AR5,4)) | AT5: =CONCATENATE("FY",RIGHT(AO5,4)+1) | AU5: =CONCATENATE("Q1","-",RIGHT(AT5,4)+1) | AV5: =CONCATENATE("Q2","-",RIGHT(AU5,4)) | AW5: =CONCATENATE("Q3","-",RIGHT(AV5,4)) | AX5: =CONCATENATE("Q4","-",RIGHT(AW5,4)) | AY5: =CONCATENATE("FY",RIGHT(AT5,4)+1) | AZ5: =CONCATENATE("Q1","-",RIGHT(AY5,4)+1) | BA5: =CONCATENATE("Q2","-",RIGHT(AZ5,4)) | BB5: =CONCATENATE("Q3","-",RIGHT(BA5,4)) | BC5: =CONCATENATE("Q4","-",RIGHT(BB5,4)) | BD5: =CONCATENATE("FY",RIGHT(AY5,4)+1) | BE5: =CONCATENATE("Q1","-",RIGHT(BD5,4)+1) | BF5: =CONCATENATE("Q2","-",RIGHT(BE5,4)) | BG5: =CONCATENATE("Q3","-",RIGHT(BF5,4)) | BH5: =CONCATENATE("Q4","-",RIGHT(BG5,4)) | BI5: =CONCATENATE("FY",RIGHT(BD5,4)+1) | BJ5: =CONCATENATE("Q1","-",RIGHT(BI5,4)+1) | BK5: =CONCATENATE("Q2","-",RIGHT(BJ5,4)) | BL5: =CONCATENATE("Q3","-",RIGHT(BK5,4)) | BM5: =CONCATENATE("Q4","-",RIGHT(BL5,4)) | BN5: =CONCATENATE("FY",RIGHT(BI5,4)+1) | BO5: =CONCATENATE("Q1","-",RIGHT(BN5,4)+1) | BP5: =CONCATENATE("Q2","-",RIGHT(BO5,4)) | BQ5: =CONCATENATE("Q3","-",RIGHT(BP5,4)) | BR5: =CONCATENATE("Q4","-",RIGHT(BQ5,4)) | BS5: =CONCATENATE("FY",RIGHT(BN5,4)+1) | BT5: =CONCATENATE("Q1","-",RIGHT(BS5,4)+1) | BU5: =CONCATENATE("Q2","-",RIGHT(BT5,4)) | BV5: =CONCATENATE("Q3","-",RIGHT(BU5,4)) | BW5: =CONCATENATE("Q4","-",RIGHT(BV5,4)) | BX5: =CONCATENATE("FY",RIGHT(BS5,4)+1) | BY5: =CONCATENATE("FY",RIGHT(BX5,4)+1) | BZ5: =CONCATENATE("FY",RIGHT(BY5,4)+1) | CA5: =CONCATENATE("FY",RIGHT(BZ5,4)+1)
A6: Revenue Build
A7: Functional Verification (including Emulation Hardware revenue), mm | C7: =C24*C454 | D7: =D24*D454 | E7: =E24*E454 | F7: =F24*F454 | G7: =G24*G454 | H7: =H24*H454 | I7: =I24*I454 | J7: =J24*J454 | ... BL7: =BL24*BL454
A8: Y/Y Functional Verification (including Emulation Hardware revenue) growth, % | D8: =D7/C7-1 | E8: =E7/D7-1 | F8: =F7/E7-1 | K8: =K7/F7-1 | L8: =L7/G7-1 | M8: =M7/H7-1 | N8: =N7/I7-1 | O8: =O7/J7-1 | P8: =P7/K7-1 | Q8: =Q7/L7-1 | R8: =R7/M7-1 | ... BL8: =BL7/BG7-1
A9: Digital IC Design and Signoff revenue, mm | C9: =C25*C454 | D9: =D25*D454 | E9: =E25*E454 | F9: =F25*F454 | G9: =G25*G454 | H9: =H25*H454 | I9: =I25*I454 | J9: =J25*J454 | ... BL9: =BL25*BL454
A10: Y/Y Digital IC Design and Signoff revenue growth, % | D10: =D9/C9-1 | E10: =E9/D9-1 | F10: =F9/E9-1 | K10: =K9/F9-1 | L10: =L9/G9-1 | M10: =M9/H9-1 | N10: =N9/I9-1 | O10: =O9/J9-1 | P10: =P9/K9-1 | Q10: =Q9/L9-1 | R10: =R9/M9-1 | ... BL10: =BL9/BG9-1
A11: Custom IC Design revenue, mm | C11: =C26*C454 | D11: =D26*D454 | E11: =E26*E454 | F11: =F26*F454 | G11: =G26*G454 | H11: =H26*H454 | I11: =I26*I454 | J11: =J26*J454 | ... BL11: =BL26*BL454
A12: Y/Y Custom IC Design revenue growth, % | D12: =D11/C11-1 | E12: =E11/D11-1 | F12: =F11/E11-1 | K12: =K11/F11-1 | L12: =L11/G11-1 | M12: =M11/H11-1 | N12: =N11/I11-1 | O12: =O11/J11-1 | P12: =P11/K11-1 | Q12: =Q11/L11-1 | R12: =R11/M11-1 | ... BL12: =BL11/BG11-1
A13: Core EDA revenue, mm | C13: =+C11+C9+C7 | D13: =+D11+D9+D7 | E13: =+E11+E9+E7 | F13: =+F11+F9+F7 | G13: =+G11+G9+G7 | H13: =+H11+H9+H7 | I13: =+I11+I9+I7 | J13: =+J11+J9+J7 | ... BL13: =+BL11+BL9+BL7 | BM13: =BM27*BM454 | BN13: =BN27*BN454 | BO13: =BO27*BO454 | BP13: =BP27*BP454 | BQ13: =BQ27*BQ454 | BR13: =BM13*(1+BR14) | BS13: =SUM(BO13,BP13,BQ13,BR13) | BT13: =BO13*(1+BT14) | BU13: =BP13*(1+BU14) | BV13: =BQ13*(1+BV14) | BW13: =BR13*(1+BW14) | BX13: =SUM(BT13,BU13,BV13,BW13) | BY13: =BX13*(1+BY14) | BZ13: =BY13*(1+BZ14) | CA13: =BZ13*(1+CA14)
A14: Y/Y Core EDA revenue growth, % | D14: =D13/C13-1 | E14: =E13/D13-1 | F14: =F13/E13-1 | K14: =K13/F13-1 | L14: =L13/G13-1 | M14: =M13/H13-1 | N14: =N13/I13-1 | O14: =O13/J13-1 | P14: =P13/K13-1 | Q14: =Q13/L13-1 | R14: =R13/M13-1 | ... BQ14: =BQ13/BL13-1 | BR14: 0.05 | BS14: =BS13/BN13-1 | BT14: 0.05 | BU14: 0.1 | BV14: 0.01 | BW14: 0.01 | BX14: =BX13/BS13-1 | BY14: 0.02 | BZ14: 0.02 | CA14: 0.02
A15: Design for Manufacturing revenue, mm | C15: =C28*C454 | D15: =D28*D454 | E15: =E28*E454 | F15: =F28*F454
A16: System Interconnect and Analysis revenue, mm | C16: =C29*C454 | D16: =D29*D454 | E16: =E29*E454 | F16: =F29*F454 | G16: =G29*G454 | H16: =H29*H454 | I16: =I29*I454 | J16: =J29*J454 | ... BQ16: =BQ29*BQ454 | BR16: =BM16*(1+BR17) | BS16: =SUM(BO16,BP16,BQ16,BR16) | BT16: =BO16*(1+BT17) | BU16: =BP16*(1+BU17) | BV16: =BQ16*(1+BV17) | BW16: =BR16*(1+BW17) | BX16: =SUM(BT16,BU16,BV16,BW16) | BY16: =BX16*(1+BY17) | BZ16: =BY16*(1+BZ17) | CA16: =BZ16*(1+CA17)
A17: Y/Y System Interconnect and Analysis revenue growth, % | D17: =D16/C16-1 | E17: =E16/D16-1 | F17: =F16/E16-1 | K17: =K16/F16-1 | L17: =L16/G16-1 | M17: =M16/H16-1 | N17: =N16/I16-1 | O17: =O16/J16-1 | P17: =P16/K16-1 | Q17: =Q16/L16-1 | R17: =R16/M16-1 | ... BQ17: =BQ16/BL16-1 | BR17: 0.05 | BS17: =BS16/BN16-1 | BT17: 0.12 | BU17: 0.12 | BV17: 0.005 | BW17: 0.005 | BX17: =BX16/BS16-1 | BY17: 0.01 | BZ17: 0.01 | CA17: 0.01
A18: IP revenue, mm | C18: =C30*C454 | D18: =D30*D454 | E18: =E30*E454 | F18: =F30*F454 | G18: =G30*G454 | H18: =H30*H454 | I18: =I30*I454 | J18: =J30*J454 | ... BQ18: =BQ30*BQ454 | BR18: =BM18*(1+BR19) | BS18: =SUM(BO18,BP18,BQ18,BR18) | BT18: =BO18*(1+BT19) | BU18: =BP18*(1+BU19) | BV18: =BQ18*(1+BV19) | BW18: =BR18*(1+BW19) | BX18: =SUM(BT18,BU18,BV18,BW18) | BY18: =BX18*(1+BY19) | BZ18: =BY18*(1+BZ19) | CA18: =BZ18*(1+CA19)
A19: Y/Y IP revenue growth, % | D19: =D18/C18-1 | E19: =E18/D18-1 | F19: =F18/E18-1 | K19: =K18/F18-1 | L19: =L18/G18-1 | M19: =M18/H18-1 | N19: =N18/I18-1 | O19: =O18/J18-1 | P19: =P18/K18-1 | Q19: =Q18/L18-1 | R19: =R18/M18-1 | ... BQ19: =BQ18/BL18-1 | BR19: 0.05 | BS19: =BS18/BN18-1 | BT19: 0.12 | BU19: 0.12 | BV19: 0.005 | BW19: 0.005 | BX19: =BX18/BS18-1 | BY19: 0.01 | BZ19: 0.01 | CA19: 0.01
A20: Total revenue, mm | C20: =+C18+C16+C15+C13 | D20: =+D18+D16+D15+D13 | E20: =+E18+E16+E15+E13 | F20: =+F18+F16+F15+F13 | G20: =+G18+G16+G15+G13 | H20: =+H18+H16+H15+H13 | I20: =+I18+I16+I15+I13 | J20: =+J18+J16+J15+J13 | ... CA20: =+CA18+CA16+CA15+CA13
A21: =A455 | BR21: =BR455 | BS21: =BS455 | BT21: =BT455 | BU21: =BU455 | BV21: =BV455 | BW21: =BW455 | BX21: =BX455 | BY21: =BY455 | ... CA21: =CA455
A22: Y/Y Total revenue growth, % | D22: =D20/C20-1 | E22: =E20/D20-1 | F22: =F20/E20-1 | K22: =K20/F20-1 | L22: =L20/G20-1 | M22: =M20/H20-1 | N22: =N20/I20-1 | O22: =O20/J20-1 | P22: =P20/K20-1 | Q22: =Q20/L20-1 | R22: =R20/M20-1 | ... BX22: =BX20/BS20-1 | BY22: =BY20/BX20-1 | BZ22: =BZ20/BY20-1 | CA22: =CA20/BZ20-1
A24: Functional Verification, including Emulation Hardware revenue mix, % | C24: 0.22 | D24: 0.24 | E24: 0.3 | F24: 0.3 | G24: 0.22 | H24: 0.22 | I24: =24%+1% | J24: 0.25 | K24: 0.23 | L24: 0.23 | M24: 0.21 | N24: 0.23 | O24: 0.21 | P24: 0.22 | Q24: 0.23 | R24: 0.21 | S24: 0.23 | T24: 0.25 | U24: 0.23 | V24: 0.26 | W24: 0.27 | X24: 0.24 | Y24: 0.25 | Z24: 0.25 | AA24: 0.23 | AB24: 0.23 | AC24: 0.21 | AD24: 0.23 | AE24: 0.22 | AF24: 0.26 | AG24: 0.23 | AH24: 0.22 | AI24: 0.25 | AJ24: 0.24 | AK24: 0.24 | AL24: 0.22 | AM24: 0.2 | AN24: 0.24 | AO24: 0.23 | AP24: 0.23 | AQ24: 0.24 | AR24: 0.23 | AS24: 0.19 | AT24: 0.22 | AU24: 0.26 | AV24: 0.25 | AW24: 0.23 | AX24: 0.21 | AY24: 0.24 | AZ24: 0.28 | BA24: 0.24 | BB24: 0.25 | BC24: 0.25 | BD24: 0.26 | BE24: 0.32 | BF24: 0.27 | BG24: 0.26 | BH24: 0.24 | BI24: 0.27 | BJ24: 0.25 | BK24: 0.25 | BL24: 0.27
A25: Digital IC Design and Signoff revenue mix, % | C25: 0.21 | D25: 0.23 | E25: 0.22 | F25: 0.23 | G25: 0.33 | H25: 0.31 | I25: 0.29 | J25: 0.29 | K25: 0.3 | L25: 0.3 | M25: 0.3 | N25: 0.29 | O25: 0.28 | P25: 0.29 | Q25: 0.28 | R25: 0.29 | S25: 0.28 | T25: 0.28 | U25: 0.28 | V25: 0.3 | W25: 0.27 | X25: 0.28 | Y25: 0.3 | Z25: 0.29 | AA25: 0.29 | AB25: 0.3 | AC25: 0.3 | AD25: 0.29 | AE25: 0.29 | AF25: 0.3 | AG25: 0.3 | AH25: 0.3 | AI25: 0.28 | AJ25: 0.29 | AK25: 0.3 | AL25: 0.31 | AM25: 0.3 | AN25: 0.29 | AO25: 0.3 | AP25: 0.29 | AQ25: 0.28 | AR25: 0.27 | AS25: 0.31 | AT25: 0.29 | AU25: 0.27 | AV25: 0.28 | AW25: 0.29 | AX25: 0.29 | AY25: 0.29 | AZ25: 0.27 | BA25: 0.27 | BB25: 0.29 | BC25: 0.28 | BD25: 0.28 | BE25: 0.25 | BF25: 0.27 | BG25: 0.28 | BH25: 0.29 | BI25: 0.27 | BJ25: 0.29 | BK25: 0.27 | BL25: 0.24
A26: Custom IC Design revenue mix, % | C26: 0.27 | D26: 0.26 | E26: 0.22 | F26: 0.23 | G26: 0.28 | H26: 0.28 | I26: 0.26 | J26: 0.26 | K26: 0.27 | L26: 0.27 | M26: 0.28 | N26: 0.27 | O26: 0.28 | P26: 0.27 | Q26: 0.27 | R26: 0.27 | S26: 0.26 | T26: 0.25 | U26: 0.26 | V26: 0.25 | W26: 0.26 | X26: 0.27 | Y26: 0.25 | Z26: 0.25 | AA26: 0.26 | AB26: 0.26 | AC26: 0.28 | AD26: 0.26 | AE26: 0.27 | AF26: 0.26 | AG26: 0.26 | AH26: 0.26 | AI26: 0.25 | AJ26: 0.26 | AK26: 0.25 | AL26: 0.26 | AM26: 0.26 | AN26: 0.25 | AO26: 0.25 | AP26: 0.25 | AQ26: 0.24 | AR26: 0.24 | AS26: 0.26 | AT26: 0.25 | AU26: 0.23 | AV26: 0.23 | AW26: 0.23 | AX26: 0.24 | AY26: 0.23 | AZ26: 0.22 | BA26: 0.23 | BB26: 0.22 | BC26: 0.22 | BD26: 0.22 | BE26: 0.2 | BF26: 0.22 | BG26: 0.22 | BH26: 0.22 | BI26: 0.22 | BJ26: 0.22 | BK26: 0.21 | BL26: 0.19
A27: Core EDA revenue mix, % | C27: =SUM(C24:C26) | D27: =SUM(D24:D26) | E27: =SUM(E24:E26) | F27: =SUM(F24:F26) | G27: =SUM(G24:G26) | H27: =SUM(H24:H26) | I27: =SUM(I24:I26) | J27: =SUM(J24:J26) | ... BL27: =SUM(BL24:BL26) | BM27: 0.68 | BN27: 0.71 | BO27: 0.71 | BP27: 0.71 | BQ27: 0.71
A28: Design for Manufacturing revenue mix, % | C28: 0.07 | D28: 0.07 | E28: 0.07 | F28: 0.06
A29: System Interconnect and Analysis revenue mix, % | C29: 0.11 | D29: 0.09 | E29: 0.09 | F29: 0.09 | G29: 0.1 | H29: 0.11 | I29: 0.1 | J29: 0.1 | K29: 0.11 | L29: 0.1 | M29: 0.11 | N29: 0.1 | O29: 0.11 | P29: 0.11 | Q29: 0.11 | R29: 0.11 | S29: 0.1 | T29: 0.1 | U29: 0.11 | V29: 0.09 | W29: 0.1 | X29: 0.1 | Y29: 0.09 | Z29: 0.1 | AA29: 0.1 | AB29: 0.1 | AC29: 0.1 | AD29: 0.1 | AE29: 0.1 | AF29: 0.09 | AG29: 0.09 | AH29: 0.09 | AI29: 0.09 | AJ29: 0.09 | AK29: 0.09 | AL29: 0.1 | AM29: 0.09 | AN29: 0.09 | AO29: 0.09 | AP29: 0.09 | AQ29: 0.1 | AR29: 0.11 | AS29: 0.11 | AT29: 0.1 | AU29: 0.1 | AV29: 0.11 | AW29: 0.11 | AX29: 0.12 | AY29: 0.11 | AZ29: 0.1 | BA29: 0.12 | BB29: 0.12 | BC29: 0.13 | BD29: 0.12 | BE29: 0.12 | BF29: 0.13 | BG29: 0.13 | BH29: 0.12 | BI29: 0.12 | BJ29: 0.12 | BK29: 0.14 | BL29: 0.16 | BM29: 0.19 | BN29: 0.16 | BO29: 0.15 | BP29: 0.16 | BQ29: 0.15 | BR29: =BR16/BR20 | BS29: =BS16/BS20 | BT29: =BT16/BT20 | BU29: =BU16/BU20 | BV29: =BV16/BV20 | BW29: =BW16/BW20 | BX29: =BX16/BX20 | BY29: =BY16/BY20 | ... CA29: =CA16/CA20
A30: IP revenue mix, % | C30: 0.12 | D30: 0.11 | E30: 0.1 | F30: 0.09 | G30: 0.07 | H30: 0.08 | I30: 0.1 | J30: 0.1 | K30: 0.09 | L30: 0.1 | M30: 0.1 | N30: 0.11 | O30: 0.12 | P30: 0.11 | Q30: 0.11 | R30: 0.12 | S30: 0.13 | T30: 0.12 | U30: 0.12 | V30: 0.1 | W30: 0.1 | X30: 0.11 | Y30: 0.11 | Z30: 0.11 | AA30: 0.12 | AB30: 0.11 | AC30: 0.11 | AD30: 0.12 | AE30: 0.12 | AF30: 0.09 | AG30: 0.12 | AH30: 0.13 | AI30: 0.13 | AJ30: 0.12 | AK30: 0.12 | AL30: 0.11 | AM30: 0.15 | AN30: 0.13 | AO30: 0.13 | AP30: 0.14 | AQ30: 0.14 | AR30: 0.15 | AS30: 0.13 | AT30: 0.14 | AU30: 0.14 | AV30: 0.13 | AW30: 0.14 | AX30: 0.14 | AY30: 0.13 | AZ30: 0.13 | BA30: 0.14 | BB30: 0.12 | BC30: 0.12 | BD30: 0.12 | BE30: 0.11 | BF30: 0.11 | BG30: 0.11 | BH30: 0.13 | BI30: 0.12 | BJ30: 0.12 | BK30: 0.13 | BL30: 0.14 | BM30: 0.13 | BN30: 0.13 | BO30: 0.14 | BP30: 0.13 | BQ30: 0.14 | BR30: =BR18/BR20 | BS30: =BS18/BS20 | BT30: =BT18/BT20 | BU30: =BU18/BU20 | BV30: =BV18/BV20 | BW30: =BW18/BW20 | BX30: =BX18/BX20 | BY30: =BY18/BY20 | ... CA30: =CA18/CA20
A31: Total revenue mix, % | C31: =SUM(C27:C30) | D31: =SUM(D27:D30) | E31: =SUM(E27:E30) | F31: =SUM(F27:F30) | G31: =SUM(G27:G30) | H31: =SUM(H27:H30) | I31: =SUM(I27:I30) | J31: =SUM(J27:J30) | ... CA31: =SUM(CA27:CA30)
A33: Operating Expense Forecasting
A34: Net revenue, mm | C34: =C454 | D34: =D454 | E34: =E454 | F34: =F454 | G34: =G454 | H34: =H454 | I34: =I454 | J34: =J454 | ... BQ34: =BQ454 | BR34: =BR20 | BS34: =SUM(BO34,BP34,BQ34,BR34) | BT34: =BT20 | BU34: =BU20 | BV34: =BV20 | BW34: =BW20 | BX34: =SUM(BT34,BU34,BV34,BW34) | BY34: =BY20 | BZ34: =BZ20 | CA34: =CA20
A35: Total cost of revenue, mm | C35: =C346 | D35: =D346 | E35: =E346 | F35: =F346 | G35: =G346 | H35: =H346 | I35: =I346 | J35: =J346 | ... BQ35: =BQ346 | BR35: =BR34-BR36 | BS35: =SUM(BO35,BP35,BQ35,BR35) | BT35: =BT34-BT36 | BU35: =BU34-BU36 | BV35: =BV34-BV36 | BW35: =BW34-BW36 | BX35: =SUM(BT35,BU35,BV35,BW35) | BY35: =BY34-BY36 | BZ35: =BZ34-BZ36 | CA35: =CA34-CA36
A36: GAAP Gross Profit, mm | C36: =C34-C35 | D36: =D34-D35 | E36: =E34-E35 | F36: =F34-F35 | G36: =G34-G35 | H36: =H34-H35 | I36: =I34-I35 | J36: =J34-J35 | ... BQ36: =BQ34-BQ35 | BR36: =BR45-BR44-BR43-BR41 | BS36: =BS34-BS35 | BT36: =BT45-BT44-BT43-BT41 | BU36: =BU45-BU44-BU43-BU41 | BV36: =BV45-BV44-BV43-BV41 | BW36: =BW45-BW44-BW43-BW41 | BX36: =BX34-BX35 | BY36: =BY45-BY44-BY43-BY41 | BZ36: =BZ45-BZ44-BZ43-BZ41 | CA36: =CA45-CA44-CA43-CA41
A37: Y/Y GAAP Gross Profit growth, % | D37: =D36/C36-1 | E37: =E36/D36-1 | F37: =F36/E36-1 | K37: =K36/F36-1 | L37: =L36/G36-1 | M37: =M36/H36-1 | N37: =N36/I36-1 | O37: =O36/J36-1 | P37: =P36/K36-1 | Q37: =Q36/L36-1 | R37: =R36/M36-1 | ... BX37: =BX36/BS36-1 | BY37: =BY36/BX36-1 | BZ37: =BZ36/BY36-1 | CA37: =CA36/BZ36-1
A38: GAAP Gross Profit margin, % | C38: =C36/C34 | D38: =D36/D34 | E38: =E36/E34 | F38: =F36/F34 | G38: =G36/G34 | H38: =H36/H34 | I38: =I36/I34 | J38: =J36/J34 | ... CA38: =CA36/CA34
A39: Y/Y GAAP Gross Profit margin improvement, bps | D39: =(D38-C38)*10000 | E39: =(E38-D38)*10000 | F39: =(F38-E38)*10000 | K39: =(K38-F38)*10000 | L39: =(L38-G38)*10000 | M39: =(M38-H38)*10000 | N39: =(N38-I38)*10000 | O39: =(O38-J38)*10000 | P39: =(P38-K38)*10000 | Q39: =(Q38-L38)*10000 | R39: =(R38-M38)*10000 | ... BX39: =(BX38-BS38)*10000 | BY39: =(BY38-BX38)*10000 | BZ39: =(BZ38-BY38)*10000 | CA39: =(CA38-BZ38)*10000
A41: SBC COGS, mm | D41: =-D459 | E41: =-E459 | F41: =-F459 | G41: =-G459 | H41: =-H459 | I41: =-I459 | J41: =-J459 | K41: =-K459 | ... BQ41: =-BQ459 | BR41: =BR42*BR34 | BS41: =SUM(BO41,BP41,BQ41,BR41) | BT41: =BT42*BT34 | BU41: =BU42*BU34 | BV41: =BV42*BV34 | BW41: =BW42*BW34 | BX41: =SUM(BT41,BU41,BV41,BW41) | BY41: =BY42*BY34 | BZ41: =BZ42*BZ34 | CA41: =CA42*CA34
A42: SBC COGS as a % of revenue, % | D42: =D41/D34 | E42: =E41/E34 | F42: =F41/F34 | G42: =G41/G34 | H42: =H41/H34 | I42: =I41/I34 | J42: =J41/J34 | K42: =K41/K34 | ... BQ42: =BQ41/BQ34 | BR42: 0.003 | BS42: =BS41/BS34 | BT42: 0.005 | BU42: 0.005 | BV42: 0.005 | BW42: 0.005 | BX42: =BX41/BX34 | BY42: 0.005 | BZ42: 0.005 | CA42: 0.005
A43: Intangible amortization COGS, mm | D43: =-D460 | E43: =-E460 | F43: =-F460 | G43: =-G460 | H43: =-H460 | I43: =-I460 | J43: =-J460 | K43: =-K460 | ... BQ43: =-BQ460 | BR43: =BR166 | BS43: =SUM(BO43,BP43,BQ43,BR43) | BT43: =BT166 | BU43: =BU166 | BV43: =BV166 | BW43: =BW166 | BX43: =SUM(BT43,BU43,BV43,BW43) | BY43: =BY166 | BZ43: =BZ166 | CA43: =CA166
...

Sheet Exec Comp
A1: =MO.CompanyName
A2: =MO.Ticker | C2: =Model!C2 | D2: =Model!D2 | E2: =Model!E2 | F2: =Model!F2 | G2: =Model!G2 | H2: =Model!H2 | I2: =Model!I2 | J2: =Model!J2 | ... CA2: =Model!CA2
A3: =MO.TradingCurrency | B3: =MO.LastPrice | C3: =INDEX(MO_Common_FPDays,0,MATCH(C$5,MO_Common_ColumnHeader,0)) | D3: =INDEX(MO_Common_FPDays,0,MATCH(D$5,MO_Common_ColumnHeader,0)) | E3: =INDEX(MO_Common_FPDays,0,MATCH(E$5,MO_Common_ColumnHeader,0)) | F3: =INDEX(MO_Common_FPDays,0,MATCH(F$5,MO_Common_ColumnHeader,0)) | G3: =INDEX(MO_Common_FPDays,0,MATCH(G$5,MO_Common_ColumnHeader,0)) | H3: =INDEX(MO_Common_FPDays,0,MATCH(H$5,MO_Common_ColumnHeader,0)) | I3: =INDEX(MO_Common_FPDays,0,MATCH(I$5,MO_Common_ColumnHeader,0)) | J3: =INDEX(MO_Common_FPDays,0,MATCH(J$5,MO_Common_ColumnHeader,0)) | ... CA3: =INDEX(MO_Common_FPDays,0,MATCH(CA$5,MO_Common_ColumnHeader,0))
A4: =MO.DataSourceName | B4: =MO.RealTime | C4: =INDEX(MO_Common_QEndDate,0,MATCH(C$5,MO_Common_ColumnHeader,0)) | D4: =INDEX(MO_Common_QEndDate,0,MATCH(D$5,MO_Common_ColumnHeader,0)) | E4: =INDEX(MO_Common_QEndDate,0,MATCH(E$5,MO_Common_ColumnHeader,0)) | F4: =INDEX(MO_Common_QEndDate,0,MATCH(F$5,MO_Common_ColumnHeader,0)) | G4: =INDEX(MO_Common_QEndDate,0,MATCH(G$5,MO_Common_ColumnHeader,0)) | H4: =INDEX(MO_Common_QEndDate,0,MATCH(H$5,MO_Common_ColumnHeader,0)) | I4: =INDEX(MO_Common_QEndDate,0,MATCH(I$5,MO_Common_ColumnHeader,0)) | J4: =INDEX(MO_Common_QEndDate,0,MATCH(J$5,MO_Common_ColumnHeader,0)) | ... CA4: =INDEX(MO_Common_QEndDate,0,MATCH(CA$5,MO_Common_ColumnHeader,0))
A5: =MO.ReportFX | C5: =Model!C5 | D5: =Model!D5 | E5: =Model!E5 | F5: =Model!F5 | G5: =Model!G5 | H5: =Model!H5 | I5: =Model!I5 | J5: =Model!J5 | ... CA5: =Model!CA5
A6: Executive compensation
A7: Outgoing CEO - Base Pay, 000s | AY7: 720.192
A8: Outgoing CEO - Stock Awards, 000s | AY8: 4500.004
A9: Outgoing CEO - Option Awards, 000s | AY9: 4499.646
A10: Outgoing CEO - Non-equity incentive plans, 000s | AY10: 1372.29
A11: Outgoing CEO - All other compensation, 000s | AY11: 73.884
A12: Outgoing CEO - Total Comp, 000s | AY12: =SUM(AY7:AY11)
A13: Incoming CEO - Base Pay, 000s | AY13: 604.808
A14: Incoming CEO - Stock Awards, 000s | AY14: 2499.956
A15: Incoming CEO - Option Awards, 000s | AY15: 17496.404
A16: Incoming CEO - Non-equity incentive plans, 000s | AY16: 1109.054
A17: Incoming CEO - All other compensation, 000s | AY17: 25.572
A18: Incoming CEO - Total Comp, 000s | AY18: =SUM(AY13:AY17)
A20: CEO - Base Pay, 000s | AT20: 738.942 | AY20: =SUM(AY7,AY13) | BD20: 725 | BI20: 750
A21: CEO - Stock Awards, 000s | AT21: 3750 | AY21: =SUM(AY8,AY14) | BD21: 25318.495 | BI21: 7702.791
A22: CEO - Option Awards, 000s | AT22: 3748.545 | AY22: =SUM(AY9,AY15) | BD22: 4779.658 | BI22: 7689.913
A23: CEO - Non-equity incentive plans, 000s | AT23: 1353.419 | AY23: =SUM(AY10,AY16) | BD23: 1381.859 | BI23: 1187.386
A24: CEO - All other compensation, 000s | AT24: 13.734 | AY24: =SUM(AY11,AY17) | BD24: 11.022 | BI24: 11.772
A25: CEO - Total Comp, 000s | AT25: =SUM(AT20:AT24) | AY25: =SUM(AY20:AY24) | BD25: =SUM(BD20:BD24) | BI25: =SUM(BI20:BI24)
A26: CEO - comp tied to equity, % | AT26: =SUM(AT21,AT22)/AT25 | AY26: =SUM(AY21,AY22)/AY25 | BD26: =SUM(BD21,BD22)/BD25 | BI26: =SUM(BI21,BI22)/BI25
A27: Market Cap - EoP, mm | AT27: =Model!AT982 | AU27: =Model!AU982 | AV27: =Model!AV982 | AW27: =Model!AW982 | AX27: =Model!AX982 | AY27: =Model!AY982 | AZ27: =Model!AZ982 | BA27: =Model!BA982 | ... BQ27: =Model!BQ982
A29: CEO - Options 02/09/22 # of unexercised exercisable options, 000s | AT29: 500
A30: CEO - Options 02/09/22 exercise price, $ | AT30: 17.16
A32: CEO - Options 02/08/23 # of unexercised exercisable options, 000s | AT32: 500
A33: CEO - Options 02/08/23 exercise price, $ | AT33: 19.6
A35: CEO - Options 02/21/24 # of unexercised exercisable options, 000s | AT35: 407.291
A36: CEO - Options 02/21/24 # of unexercised unexercisable options, 000s | AT36: 17.709
A37: CEO - Options 02/21/24 exercise price, $ | AT37: 30.79
A39: CEO - Options 02/06/25 # of unexercised exercisable options, 000s | AT39: 190.754 | AY39: 95.724 | BD39: 99.886 | BI39: 99.886
A40: CEO - Options 02/06/25 # of unexercised unexercisable options, 000s | AT40: 78.547 | AY40: 4.162 | BD40: 0 | BI40: 0
A41: CEO - Options 02/06/25 exercise price, $ | AT41: 39.58 | AY41: 39.58 | BD41: 39.58 | BI41: 39.58
A43: CEO - Options 02/22/26 # of unexercised exercisable options, 000s | AT43: 94.177 | AY43: 65.981 | BD43: 89.269 | BI43: 93.151
A44: CEO - Options 02/22/26 # of unexercised unexercisable options, 000s | AT44: 111.302 | AY44: 27.17 | BD44: 3.882 | BI44: 0
A45: CEO - Options 02/22/26 exercise price, $ | AT45: 56.57 | AY45: 56.57 | BD45: 56.57 | BI45: 56.57
A47: CEO - Options 02/14/27 # of unexercised exercisable options, 000s | AT47: 41.257 | AY47: 32.917 | BD47: 50.873 | BI47: 68.828
...

Sheet Guidance
B1: =MO.CompanyName
B2: Most Recent Period: | F2: =UL.MRQ
I4: Guidance | M4: Model | P4: Difference vs. Mid | S4: Update Log
B5: Type | D5: Item | E5: Item Name | F5: Fiscal Period | G5: Base Period | I5: Low | J5: High | K5: Mid | M5: Type | N5: Output | P5: Absolute | Q5: Relative | S5: Date | T5: Link
A6: 958 | B6: =IF(INDEX(MO_SNA_IsHistoricalPeriod,,MATCH(F6,MO_Common_ColumnHeader,0)),"Historical","Forward") | D6: Recurring Revenue % | F6: FY2025 | I6: 0.8 | J6: 0.8 | K6: =AVERAGE(I6:J6) | M6: =IF(INDEX(MO_SNA_IsHistoricalPeriod,,MATCH(F6,MO_Common_ColumnHeader,0)),"Actual","Estimate") | N6: =IFERROR(INDEX(INDIRECT(E6),0,MATCH(F6,MO_Common_ColumnHeader,0)),"N/A") | P6: =IF(ISNUMBER(N6),N6-K6,"N/A") | Q6: =IFERROR(IF(ISNUMBER(N6),(N6-K6)/ABS(K6),"N/A"),"N/A") | S6: 45957 | T6: CFO Commentary
A7: 957 | B7: =IF(INDEX(MO_SNA_IsHistoricalPeriod,,MATCH(F7,MO_Common_ColumnHeader,0)),"Historical","Forward") | D7: Revenue from Beginning Backlog % | F7: FY2025 | I7: 0.7 | J7: 0.7 | K7: =AVERAGE(I7:J7) | M7: =IF(INDEX(MO_SNA_IsHistoricalPeriod,,MATCH(F7,MO_Common_ColumnHeader,0)),"Actual","Estimate") | N7: =IFERROR(INDEX(INDIRECT(E7),0,MATCH(F7,MO_Common_ColumnHeader,0)),"N/A") | P7: =IF(ISNUMBER(N7),N7-K7,"N/A") | Q7: =IFERROR(IF(ISNUMBER(N7),(N7-K7)/ABS(K7),"N/A"),"N/A") | S7: 45957 | T7: CFO Commentary
A8: 956 | B8: =IF(INDEX(MO_SNA_IsHistoricalPeriod,,MATCH(F8,MO_Common_ColumnHeader,0)),"Historical","Forward") | D8: =INDEX(INDIRECT(E8),0,COLUMN(MO_Common_Column_A)) | E8: MO_RIS_REV | F8: FY2025 | I8: 5262 | J8: 5292 | K8: =AVERAGE(I8:J8) | M8: =IF(INDEX(MO_SNA_IsHistoricalPeriod,,MATCH(F8,MO_Common_ColumnHeader,0)),"Actual","Estimate") | N8: =IFERROR(INDEX(INDIRECT(E8),0,MATCH(F8,MO_Common_ColumnHeader,0)),"N/A") | P8: =IF(ISNUMBER(N8),N8-K8,"N/A") | Q8: =IFERROR(IF(ISNUMBER(N8),(N8-K8)/ABS(K8),"N/A"),"N/A") | S8: 45957 | T8: CFO Commentary
A9: 955 | B9: =IF(INDEX(MO_SNA_IsHistoricalPeriod,,MATCH(F9,MO_Common_ColumnHeader,0)),"Historical","Forward") | D9: GAAP Operating Margin | E9: MO_MA_EBIT | F9: FY2025 | I9: 0.279 | J9: 0.289 | K9: =AVERAGE(I9:J9) | M9: =IF(INDEX(MO_SNA_IsHistoricalPeriod,,MATCH(F9,MO_Common_ColumnHeader,0)),"Actual","Estimate") | N9: =IFERROR(INDEX(INDIRECT(E9),0,MATCH(F9,MO_Common_ColumnHeader,0)),"N/A") | P9: =IF(ISNUMBER(N9),N9-K9,"N/A") | Q9: =IFERROR(IF(ISNUMBER(N9),(N9-K9)/ABS(K9),"N/A"),"N/A") | S9: 45957 | T9: CFO Commentary
A10: 954 | B10: =IF(INDEX(MO_SNA_IsHistoricalPeriod,,MATCH(F10,MO_Common_ColumnHeader,0)),"Historical","Forward") | D10: =INDEX(INDIRECT(E10),0,COLUMN(MO_Common_Column_A)) | E10: MO_MA_OperatingIncome_NONGAAP | F10: FY2025 | I10: 0.439 | J10: 0.449 | K10: =AVERAGE(I10:J10) | M10: =IF(INDEX(MO_SNA_IsHistoricalPeriod,,MATCH(F10,MO_Common_ColumnHeader,0)),"Actual","Estimate") | N10: =IFERROR(INDEX(INDIRECT(E10),0,MATCH(F10,MO_Common_ColumnHeader,0)),"N/A") | P10: =IF(ISNUMBER(N10),N10-K10,"N/A") | Q10: =IFERROR(IF(ISNUMBER(N10),(N10-K10)/ABS(K10),"N/A"),"N/A") | S10: 45957 | T10: CFO Commentary
A11: 953 | B11: =IF(INDEX(MO_SNA_IsHistoricalPeriod,,MATCH(F11,MO_Common_ColumnHeader,0)),"Historical","Forward") | D11: =INDEX(INDIRECT(E11),0,COLUMN(MO_Common_Column_A)) | E11: MO_RIS_EPS_WAD | F11: FY2025 | I11: 3.8 | J11: 3.86 | K11: =AVERAGE(I11:J11) | M11: =IF(INDEX(MO_SNA_IsHistoricalPeriod,,MATCH(F11,MO_Common_ColumnHeader,0)),"Actual","Estimate") | N11: =IFERROR(INDEX(INDIRECT(E11),0,MATCH(F11,MO_Common_ColumnHeader,0)),"N/A") | P11: =IF(ISNUMBER(N11),N11-K11,"N/A") | Q11: =IFERROR(IF(ISNUMBER(N11),(N11-K11)/ABS(K11),"N/A"),"N/A") | S11: 45957 | T11: CFO Commentary
A12: 952 | B12: =IF(INDEX(MO_SNA_IsHistoricalPeriod,,MATCH(F12,MO_Common_ColumnHeader,0)),"Historical","Forward") | D12: =INDEX(INDIRECT(E12),0,COLUMN(MO_Common_Column_A)) | E12: MO_RIS_EPS_WAD_Adj | F12: FY2025 | I12: 7.02 | J12: 7.08 | K12: =AVERAGE(I12:J12) | M12: =IF(INDEX(MO_SNA_IsHistoricalPeriod,,MATCH(F12,MO_Common_ColumnHeader,0)),"Actual","Estimate") | N12: =IFERROR(INDEX(INDIRECT(E12),0,MATCH(F12,MO_Common_ColumnHeader,0)),"N/A") | P12: =IF(ISNUMBER(N12),N12-K12,"N/A") | Q12: =IFERROR(IF(ISNUMBER(N12),(N12-K12)/ABS(K12),"N/A"),"N/A") | S12: 45957 | T12: CFO Commentary
A13: 951 | B13: =IF(INDEX(MO_SNA_IsHistoricalPeriod,,MATCH(F13,MO_Common_ColumnHeader,0)),"Historical","Forward") | D13: =INDEX(INDIRECT(E13),0,COLUMN(MO_Common_Column_A)) | E13: MO_CFS_CFO | F13: FY2025 | I13: 1650 | J13: 1750 | K13: =AVERAGE(I13:J13) | M13: =IF(INDEX(MO_SNA_IsHistoricalPeriod,,MATCH(F13,MO_Common_ColumnHeader,0)),"Actual","Estimate") | N13: =IFERROR(INDEX(INDIRECT(E13),0,MATCH(F13,MO_Common_ColumnHeader,0)),"N/A") | P13: =IF(ISNUMBER(N13),N13-K13,"N/A") | Q13: =IFERROR(IF(ISNUMBER(N13),(N13-K13)/ABS(K13),"N/A"),"N/A") | S13: 45957 | T13: CFO Commentary
A14: 950 | B14: =IF(INDEX(MO_SNA_IsHistoricalPeriod,,MATCH(F14,MO_Common_ColumnHeader,0)),"Historical","Forward") | D14: GAAP Other Income & Expense | F14: FY2025 | I14: -18 | J14: -10 | K14: =AVERAGE(I14:J14) | M14: =IF(INDEX(MO_SNA_IsHistoricalPeriod,,MATCH(F14,MO_Common_ColumnHeader,0)),"Actual","Estimate") | N14: =-IFERROR(INDEX(MO_RIS_IE_Net,0,MATCH(F14,MO_Common_ColumnHeader,0)),"N/A")-IFERROR(INDEX(MO_RIS_OI,0,MATCH(F14,MO_Common_ColumnHeader,0)),"N/A") | P14: =IF(ISNUMBER(N14),N14-K14,"N/A") | Q14: =IFERROR(IF(ISNUMBER(N14),(N14-K14)/ABS(K14),"N/A"),"N/A") | S14: 45957 | T14: CFO Commentary
A15: 949 | B15: =IF(INDEX(MO_SNA_IsHistoricalPeriod,,MATCH(F15,MO_Common_ColumnHeader,0)),"Historical","Forward") | D15: Non-GAAP Other Income & Expense | F15: FY2025 | I15: -33 | J15: -25 | K15: =AVERAGE(I15:J15) | M15: =IF(INDEX(MO_SNA_IsHistoricalPeriod,,MATCH(F15,MO_Common_ColumnHeader,0)),"Actual","Estimate") | N15: =-IFERROR(INDEX(MO_RIS_IE_Net_NONGAAP,0,MATCH(F15,MO_Common_ColumnHeader,0)),"N/A")-IFERROR(INDEX(MO_RIS_OI_NONGAAP,0,MATCH(F15,MO_Common_ColumnHeader,0)),"N/A") | P15: =IF(ISNUMBER(N15),N15-K15,"N/A") | Q15: =IFERROR(IF(ISNUMBER(N15),(N15-K15)/ABS(K15),"N/A"),"N/A") | S15: 45957 | T15: CFO Commentary
A16: 948 | B16: =IF(INDEX(MO_SNA_IsHistoricalPeriod,,MATCH(F16,MO_Common_ColumnHeader,0)),"Historical","Forward") | D16: GAAP Tax Rate | E16: MO_RIS_TaxRate | F16: FY2025 | I16: 0.29 | J16: 0.29 | K16: =AVERAGE(I16:J16) | M16: =IF(INDEX(MO_SNA_IsHistoricalPeriod,,MATCH(F16,MO_Common_ColumnHeader,0)),"Actual","Estimate") | N16: =IFERROR(INDEX(INDIRECT(E16),0,MATCH(F16,MO_Common_ColumnHeader,0)),"N/A") | P16: =IF(ISNUMBER(N16),N16-K16,"N/A") | Q16: =IFERROR(IF(ISNUMBER(N16),(N16-K16)/ABS(K16),"N/A"),"N/A") | S16: 45957 | T16: CFO Commentary
A17: 947 | B17: =IF(INDEX(MO_SNA_IsHistoricalPeriod,,MATCH(F17,MO_Common_ColumnHeader,0)),"Historical","Forward") | D17: =INDEX(INDIRECT(E17),0,COLUMN(MO_Common_Column_A)) | E17: MO_RIS_TaxRate_NONGAAP | F17: FY2025 | I17: 0.165 | J17: 0.165 | K17: =AVERAGE(I17:J17) | M17: =IF(INDEX(MO_SNA_IsHistoricalPeriod,,MATCH(F17,MO_Common_ColumnHeader,0)),"Actual","Estimate") | N17: =IFERROR(INDEX(INDIRECT(E17),0,MATCH(F17,MO_Common_ColumnHeader,0)),"N/A") | P17: =IF(ISNUMBER(N17),N17-K17,"N/A") | Q17: =IFERROR(IF(ISNUMBER(N17),(N17-K17)/ABS(K17),"N/A"),"N/A") | S17: 45957 | T17: CFO Commentary
A18: 946 | B18: =IF(INDEX(MO_SNA_IsHistoricalPeriod,,MATCH(F18,MO_Common_ColumnHeader,0)),"Historical","Forward") | D18: =INDEX(INDIRECT(E18),0,COLUMN(MO_Common_Column_A)) | E18: MO_RIS_ShareCount_WAD | F18: FY2025 | I18: 273 | J18: 275 | K18: =AVERAGE(I18:J18) | M18: =IF(INDEX(MO_SNA_IsHistoricalPeriod,,MATCH(F18,MO_Common_ColumnHeader,0)),"Actual","Estimate") | N18: =IFERROR(INDEX(INDIRECT(E18),0,MATCH(F18,MO_Common_ColumnHeader,0)),"N/A") | P18: =IF(ISNUMBER(N18),N18-K18,"N/A") | Q18: =IFERROR(IF(ISNUMBER(N18),(N18-K18)/ABS(K18),"N/A"),"N/A") | S18: 45957 | T18: CFO Commentary
A19: 945 | B19: =IF(INDEX(MO_SNA_IsHistoricalPeriod,,MATCH(F19,MO_Common_ColumnHeader,0)),"Historical","Forward") | D19: DSO | F19: FY2025 | I19: 50 | J19: 50 | K19: =AVERAGE(I19:J19) | M19: =IF(INDEX(MO_SNA_IsHistoricalPeriod,,MATCH(F19,MO_Common_ColumnHeader,0)),"Actual","Estimate") | N19: =IFERROR(INDEX(INDIRECT(E19),0,MATCH(F19,MO_Common_ColumnHeader,0)),"N/A") | P19: =IF(ISNUMBER(N19),N19-K19,"N/A") | Q19: =IFERROR(IF(ISNUMBER(N19),(N19-K19)/ABS(K19),"N/A"),"N/A") | S19: 45957 | T19: CFO Commentary
A20: 944 | B20: =IF(INDEX(MO_SNA_IsHistoricalPeriod,,MATCH(F20,MO_Common_ColumnHeader,0)),"Historical","Forward") | D20: =INDEX(INDIRECT(E20),0,COLUMN(MO_Common_Column_A)) | E20: MO_CFSum_Capex | F20: FY2025 | I20: -150 | J20: -150 | K20: =AVERAGE(I20:J20) | M20: =IF(INDEX(MO_SNA_IsHistoricalPeriod,,MATCH(F20,MO_Common_ColumnHeader,0)),"Actual","Estimate") | N20: =IFERROR(INDEX(INDIRECT(E20),0,MATCH(F20,MO_Common_ColumnHeader,0)),"N/A") | P20: =IF(ISNUMBER(N20),N20-K20,"N/A") | Q20: =IFERROR(IF(ISNUMBER(N20),(N20-K20)/ABS(K20),"N/A"),"N/A") | S20: 45957 | T20: CFO Commentary
A21: 943 | B21: =IF(INDEX(MO_SNA_IsHistoricalPeriod,,MATCH(F21,MO_Common_ColumnHeader,0)),"Historical","Forward") | D21: =INDEX(INDIRECT(E21),0,COLUMN(MO_Common_Column_A)) | E21: MO_RIS_SBC | F21: FY2025 | I21: 455 | J21: 455 | K21: =AVERAGE(I21:J21) | M21: =IF(INDEX(MO_SNA_IsHistoricalPeriod,,MATCH(F21,MO_Common_ColumnHeader,0)),"Actual","Estimate") | N21: =IFERROR(INDEX(INDIRECT(E21),0,MATCH(F21,MO_Common_ColumnHeader,0)),"N/A") | P21: =IF(ISNUMBER(N21),N21-K21,"N/A") | Q21: =IFERROR(IF(ISNUMBER(N21),(N21-K21)/ABS(K21),"N/A"),"N/A") | S21: 45957 | T21: CFO Commentary
A22: 942 | B22: =IF(INDEX(MO_SNA_IsHistoricalPeriod,,MATCH(F22,MO_Common_ColumnHeader,0)),"Historical","Forward") | D22: =INDEX(INDIRECT(E22),0,COLUMN(MO_Common_Column_A)) | E22: MO_RIS_Daintangibles | F22: FY2025 | I22: 103 | J22: 103 | K22: =AVERAGE(I22:J22) | M22: =IF(INDEX(MO_SNA_IsHistoricalPeriod,,MATCH(F22,MO_Common_ColumnHeader,0)),"Actual","Estimate") | N22: =IFERROR(INDEX(INDIRECT(E22),0,MATCH(F22,MO_Common_ColumnHeader,0)),"N/A") | P22: =IF(ISNUMBER(N22),N22-K22,"N/A") | Q22: =IFERROR(IF(ISNUMBER(N22),(N22-K22)/ABS(K22),"N/A"),"N/A") | S22: 45957 | T22: CFO Commentary
A23: 941 | B23: =IF(INDEX(MO_SNA_IsHistoricalPeriod,,MATCH(F23,MO_Common_ColumnHeader,0)),"Historical","Forward") | D23: Acquisition and integration-related costs | F23: FY2025 | I23: 115 | J23: 115 | K23: =AVERAGE(I23:J23) | M23: =IF(INDEX(MO_SNA_IsHistoricalPeriod,,MATCH(F23,MO_Common_ColumnHeader,0)),"Actual","Estimate") | N23: =IFERROR(INDEX(INDIRECT(E23),0,MATCH(F23,MO_Common_ColumnHeader,0)),"N/A") | P23: =IF(ISNUMBER(N23),N23-K23,"N/A") | Q23: =IFERROR(IF(ISNUMBER(N23),(N23-K23)/ABS(K23),"N/A"),"N/A") | S23: 45957 | T23: CFO Commentary
A24: 940 | B24: =IF(INDEX(MO_SNA_IsHistoricalPeriod,,MATCH(F24,MO_Common_ColumnHeader,0)),"Historical","Forward") | D24: Restructuring and other credits | F24: FY2025 | I24: 27 | J24: 27 | K24: =AVERAGE(I24:J24) | M24: =IF(INDEX(MO_SNA_IsHistoricalPeriod,,MATCH(F24,MO_Common_ColumnHeader,0)),"Actual","Estimate") | N24: =IFERROR(INDEX(INDIRECT(E24),0,MATCH(F24,MO_Common_ColumnHeader,0)),"N/A") | P24: =IF(ISNUMBER(N24),N24-K24,"N/A") | Q24: =IFERROR(IF(ISNUMBER(N24),(N24-K24)/ABS(K24),"N/A"),"N/A") | S24: 45957 | T24: CFO Commentary
A25: 939 | B25: =IF(INDEX(MO_SNA_IsHistoricalPeriod,,MATCH(F25,MO_Common_ColumnHeader,0)),"Historical","Forward") | D25: Non-Qualified deferred compensation expenses | F25: FY2025 | I25: 12 | J25: 12 | K25: =AVERAGE(I25:J25) | M25: =IF(INDEX(MO_SNA_IsHistoricalPeriod,,MATCH(F25,MO_Common_ColumnHeader,0)),"Actual","Estimate") | N25: =IFERROR(INDEX(INDIRECT(E25),0,MATCH(F25,MO_Common_ColumnHeader,0)),"N/A") | P25: =IF(ISNUMBER(N25),N25-K25,"N/A") | Q25: =IFERROR(IF(ISNUMBER(N25),(N25-K25)/ABS(K25),"N/A"),"N/A") | S25: 45957 | T25: CFO Commentary
A26: 938 | B26: =IF(INDEX(MO_SNA_IsHistoricalPeriod,,MATCH(F26,MO_Common_ColumnHeader,0)),"Historical","Forward") | D26: Special charges | F26: FY2025 | I26: 2 | J26: 2 | K26: =AVERAGE(I26:J26) | M26: =IF(INDEX(MO_SNA_IsHistoricalPeriod,,MATCH(F26,MO_Common_ColumnHeader,0)),"Actual","Estimate") | N26: =IFERROR(INDEX(INDIRECT(E26),0,MATCH(F26,MO_Common_ColumnHeader,0)),"N/A") | P26: =IF(ISNUMBER(N26),N26-K26,"N/A") | Q26: =IFERROR(IF(ISNUMBER(N26),(N26-K26)/ABS(K26),"N/A"),"N/A") | S26: 45957 | T26: CFO Commentary
A27: 937 | B27: =IF(INDEX(MO_SNA_IsHistoricalPeriod,,MATCH(F27,MO_Common_ColumnHeader,0)),"Historical","Forward") | D27: Loss related to contingent liability | F27: FY2025 | I27: 129 | J27: 129 | K27: =AVERAGE(I27:J27) | M27: =IF(INDEX(MO_SNA_IsHistoricalPeriod,,MATCH(F27,MO_Common_ColumnHeader,0)),"Actual","Estimate") | N27: =IFERROR(INDEX(INDIRECT(E27),0,MATCH(F27,MO_Common_ColumnHeader,0)),"N/A") | P27: =IF(ISNUMBER(N27),N27-K27,"N/A") | Q27: =IFERROR(IF(ISNUMBER(N27),(N27-K27)/ABS(K27),"N/A"),"N/A") | S27: 45957 | T27: CFO Commentary
A28: 936 | B28: =IF(INDEX(MO_SNA_IsHistoricalPeriod,,MATCH(F28,MO_Common_ColumnHeader,0)),"Historical","Forward") | D28: GAAP Operating Expenses | F28: FY2025 | I28: 3778 | J28: 3778 | K28: =AVERAGE(I28:J28) | M28: =IF(INDEX(MO_SNA_IsHistoricalPeriod,,MATCH(F28,MO_Common_ColumnHeader,0)),"Actual","Estimate") | N28: =IFERROR(INDEX(MO_RIS_COGS,0,MATCH(Guidance!F28,MO_Common_ColumnHeader,0))+INDEX(MO_RIS_RD,0,MATCH(Guidance!F28,MO_Common_ColumnHeader,0))+INDEX(MO_RIS_GA,0,MATCH(Guidance!F28,MO_Common_ColumnHeader,0))+INDEX(MO_RIS_SM,0,MATCH(Guidance!F28,MO_Common_ColumnHeader,0)),"N/A") | P28: =IF(ISNUMBER(N28),N28-K28,"N/A") | Q28: =IFERROR(IF(ISNUMBER(N28),(N28-K28)/ABS(K28),"N/A"),"N/A") | S28: 45957 | T28: CFO Commentary
A29: 935 | B29: =IF(INDEX(MO_SNA_IsHistoricalPeriod,,MATCH(F29,MO_Common_ColumnHeader,0)),"Historical","Forward") | D29: Non-GAAP Operating Expenses | F29: FY2025 | I29: 2935 | J29: 2935 | K29: =AVERAGE(I29:J29) | M29: =IF(INDEX(MO_SNA_IsHistoricalPeriod,,MATCH(F29,MO_Common_ColumnHeader,0)),"Actual","Estimate") | N29: =IFERROR(INDEX(MO_RIS_REV,0,MATCH(Guidance!F29,MO_Common_ColumnHeader,0))+INDEX(MO_RIS_RD_NONGAAP,0,MATCH(Guidance!F29,MO_Common_ColumnHeader,0))+INDEX(MO_RIS_GA_NONGAAP,0,MATCH(Guidance!F29,MO_Common_ColumnHeader,0))+INDEX(MO_RIS_SM_NONGAAP,0,MATCH(Guidance!F29,MO_Common_ColumnHeader,0))-INDEX(MO_RIS_GP_NONGAAP,0,MATCH(Guidance!F29,MO_Common_ColumnHeader,0)),"N/A") | P29: =IF(ISNUMBER(N29),N29-K29,"N/A") | Q29: =IFERROR(IF(ISNUMBER(N29),(N29-K29)/ABS(K29),"N/A"),"N/A") | S29: 45957 | T29: CFO Commentary
A30: 934
A31: 933 | B31: =IF(INDEX(MO_SNA_IsHistoricalPeriod,,MATCH(F31,MO_Common_ColumnHeader,0)),"Historical","Forward") | D31: =INDEX(INDIRECT(E31),0,COLUMN(MO_Common_Column_A)) | E31: MO_RIS_REV | F31: Q4-2025 | I31: 1405 | J31: 1435 | K31: =AVERAGE(I31:J31) | M31: =IF(INDEX(MO_SNA_IsHistoricalPeriod,,MATCH(F31,MO_Common_ColumnHeader,0)),"Actual","Estimate") | N31: =IFERROR(INDEX(INDIRECT(E31),0,MATCH(F31,MO_Common_ColumnHeader,0)),"N/A") | P31: =IF(ISNUMBER(N31),N31-K31,"N/A") | Q31: =IFERROR(IF(ISNUMBER(N31),(N31-K31)/ABS(K31),"N/A"),"N/A") | S31: 45957 | T31: CFO Commentary
A32: 932 | B32: =IF(INDEX(MO_SNA_IsHistoricalPeriod,,MATCH(F32,MO_Common_ColumnHeader,0)),"Historical","Forward") | D32: GAAP Operating Margin | E32: MO_MA_EBIT | F32: Q4-2025 | I32: 0.325 | J32: 0.335 | K32: =AVERAGE(I32:J32) | M32: =IF(INDEX(MO_SNA_IsHistoricalPeriod,,MATCH(F32,MO_Common_ColumnHeader,0)),"Actual","Estimate") | N32: =IFERROR(INDEX(INDIRECT(E32),0,MATCH(F32,MO_Common_ColumnHeader,0)),"N/A") | P32: =IF(ISNUMBER(N32),N32-K32,"N/A") | Q32: =IFERROR(IF(ISNUMBER(N32),(N32-K32)/ABS(K32),"N/A"),"N/A") | S32: 45957 | T32: CFO Commentary
A33: 931 | B33: =IF(INDEX(MO_SNA_IsHistoricalPeriod,,MATCH(F33,MO_Common_ColumnHeader,0)),"Historical","Forward") | D33: =INDEX(INDIRECT(E33),0,COLUMN(MO_Common_Column_A)) | E33: MO_MA_OperatingIncome_NONGAAP | F33: Q4-2025 | I33: 0.445 | J33: 0.455 | K33: =AVERAGE(I33:J33) | M33: =IF(INDEX(MO_SNA_IsHistoricalPeriod,,MATCH(F33,MO_Common_ColumnHeader,0)),"Actual","Estimate") | N33: =IFERROR(INDEX(INDIRECT(E33),0,MATCH(F33,MO_Common_ColumnHeader,0)),"N/A") | P33: =IF(ISNUMBER(N33),N33-K33,"N/A") | Q33: =IFERROR(IF(ISNUMBER(N33),(N33-K33)/ABS(K33),"N/A"),"N/A") | S33: 45957 | T33: CFO Commentary
A34: 930 | B34: =IF(INDEX(MO_SNA_IsHistoricalPeriod,,MATCH(F34,MO_Common_ColumnHeader,0)),"Historical","Forward") | D34: =INDEX(INDIRECT(E34),0,COLUMN(MO_Common_Column_A)) | E34: MO_RIS_EPS_WAD | F34: Q4-2025 | I34: 1.17 | J34: 1.23 | K34: =AVERAGE(I34:J34) | M34: =IF(INDEX(MO_SNA_IsHistoricalPeriod,,MATCH(F34,MO_Common_ColumnHeader,0)),"Actual","Estimate") | N34: =IFERROR(INDEX(INDIRECT(E34),0,MATCH(F34,MO_Common_ColumnHeader,0)),"N/A") | P34: =IF(ISNUMBER(N34),N34-K34,"N/A") | Q34: =IFERROR(IF(ISNUMBER(N34),(N34-K34)/ABS(K34),"N/A"),"N/A") | S34: 45957 | T34: CFO Commentary
A35: 929 | B35: =IF(INDEX(MO_SNA_IsHistoricalPeriod,,MATCH(F35,MO_Common_ColumnHeader,0)),"Historical","Forward") | D35: =INDEX(INDIRECT(E35),0,COLUMN(MO_Common_Column_A)) | E35: MO_RIS_EPS_WAD_Adj | F35: Q4-2025 | I35: 1.88 | J35: 1.94 | K35: =AVERAGE(I35:J35) | M35: =IF(INDEX(MO_SNA_IsHistoricalPeriod,,MATCH(F35,MO_Common_ColumnHeader,0)),"Actual","Estimate") | N35: =IFERROR(INDEX(INDIRECT(E35),0,MATCH(F35,MO_Common_ColumnHeader,0)),"N/A") | P35: =IF(ISNUMBER(N35),N35-K35,"N/A") | Q35: =IFERROR(IF(ISNUMBER(N35),(N35-K35)/ABS(K35),"N/A"),"N/A") | S35: 45957 | T35: CFO Commentary
A36: 928 | B36: =IF(INDEX(MO_SNA_IsHistoricalPeriod,,MATCH(F36,MO_Common_ColumnHeader,0)),"Historical","Forward") | D36: =INDEX(INDIRECT(E36),0,COLUMN(MO_Common_Column_A)) | E36: MO_CFSum_NetShares | F36: Q4-2025 | I36: -200 | J36: -200 | K36: =AVERAGE(I36:J36) | M36: =IF(INDEX(MO_SNA_IsHistoricalPeriod,,MATCH(F36,MO_Common_ColumnHeader,0)),"Actual","Estimate") | N36: =IFERROR(INDEX(INDIRECT(E36),0,MATCH(F36,MO_Common_ColumnHeader,0)),"N/A") | P36: =IF(ISNUMBER(N36),N36-K36,"N/A") | Q36: =IFERROR(IF(ISNUMBER(N36),(N36-K36)/ABS(K36),"N/A"),"N/A") | S36: 45957 | T36: CFO Commentary
A37: 927
A38: 926 | B38: =IF(INDEX(MO_SNA_IsHistoricalPeriod,,MATCH(F38,MO_Common_ColumnHeader,0)),"Historical","Forward") | D38: Recurring Revenue % | F38: FY2025 | I38: 0.8 | J38: 0.8 | K38: =AVERAGE(I38:J38) | M38: =IF(INDEX(MO_SNA_IsHistoricalPeriod,,MATCH(F38,MO_Common_ColumnHeader,0)),"Actual","Estimate") | N38: =IFERROR(INDEX(INDIRECT(E38),0,MATCH(F38,MO_Common_ColumnHeader,0)),"N/A") | P38: =IF(ISNUMBER(N38),N38-K38,"N/A") | Q38: =IFERROR(IF(ISNUMBER(N38),(N38-K38)/ABS(K38),"N/A"),"N/A") | S38: 45866 | T38: CFO Commentary
A39: 925 | B39: =IF(INDEX(MO_SNA_IsHistoricalPeriod,,MATCH(F39,MO_Common_ColumnHeader,0)),"Historical","Forward") | D39: Revenue from Beginning Backlog % | F39: FY2025 | I39: 0.7 | J39: 0.7 | K39: =AVERAGE(I39:J39) | M39: =IF(INDEX(MO_SNA_IsHistoricalPeriod,,MATCH(F39,MO_Common_ColumnHeader,0)),"Actual","Estimate") | N39: =IFERROR(INDEX(INDIRECT(E39),0,MATCH(F39,MO_Common_ColumnHeader,0)),"N/A") | P39: =IF(ISNUMBER(N39),N39-K39,"N/A") | Q39: =IFERROR(IF(ISNUMBER(N39),(N39-K39)/ABS(K39),"N/A"),"N/A") | S39: 45866 | T39: CFO Commentary
A40: 924 | B40: =IF(INDEX(MO_SNA_IsHistoricalPeriod,,MATCH(F40,MO_Common_ColumnHeader,0)),"Historical","Forward") | D40: =INDEX(INDIRECT(E40),0,COLUMN(MO_Common_Column_A)) | E40: MO_RIS_REV | F40: FY2025 | I40: 5210 | J40: 5270 | K40: =AVERAGE(I40:J40) | M40: =IF(INDEX(MO_SNA_IsHistoricalPeriod,,MATCH(F40,MO_Common_ColumnHeader,0)),"Actual","Estimate") | N40: =IFERROR(INDEX(INDIRECT(E40),0,MATCH(F40,MO_Common_ColumnHeader,0)),"N/A") | P40: =IF(ISNUMBER(N40),N40-K40,"N/A") | Q40: =IFERROR(IF(ISNUMBER(N40),(N40-K40)/ABS(K40),"N/A"),"N/A") | S40: 45866 | T40: CFO Commentary
A41: 923 | B41: =IF(INDEX(MO_SNA_IsHistoricalPeriod,,MATCH(F41,MO_Common_ColumnHeader,0)),"Historical","Forward") | D41: GAAP Operating Margin | E41: MO_MA_EBIT | F41: FY2025 | I41: 0.285 | J41: 0.295 | K41: =AVERAGE(I41:J41) | M41: =IF(INDEX(MO_SNA_IsHistoricalPeriod,,MATCH(F41,MO_Common_ColumnHeader,0)),"Actual","Estimate") | N41: =IFERROR(INDEX(INDIRECT(E41),0,MATCH(F41,MO_Common_ColumnHeader,0)),"N/A") | P41: =IF(ISNUMBER(N41),N41-K41,"N/A") | Q41: =IFERROR(IF(ISNUMBER(N41),(N41-K41)/ABS(K41),"N/A"),"N/A") | S41: 45866 | T41: CFO Commentary
...

Sheet Summary Page
A1: =MO.CompanyName | C1: =INDEX(MO_Common_QEndDate,0,COLUMN()) | D1: =INDEX(MO_Common_QEndDate,0,COLUMN()) | E1: =INDEX(MO_Common_QEndDate,0,COLUMN()) | F1: =INDEX(MO_Common_QEndDate,0,COLUMN()) | G1: =INDEX(MO_Common_QEndDate,0,COLUMN()) | H1: =INDEX(MO_Common_QEndDate,0,COLUMN()) | I1: =INDEX(MO_Common_QEndDate,0,COLUMN()) | J1: =INDEX(MO_Common_QEndDate,0,COLUMN()) | ... CA1: =INDEX(MO_Common_QEndDate,0,COLUMN())
A2: Reports | B2: =MO.ReportFX | C2: =INDEX(MO_Common_ColumnHeader,0,COLUMN()) | D2: =INDEX(MO_Common_ColumnHeader,0,COLUMN()) | E2: =INDEX(MO_Common_ColumnHeader,0,COLUMN()) | F2: =INDEX(MO_Common_ColumnHeader,0,COLUMN()) | G2: =INDEX(MO_Common_ColumnHeader,0,COLUMN()) | H2: =INDEX(MO_Common_ColumnHeader,0,COLUMN()) | I2: =INDEX(MO_Common_ColumnHeader,0,COLUMN()) | J2: =INDEX(MO_Common_ColumnHeader,0,COLUMN()) | ... CA2: =INDEX(MO_Common_ColumnHeader,0,COLUMN())
A3: Capitalization Summary
