Workbook
Name AA.AlternatePriceSourceStartPeriod: "FY2009"
Name AA.CIK: "1769628"
Name AA.CSIN: "JNYFJ20168"
Name AA.CurationVersion: "2023.3.2.0"
Name AA.DBMacroVersion: "1.0.12.0"
Name AA.FreeCashFlow: "TRUE"
Name AA.ModelVersion: "Q3-2025.25"
Name AA.PartialUpdate.BsAvailable: "TRUE"
Name AA.PartialUpdate.CfsAvailable: "TRUE"
Name AA.PartialUpdate.IsAvailable: "TRUE"
Name AA.PeriodLayout: "QFY"
Name AA.RowNameEnforcerVersion: "2023.11.1.0"
Name AA.SessionToUploadId: ""
Name AA.StartWorkModelVersion: "Q3-2025.24"
Name AA.StartWorkType: ""
Name AA.SubyearType: "Q"
Name AA.TemplateUpgradeAttempted: "TRUE"
Name AA.TemplateVersion: "7.5.4.0"
Name AA.UpdateType: "Regular"
Name FP.DataSource: 'Front Page'!$H$16
Name FP.DataSourceName: 'Front Page'!$H$15
Name FP.Disclaimer: 'Front Page'!$C$22
Name FP.LastPrice: 'Front Page'!$H$20
Name FP.LastPriceDate: 'Front Page'!$F$20
Name FP.RealTimeToggle: 'Front Page'!$H$18
Name FP.UpdateDate: 'Front Page'!$H$11
Name FP.UpdateEvent: 'Front Page'!$H$13
Name FP_Comment: 'Front Page'!$M$13:$P$20
Name FP_StockPriceOverride: 'Front Page'!$C$20:$H$20
Name GD.CompanyName: Guidance!$B$1
Name GD.MRQ: Guidance!$F$2
Name GD_Difference_Mid_Absolute: Guidance!$P:$P
Name GD_Difference_Mid_Relative: Guidance!$Q:$Q
Name GD_Guidance_High: Guidance!$J:$J
Name GD_Guidance_Low: Guidance!$I:$I
Name GD_Guidance_Mid: Guidance!$K:$K
Name GD_Header_Column: Guidance!$5:$5
Name GD_Header_Section: Guidance!$4:$4
Name GD_Index: Guidance!$A:$A
Name GD_Item: Guidance!$D:$D
Name GD_Item_BasePeriod: Guidance!$G:$G
Name GD_Item_FiscalPeriod: Guidance!$F:$F
Name GD_Item_Name: Guidance!$E:$E
Name GD_Model_Output: Guidance!$N:$N
Name GD_Model_Type: Guidance!$M:$M
Name GD_Type: Guidance!$B:$B
Name GD_Update_Date: Guidance!$S:$S
Name GD_Update_Link: Guidance!$T:$T
Name HP.MRFX: Model!$B$868
Name HP.ReportCurrency: Model!$B$867
Name HP.Ticker: Model!$A$2
Name HP.TradeCurrency: Model!$B$865
Name HP.TradeCurrency.HardCoded: Model!$B$866
Name IPO.AdditionalSharesIssuedFromOverallotment: IPO!$B$14
Name IPO.CommencedTrading: IPO!$C$6
Name IPO.DiscreteFees: IPO!$C$27
Name IPO.Fees: IPO!$B$26
Name IPO.OverallotmentToggle: IPO!$D$14
Name IPO.Period: IPO!$C$4
Name IPO.PreIPO.ShareCount: IPO!$C$33

Sheet Front Page
M6: Please contact this email for any model-specific questions:
M7: modelsupport@alpha-sense.com | N7: mailto:support@tegus.com?subject=Tegus%20Support:%20CoreWeave%20CRWV%20US&body=Model%20Version:%20 | O7: mailto:support@tegus.com?subject=Tegus%20Support:%20CoreWeave%20CRWV%20US&body=Model%20Version:%20
C9: Company Model: | H9: =Model!A1
C11: Updated: | H11: =OFFSET('Update Log'!$C$10,1,0,1,1)
M12: Comments on Model:
C13: For: | H13: =OFFSET('Update Log'!$E$10,1,0,1,1) | M13: n November 2025, the Company acquired Monolith AI Limited, a pioneer in applying artificial intelligence and machine learning to solve complex physics and engineering challenges. The acquisition is expected to help the Company offer a full-stack AI platform for industrial and manufacturing enterprises. In October 2025, the Company acquired Marimo Inc., the creator of the open-source marimo notebook, an AI-native, reactive development environment for Python, purpose-built for AI and data workloads. The acquisition is expected to strengthen CoreWeave's vertically integrated platform, empowering developers to build, scale, and deploy applications faster and more efficiently. On July 7, 2025, CoreWeave, Inc. entered into a merger agreement with Core Scientific, Inc., under which CoreWeave’s wholly owned subsidiary, Miami Merger Sub I, Inc., will merge with Core Scientific. Core Scientific will survive as a wholly owned subsidiary of CoreWeave. At closing, each share of Core Scientific common stock (excluding treasury shares and shares held by the parties) will be exchanged for 0.1235 shares of CoreWeave Class A common stock. The transaction is expected to close in the fourth quarter of 2025. 'In April 2025, the Company borrowed an additional $512 million under the DDTL 2.0 Facility, bringing the total borrowings on the DDTL 2.0 Facility to $4.9 billion. Refer to Note 10—Debt for additional information. In April and May 2025, the Company entered into additional lease agreements, primarily for data centers and office buildings. The Company expects to make approximately $449 million of additional rent payments over the next 10 years related to the leases. In May 2025, the Company entered into additional financing arrangements, for specified purchase orders, with various original equipment manufacturers. The financing arrangements will have an aggregate available balance of up to $4.0 billion, which is expected to be drawn in the future as equipment is purchased and delivered. These financing arrangements will have terms ranging from eighteen to sixty months. Additionally, in April 2025 and in May 2025, the Company entered into various additional financing agreements with an OEM. The financing agreements have an aggregate notional balance of $188 million. The financing arrangements have terms ranging from twenty-four to thirty-six months. The Company granted a security interest for the financed equipment. In May 2025, the Company drew $400 million on the Revolving Credit Facility. In May 2025, the Company entered into an additional agreement with OpenAI, pursuant to which the Company will provide OpenAI access to cloud computing capacity through fulfillment of reserved capacity orders submitted to the Company by OpenAI. As of May 14, 2025, subject to the satisfaction of delivery and availability of service requirements, OpenAI has committed to pay the Company up to $4.0 billion through April 2029 related to this agreement.
C15: Consensus Data and Real-Time Stock Price: | H15: Bloomberg
H16: =IF(FP.DataSourceName="Bloomberg",1,IF(FP.DataSourceName="Capital IQ",2,IF(FP.DataSourceName="FactSet",3,IF(FP.DataSourceName="Refinitiv",4))))
C18: Real-Time Stock Price: | H18: OFF
C20: Stock Price Override: | F20: 46057 | H20: 82.46
C22: DISCLAIMER Access to and use of this model, including the data contained herein (this "Model") is subject to Tegus, Inc.'s (a successor entity to Canalyst Financial Modeling Corporation) ("Company") Terms of Use that you accepted prior to accessing this Model, the applicable Service Agreement between the Company and you (or a corporate entity that has authorized you to access and use this Model on its behalf in accordance with the terms of such Service Agreement) or other similar agreement between you and the Company. BY CONTINUING TO ACCESS OR USE THIS MODEL, YOU EXPRESSLY AGREE TO THE TERMS AND CONDITIONS OF SUCH AGREEMENTS. The Company and certain of its licensors have exclusive proprietary rights in this Model. This Model is being provided for internal use only. Unless prior written consent by the Company and its licensors has been provided to you, you may not distribute or otherwise furnish this Model to any third party, nor use or permit anyone to use this Model for any unlawful or unauthorized purpose. IF YOU HAVE UNLAWFULLY OBTAINED, OR ARE NOT AUTHORIZED TO USE THIS MODEL, YOU ARE OBLIGATED TO PROMPTLY: (I) RETURN THIS MODEL (AND ANY DERIVATIVE WORKS ARISING FROM OR RELATING THERETO) TO THE AUTHORIZED USER OF THIS MODEL; (II) PROVIDE NOTICE TO THE COMPANY AT LEGAL@TEGUS.COM OF SUCH UNLAWFUL OR UNAUTHORIZED ACCESS AND USE; AND, (III) CERTIFY THAT YOU HAVE DESTROYED THIS MODEL (AND ANY DERIVATIVE WORKS ARISING FROM OR RELATING THERETO) AND ANY COPIES FROM YOUR SYSTEMS SO AS TO ENSURE THEY ARE INCAPABLE OF RETRIEVAL. A portion of the data contained in this Model may be powered by third party contributors and their respective licensors, or derived from data provided by such contributors, including (but not limited to): (i) QuoteMedia Inc.: A portion of the market data is powered by Quotemedia.com. All rights reserved. Data delayed 15 minutes unless otherwise indicated; (ii) S&P Global Market Intelligence LLC: Copyright (c) {{YEAR}} S&P Global Market Intelligence LLC (and its affiliates as applicable). All rights reserved. Reproduction of any information, opinions, views, data or material, including ratings ("Content") in any form is prohibited except with the prior written permission of the relevant party. Such party, its affiliates and suppliers ("Content Providers") do not guarantee the accuracy, adequacy, completeness, timeliness or availability of any Content and are not responsible for any errors or omissions (negligent or otherwise), regardless of the cause, or for the results obtained from the use of such Content. In no event shall Content Providers be liable for any damages, costs, expenses, legal fees, or losses (including lost income or lost profit and opportunity costs) in connection with any use of the Content. A reference to a particular investment or security, a rating or any observation concerning an investment that is part of the Content is not a recommendation to buy, sell or hold such investment or security, does not address the suitability of an investment or security and should not be relied on as investment advice. Credit ratings are statements of opinions and are not statements of fact; and, (iii) Refinitiv Canada Holdings Limited: A portion of the information may be provided by or derived from data provided by Refinitiv. By accessing or using this Model (including any portion of the data contained herein) you expressly represent that such access or use does not constitute a violation of any applicable law or regulation to which you or the securities are subject. This Model does not constitute investment advice by the Company or any of its licensors. Reference to a particular investment or security, credit rating or any observation concerning a security or investment in this Model is not a recommendation or solicitation to buy, sell or hold such investment or security or make any other investment decisions. For greater certainty, any forecasts or forward-looking information expressed herein are for illustrative purposes only and do not purport to express any view on what may transpire. Neither the Company nor any of its licensors have performed company-specific research on any projected information, as such, it is your responsibility to express your own views on projected results. This Model does not guarantee future performance and undue reliance should not be placed on such. You are solely responsible for evaluating the merits and risks of any investment based on your own business and financial expertise, the business and financial expertise of professional advisors with whom you have consulted, your financial situation and risk tolerance. Neither the Company, nor any of its licensors, undertake any liability with respect to your reliance on this Model. This Model is a quantitative tool with no investment views. The Company and its respective directors, officers, employees, agents, contractors, and affiliates may hold long or short positions in the security to which this Model relates, based on their personal views, and may initiate or close out any positions in such security at any time without any notice. THIS MODEL IS PROVIDED "AS IS" AND ON AN "AS AVAILABLE" BASIS ONLY, WITHOUT WARRANTIES OR CONDITIONS OF ANY KIND. NEITHER THE COMPANY NOR ANY OF ITS LICENSORS NOR THEIR RESPECTIVE AFFILIATES OR SUPPLIERS HAVE LIABILITY FOR THE ACCURACY, TIMELINESS OR COMPLETENESS OF THIS MODEL, OR FOR DELAYS, INTERRUPTIONS OR OMISSIONS HEREIN, NOR FOR ANY LOST PROFITS, INDIRECT, SPECIAL OR CONSEQUENTIAL DAMAGES. Access to data in this Model that is sourced from third party contributors is subject to termination in the event that any agreement between the Company and such third party contributors terminates for any reason. Copyright 2023 Tegus. All rights reserved.

Sheet DCF
A1: CoreWeave DCF Valuation Analysis
A4: Period | F4: FY2025 | G4: FY2026 | H4: FY2027 | I4: FY2028 | J4: FY2029
A6: REVENUE BUILD
A7: Total Revenue | F7: =Model!S7 | G7: =Model!X7 | H7: =Model!AC7 | I7: =Model!AH7 | J7: =Model!AM7
A8: Y/Y Growth % | G8: =G7/F7 - 1 | H8: =H7/G7 - 1 | I8: =I7/H7 - 1 | J8: =J7/I7 - 1
A10: OPERATING METRICS
A11: EBITDA Margin % | F11: =Model!S15 | G11: =Model!X15 | H11: =Model!AC15 | I11: =Model!AH15 | J11: =Model!AM15
A12: Operating Income (GAAP) | F12: =Model!S99 | G12: =Model!X99 | H12: =Model!AC99 | I12: =Model!AH99 | J12: =Model!AM99
A13: Operating Margin % | F13: =F12/F7 | G13: =G12/G7 | H13: =H12/H7 | I13: =I12/I7 | J13: =J12/J7
A16: UFCF BUILD
A17: Revenue | F17: =F7 | G17: =G7 | H17: =H7 | I17: =I7 | J17: =J7
A18: Operating Income | F18: =F12 | G18: =G12 | H18: =H12 | I18: =I12 | J18: =J12
A19: Tax Rate % | F19: 0.21 | G19: 0.21 | H19: 0.21 | I19: 0.21 | J19: 0.21
A20: NOPAT (OpInc × (1-Tax)) | F20: =F18 * (1 - F19) | G20: =G18 * (1 - G19) | H20: =H18 * (1 - H19) | I20: =I18 * (1 - I19) | J20: =J18 * (1 - J19)
A21: D&A | F21: =Model!S129 | G21: =Model!X129 | H21: =Model!AC129 | I21: =Model!AH129 | J21: =Model!AM129
A22: CapEx | F22: =Model!S216 | G22: =Model!X216 | H22: =Model!AC216 | I22: =Model!AH216 | J22: =Model!AM216
A23: Change in Working Capital | F23: =F17 * 0.08 | G23: =G17 * 0.08 | H23: =H17 * 0.08 | I23: =I17 * 0.08 | J23: =J17 * 0.08
A24: Unlevered FCF | F24: =F20 + F21 - F22 - F23 | G24: =G20 + G21 - G22 - G23 | H24: =H20 + H21 - H22 - H23 | I24: =I20 + I21 - I22 - I23 | J24: =J20 + J21 - J22 - J23
A26: DISCOUNTING
A27: WACC % | F27: 0.1 | G27: 0.1 | H27: 0.1 | I27: 0.1 | J27: 0.1
A28: Discount Factor | F28: =1 / (1 + F27)^1 | G28: =1 / (1 + G27)^2 | H28: =1 / (1 + H27)^3 | I28: =1 / (1 + I27)^4 | J28: =1 / (1 + J27)^5
A29: PV of UFCF | F29: =F24 * F28 | G29: =G24 * G28 | H29: =H24 * H28 | I29: =I24 * I28 | J29: =J24 * J28
A31: TERMINAL VALUE
A32: Terminal Growth % | F32: 0.03
A33: Terminal Value | F33: =F24 * (1 + F32) / (F27 - F32)
A34: PV of TV | F34: =F33 * F28
A36: VALUATION
A37: Sum PV UFCF | F37: =SUM(F29:J29)
A38: PV Terminal Value | F38: =F34
A39: Enterprise Value | F39: =F37 + F38
A40: Less: Net Debt | F40: =Model!L600 - Model!L550
A41: Equity Value | F41: =F39 - F40
A42: Shares Outstanding (mm) | F42: =Model!L700
A43: Implied Price | F43: =F41 / F42
A44: Current Price | F44: ='Front Page'!H20
A45: Upside % | F45: =F43 / F44 - 1

Sheet Model
A1: CoreWeave
A2: =CHOOSE(MO.DataSourceIndex,MO.Ticker.Bloomberg,MO.Ticker.CapIQ,MO.Ticker.FactSet,MO.Ticker.Thomson) | C2: =EOMONTH(C4,-12)
A3: =HP.TradeCurrency | B3: =IF(MO.RealTime="OFF",MO.LastPriceHardcoded,MO.LastPriceFormula) | C3: =C4-C2 | D3: =D4-C4 | E3: =E4-D4 | F3: =F4-E4 | G3: =G4-F4 | H3: =H4-G4 | I3: =I4-H4 | J3: =J4-I4 | K3: =K4-J4 | ... R3: =R4-Q4 | S3: =S4-N4 | T3: =T4-S4 | U3: =U4-T4 | V3: =V4-U4 | W3: =W4-V4 | X3: =X4-S4 | Y3: =Y4-X4 | Z3: =Z4-Y4 | AA3: =AA4-Z4 | AB3: =AB4-AA4 | AC3: =AC4-X4 | AD3: =AD4-AC4 | AE3: =AE4-AD4 | AF3: =AF4-AE4 | AG3: =AG4-AF4 | AH3: =AH4-AC4 | AI3: =AI4-AH4 | AJ3: =AJ4-AI4 | AK3: =AK4-AJ4 | AL3: =AL4-AK4 | AM3: =AM4-AH4 | AN3: =AN4-AM4 | AO3: =AO4-AN4 | AP3: =AP4-AO4 | AQ3: =AQ4-AP4 | AR3: =AR4-AM4 | AS3: =AS4-AR4 | AT3: =AT4-AS4 | AU3: =AU4-AT4
A4: =FP.DataSourceName | B4: =IF(AND(MO.RealTimeStockPriceToggle,MO.LastPriceFormula<>"N/A"),"ON","OFF") | C4: 40178 | D4: =EOMONTH(C4,12) | E4: =EOMONTH(D4,12) | F4: =EOMONTH(E4,12) | G4: =EOMONTH(F4,12) | H4: =EOMONTH(G4,12) | I4: =EOMONTH(H4,12) | J4: =EOMONTH(I4,12) | K4: =EOMONTH(J4,12) | ... N4: =EOMONTH(M4,12) | O4: =EOMONTH(N4,3) | P4: =EOMONTH(O4,3) | Q4: =EOMONTH(P4,3) | R4: =EOMONTH(Q4,3) | S4: =R4 | T4: =EOMONTH(S4,3) | U4: =EOMONTH(T4,3) | V4: =EOMONTH(U4,3) | W4: =EOMONTH(V4,3) | X4: =W4 | Y4: =EOMONTH(X4,3) | Z4: =EOMONTH(Y4,3) | AA4: =EOMONTH(Z4,3) | AB4: =EOMONTH(AA4,3) | AC4: =AB4 | AD4: =EOMONTH(AC4,3) | AE4: =EOMONTH(AD4,3) | AF4: =EOMONTH(AE4,3) | AG4: =EOMONTH(AF4,3) | AH4: =AG4 | AI4: =EOMONTH(AH4,3) | AJ4: =EOMONTH(AI4,3) | AK4: =EOMONTH(AJ4,3) | AL4: =EOMONTH(AK4,3) | AM4: =AL4 | AN4: =EOMONTH(AM4,3) | AO4: =EOMONTH(AN4,3) | AP4: =EOMONTH(AO4,3) | AQ4: =EOMONTH(AP4,3) | AR4: =AQ4 | AS4: =EOMONTH(AR4,12) | AT4: =EOMONTH(AS4,12) | AU4: =EOMONTH(AT4,12)
A5: =MO.ReportCurrency | C5: FY2009 | D5: =CONCATENATE("FY",RIGHT(C5,4)+1) | E5: =CONCATENATE("FY",RIGHT(D5,4)+1) | F5: =CONCATENATE("FY",RIGHT(E5,4)+1) | G5: =CONCATENATE("FY",RIGHT(F5,4)+1) | H5: =CONCATENATE("FY",RIGHT(G5,4)+1) | I5: =CONCATENATE("FY",RIGHT(H5,4)+1) | J5: =CONCATENATE("FY",RIGHT(I5,4)+1) | K5: =CONCATENATE("FY",RIGHT(J5,4)+1) | ... N5: =CONCATENATE("FY",RIGHT(M5,4)+1) | O5: =CONCATENATE("Q1","-",RIGHT(N5,4)+1) | P5: =CONCATENATE("Q2","-",RIGHT(O5,4)) | Q5: =CONCATENATE("Q3","-",RIGHT(P5,4)) | R5: =CONCATENATE("Q4","-",RIGHT(Q5,4)) | S5: =CONCATENATE("FY",RIGHT(N5,4)+1) | T5: =CONCATENATE("Q1","-",RIGHT(S5,4)+1) | U5: =CONCATENATE("Q2","-",RIGHT(T5,4)) | V5: =CONCATENATE("Q3","-",RIGHT(U5,4)) | W5: =CONCATENATE("Q4","-",RIGHT(V5,4)) | X5: =CONCATENATE("FY",RIGHT(S5,4)+1) | Y5: =CONCATENATE("Q1","-",RIGHT(X5,4)+1) | Z5: =CONCATENATE("Q2","-",RIGHT(Y5,4)) | AA5: =CONCATENATE("Q3","-",RIGHT(Z5,4)) | AB5: =CONCATENATE("Q4","-",RIGHT(AA5,4)) | AC5: =CONCATENATE("FY",RIGHT(X5,4)+1) | AD5: =CONCATENATE("Q1","-",RIGHT(AC5,4)+1) | AE5: =CONCATENATE("Q2","-",RIGHT(AD5,4)) | AF5: =CONCATENATE("Q3","-",RIGHT(AE5,4)) | AG5: =CONCATENATE("Q4","-",RIGHT(AF5,4)) | AH5: =CONCATENATE("FY",RIGHT(AC5,4)+1) | AI5: =CONCATENATE("Q1","-",RIGHT(AH5,4)+1) | AJ5: =CONCATENATE("Q2","-",RIGHT(AI5,4)) | AK5: =CONCATENATE("Q3","-",RIGHT(AJ5,4)) | AL5: =CONCATENATE("Q4","-",RIGHT(AK5,4)) | AM5: =CONCATENATE("FY",RIGHT(AH5,4)+1) | AN5: =CONCATENATE("Q1","-",RIGHT(AM5,4)+1) | AO5: =CONCATENATE("Q2","-",RIGHT(AN5,4)) | AP5: =CONCATENATE("Q3","-",RIGHT(AO5,4)) | AQ5: =CONCATENATE("Q4","-",RIGHT(AP5,4)) | AR5: =CONCATENATE("FY",RIGHT(AM5,4)+1) | AS5: =CONCATENATE("FY",RIGHT(AR5,4)+1) | AT5: =CONCATENATE("FY",RIGHT(AS5,4)+1) | AU5: =CONCATENATE("FY",RIGHT(AT5,4)+1)
A6: Revenue Build | AA6: 9 months
A7: Total revenue, mm | X7: =X280 | AA7: =AA280 | AB7: =AB280 | AC7: =AC280 | AD7: =AD280 | AE7: =AE280 | AF7: =AF280 | AG7: =AG280 | AH7: =AH280 | ... AK7: =AK280 | AL7: =AG7*(1+AL10) | AM7: =SUM(AI7,AJ7,AK7,AL7) | AN7: =AI7*(1+AN10) | AO7: =AJ7*(1+AO10) | AP7: =AK7*(1+AP10) | AQ7: =AL7*(1+AQ10) | AR7: =SUM(AN7,AO7,AP7,AQ7) | AS7: =AR7*(1+AS10) | AT7: =AS7*(1+AT10) | AU7: =AT7*(1+AU10)
A8: =A334 | AL8: =AL334 | AM8: =AM334 | AN8: =AN334 | AO8: =AO334 | AP8: =AP334 | AQ8: =AQ334 | AR8: =AR334 | AS8: =AS334 | ... AU8: =AU334
A9: Q/Q Total revenue growth, % | AE9: =AE7/AD7-1 | AF9: =AF7/AE7-1 | AG9: =AG7/AF7-1 | AI9: =AI7/AG7-1 | AJ9: =AJ7/AI7-1 | AK9: =AK7/AJ7-1 | AL9: =AL7/AK7-1 | AN9: =AN7/AL7-1 | AO9: =AO7/AN7-1 | AP9: =AP7/AO7-1 | AQ9: =AQ7/AP7-1
A10: Y/Y Total revenue growth, % | AC10: =AC7/X7-1 | AG10: =AG7/AB7-1 | AH10: =AH7/AC7-1 | AI10: =AI7/AD7-1 | AJ10: =AJ7/AE7-1 | AK10: =AK7/AF7-1 | AL10: 1.1 | AM10: =AM7/AH7-1 | AN10: 0.3 | AO10: 0.3 | AP10: 0.3 | AQ10: 1 | AR10: =AR7/AM7-1 | AS10: 0.25 | AT10: 0.15 | AU10: 0.08
A12: Non-GAAP EBITDA, mm | X12: =X364 | AA12: =AA364 | AB12: =AB364 | AC12: =AC364 | AD12: =AD364 | AE12: =AE364 | AF12: =AF364 | AG12: =AG364 | AH12: =AH364 | ... AU12: =AU364
A13: =A365 | AL13: =AL365 | AM13: =AM365 | AN13: =AN365 | AO13: =AO365 | AP13: =AP365 | AQ13: =AQ365 | AR13: =AR365 | AS13: =AS365 | ... AU13: =AU365
A14: Y/Y Non-GAAP EBITDA growth, % | AC14: =AC12/X12-1 | AG14: =AG12/AB12-1 | AH14: =AH12/AC12-1 | AI14: =AI12/AD12-1 | AJ14: =AJ12/AE12-1 | AK14: =AK12/AF12-1 | AL14: =AL12/AG12-1 | AM14: =AM12/AH12-1 | AN14: =AN12/AI12-1 | ... AR14: =AR12/AM12-1 | AS14: =AS12/AR12-1 | AT14: =AT12/AS12-1 | AU14: =AU12/AT12-1
A15: Non-GAAP EBITDA Margin, % | X15: =X12/X7 | AA15: =AA12/AA7 | AB15: =AB12/AB7 | AC15: =AC12/AC7 | AD15: =AD12/AD7 | AE15: =AE12/AE7 | AF15: =AF12/AF7 | AG15: =AG12/AG7 | AH15: =AH12/AH7 | ... AU15: =AU12/AU7
A16: =CONCATENATE("Consensus Estimates - ",IFERROR(LEFT(A15,FIND("(",A15)-1),A15)) | AL16: =IFERROR(AL13/AL8,0) | AM16: =IFERROR(AM13/AM8,0) | AN16: =IFERROR(AN13/AN8,0) | AO16: =IFERROR(AO13/AO8,0) | AP16: =IFERROR(AP13/AP8,0) | AQ16: =IFERROR(AQ13/AQ8,0) | AR16: =IFERROR(AR13/AR8,0) | AS16: =IFERROR(AS13/AS8,0) | ... AU16: =IFERROR(AU13/AU8,0)
A17: Y/Y Non-GAAP EBITDA Margin Improvement, bps | AC17: =(AC15-X15)*10000 | AG17: =(AG15-AB15)*10000 | AH17: =(AH15-AC15)*10000 | AI17: =(AI15-AD15)*10000 | AJ17: =(AJ15-AE15)*10000 | AK17: =(AK15-AF15)*10000 | AL17: =(AL15-AG15)*10000 | AM17: =(AM15-AH15)*10000 | AN17: =(AN15-AI15)*10000 | ... AR17: =(AR15-AM15)*10000 | AS17: =(AS15-AR15)*10000 | AT17: =(AT15-AS15)*10000 | AU17: =(AU15-AT15)*10000
A19: Company Reported Non-GAAP Operating Income, mm | X19: =X359 | AA19: =AA359 | AB19: =AB359 | AC19: =AC359 | AD19: =AD359 | AE19: =AE359 | AF19: =AF359 | AG19: =AG359 | AH19: =AH359 | ... AU19: =AU359
A20: =A360 | AL20: =AL360 | AM20: =AM360 | AN20: =AN360 | AO20: =AO360 | AP20: =AP360 | AQ20: =AQ360 | AR20: =AR360 | AS20: =AS360 | ... AU20: =AU360
A21: Y/Y Company Reported Non-GAAP Operating Income growth, % | AC21: =AC19/X19-1 | AG21: =AG19/AB19-1 | AH21: =AH19/AC19-1 | AI21: =AI19/AD19-1 | AJ21: =AJ19/AE19-1 | AK21: =AK19/AF19-1 | AL21: =AL19/AG19-1 | AM21: =AM19/AH19-1 | AN21: =AN19/AI19-1 | ... AR21: =AR19/AM19-1 | AS21: =AS19/AR19-1 | AT21: =AT19/AS19-1 | AU21: =AU19/AT19-1
A22: Company Reported Non-GAAP Operating Income Margin, % | X22: =X19/X7 | AA22: =AA19/AA7 | AB22: =AB19/AB7 | AC22: =AC19/AC7 | AD22: =AD19/AD7 | AE22: =AE19/AE7 | AF22: =AF19/AF7 | AG22: =AG19/AG7 | AH22: =AH19/AH7 | ... AU22: =AU19/AU7
A23: =A277 | AL23: =AL277 | AM23: =AM277 | AN23: =AN277 | AO23: =AO277 | AP23: =AP277 | AQ23: =AQ277 | AR23: =AR277 | AS23: =AS277 | ... AU23: =AU277
A24: Y/Y Company Reported Non-GAAP Operating Income Margin Improvement, bps | AC24: =(AC22-X22)*10000 | AG24: =(AG22-AB22)*10000 | AH24: =(AH22-AC22)*10000 | AI24: =(AI22-AD22)*10000 | AJ24: =(AJ22-AE22)*10000 | AK24: =(AK22-AF22)*10000 | AL24: =(AL22-AG22)*10000 | AM24: =(AM22-AH22)*10000 | AN24: =(AN22-AI22)*10000 | ... AR24: =(AR22-AM22)*10000 | AS24: =(AS22-AR22)*10000 | AT24: =(AT22-AS22)*10000 | AU24: =(AU22-AT22)*10000
A26: Non-GAAP Net Income, mm | X26: =X381 | AA26: =AA381 | AB26: =AB381 | AC26: =AC381 | AD26: =AD381 | AE26: =AE381 | AF26: =AF381 | AG26: =AG381 | AH26: =AH381 | ... AU26: =AU381
A27: Y/Y Non-GAAP Net Income growth, % | AC27: =AC26/X26-1 | AG27: =AG26/AB26-1 | AH27: =AH26/AC26-1 | AI27: =AI26/AD26-1 | AJ27: =AJ26/AE26-1 | AK27: =AK26/AF26-1 | AL27: =AL26/AG26-1 | AM27: =AM26/AH26-1 | AN27: =AN26/AI26-1 | ... AR27: =AR26/AM26-1 | AS27: =AS26/AR26-1 | AT27: =AT26/AS26-1 | AU27: =AU26/AT26-1
A28: Non-GAAP Net Income Margin, % | X28: =X26/X7 | AA28: =AA26/AA7 | AB28: =AB26/AB7 | AC28: =AC26/AC7 | AD28: =AD26/AD7 | AE28: =AE26/AE7 | AF28: =AF26/AF7 | AG28: =AG26/AG7 | AH28: =AH26/AH7 | ... AU28: =AU26/AU7
A29: Y/Y Non-GAAP Net Income Margin Improvement, bps | AC29: =(AC28-X28)*10000 | AG29: =(AG28-AB28)*10000 | AH29: =(AH28-AC28)*10000 | AI29: =(AI28-AD28)*10000 | AJ29: =(AJ28-AE28)*10000 | AK29: =(AK28-AF28)*10000 | AL29: =(AL28-AG28)*10000 | AM29: =(AM28-AH28)*10000 | AN29: =(AN28-AI28)*10000 | ... AR29: =(AR28-AM28)*10000 | AS29: =(AS28-AR28)*10000 | AT29: =(AT28-AS28)*10000 | AU29: =(AU28-AT28)*10000
A31: Non-GAAP Earnings Per Share - WAD, USD/share | X31: =X401 | AA31: =AA401 | AB31: =AB401 | AC31: =AC401 | AD31: =AD401 | AE31: =AE401 | AF31: =AF401 | AG31: =AG401 | AH31: =AH401 | ... AU31: =AU401
A32: =CONCATENATE("Consensus Estimates - ",IFERROR(LEFT(A31,FIND("(",A31)-1),A31)) | AL32: =AL402 | AM32: =AM402 | AN32: =AN402 | AO32: =AO402 | AP32: =AP402 | AQ32: =AQ402 | AR32: =AR402 | AS32: =AS402 | ... AU32: =AU402
A34: RPO, mm | AC34: 9900 | AE34: 16200 | AF34: 15000 | AG34: =AH34 | AH34: 15100 | AI34: 14700 | AJ34: 30100 | AK34: 50000
A35: % of RPO to be recognized over the initial 24 months, % | AC35: 0.41 | AE35: 0.45 | AF35: 0.5 | AG35: =AH35 | AH35: 0.54 | AI35: 0.58 | AJ35: 0.5 | AK35: 0.42
A36: % of RPO to be recognized between months 25 and 48 months, % | AC36: 0.4 | AE36: 0.4 | AG36: =AH36 | AH36: 0.42 | AI36: 0.4 | AJ36: 0.4 | AK36: 0.39
A37: % of RPO to be recognized between months 49 and 72 months, % | AC37: =1-AC36-AC35 | AE37: 0.15 | AG37: =AH37 | AH37: =1-AH36-AH35 | AI37: =1-AI36-AI35 | AJ37: =1-AJ36-AJ35 | AK37: =1-AK36-AK35
A39: Operating Expense Forecasting | AA39: 9 months
A40: Revenue, mm | X40: =X333 | AA40: =AA333 | AB40: =AB333 | AC40: =AC333 | AD40: =AD333 | AE40: =AE333 | AF40: =AF333 | AG40: =AG333 | AH40: =AH333 | ... AK40: =AK333 | AL40: =AL7 | AM40: =SUM(AI40,AJ40,AK40,AL40) | AN40: =AN7 | AO40: =AO7 | AP40: =AP7 | AQ40: =AQ7 | AR40: =SUM(AN40,AO40,AP40,AQ40) | AS40: =AS7 | AT40: =AT7 | AU40: =AU7
A41: GAAP COGS, mm | X41: =X336 | AA41: =AA336 | AB41: =AB336 | AC41: =AC336 | AD41: =AD336 | AE41: =AE336 | AF41: =AF336 | AG41: =AG336 | AH41: =AH336 | ... AK41: =AK336 | AL41: =AL40-AL42 | AM41: =SUM(AI41,AJ41,AK41,AL41) | AN41: =AN40-AN42 | AO41: =AO40-AO42 | AP41: =AP40-AP42 | AQ41: =AQ40-AQ42 | AR41: =SUM(AN41,AO41,AP41,AQ41) | AS41: =AS40-AS42 | AT41: =AT40-AT42 | AU41: =AU40-AU42
A42: GAAP Gross Profit, mm | X42: =X40-X41 | AA42: =AA40-AA41 | AB42: =AB40-AB41 | AC42: =AC40-AC41 | AD42: =AD40-AD41 | AE42: =AE40-AE41 | AF42: =AF40-AF41 | AG42: =AG40-AG41 | AH42: =AH40-AH41 | ... AK42: =AK40-AK41 | AL42: =+AL51+AL47+AL49+AL50 | AM42: =AM40-AM41 | AN42: =+AN51+AN47+AN49+AN50 | AO42: =+AO51+AO47+AO49+AO50 | AP42: =+AP51+AP47+AP49+AP50 | AQ42: =+AQ51+AQ47+AQ49+AQ50 | AR42: =AR40-AR41 | AS42: =+AS51+AS47+AS49+AS50 | AT42: =+AT51+AT47+AT49+AT50 | AU42: =+AU51+AU47+AU49+AU50
A43: Y/Y growth in GAAP Gross Profit, % | AC43: =AC42/X42-1 | AG43: =AG42/AB42-1 | AH43: =AH42/AC42-1 | AI43: =AI42/AD42-1 | AJ43: =AJ42/AE42-1 | AK43: =AK42/AF42-1 | AL43: =AL42/AG42-1 | AM43: =AM42/AH42-1 | AN43: =AN42/AI42-1 | ... AR43: =AR42/AM42-1 | AS43: =AS42/AR42-1 | AT43: =AT42/AS42-1 | AU43: =AU42/AT42-1
A44: GAAP Gross Margin, % | X44: =X42/X40 | AA44: =AA42/AA40 | AB44: =AB42/AB40 | AC44: =AC42/AC40 | AD44: =AD42/AD40 | AE44: =AE42/AE40 | AF44: =AF42/AF40 | AG44: =AG42/AG40 | AH44: =AH42/AH40 | ... AU44: =AU42/AU40
A45: Y/Y improvement in GAAP Gross Margin, bps | AC45: =(AC44-X44)*10000 | AG45: =(AG44-AB44)*10000 | AH45: =(AH44-AC44)*10000 | AI45: =(AI44-AD44)*10000 | AJ45: =(AJ44-AE44)*10000 | AK45: =(AK44-AF44)*10000 | AL45: =(AL44-AG44)*10000 | AM45: =(AM44-AH44)*10000 | AN45: =(AN44-AI44)*10000 | ... AR45: =(AR44-AM44)*10000 | AS45: =(AS44-AR44)*10000 | AT45: =(AT44-AS44)*10000 | AU45: =(AU44-AT44)*10000
A47: SBC COGS, mm | X47: =X337 | AA47: =AA337 | AB47: =AB337 | AC47: =AC337 | AD47: =AD337 | AE47: =AE337 | AF47: =AF337 | AG47: =AG337 | AH47: =AH337 | ... AK47: =AK337 | AL47: =-AL48*AL40 | AM47: =SUM(AI47,AJ47,AK47,AL47) | AN47: =-AN48*AN40 | AO47: =-AO48*AO40 | AP47: =-AP48*AP40 | AQ47: =-AQ48*AQ40 | AR47: =SUM(AN47,AO47,AP47,AQ47) | AS47: =-AS48*AS40 | AT47: =-AT48*AT40 | AU47: =-AU48*AU40
...

Sheet Guidance
B1: =MO.CompanyName
B2: Most Recent Period: | F2: =UL.MRQ
I4: Guidance | M4: Model | P4: Difference vs. Mid | S4: Update Log
B5: Type | D5: Item | E5: Item Name | F5: Fiscal Period | G5: Base Period | I5: Low | J5: High | K5: Mid | M5: Type | N5: Output | P5: Absolute | Q5: Relative | S5: Date | T5: Link
A6: 22 | B6: =IF(INDEX(MO_SNA_IsHistoricalPeriod,,MATCH(F6,MO_Common_ColumnHeader,0)),"Historical","Forward") | D6: =INDEX(INDIRECT(E6),0,COLUMN(MO_Common_Column_A)) | E6: MO_RIS_REV | F6: FY2025 | I6: 5050 | J6: 5150 | K6: =AVERAGE(I6:J6) | M6: =IF(INDEX(MO_SNA_IsHistoricalPeriod,,MATCH(F6,MO_Common_ColumnHeader,0)),"Actual","Estimate") | N6: =IFERROR(INDEX(INDIRECT(E6),0,MATCH(F6,MO_Common_ColumnHeader,0)),"N/A") | P6: =IF(ISNUMBER(N6),N6-K6,"N/A") | Q6: =IFERROR(IF(ISNUMBER(N6),(N6-K6)/ABS(K6),"N/A"),"N/A") | S6: 45971 | T6: Earnings Presentation
A7: 21 | B7: =IF(INDEX(MO_SNA_IsHistoricalPeriod,,MATCH(F7,MO_Common_ColumnHeader,0)),"Historical","Forward") | D7: =INDEX(INDIRECT(E7),0,COLUMN(MO_Common_Column_A)) | E7: MO_RIS_Reported_OperatingIncome_NONGAAP | F7: FY2025 | I7: 690 | J7: 720 | K7: =AVERAGE(I7:J7) | M7: =IF(INDEX(MO_SNA_IsHistoricalPeriod,,MATCH(F7,MO_Common_ColumnHeader,0)),"Actual","Estimate") | N7: =IFERROR(INDEX(INDIRECT(E7),0,MATCH(F7,MO_Common_ColumnHeader,0)),"N/A") | P7: =IF(ISNUMBER(N7),N7-K7,"N/A") | Q7: =IFERROR(IF(ISNUMBER(N7),(N7-K7)/ABS(K7),"N/A"),"N/A") | S7: 45971 | T7: Earnings Presentation
A8: 20 | B8: =IF(INDEX(MO_SNA_IsHistoricalPeriod,,MATCH(F8,MO_Common_ColumnHeader,0)),"Historical","Forward") | D8: =INDEX(INDIRECT(E8),0,COLUMN(MO_Common_Column_A)) | E8: MO_RIS_IE_Net | F8: FY2025 | I8: 1210 | J8: 1250 | K8: =AVERAGE(I8:J8) | M8: =IF(INDEX(MO_SNA_IsHistoricalPeriod,,MATCH(F8,MO_Common_ColumnHeader,0)),"Actual","Estimate") | N8: =IFERROR(INDEX(INDIRECT(E8),0,MATCH(F8,MO_Common_ColumnHeader,0)),"N/A") | P8: =IF(ISNUMBER(N8),N8-K8,"N/A") | Q8: =IFERROR(IF(ISNUMBER(N8),(N8-K8)/ABS(K8),"N/A"),"N/A") | S8: 45971 | T8: Earnings Presentation
A9: 19 | B9: =IF(INDEX(MO_SNA_IsHistoricalPeriod,,MATCH(F9,MO_Common_ColumnHeader,0)),"Historical","Forward") | D9: =INDEX(INDIRECT(E9),0,COLUMN(MO_Common_Column_A)) | E9: MO_CFSum_Capex | F9: FY2025 | I9: -14000 | J9: -12000 | K9: =AVERAGE(I9:J9) | M9: =IF(INDEX(MO_SNA_IsHistoricalPeriod,,MATCH(F9,MO_Common_ColumnHeader,0)),"Actual","Estimate") | N9: =IFERROR(INDEX(INDIRECT(E9),0,MATCH(F9,MO_Common_ColumnHeader,0)),"N/A") | P9: =IF(ISNUMBER(N9),N9-K9,"N/A") | Q9: =IFERROR(IF(ISNUMBER(N9),(N9-K9)/ABS(K9),"N/A"),"N/A") | S9: 45971 | T9: Earnings Presentation
A10: 18
A11: 17 | B11: =IF(INDEX(MO_SNA_IsHistoricalPeriod,,MATCH(F11,MO_Common_ColumnHeader,0)),"Historical","Forward") | D11: =INDEX(INDIRECT(E11),0,COLUMN(MO_Common_Column_A)) | E11: MO_RIS_REV | F11: FY2025 | I11: 5150 | J11: 5350 | K11: =AVERAGE(I11:J11) | M11: =IF(INDEX(MO_SNA_IsHistoricalPeriod,,MATCH(F11,MO_Common_ColumnHeader,0)),"Actual","Estimate") | N11: =IFERROR(INDEX(INDIRECT(E11),0,MATCH(F11,MO_Common_ColumnHeader,0)),"N/A") | P11: =IF(ISNUMBER(N11),N11-K11,"N/A") | Q11: =IFERROR(IF(ISNUMBER(N11),(N11-K11)/ABS(K11),"N/A"),"N/A") | S11: 45881 | T11: Earnings Presentation
A12: 16 | B12: =IF(INDEX(MO_SNA_IsHistoricalPeriod,,MATCH(F12,MO_Common_ColumnHeader,0)),"Historical","Forward") | D12: =INDEX(INDIRECT(E12),0,COLUMN(MO_Common_Column_A)) | E12: MO_RIS_Reported_OperatingIncome_NONGAAP | F12: FY2025 | I12: 800 | J12: 830 | K12: =AVERAGE(I12:J12) | M12: =IF(INDEX(MO_SNA_IsHistoricalPeriod,,MATCH(F12,MO_Common_ColumnHeader,0)),"Actual","Estimate") | N12: =IFERROR(INDEX(INDIRECT(E12),0,MATCH(F12,MO_Common_ColumnHeader,0)),"N/A") | P12: =IF(ISNUMBER(N12),N12-K12,"N/A") | Q12: =IFERROR(IF(ISNUMBER(N12),(N12-K12)/ABS(K12),"N/A"),"N/A") | S12: 45881 | T12: Earnings Presentation
A13: 15 | B13: =IF(INDEX(MO_SNA_IsHistoricalPeriod,,MATCH(F13,MO_Common_ColumnHeader,0)),"Historical","Forward") | D13: =INDEX(INDIRECT(E13),0,COLUMN(MO_Common_Column_A)) | E13: MO_CFSum_Capex | F13: FY2025 | I13: -23000 | J13: -20000 | K13: =AVERAGE(I13:J13) | M13: =IF(INDEX(MO_SNA_IsHistoricalPeriod,,MATCH(F13,MO_Common_ColumnHeader,0)),"Actual","Estimate") | N13: =IFERROR(INDEX(INDIRECT(E13),0,MATCH(F13,MO_Common_ColumnHeader,0)),"N/A") | P13: =IF(ISNUMBER(N13),N13-K13,"N/A") | Q13: =IFERROR(IF(ISNUMBER(N13),(N13-K13)/ABS(K13),"N/A"),"N/A") | S13: 45881 | T13: Earnings Presentation
A14: 14
A15: 13 | B15: =IF(INDEX(MO_SNA_IsHistoricalPeriod,,MATCH(F15,MO_Common_ColumnHeader,0)),"Historical","Forward") | D15: =INDEX(INDIRECT(E15),0,COLUMN(MO_Common_Column_A)) | E15: MO_RIS_REV | F15: Q3-2025 | I15: 1260 | J15: 1300 | K15: =AVERAGE(I15:J15) | M15: =IF(INDEX(MO_SNA_IsHistoricalPeriod,,MATCH(F15,MO_Common_ColumnHeader,0)),"Actual","Estimate") | N15: =IFERROR(INDEX(INDIRECT(E15),0,MATCH(F15,MO_Common_ColumnHeader,0)),"N/A") | P15: =IF(ISNUMBER(N15),N15-K15,"N/A") | Q15: =IFERROR(IF(ISNUMBER(N15),(N15-K15)/ABS(K15),"N/A"),"N/A") | S15: 45881 | T15: Earnings Presentation
A16: 12 | B16: =IF(INDEX(MO_SNA_IsHistoricalPeriod,,MATCH(F16,MO_Common_ColumnHeader,0)),"Historical","Forward") | D16: =INDEX(INDIRECT(E16),0,COLUMN(MO_Common_Column_A)) | E16: MO_RIS_Reported_OperatingIncome_NONGAAP | F16: Q3-2025 | I16: 160 | J16: 190 | K16: =AVERAGE(I16:J16) | M16: =IF(INDEX(MO_SNA_IsHistoricalPeriod,,MATCH(F16,MO_Common_ColumnHeader,0)),"Actual","Estimate") | N16: =IFERROR(INDEX(INDIRECT(E16),0,MATCH(F16,MO_Common_ColumnHeader,0)),"N/A") | P16: =IF(ISNUMBER(N16),N16-K16,"N/A") | Q16: =IFERROR(IF(ISNUMBER(N16),(N16-K16)/ABS(K16),"N/A"),"N/A") | S16: 45881 | T16: Earnings Presentation
A17: 11 | B17: =IF(INDEX(MO_SNA_IsHistoricalPeriod,,MATCH(F17,MO_Common_ColumnHeader,0)),"Historical","Forward") | D17: =INDEX(INDIRECT(E17),0,COLUMN(MO_Common_Column_A)) | E17: MO_RIS_IE_Net | F17: Q3-2025 | I17: 350 | J17: 390 | K17: =AVERAGE(I17:J17) | M17: =IF(INDEX(MO_SNA_IsHistoricalPeriod,,MATCH(F17,MO_Common_ColumnHeader,0)),"Actual","Estimate") | N17: =IFERROR(INDEX(INDIRECT(E17),0,MATCH(F17,MO_Common_ColumnHeader,0)),"N/A") | P17: =IF(ISNUMBER(N17),N17-K17,"N/A") | Q17: =IFERROR(IF(ISNUMBER(N17),(N17-K17)/ABS(K17),"N/A"),"N/A") | S17: 45881 | T17: Earnings Presentation
A18: 10 | B18: =IF(INDEX(MO_SNA_IsHistoricalPeriod,,MATCH(F18,MO_Common_ColumnHeader,0)),"Historical","Forward") | D18: =INDEX(INDIRECT(E18),0,COLUMN(MO_Common_Column_A)) | E18: MO_CFSum_Capex | F18: Q3-2025 | I18: -3400 | J18: -2900 | K18: =AVERAGE(I18:J18) | M18: =IF(INDEX(MO_SNA_IsHistoricalPeriod,,MATCH(F18,MO_Common_ColumnHeader,0)),"Actual","Estimate") | N18: =IFERROR(INDEX(INDIRECT(E18),0,MATCH(F18,MO_Common_ColumnHeader,0)),"N/A") | P18: =IF(ISNUMBER(N18),N18-K18,"N/A") | Q18: =IFERROR(IF(ISNUMBER(N18),(N18-K18)/ABS(K18),"N/A"),"N/A") | S18: 45881 | T18: Earnings Presentation
A19: 9
A20: 8 | B20: =IF(INDEX(MO_SNA_IsHistoricalPeriod,,MATCH(F20,MO_Common_ColumnHeader,0)),"Historical","Forward") | D20: =INDEX(INDIRECT(E20),0,COLUMN(MO_Common_Column_A)) | E20: MO_RIS_REV | F20: FY2025 | I20: 4900 | J20: 5100 | K20: =AVERAGE(I20:J20) | M20: =IF(INDEX(MO_SNA_IsHistoricalPeriod,,MATCH(F20,MO_Common_ColumnHeader,0)),"Actual","Estimate") | N20: =IFERROR(INDEX(INDIRECT(E20),0,MATCH(F20,MO_Common_ColumnHeader,0)),"N/A") | P20: =IF(ISNUMBER(N20),N20-K20,"N/A") | Q20: =IFERROR(IF(ISNUMBER(N20),(N20-K20)/ABS(K20),"N/A"),"N/A") | S20: 45791 | T20: Earnings Presentation
A21: 7 | B21: =IF(INDEX(MO_SNA_IsHistoricalPeriod,,MATCH(F21,MO_Common_ColumnHeader,0)),"Historical","Forward") | D21: =INDEX(INDIRECT(E21),0,COLUMN(MO_Common_Column_A)) | E21: MO_RIS_Reported_OperatingIncome_NONGAAP | F21: FY2025 | I21: 800 | J21: 830 | K21: =AVERAGE(I21:J21) | M21: =IF(INDEX(MO_SNA_IsHistoricalPeriod,,MATCH(F21,MO_Common_ColumnHeader,0)),"Actual","Estimate") | N21: =IFERROR(INDEX(INDIRECT(E21),0,MATCH(F21,MO_Common_ColumnHeader,0)),"N/A") | P21: =IF(ISNUMBER(N21),N21-K21,"N/A") | Q21: =IFERROR(IF(ISNUMBER(N21),(N21-K21)/ABS(K21),"N/A"),"N/A") | S21: 45791 | T21: Earnings Presentation
A22: 6 | B22: =IF(INDEX(MO_SNA_IsHistoricalPeriod,,MATCH(F22,MO_Common_ColumnHeader,0)),"Historical","Forward") | D22: =INDEX(INDIRECT(E22),0,COLUMN(MO_Common_Column_A)) | E22: MO_CFSum_Capex | F22: FY2025 | I22: -23000 | J22: -20000 | K22: =AVERAGE(I22:J22) | M22: =IF(INDEX(MO_SNA_IsHistoricalPeriod,,MATCH(F22,MO_Common_ColumnHeader,0)),"Actual","Estimate") | N22: =IFERROR(INDEX(INDIRECT(E22),0,MATCH(F22,MO_Common_ColumnHeader,0)),"N/A") | P22: =IF(ISNUMBER(N22),N22-K22,"N/A") | Q22: =IFERROR(IF(ISNUMBER(N22),(N22-K22)/ABS(K22),"N/A"),"N/A") | S22: 45791 | T22: Earnings Presentation
A23: 5
A24: 4 | B24: =IF(INDEX(MO_SNA_IsHistoricalPeriod,,MATCH(F24,MO_Common_ColumnHeader,0)),"Historical","Forward") | D24: =INDEX(INDIRECT(E24),0,COLUMN(MO_Common_Column_A)) | E24: MO_RIS_REV | F24: Q2-2025 | I24: 1060 | J24: 1100 | K24: =AVERAGE(I24:J24) | M24: =IF(INDEX(MO_SNA_IsHistoricalPeriod,,MATCH(F24,MO_Common_ColumnHeader,0)),"Actual","Estimate") | N24: =IFERROR(INDEX(INDIRECT(E24),0,MATCH(F24,MO_Common_ColumnHeader,0)),"N/A") | P24: =IF(ISNUMBER(N24),N24-K24,"N/A") | Q24: =IFERROR(IF(ISNUMBER(N24),(N24-K24)/ABS(K24),"N/A"),"N/A") | S24: 45791 | T24: Earnings Presentation
A25: 3 | B25: =IF(INDEX(MO_SNA_IsHistoricalPeriod,,MATCH(F25,MO_Common_ColumnHeader,0)),"Historical","Forward") | D25: =INDEX(INDIRECT(E25),0,COLUMN(MO_Common_Column_A)) | E25: MO_RIS_Reported_OperatingIncome_NONGAAP | F25: Q2-2025 | I25: 140 | J25: 170 | K25: =AVERAGE(I25:J25) | M25: =IF(INDEX(MO_SNA_IsHistoricalPeriod,,MATCH(F25,MO_Common_ColumnHeader,0)),"Actual","Estimate") | N25: =IFERROR(INDEX(INDIRECT(E25),0,MATCH(F25,MO_Common_ColumnHeader,0)),"N/A") | P25: =IF(ISNUMBER(N25),N25-K25,"N/A") | Q25: =IFERROR(IF(ISNUMBER(N25),(N25-K25)/ABS(K25),"N/A"),"N/A") | S25: 45791 | T25: Earnings Presentation
A26: 2 | B26: =IF(INDEX(MO_SNA_IsHistoricalPeriod,,MATCH(F26,MO_Common_ColumnHeader,0)),"Historical","Forward") | D26: =INDEX(INDIRECT(E26),0,COLUMN(MO_Common_Column_A)) | E26: MO_RIS_IE_Net | F26: Q2-2025 | I26: 260 | J26: 300 | K26: =AVERAGE(I26:J26) | M26: =IF(INDEX(MO_SNA_IsHistoricalPeriod,,MATCH(F26,MO_Common_ColumnHeader,0)),"Actual","Estimate") | N26: =IFERROR(INDEX(INDIRECT(E26),0,MATCH(F26,MO_Common_ColumnHeader,0)),"N/A") | P26: =IF(ISNUMBER(N26),N26-K26,"N/A") | Q26: =IFERROR(IF(ISNUMBER(N26),(N26-K26)/ABS(K26),"N/A"),"N/A") | S26: 45791 | T26: Earnings Presentation
A27: 1 | B27: =IF(INDEX(MO_SNA_IsHistoricalPeriod,,MATCH(F27,MO_Common_ColumnHeader,0)),"Historical","Forward") | D27: =INDEX(INDIRECT(E27),0,COLUMN(MO_Common_Column_A)) | E27: MO_CFSum_Capex | F27: Q2-2025 | I27: -3500 | J27: -3000 | K27: =AVERAGE(I27:J27) | M27: =IF(INDEX(MO_SNA_IsHistoricalPeriod,,MATCH(F27,MO_Common_ColumnHeader,0)),"Actual","Estimate") | N27: =IFERROR(INDEX(INDIRECT(E27),0,MATCH(F27,MO_Common_ColumnHeader,0)),"N/A") | P27: =IF(ISNUMBER(N27),N27-K27,"N/A") | Q27: =IFERROR(IF(ISNUMBER(N27),(N27-K27)/ABS(K27),"N/A"),"N/A") | S27: 45791 | T27: Earnings Presentation
A28: 0

Sheet IPO
A1: =MO.CompanyName
A2: =CHOOSE(MO.DataSourceIndex,MO.Ticker.Bloomberg,MO.Ticker.CapIQ,MO.Ticker.FactSet,MO.Ticker.Thomson)
A3: Last Update Event: | C3: =FP.UpdateEvent
A4: Period of the IPO: | C4: Q1-2025
A5: Trading Date: | C5: 45744
A6: Commenced Trading: | C6: =IFERROR(AND(ISNUMBER(IPO.TradingDate),TODAY()>=IPO.TradingDate),FALSE)
A8: Total Transaction Summary
A9: IPO Price in Reporting Currency, $ | C9: 40 | D9: =IF(_xlfn.ISFORMULA(C9),"Dependant","Variable") | F9: Lock-Up Agreements
A10: Total Shares Issued in Financing Including Secondary, mm | C10: =C19 | F10: In connection with this offering, all of our directors and executive officers, the selling stockholders, and certain other holders that together represent approximately 84.0% of our outstanding Class A common stock and securities directly or indirectly convertible into or exchangeable or exercisable for our Class A common stock are subject to lock-up agreements with the underwriters pursuant to which they have agreed, subject to certain exceptions, that without the prior written consent of Morgan Stanley & Co. LLC (“Morgan Stanley”), on behalf of the underwriters, and Magnetar, they will not, in accordance with the terms of such agreements during the period ending on the earlier of (i) the close of trading on the second trading day after the date that we publicly announce earnings for the second quarter following the most recent period for which financial statements are included in this prospectus, and (ii) 180 days after the date of this prospectus (such period, the “Lock-up Period”): (1) offer, pledge, sell, contract to sell, sell any option or contract to purchase, purchase any option or contract to sell, grant any option, right, or warrant to purchase, lend, or otherwise transfer or dispose of, directly or indirectly, any shares of our Class A common stock and securities directly or indirectly convertible into or exchangeable or exercisable for our Class A common stock; (2) enter into any swap, hedging transaction, or other arrangement that transfers to another, in whole or in part, any of the economic consequences of ownership of our Class A common stock, whether any such transaction described above is to be settled by delivery of our Class A common stock or such other securities, in cash or otherwise; (3) publicly disclose the intention to take any of the actions restricted by clause (1) or (2) above; or (4) make any demand for, or exercise any right with respect to, the registration of any shares of our Class A common stock or any security convertible into or exercisable or exchangeable for our Class A common stock. Furthermore, an additional approximately 14.3% of our outstanding Class A common stock and securities directly or indirectly convertible into or exchangeable or exercisable for our Class A common stock are subject to the market standoff provisions, pursuant to which such holders agreed to not lend, offer, sell, contract to sell, sell any option or contract to purchase, purchase any option or contract to sell, grant any option, right, or warrant to purchase, or otherwise transfer or dispose of, directly or indirectly, any shares of our Class A common stock or any securities convertible into or exercisable or exchangeable for our Class A common stock held immediately prior to the effectiveness of this registration statement, or enter into any swap or other arrangement that transfers to another, in whole or in part, any of the economic consequences of ownership of such Class A common stock during the Lock-up Period. The forms and specific restrictive provisions within these market standoff provisions vary among security holders. For example, although some of these market standoff agreements do not specifically restrict hedging transactions and others may be subject to different interpretations between us and security holders as to whether they restrict hedging, our insider trading policy prohibits hedging by all of our current directors, officers, employees, contractors, and consultants. Sales, short sales, or hedging transactions involving our equity securities, whether before or after this offering and whether or not we believe them to be prohibited, could adversely affect the price of our Class A common stock. As a result of the foregoing, substantially all of our outstanding Class A common stock and securities directly or indirectly convertible into or exchangeable or exercisable for our Class A common stock are subject to a lock-up agreement or market standoff provisions during the Lock-up Period. We have agreed to enforce all such market standoff restrictions on behalf of the underwriters and not to amend or waive any such market standoff provisions during the Lock-up Period without the prior written consent of Magnetar and Morgan Stanley, on behalf of the underwriters, provided that we may release shares from such restrictions to the extent such shares would be entitled to release under the form of lock-up agreement with the underwriters entered into by our directors and executive officers, the selling stockholders, and certain other holders of our securities as described herein. Certain of our security holders that are not bound by market standoff restrictions or lock-up agreements could enter into transactions with respect to those shares of our Class A common stock that negatively impact our stock price. In addition, a security holder who is neither subject to market standoff restrictions with us nor a lock-up agreement with the underwriters may be able to sell, short sell, transfer, pledge, or otherwise dispose of or attempt to sell, short sell, transfer, hedge, pledge, or otherwise dispose of their equity interests at any time, subject to our insider trading policy, as applicable, and applicable securities laws. In addition, pursuant to certain exceptions to the lock-up agreements and market standoff agreements, up to approximately 727,342 shares of our Class A common stock will be eligible for sale in the open market during the Lock-up Period in sell-to-cover transactions in order to satisfy tax withholding obligations. Furthermore, approximately 963,140 shares of our outstanding Class A common stock and securities directly or indirectly convertible into or exchangeable or exercisable for our common stock held by our current employees and service providers (excluding the Management Holders and directors) may be sold at the close of trading of the second trading day after the date that we publicly announce earnings for the first quarter following the most recent period for which financial statements are included in this prospectus, if the closing price per share of our Class A common stock on Nasdaq for any five trading days out of the ten consecutive trading day period including at least one day occurring after the Initial Post-Offering Earnings Release Date is at least 25% greater than the initial public offering price of our Class A common stock set forth on the cover of this prospectus. (Page 229-230)
A11: Total Transaction Size, mm | C11: =C9*C10
A13: Class A Treasury IPO Shares Issued, mm | C13: 36.59 | D13: =IF(_xlfn.ISFORMULA(C13),"Dependant","Variable")
A14: Class A Treasury Shares Issued from Overallotment, mm | B14: =5.625/IPO.TreasurySharesIssued | C14: =IF(D14="Yes",C13*B14,0) | D14: Yes
A15: Class A Treasury Shares Issued in Concurrent Private Placement, mm | C15: 0
A16: Class A Treasury IPO Shares Issued Including Overallotment, mm | C16: =C13+C14+C15
A17: Class A Secondary Shares Issued, mm | C17: 0.91
A18: Secondary Shares Issued from Overallotment, mm | B18: 0 | C18: =IF(D18="Yes",C17*B18,0) | D18: No
A19: Total Shares Issued in Financing Including Secondary, mm | C19: =C16+C17+C18
A21: IPO Proceeds Details
A22: Gross IPO Amount to Company, mm | C22: =C9*C13 | D22: =IF(_xlfn.ISFORMULA(C22),"Dependant","Variable")
A23: Gross Overallotment Amount to Company, mm | C23: =C9*C14
A24: Gross Amount from Concurrent Private Placement, mm | C24: =C9*C15
A25: Total Gross IPO Amount to Company Including Overallotment, mm | C25: =C22+C23+C24
A26: IPO Fees Dependant on Transaction Size, mm | B26: =IF(IPO.OverallotmentToggle="No",0.024596,0.036124) | C26: =-B26*C25
A27: Other IPO expenses, mm | C27: -27.6
A28: IPO Amount to Company Including Overallotment Less Fees, mm | C28: =C25+C26+C27
A30: Share Analysis
A31: Pre-Existing Class A Common Shares, mm | C31: 300.65741
A32: Pre-Existing Class B Common Shares, mm | C32: 118.10204
A33: Pre-IPO Pro Forma Shares, mm | C33: =C31+C32
A34: Class A Treasury IPO Shares Issued, mm | C34: =C16
A35: Class A Treasury Shares Issued in Concurrent Private Placement, mm | C35: 8.75
A36: Post-IPO and Concurrent Private Placement Pro Forma Basic Shares, mm | C36: =C33+C34+C35
A37: Stock Options (treasury method, based on toggle), mm | C37: =IF($D$37="Vested",IF(C9>C68,C60-C60*C68/C9,0),IF(C9>C67,C59-C59*C67/C9,0)+IF(C9>C69,C61-C61*C69/C9,0)) | D37: Outstanding
A38: Warrants, mm | C38: =IF(C9>C73,C72-C72*C73/C9,0)+IF(C9>C75,C74-C74*C75/C9,0)
A39: RSUs, mm | C39: =C78
A40: Post-IPO and Concurrent Private Placement Pro Forma Diluted Shares, mm | C40: =IPO.ShareCount.WAB+SUM(C37:C39)
A42: Post-IPO Pro Forma Class A Common Shares, mm | C42: =C31+C34+C35
A43: Post-IPO Pro Forma Class B Common Shares, mm | C43: =C32
A44: Post-IPO Pro Forma Total Common Shares, mm | C44: =C42+C43
A46: EV Calculation
...

Sheet Summary Page
A1: =MO.CompanyName | C1: =INDEX(MO_Common_QEndDate,0,COLUMN()) | D1: =INDEX(MO_Common_QEndDate,0,COLUMN()) | E1: =INDEX(MO_Common_QEndDate,0,COLUMN()) | F1: =INDEX(MO_Common_QEndDate,0,COLUMN()) | G1: =INDEX(MO_Common_QEndDate,0,COLUMN()) | H1: =INDEX(MO_Common_QEndDate,0,COLUMN()) | I1: =INDEX(MO_Common_QEndDate,0,COLUMN()) | J1: =INDEX(MO_Common_QEndDate,0,COLUMN()) | ... AU1: =INDEX(MO_Common_QEndDate,0,COLUMN())
A2: Reports | B2: =MO.ReportFX | C2: =INDEX(MO_Common_ColumnHeader,0,COLUMN()) | D2: =INDEX(MO_Common_ColumnHeader,0,COLUMN()) | E2: =INDEX(MO_Common_ColumnHeader,0,COLUMN()) | F2: =INDEX(MO_Common_ColumnHeader,0,COLUMN()) | G2: =INDEX(MO_Common_ColumnHeader,0,COLUMN()) | H2: =INDEX(MO_Common_ColumnHeader,0,COLUMN()) | I2: =INDEX(MO_Common_ColumnHeader,0,COLUMN()) | J2: =INDEX(MO_Common_ColumnHeader,0,COLUMN()) | ... AU2: =INDEX(MO_Common_ColumnHeader,0,COLUMN())
A3: Capitalization Summary
A4: ="Stock Price - "&SP.ValuationToggle | B4: EoP | AI4: =IF(INDEX(MO_SNA_IsHistoricalPeriod,1,COLUMN())=FALSE,MO.LastPrice/HP.MRFX,CHOOSE(VLOOKUP(SP.ValuationToggle,tb_ValuationToggle,COLUMNS(tb_ValuationToggle),FALSE),INDEX(MO_SPT_StockHigh,1,COLUMN()),INDEX(MO_SPT_StockLow,1,COLUMN()),INDEX(MO_SPT_StockAverage,1,COLUMN()),INDEX(MO_SPT_StockEoP,1,COLUMN()))/IF(SP.ValuationToggle="EoP",IF(INDEX(MO_SPT_FXEoP,1,COLUMN())=0,1,INDEX(MO_SPT_FXEoP,1,COLUMN())),IF(INDEX(MO_SPT_FXAverage,1,COLUMN())=0,1,INDEX(MO_SPT_FXAverage,1,COLUMN())))) | AJ4: =IF(INDEX(MO_SNA_IsHistoricalPeriod,1,COLUMN())=FALSE,MO.LastPrice/HP.MRFX,CHOOSE(VLOOKUP(SP.ValuationToggle,tb_ValuationToggle,COLUMNS(tb_ValuationToggle),FALSE),INDEX(MO_SPT_StockHigh,1,COLUMN()),INDEX(MO_SPT_StockLow,1,COLUMN()),INDEX(MO_SPT_StockAverage,1,COLUMN()),INDEX(MO_SPT_StockEoP,1,COLUMN()))/IF(SP.ValuationToggle="EoP",IF(INDEX(MO_SPT_FXEoP,1,COLUMN())=0,1,INDEX(MO_SPT_FXEoP,1,COLUMN())),IF(INDEX(MO_SPT_FXAverage,1,COLUMN())=0,1,INDEX(MO_SPT_FXAverage,1,COLUMN())))) | AK4: =IF(INDEX(MO_SNA_IsHistoricalPeriod,1,COLUMN())=FALSE,MO.LastPrice/HP.MRFX,CHOOSE(VLOOKUP(SP.ValuationToggle,tb_ValuationToggle,COLUMNS(tb_ValuationToggle),FALSE),INDEX(MO_SPT_StockHigh,1,COLUMN()),INDEX(MO_SPT_StockLow,1,COLUMN()),INDEX(MO_SPT_StockAverage,1,COLUMN()),INDEX(MO_SPT_StockEoP,1,COLUMN()))/IF(SP.ValuationToggle="EoP",IF(INDEX(MO_SPT_FXEoP,1,COLUMN())=0,1,INDEX(MO_SPT_FXEoP,1,COLUMN())),IF(INDEX(MO_SPT_FXAverage,1,COLUMN())=0,1,INDEX(MO_SPT_FXAverage,1,COLUMN())))) | AL4: =IF(INDEX(MO_SNA_IsHistoricalPeriod,1,COLUMN())=FALSE,MO.LastPrice/HP.MRFX,CHOOSE(VLOOKUP(SP.ValuationToggle,tb_ValuationToggle,COLUMNS(tb_ValuationToggle),FALSE),INDEX(MO_SPT_StockHigh,1,COLUMN()),INDEX(MO_SPT_StockLow,1,COLUMN()),INDEX(MO_SPT_StockAverage,1,COLUMN()),INDEX(MO_SPT_StockEoP,1,COLUMN()))/IF(SP.ValuationToggle="EoP",IF(INDEX(MO_SPT_FXEoP,1,COLUMN())=0,1,INDEX(MO_SPT_FXEoP,1,COLUMN())),IF(INDEX(MO_SPT_FXAverage,1,COLUMN())=0,1,INDEX(MO_SPT_FXAverage,1,COLUMN())))) | AM4: =IF(INDEX(MO_SNA_IsHistoricalPeriod,1,COLUMN())=FALSE,MO.LastPrice/HP.MRFX,CHOOSE(VLOOKUP(SP.ValuationToggle,tb_ValuationToggle,COLUMNS(tb_ValuationToggle),FALSE),INDEX(MO_SPT_StockHigh,1,COLUMN()),INDEX(MO_SPT_StockLow,1,COLUMN()),INDEX(MO_SPT_StockAverage,1,COLUMN()),INDEX(MO_SPT_StockEoP,1,COLUMN()))/IF(SP.ValuationToggle="EoP",IF(INDEX(MO_SPT_FXEoP,1,COLUMN())=0,1,INDEX(MO_SPT_FXEoP,1,COLUMN())),IF(INDEX(MO_SPT_FXAverage,1,COLUMN())=0,1,INDEX(MO_SPT_FXAverage,1,COLUMN())))) | AN4: =IF(INDEX(MO_SNA_IsHistoricalPeriod,1,COLUMN())=FALSE,MO.LastPrice/HP.MRFX,CHOOSE(VLOOKUP(SP.ValuationToggle,tb_ValuationToggle,COLUMNS(tb_ValuationToggle),FALSE),INDEX(MO_SPT_StockHigh,1,COLUMN()),INDEX(MO_SPT_StockLow,1,COLUMN()),INDEX(MO_SPT_StockAverage,1,COLUMN()),INDEX(MO_SPT_StockEoP,1,COLUMN()))/IF(SP.ValuationToggle="EoP",IF(INDEX(MO_SPT_FXEoP,1,COLUMN())=0,1,INDEX(MO_SPT_FXEoP,1,COLUMN())),IF(INDEX(MO_SPT_FXAverage,1,COLUMN())=0,1,INDEX(MO_SPT_FXAverage,1,COLUMN())))) | AO4: =IF(INDEX(MO_SNA_IsHistoricalPeriod,1,COLUMN())=FALSE,MO.LastPrice/HP.MRFX,CHOOSE(VLOOKUP(SP.ValuationToggle,tb_ValuationToggle,COLUMNS(tb_ValuationToggle),FALSE),INDEX(MO_SPT_StockHigh,1,COLUMN()),INDEX(MO_SPT_StockLow,1,COLUMN()),INDEX(MO_SPT_StockAverage,1,COLUMN()),INDEX(MO_SPT_StockEoP,1,COLUMN()))/IF(SP.ValuationToggle="EoP",IF(INDEX(MO_SPT_FXEoP,1,COLUMN())=0,1,INDEX(MO_SPT_FXEoP,1,COLUMN())),IF(INDEX(MO_SPT_FXAverage,1,COLUMN())=0,1,INDEX(MO_SPT_FXAverage,1,COLUMN())))) | AP4: =IF(INDEX(MO_SNA_IsHistoricalPeriod,1,COLUMN())=FALSE,MO.LastPrice/HP.MRFX,CHOOSE(VLOOKUP(SP.ValuationToggle,tb_ValuationToggle,COLUMNS(tb_ValuationToggle),FALSE),INDEX(MO_SPT_StockHigh,1,COLUMN()),INDEX(MO_SPT_StockLow,1,COLUMN()),INDEX(MO_SPT_StockAverage,1,COLUMN()),INDEX(MO_SPT_StockEoP,1,COLUMN()))/IF(SP.ValuationToggle="EoP",IF(INDEX(MO_SPT_FXEoP,1,COLUMN())=0,1,INDEX(MO_SPT_FXEoP,1,COLUMN())),IF(INDEX(MO_SPT_FXAverage,1,COLUMN())=0,1,INDEX(MO_SPT_FXAverage,1,COLUMN())))) | ... AU4: =IF(INDEX(MO_SNA_IsHistoricalPeriod,1,COLUMN())=FALSE,MO.LastPrice/HP.MRFX,CHOOSE(VLOOKUP(SP.ValuationToggle,tb_ValuationToggle,COLUMNS(tb_ValuationToggle),FALSE),INDEX(MO_SPT_StockHigh,1,COLUMN()),INDEX(MO_SPT_StockLow,1,COLUMN()),INDEX(MO_SPT_StockAverage,1,COLUMN()),INDEX(MO_SPT_StockEoP,1,COLUMN()))/IF(SP.ValuationToggle="EoP",IF(INDEX(MO_SPT_FXEoP,1,COLUMN())=0,1,INDEX(MO_SPT_FXEoP,1,COLUMN())),IF(INDEX(MO_SPT_FXAverage,1,COLUMN())=0,1,INDEX(MO_SPT_FXAverage,1,COLUMN()))))
A5: =INDEX(MO_SCA_ShareCount_EoP_Diluted,0,COLUMN()) | X5: =INDEX(MO_SCA_ShareCount_EoP_Diluted,0,COLUMN()) | AA5: =INDEX(MO_SCA_ShareCount_EoP_Diluted,0,COLUMN()) | AB5: =INDEX(MO_SCA_ShareCount_EoP_Diluted,0,COLUMN()) | AC5: =INDEX(MO_SCA_ShareCount_EoP_Diluted,0,COLUMN()) | AD5: =INDEX(MO_SCA_ShareCount_EoP_Diluted,0,COLUMN()) | AE5: =INDEX(MO_SCA_ShareCount_EoP_Diluted,0,COLUMN()) | AF5: =INDEX(MO_SCA_ShareCount_EoP_Diluted,0,COLUMN()) | AG5: =INDEX(MO_SCA_ShareCount_EoP_Diluted,0,COLUMN()) | AH5: =INDEX(MO_SCA_ShareCount_EoP_Diluted,0,COLUMN()) | ... AU5: =INDEX(MO_SCA_ShareCount_EoP_Diluted,0,COLUMN())
A6: ="Market Cap - "&SP.ValuationToggle | AI6: =INDEX(SP_CS_StockPrice,0,COLUMN())*INDEX(SP_CS_ShareCount_EoP_Diluted,0,COLUMN()) | AJ6: =INDEX(SP_CS_StockPrice,0,COLUMN())*INDEX(SP_CS_ShareCount_EoP_Diluted,0,COLUMN()) | AK6: =INDEX(SP_CS_StockPrice,0,COLUMN())*INDEX(SP_CS_ShareCount_EoP_Diluted,0,COLUMN()) | AL6: =INDEX(SP_CS_StockPrice,0,COLUMN())*INDEX(SP_CS_ShareCount_EoP_Diluted,0,COLUMN()) | AM6: =INDEX(SP_CS_StockPrice,0,COLUMN())*INDEX(SP_CS_ShareCount_EoP_Diluted,0,COLUMN()) | AN6: =INDEX(SP_CS_StockPrice,0,COLUMN())*INDEX(SP_CS_ShareCount_EoP_Diluted,0,COLUMN()) | AO6: =INDEX(SP_CS_StockPrice,0,COLUMN())*INDEX(SP_CS_ShareCount_EoP_Diluted,0,COLUMN()) | AP6: =INDEX(SP_CS_StockPrice,0,COLUMN())*INDEX(SP_CS_ShareCount_EoP_Diluted,0,COLUMN()) | ... AU6: =INDEX(SP_CS_StockPrice,0,COLUMN())*INDEX(SP_CS_ShareCount_EoP_Diluted,0,COLUMN())
A7: =INDEX(MO_BSS_Cash,0,COLUMN()) | AB7: =INDEX(MO_BSS_Cash,0,COLUMN()) | AC7: =INDEX(MO_BSS_Cash,0,COLUMN()) | AG7: =INDEX(MO_BSS_Cash,0,COLUMN()) | AH7: =INDEX(MO_BSS_Cash,0,COLUMN()) | AI7: =INDEX(MO_BSS_Cash,0,COLUMN()) | AJ7: =INDEX(MO_BSS_Cash,0,COLUMN()) | AK7: =INDEX(MO_BSS_Cash,0,COLUMN()) | AL7: =INDEX(MO_BSS_Cash,0,COLUMN()) | AM7: =INDEX(MO_BSS_Cash,0,COLUMN()) | AN7: =INDEX(MO_BSS_Cash,0,COLUMN()) | ... AU7: =INDEX(MO_BSS_Cash,0,COLUMN())
A8: =INDEX(MO_BSS_Debt,0,COLUMN()) | AB8: =INDEX(MO_BSS_Debt,0,COLUMN()) | AC8: =INDEX(MO_BSS_Debt,0,COLUMN()) | AG8: =INDEX(MO_BSS_Debt,0,COLUMN()) | AH8: =INDEX(MO_BSS_Debt,0,COLUMN()) | AI8: =INDEX(MO_BSS_Debt,0,COLUMN()) | AJ8: =INDEX(MO_BSS_Debt,0,COLUMN()) | AK8: =INDEX(MO_BSS_Debt,0,COLUMN()) | AL8: =INDEX(MO_BSS_Debt,0,COLUMN()) | AM8: =INDEX(MO_BSS_Debt,0,COLUMN()) | AN8: =INDEX(MO_BSS_Debt,0,COLUMN()) | ... AU8: =INDEX(MO_BSS_Debt,0,COLUMN())
A9: =INDEX(MO_BSS_OL,0,COLUMN()) | AB9: =INDEX(MO_BSS_OL,0,COLUMN()) | AC9: =INDEX(MO_BSS_OL,0,COLUMN()) | AG9: =INDEX(MO_BSS_OL,0,COLUMN()) | AH9: =INDEX(MO_BSS_OL,0,COLUMN()) | AI9: =INDEX(MO_BSS_OL,0,COLUMN()) | AJ9: =INDEX(MO_BSS_OL,0,COLUMN()) | AK9: =INDEX(MO_BSS_OL,0,COLUMN()) | AL9: =INDEX(MO_BSS_OL,0,COLUMN()) | AM9: =INDEX(MO_BSS_OL,0,COLUMN()) | AN9: =INDEX(MO_BSS_OL,0,COLUMN()) | ... AU9: =INDEX(MO_BSS_OL,0,COLUMN())
A10: Other EV Components | AB10: =INDEX(MO_VA_EVCalc_NCI,0,COLUMN())+INDEX(MO_VA_EVCalc_Prefs,0,COLUMN())+INDEX(MO_VA_EVCalc_Other,0,COLUMN()) | AC10: =INDEX(MO_VA_EVCalc_NCI,0,COLUMN())+INDEX(MO_VA_EVCalc_Prefs,0,COLUMN())+INDEX(MO_VA_EVCalc_Other,0,COLUMN()) | AG10: =INDEX(MO_VA_EVCalc_NCI,0,COLUMN())+INDEX(MO_VA_EVCalc_Prefs,0,COLUMN())+INDEX(MO_VA_EVCalc_Other,0,COLUMN()) | AH10: =INDEX(MO_VA_EVCalc_NCI,0,COLUMN())+INDEX(MO_VA_EVCalc_Prefs,0,COLUMN())+INDEX(MO_VA_EVCalc_Other,0,COLUMN()) | AI10: =INDEX(MO_VA_EVCalc_NCI,0,COLUMN())+INDEX(MO_VA_EVCalc_Prefs,0,COLUMN())+INDEX(MO_VA_EVCalc_Other,0,COLUMN()) | AJ10: =INDEX(MO_VA_EVCalc_NCI,0,COLUMN())+INDEX(MO_VA_EVCalc_Prefs,0,COLUMN())+INDEX(MO_VA_EVCalc_Other,0,COLUMN()) | AK10: =INDEX(MO_VA_EVCalc_NCI,0,COLUMN())+INDEX(MO_VA_EVCalc_Prefs,0,COLUMN())+INDEX(MO_VA_EVCalc_Other,0,COLUMN()) | AL10: =INDEX(MO_VA_EVCalc_NCI,0,COLUMN())+INDEX(MO_VA_EVCalc_Prefs,0,COLUMN())+INDEX(MO_VA_EVCalc_Other,0,COLUMN()) | AM10: =INDEX(MO_VA_EVCalc_NCI,0,COLUMN())+INDEX(MO_VA_EVCalc_Prefs,0,COLUMN())+INDEX(MO_VA_EVCalc_Other,0,COLUMN()) | AN10: =INDEX(MO_VA_EVCalc_NCI,0,COLUMN())+INDEX(MO_VA_EVCalc_Prefs,0,COLUMN())+INDEX(MO_VA_EVCalc_Other,0,COLUMN()) | ... AU10: =INDEX(MO_VA_EVCalc_NCI,0,COLUMN())+INDEX(MO_VA_EVCalc_Prefs,0,COLUMN())+INDEX(MO_VA_EVCalc_Other,0,COLUMN())
A11: ="Enterprise Value - "&SP.ValuationToggle | AI11: =INDEX(SP_CS_MarketCap,0,COLUMN())-INDEX(SP_CS_Cash,0,COLUMN())+INDEX(SP_CS_Debt,0,COLUMN())+INDEX(SP_CS_OL,0,COLUMN())+INDEX(SP_CS_EVCalc_Other,0,COLUMN()) | AJ11: =INDEX(SP_CS_MarketCap,0,COLUMN())-INDEX(SP_CS_Cash,0,COLUMN())+INDEX(SP_CS_Debt,0,COLUMN())+INDEX(SP_CS_OL,0,COLUMN())+INDEX(SP_CS_EVCalc_Other,0,COLUMN()) | AK11: =INDEX(SP_CS_MarketCap,0,COLUMN())-INDEX(SP_CS_Cash,0,COLUMN())+INDEX(SP_CS_Debt,0,COLUMN())+INDEX(SP_CS_OL,0,COLUMN())+INDEX(SP_CS_EVCalc_Other,0,COLUMN()) | AL11: =INDEX(SP_CS_MarketCap,0,COLUMN())-INDEX(SP_CS_Cash,0,COLUMN())+INDEX(SP_CS_Debt,0,COLUMN())+INDEX(SP_CS_OL,0,COLUMN())+INDEX(SP_CS_EVCalc_Other,0,COLUMN()) | AM11: =INDEX(SP_CS_MarketCap,0,COLUMN())-INDEX(SP_CS_Cash,0,COLUMN())+INDEX(SP_CS_Debt,0,COLUMN())+INDEX(SP_CS_OL,0,COLUMN())+INDEX(SP_CS_EVCalc_Other,0,COLUMN()) | AN11: =INDEX(SP_CS_MarketCap,0,COLUMN())-INDEX(SP_CS_Cash,0,COLUMN())+INDEX(SP_CS_Debt,0,COLUMN())+INDEX(SP_CS_OL,0,COLUMN())+INDEX(SP_CS_EVCalc_Other,0,COLUMN()) | AO11: =INDEX(SP_CS_MarketCap,0,COLUMN())-INDEX(SP_CS_Cash,0,COLUMN())+INDEX(SP_CS_Debt,0,COLUMN())+INDEX(SP_CS_OL,0,COLUMN())+INDEX(SP_CS_EVCalc_Other,0,COLUMN()) | AP11: =INDEX(SP_CS_MarketCap,0,COLUMN())-INDEX(SP_CS_Cash,0,COLUMN())+INDEX(SP_CS_Debt,0,COLUMN())+INDEX(SP_CS_OL,0,COLUMN())+INDEX(SP_CS_EVCalc_Other,0,COLUMN()) | ... AU11: =INDEX(SP_CS_MarketCap,0,COLUMN())-INDEX(SP_CS_Cash,0,COLUMN())+INDEX(SP_CS_Debt,0,COLUMN())+INDEX(SP_CS_OL,0,COLUMN())+INDEX(SP_CS_EVCalc_Other,0,COLUMN())
A13: Company-Specific Operational Data
A14: =Model!A9 | AE14: =Model!AE9 | AF14: =Model!AF9 | AG14: =Model!AG9 | AI14: =Model!AI9 | AJ14: =Model!AJ9 | AK14: =Model!AK9 | AL14: =Model!AL9 | AN14: =Model!AN9 | AO14: =Model!AO9 | AP14: =Model!AP9 | AQ14: =Model!AQ9
A15: =Model!A10 | AC15: =Model!AC10 | AG15: =Model!AG10 | AH15: =Model!AH10 | AI15: =Model!AI10 | AJ15: =Model!AJ10 | AK15: =Model!AK10 | AL15: =Model!AL10 | AM15: =Model!AM10 | AN15: =Model!AN10 | ... AU15: =Model!AU10
A17: =Model!A34 | AC17: =Model!AC34 | AH17: =Model!AH34 | AI17: =Model!AI34 | AJ17: =Model!AJ34 | AK17: =Model!AK34
A18: =Model!A35 | AC18: =Model!AC35 | AH18: =Model!AH35 | AI18: =Model!AI35 | AJ18: =Model!AJ35 | AK18: =Model!AK35
A19: =Model!A36 | AC19: =Model!AC36 | AH19: =Model!AH36 | AI19: =Model!AI36 | AJ19: =Model!AJ36 | AK19: =Model!AK36
A20: =Model!A37 | AC20: =Model!AC37 | AH20: =Model!AH37 | AI20: =Model!AI37 | AJ20: =Model!AJ37 | AK20: =Model!AK37
A22: GAAP Financials and Non-GAAP Financials | AA22: 9 months
A23: =INDEX(MO_RIS_REV,0,COLUMN()) | X23: =INDEX(MO_RIS_REV,0,COLUMN()) | AA23: =INDEX(MO_RIS_REV,0,COLUMN()) | AB23: =INDEX(MO_RIS_REV,0,COLUMN()) | AC23: =INDEX(MO_RIS_REV,0,COLUMN()) | AD23: =INDEX(MO_RIS_REV,0,COLUMN()) | AE23: =INDEX(MO_RIS_REV,0,COLUMN()) | AF23: =INDEX(MO_RIS_REV,0,COLUMN()) | AG23: =INDEX(MO_RIS_REV,0,COLUMN()) | AH23: =INDEX(MO_RIS_REV,0,COLUMN()) | ... AU23: =INDEX(MO_RIS_REV,0,COLUMN())
