Workbook
Name AA.AlternatePriceSourceStartPeriod: "Q1-2019"
Name AA.CIK: "1045810"
Name AA.ColorizerVersion: "2.0.4.0"
Name AA.CompareQuarters.LatestMRQ: "Q2-2025"
Name AA.CSIN: "A7FLSL0150"
Name AA.CurationVersion: "2023.11.1.0"
Name AA.DBMacroVersion: "1.0.13.0"
Name AA.FreeCashFlow: "TRUE"
Name AA.GuidanceAnalysisNonGaapGrossProfitVersion: "1.0.0.0"
Name AA.GuidanceAnalysisRevenueVersion: "1.0.0.0"
Name AA.HardcodeChecker.LatestMRQ: "Q3-2020"
Name AA.ModelChecks.LatestMRQ: "Q3-2022"
Name AA.ModelChecks.LatestVersionNumber: "2.38.25.0"
Name AA.ModelColorScheme: "Classic"
Name AA.ModelVersion: "Q3-2026.20"
Name AA.NonLibraryWideCurationVersion: "4"
Name AA.PartialUpdate.BsAvailable: "TRUE"
Name AA.PartialUpdate.CfsAvailable: "TRUE"
Name AA.PartialUpdate.IsAvailable: "TRUE"
Name AA.PeriodLayout: "QFY"
Name AA.PersonalMacro.VersionNumber: ""
Name AA.RowNameEnforcerVersion: "2023.11.1.0"
Name AA.SessionToUploadId: ""
Name AA.StartWorkModelVersion: "Q2-2026.22"
Name AA.StartWorkType: ""
Name AA.SubyearType: "Q"
Name AA.TemplateUpgradeAttempted: "TRUE"
Name AA.TemplateVersion: "7.5.4.0"
Name AA.UpdateType: "Regular"
Name AA.VerifyUnitsAtModelVersion: "Q2-2019.21"
Name EC_CEO_BasePay: 'Exec Comp'!$7:$7
Name EC_CEO_EquityComp_Percent: 'Exec Comp'!$12:$12
Name EC_CEO_SharesOwned: 'Exec Comp'!$38:$38
Name EC_CEO_TotalComp: 'Exec Comp'!$11:$11
Name EC_CFO_BasePay: 'Exec Comp'!$40:$40
Name EC_CFO_EquityComp_Percent: 'Exec Comp'!$45:$45
Name EC_CFO_SharesOwned: 'Exec Comp'!$49:$49
Name EC_CFO_TotalComp: 'Exec Comp'!$44:$44
Name EC_Director_Compensation_Cash: 'Exec Comp'!$74:$74
Name EC_Director_Compensation_Total: 'Exec Comp'!$103:$103
Name EC_Directors_Current: 'Exec Comp'!$52:$52
Name EC_Directors_Current_Diverse: 'Exec Comp'!$55:$55
Name EC_Directors_Current_Female: 'Exec Comp'!$54:$54
Name EC_Directors_Current_Independent: 'Exec Comp'!$53:$53
Name EC_Directors_Nominees: 'Exec Comp'!$57:$57
Name EC_Directors_Nominees_Independent: 'Exec Comp'!$58:$58
Name EC_OperatingIncome_Target_NONGAAP: 'Exec Comp'!$118:$118
Name EC_Revenue_Target: 'Exec Comp'!$113:$113
Name FP_Comment: 'Front Page'!$M$13:$P$20
Name FP_StockPriceOverride: 'Front Page'!$C$20:$H$20
Name FP.DataSource: 'Front Page'!$H$16
Name FP.DataSourceName: 'Front Page'!$H$15
Name FP.Disclaimer: 'Front Page'!$C$22
Name FP.LastPrice: 'Front Page'!$H$20
Name FP.LastPriceDate: 'Front Page'!$F$20
Name FP.RealTimeToggle: 'Front Page'!$H$18
Name FP.UpdateDate: 'Front Page'!$H$11
Name FP.UpdateEvent: 'Front Page'!$H$13
Name GD_Difference_Mid_Absolute: Guidance!$P:$P
Name GD_Difference_Mid_Relative: Guidance!$Q:$Q

Sheet Front Page
M6: Please contact this email for any model-specific questions:
M7: modelsupport@alpha-sense.com | N7: mailto:support@canalyst.com?subject=Canalyst%20Support:%20NVIDIA%20Corporation%20NVDA%20US&body=Model%20Version:%20Q1-2020.20 | O7: mailto:support@canalyst.com?subject=Canalyst%20Support:%20NVIDIA%20Corporation%20NVDA%20US&body=Model%20Version:%20Q1-2020.20
C9: Company Model: | H9: =Model!A1
C11: Updated: | H11: =OFFSET('Update Log'!$C$10,1,0,1,1)
M12: Comments on Model:
C13: For: | H13: =OFFSET('Update Log'!$E$10,1,0,1,1) | M13: On August 26, 2024, the Board of Directors approved an additional $50.0 billion in share repurchase authorization, without expiration. 'On, May 21, 2021, The company announced a 4-for-1 stock split. The model was adjusted for the split on July 20, 2021' 'Starting with the first quarter of fiscal 2021, the company's reportable segments have changed to “Graphics” and “Compute & Networking.” During the third quarter, NVIDIA announced a definitive agreement to acquire Arm Limited from SoftBank Capital Limited and SVF Holdco (UK) Limited in a transaction valued at $40 billion. The transaction -- which is expected to be immediately accretive to NVIDIA’s non-GAAP gross margin and non-GAAP earnings per share -- is expected to close in the first quarter of calendar 2022.
C15: Consensus Data and Real-Time Stock Price: | H15: Bloomberg
H16: =IF(FP.DataSourceName="Bloomberg",1,IF(FP.DataSourceName="Capital IQ",2,IF(FP.DataSourceName="FactSet",3,IF(FP.DataSourceName="Refinitiv",4))))
C18: Real-Time Stock Price: | H18: OFF
C20: Stock Price Override: | F20: 45979 | H20: 181.36
C22: DISCLAIMER Access to and use of this model, including the data contained herein (this "Model") is subject to Tegus, Inc.'s (a successor entity to Canalyst Financial Modeling Corporation) ("Company") Terms of Use that you accepted prior to accessing this Model, the applicable Service Agreement between the Company and you (or a corporate entity that has authorized you to access and use this Model on its behalf in accordance with the terms of such Service Agreement) or other similar agreement between you and the Company. BY CONTINUING TO ACCESS OR USE THIS MODEL, YOU EXPRESSLY AGREE TO THE TERMS AND CONDITIONS OF SUCH AGREEMENTS. The Company and certain of its licensors have exclusive proprietary rights in this Model. This Model is being provided for internal use only. Unless prior written consent by the Company and its licensors has been provided to you, you may not distribute or otherwise furnish this Model to any third party, nor use or permit anyone to use this Model for any unlawful or unauthorized purpose. IF YOU HAVE UNLAWFULLY OBTAINED, OR ARE NOT AUTHORIZED TO USE THIS MODEL, YOU ARE OBLIGATED TO PROMPTLY: (I) RETURN THIS MODEL (AND ANY DERIVATIVE WORKS ARISING FROM OR RELATING THERETO) TO THE AUTHORIZED USER OF THIS MODEL; (II) PROVIDE NOTICE TO THE COMPANY AT LEGAL@TEGUS.COM OF SUCH UNLAWFUL OR UNAUTHORIZED ACCESS AND USE; AND, (III) CERTIFY THAT YOU HAVE DESTROYED THIS MODEL (AND ANY DERIVATIVE WORKS ARISING FROM OR RELATING THERETO) AND ANY COPIES FROM YOUR SYSTEMS SO AS TO ENSURE THEY ARE INCAPABLE OF RETRIEVAL. A portion of the data contained in this Model may be powered by third party contributors and their respective licensors, or derived from data provided by such contributors, including (but not limited to): (i) QuoteMedia Inc.: A portion of the market data is powered by Quotemedia.com. All rights reserved. Data delayed 15 minutes unless otherwise indicated; (ii) S&P Global Market Intelligence LLC: Copyright (c) {{YEAR}} S&P Global Market Intelligence LLC (and its affiliates as applicable). All rights reserved. Reproduction of any information, opinions, views, data or material, including ratings ("Content") in any form is prohibited except with the prior written permission of the relevant party. Such party, its affiliates and suppliers ("Content Providers") do not guarantee the accuracy, adequacy, completeness, timeliness or availability of any Content and are not responsible for any errors or omissions (negligent or otherwise), regardless of the cause, or for the results obtained from the use of such Content. In no event shall Content Providers be liable for any damages, costs, expenses, legal fees, or losses (including lost income or lost profit and opportunity costs) in connection with any use of the Content. A reference to a particular investment or security, a rating or any observation concerning an investment that is part of the Content is not a recommendation to buy, sell or hold such investment or security, does not address the suitability of an investment or security and should not be relied on as investment advice. Credit ratings are statements of opinions and are not statements of fact; and, (iii) Refinitiv Canada Holdings Limited: A portion of the information may be provided by or derived from data provided by Refinitiv. By accessing or using this Model (including any portion of the data contained herein) you expressly represent that such access or use does not constitute a violation of any applicable law or regulation to which you or the securities are subject. This Model does not constitute investment advice by the Company or any of its licensors. Reference to a particular investment or security, credit rating or any observation concerning a security or investment in this Model is not a recommendation or solicitation to buy, sell or hold such investment or security or make any other investment decisions. For greater certainty, any forecasts or forward-looking information expressed herein are for illustrative purposes only and do not purport to express any view on what may transpire. Neither the Company nor any of its licensors have performed company-specific research on any projected information, as such, it is your responsibility to express your own views on projected results. This Model does not guarantee future performance and undue reliance should not be placed on such. You are solely responsible for evaluating the merits and risks of any investment based on your own business and financial expertise, the business and financial expertise of professional advisors with whom you have consulted, your financial situation and risk tolerance. Neither the Company, nor any of its licensors, undertake any liability with respect to your reliance on this Model. This Model is a quantitative tool with no investment views. The Company and its respective directors, officers, employees, agents, contractors, and affiliates may hold long or short positions in the security to which this Model relates, based on their personal views, and may initiate or close out any positions in such security at any time without any notice. THIS MODEL IS PROVIDED "AS IS" AND ON AN "AS AVAILABLE" BASIS ONLY, WITHOUT WARRANTIES OR CONDITIONS OF ANY KIND. NEITHER THE COMPANY NOR ANY OF ITS LICENSORS NOR THEIR RESPECTIVE AFFILIATES OR SUPPLIERS HAVE LIABILITY FOR THE ACCURACY, TIMELINESS OR COMPLETENESS OF THIS MODEL, OR FOR DELAYS, INTERRUPTIONS OR OMISSIONS HEREIN, NOR FOR ANY LOST PROFITS, INDIRECT, SPECIAL OR CONSEQUENTIAL DAMAGES. Access to data in this Model that is sourced from third party contributors is subject to termination in the event that any agreement between the Company and such third party contributors terminates for any reason. Copyright 2023 Tegus. All rights reserved.

Sheet Multiples
A1: NVIDIA — MULTIPLES-BASED VALUATION
A3: Period | F3: TTM | G3: NTM | H3: FY2027 | I3: FY2028 | J3: FY2029
A5: FINANCIAL METRICS
A6: Revenue ($M) | F6: =Model!BS34 | G6: =Model!BX34 | H6: =Model!CC34 | I6: =Model!CD34 | J6: =Model!CE34
A7: Operating Income / EBIT ($M) | F7: =Model!BS386 | G7: =Model!BX386 | H7: =Model!CC386 | I7: =Model!CD386 | J7: =Model!CE386
A8: EBITDA ($M) | F8: =Model!BS392 | G8: =Model!BX392 | H8: =Model!CC392 | I8: =Model!CD392 | J8: =Model!CE392
A9: Shares Outstanding (M) | F9: =Model!BS429 | G9: =Model!BS429 | H9: =Model!BS429 | I9: =Model!BS429 | J9: =Model!BS429
A10: Current Stock Price ($) | F10: =Model!'Front Page'!H20 | G10: =Model!'Front Page'!H20 | H10: =Model!'Front Page'!H20 | I10: =Model!'Front Page'!H20 | J10: =Model!'Front Page'!H20
A11: Market Cap ($M) | F11: =F9*F10 | G11: =G9*G10 | H11: =H9*H10 | I11: =I9*I10 | J11: =J9*J10
A13: P/E VALUATION
A14: Consensus P/E Multiple | F14: 45 | G14: 24 | H14: 22 | I14: 20 | J14: 19
A15: Earnings for P/E ($M) | F15: =F7 | G15: =G7 | H15: =H7 | I15: =I7 | J15: =J7
A16: Implied Market Cap via P/E ($M) | F16: =F14*F15 | G16: =G14*G15 | H16: =H14*H15 | I16: =I14*I15 | J16: =J14*J15
A17: Implied Price via P/E ($) | F17: =F16/F9 | G17: =G16/G9 | H17: =H16/H9 | I17: =I16/I9 | J17: =J16/J9
A18: Upside vs Current (P/E) | F18: =F17/F10-1 | G18: =G17/G10-1 | H18: =H17/H10-1 | I18: =I17/I10-1 | J18: =J17/J10-1
A20: EV/EBITDA VALUATION
A21: Consensus EV/EBITDA Multiple | F21: 35 | G21: 18 | H21: 16 | I21: 15 | J21: 14
A22: EBITDA ($M) | F22: =F8 | G22: =G8 | H22: =H8 | I22: =I8 | J22: =J8
A23: Implied TEV via EV/EBITDA ($M) | F23: =F21*F22 | G23: =G21*G22 | H23: =H21*H22 | I23: =I21*I22 | J23: =J21*J22
A24: Less: Net Debt ($M) | F24: 5000 | G24: 5000 | H24: 5000 | I24: 5000 | J24: 5000
A25: Implied Equity Value ($M) | F25: =F23-F24 | G25: =G23-G24 | H25: =H23-H24 | I25: =I23-I24 | J25: =J23-J24
A26: Implied Price via EV/EBITDA ($) | F26: =F25/F9 | G26: =G25/G9 | H26: =H25/H9 | I26: =I25/I9 | J26: =J25/J9
A27: Upside vs Current (EV/EBITDA) | F27: =F26/F10-1 | G27: =G26/G10-1 | H27: =H26/H10-1 | I27: =I26/I10-1 | J27: =J26/J10-1
A29: VALUATION SUMMARY
A30: Current Price | F30: =F10 | G30: =G10 | H30: =H10 | I30: =I10 | J30: =J10
A31: P/E Implied (NTM) | G31: =G17
A32: EV/EBITDA Implied (NTM) | G32: =G26
A33: Average Implied Price | G33: =(G17+G26)/2
A34: Upside (Avg vs Current) | G34: =G33/G30-1

Sheet DCF
B1: NVIDIA Corporation
B2: Discounted Cash Flow Valuation Analysis
F5: Historical | G5: Projected | M5: Assumptions | R5: Notes
M6: Risk Free Rate: | P6: 0.0425 | R6: 10-Year US Treasury yield
B7: ($ in millions) | F7: FY2025 | G7: FY2026 | H7: FY2027 | I7: FY2028 | J7: FY2029 | K7: FY2030 | M7: Market Risk Premium: | P7: 0.055 | R7: Damodaran equity risk premium
M8: Unlevered Beta: | P8: 1.65 | R8: Semiconductor industry avg
B9: Revenue Build by Segment | M9: Projected Equity to Value: | P9: 0.998 | R9: NVDA ~100% equity-financed
B10: Datacenter Revenue | F10: =Model!BS22 | G10: =Model!BX22 | H10: =Model!CC22 | I10: =Model!CD22 | J10: =Model!CE22 | K10: =Model!CF22 | M10: Levered Beta: | P10: =(1+(1-P12)*(1-P9)/P9)*P8 | R10: Hamada equation
B11: Y/Y Growth | F11: =Model!BS24 | G11: =Model!BX24 | H11: =Model!CC24 | I11: =Model!CD24 | J11: =Model!CE24 | K11: =Model!CF24 | M11: Cost of Equity: | P11: =P6+P7*P10 | R11: CAPM: Rf + B(Rm-Rf)
B12: Gaming Revenue | F12: =Model!BS7 | G12: =Model!BX7 | H12: =Model!CC7 | I12: =Model!CD7 | J12: =Model!CE7 | K12: =Model!CF7 | M12: Tax Rate: | P12: 0.15 | R12: Long-term effective tax rate
B13: Y/Y Growth | F13: =Model!BS9 | G13: =Model!BX9 | H13: =Model!CC9 | I13: =Model!CD9 | J13: =Model!CE9 | K13: =Model!CF9 | M13: Cost of Debt: | P13: 0.035 | R13: Based on outstanding senior notes
B14: Automotive Revenue | F14: =Model!BS26 | G14: =Model!BX26 | H14: =Model!CC26 | I14: =Model!CD26 | J14: =Model!CE26 | K14: =Model!CF26 | M14: WACC: | P14: =P11*P9+P13*(1-P12)*(1-P9) | R14: Rd*(1-T)*(D/V) + Re*(E/V)
B15: Y/Y Growth | F15: =Model!BS28 | G15: =Model!BX28 | H15: =Model!CC28 | I15: =Model!CD28 | J15: =Model!CE28 | K15: =Model!CF28 | M15: Terminal Growth Rate: | P15: 0.03 | R15: Long-term nominal GDP growth
B16: Professional Visualization Revenue | F16: =Model!BS11 | G16: =Model!BX11 | H16: =Model!CC11 | I16: =Model!CD11 | J16: =Model!CE11 | K16: =Model!CF11 | M16: Implied TV/EBITDA: | P16: =F46/Model!CF392 | R16: Terminal value / FY2030 EBITDA
B17: Y/Y Growth | F17: =Model!BS13 | G17: =Model!BX13 | H17: =Model!CC13 | I17: =Model!CD13 | J17: =Model!CE13 | K17: =Model!CF13
B18: OEM & IP Revenue | F18: =Model!BS30 | G18: =Model!BX30 | H18: =Model!CC30 | I18: =Model!CD30 | J18: =Model!CE30 | K18: =Model!CF30
B19: Y/Y Growth | F19: =Model!BS32 | G19: =Model!BX32 | H19: =Model!CC32 | I19: =Model!CD32 | J19: =Model!CE32 | K19: =Model!CF32
B20: Total Revenue | F20: =Model!BS34 | G20: =Model!BX34 | H20: =Model!CC34 | I20: =Model!CD34 | J20: =Model!CE34 | K20: =Model!CF34
B21: Y/Y Total Revenue Growth | G21: =G20/F20-1 | H21: =H20/G20-1 | I21: =I20/H20-1 | J21: =J20/I20-1 | K21: =K20/J20-1
B23: Operating Margin Drivers
B24: Non-GAAP Gross Margin % | F24: =Model!BS59 | G24: =Model!BX59 | H24: =Model!CC59 | I24: =Model!CD59 | J24: =Model!CE59 | K24: =Model!CF59
B25: Gross Margin Improvement (bps) | F25: =Model!BS62 | G25: =Model!BX62 | H25: =Model!CC62 | I25: =Model!CD62 | J25: =Model!CE62 | K25: =Model!CF62
B26: Non-GAAP R&D Margin % | F26: =Model!BS76 | G26: =Model!BX76 | H26: =Model!CC76 | I26: =Model!CD76 | J26: =Model!CE76 | K26: =Model!CF76
B27: R&D Margin Improvement (bps) | F27: =Model!BS77 | G27: =Model!BX77 | H27: =Model!CC77 | I27: =Model!CD77 | J27: =Model!CE77 | K27: =Model!CF77
B28: Non-GAAP SG&A Margin % | F28: =Model!BS91 | G28: =Model!BX91 | H28: =Model!CC91 | I28: =Model!CD91 | J28: =Model!CE91 | K28: =Model!CF91
B29: SG&A Margin Improvement (bps) | F29: =Model!BS92 | G29: =Model!BX92 | H29: =Model!CC92 | I29: =Model!CD92 | J29: =Model!CE92 | K29: =Model!CF92
B30: Non-GAAP EBIT Margin % | F30: =Model!BS109 | G30: =Model!BX109 | H30: =Model!CC109 | I30: =Model!CD109 | J30: =Model!CE109 | K30: =Model!CF109
B31: Non-GAAP Operating Income (EBIT) | F31: =Model!BS386 | G31: =Model!BX386 | H31: =Model!CC386 | I31: =Model!CD386 | J31: =Model!CE386 | K31: =Model!CF386
B33: Unlevered Free Cash Flow Build
B34: Non-GAAP EBIT | G34: =G31 | H34: =H31 | I34: =I31 | J34: =J31 | K34: =K31
B35: Less: Taxes on EBIT | G35: =-G34*$P$12 | H35: =-H34*$P$12 | I35: =-I34*$P$12 | J35: =-J34*$P$12 | K35: =-K34*$P$12
B36: NOPAT | G36: =G34+G35 | H36: =H34+H35 | I36: =I34+I35 | J36: =J34+J35 | K36: =K34+K35
B37: Plus: Depreciation & Amortization | G37: =Model!BX933 | H37: =Model!CC933 | I37: =Model!CD933 | J37: =Model!CE933 | K37: =Model!CF933
B38: Less: Capital Expenditures | G38: =-Model!BX934 | H38: =-Model!CC934 | I38: =-Model!CD934 | J38: =-Model!CE934 | K38: =-Model!CF934
B39: Less: Increase in Net Working Capital | G39: =-G72 | H39: =-H72 | I39: =-I72 | J39: =-J72 | K39: =-K72
B40: Unlevered Free Cash Flow | G40: =SUM(G36:G39) | H40: =SUM(H36:H39) | I40: =SUM(I36:I39) | J40: =SUM(J36:J39) | K40: =SUM(K36:K39)
B42: Times: Discount Factor | G42: =1/(1+$P$14)^1 | H42: =1/(1+$P$14)^2 | I42: =1/(1+$P$14)^3 | J42: =1/(1+$P$14)^4 | K42: =1/(1+$P$14)^5
B43: Discounted Cash Flows | G43: =G40*G42 | H43: =H40*H42 | I43: =I40*I42 | J43: =J40*J42 | K43: =K40*K42
B45: Sum of Discounted Cash Flows | F45: =SUM(G43:K43)
B46: Terminal Value: | F46: =(K40*(1+$P$15))/($P$14-$P$15)
...

Sheet Model
A1: NVIDIA Corporation
A2: =CHOOSE(MO.DataSourceIndex,MO.Ticker.Bloomberg,MO.Ticker.CapIQ,MO.Ticker.FactSet,MO.Ticker.Thomson) | C2: =EOMONTH(C4,-12) | AA2: Restated | AB2: Restated | AC2: Restated | AD2: Restated | AE2: Restated
A3: =HP.TradeCurrency | B3: =IF(MO.RealTime="OFF",MO.LastPriceHardcoded,MO.LastPriceFormula) | C3: =C4-C2 | D3: =D4-C4 | E3: =E4-D4 | F3: =F4-E4 | G3: =G4-F4 | H3: =H4-G4 | I3: =I4-H4 | J3: =J4-I4 | K3: =K4-F4 | L3: =L4-K4 | M3: =M4-L4 | N3: =N4-M4 | O3: =O4-N4 | P3: =P4-K4 | Q3: =Q4-P4 | R3: =R4-Q4 | S3: =S4-R4 | T3: =T4-S4 | U3: =U4-P4 | V3: =V4-U4 | W3: =W4-V4 | X3: =X4-W4 | Y3: =Y4-X4 | Z3: =Z4-U4 | AA3: =AA4-Z4 | AB3: =AB4-AA4 | AC3: =AC4-AB4 | AD3: =AD4-AC4 | AE3: =AE4-Z4 | AF3: =AF4-AE4 | AG3: =AG4-AF4 | AH3: =AH4-AG4 | AI3: =AI4-AH4 | AJ3: =AJ4-AE4 | AK3: =AK4-AJ4 | AL3: =AL4-AK4 | AM3: =AM4-AL4 | AN3: =AN4-AM4 | AO3: =AO4-AJ4 | AP3: =AP4-AO4 | AQ3: =AQ4-AP4 | AR3: =AR4-AQ4 | AS3: =AS4-AR4 | AT3: =AT4-AO4 | AU3: =AU4-AT4 | AV3: =AV4-AU4 | AW3: =AW4-AV4 | AX3: =AX4-AW4 | AY3: =AY4-AT4 | AZ3: =AZ4-AY4 | BA3: =BA4-AZ4 | BB3: =BB4-BA4 | BC3: =BC4-BB4 | BD3: =BD4-AY4 | BE3: =BE4-BD4 | BF3: =BF4-BE4 | BG3: =BG4-BF4 | BH3: =BH4-BG4 | BI3: =BI4-BD4 | BJ3: =BJ4-BI4 | BK3: =BK4-BJ4 | BL3: =BL4-BK4 | BM3: =BM4-BL4 | BN3: =BN4-BI4 | BO3: =BO4-BN4 | BP3: =BP4-BO4 | BQ3: =BQ4-BP4 | BR3: =BR4-BQ4 | BS3: =BS4-BN4 | BT3: =BT4-BS4 | BU3: =BU4-BT4 | BV3: =BV4-BU4 | BW3: =BW4-BV4 | BX3: =BX4-BS4 | BY3: =BY4-BX4 | BZ3: =BZ4-BY4 | CA3: =CA4-BZ4 | CB3: =CB4-CA4 | CC3: =CC4-BX4 | CD3: =CD4-CC4 | CE3: =CE4-CD4 | CF3: =CF4-CE4
A4: =FP.DataSourceName | B4: =IF(AND(MO.RealTimeStockPriceToggle,MO.LastPriceFormula<>"N/A"),"ON","OFF") | C4: 39838 | D4: 40209 | E4: 40573 | F4: 40937 | G4: 41028 | H4: 41119 | I4: 41210 | J4: =K4 | K4: 41301 | L4: 41392 | M4: 41483 | N4: 41574 | O4: =P4 | P4: 41665 | Q4: 41756 | R4: 41847 | S4: 41938 | T4: =U4 | U4: 42029 | V4: 42120 | W4: 42211 | X4: 42302 | Y4: =Z4 | Z4: 42400 | AA4: 42491 | AB4: 42582 | AC4: 42673 | AD4: =AE4 | AE4: 42764 | AF4: 42855 | AG4: 42946 | AH4: 43037 | AI4: =AJ4 | AJ4: 43128 | AK4: 43219 | AL4: 43310 | AM4: 43401 | AN4: =AO4 | AO4: 43492 | AP4: 43583 | AQ4: 43674 | AR4: 43765 | AS4: =AT4 | AT4: 43856 | AU4: 43947 | AV4: 44038 | AW4: 44129 | AX4: =AY4 | AY4: 44227 | AZ4: 44318 | BA4: 44409 | BB4: 44500 | BC4: =BD4 | BD4: 44591 | BE4: 44682 | BF4: 44773 | BG4: 44864 | BH4: =BI4 | BI4: 44955 | BJ4: 45046 | BK4: 45137 | BL4: 45228 | BM4: =BN4 | BN4: 45319 | BO4: 45410 | BP4: 45501 | BQ4: 45592 | BR4: =BS4 | BS4: 45683 | BT4: 45774 | BU4: 45865 | BV4: 45956 | BW4: =DATE(YEAR(BV4)+1,1,31) | BX4: =BW4 | BY4: =+EDATE(BX4,3) | BZ4: =+EDATE(BY4,3) | CA4: =+EDATE(BZ4,3) | CB4: =DATE(YEAR(CA4)+1,1,31) | CC4: =CB4 | CD4: =EOMONTH(CC4,12) | CE4: =EOMONTH(CD4,12) | CF4: =EOMONTH(CE4,12)
A5: =MO.ReportCurrency | C5: FY2009 | D5: =CONCATENATE("FY",RIGHT(C5,4)+1) | E5: =CONCATENATE("FY",RIGHT(D5,4)+1) | F5: =CONCATENATE("FY",RIGHT(E5,4)+1) | G5: =CONCATENATE("Q1","-",RIGHT(F5,4)+1) | H5: =CONCATENATE("Q2","-",RIGHT(G5,4)) | I5: =CONCATENATE("Q3","-",RIGHT(H5,4)) | J5: =CONCATENATE("Q4","-",RIGHT(I5,4)) | K5: =CONCATENATE("FY",RIGHT(F5,4)+1) | L5: =CONCATENATE("Q1","-",RIGHT(K5,4)+1) | M5: =CONCATENATE("Q2","-",RIGHT(L5,4)) | N5: =CONCATENATE("Q3","-",RIGHT(M5,4)) | O5: =CONCATENATE("Q4","-",RIGHT(N5,4)) | P5: =CONCATENATE("FY",RIGHT(K5,4)+1) | Q5: =CONCATENATE("Q1","-",RIGHT(P5,4)+1) | R5: =CONCATENATE("Q2","-",RIGHT(Q5,4)) | S5: =CONCATENATE("Q3","-",RIGHT(R5,4)) | T5: =CONCATENATE("Q4","-",RIGHT(S5,4)) | U5: =CONCATENATE("FY",RIGHT(P5,4)+1) | V5: =CONCATENATE("Q1","-",RIGHT(U5,4)+1) | W5: =CONCATENATE("Q2","-",RIGHT(V5,4)) | X5: =CONCATENATE("Q3","-",RIGHT(W5,4)) | Y5: =CONCATENATE("Q4","-",RIGHT(X5,4)) | Z5: =CONCATENATE("FY",RIGHT(U5,4)+1) | AA5: =CONCATENATE("Q1","-",RIGHT(Z5,4)+1) | AB5: =CONCATENATE("Q2","-",RIGHT(AA5,4)) | AC5: =CONCATENATE("Q3","-",RIGHT(AB5,4)) | AD5: =CONCATENATE("Q4","-",RIGHT(AC5,4)) | AE5: =CONCATENATE("FY",RIGHT(Z5,4)+1) | AF5: =CONCATENATE("Q1","-",RIGHT(AE5,4)+1) | AG5: =CONCATENATE("Q2","-",RIGHT(AF5,4)) | AH5: =CONCATENATE("Q3","-",RIGHT(AG5,4)) | AI5: =CONCATENATE("Q4","-",RIGHT(AH5,4)) | AJ5: =CONCATENATE("FY",RIGHT(AE5,4)+1) | AK5: =CONCATENATE("Q1","-",RIGHT(AJ5,4)+1) | AL5: =CONCATENATE("Q2","-",RIGHT(AK5,4)) | AM5: =CONCATENATE("Q3","-",RIGHT(AL5,4)) | AN5: =CONCATENATE("Q4","-",RIGHT(AM5,4)) | AO5: =CONCATENATE("FY",RIGHT(AJ5,4)+1) | AP5: =CONCATENATE("Q1","-",RIGHT(AO5,4)+1) | AQ5: =CONCATENATE("Q2","-",RIGHT(AP5,4)) | AR5: =CONCATENATE("Q3","-",RIGHT(AQ5,4)) | AS5: =CONCATENATE("Q4","-",RIGHT(AR5,4)) | AT5: =CONCATENATE("FY",RIGHT(AO5,4)+1) | AU5: =CONCATENATE("Q1","-",RIGHT(AT5,4)+1) | AV5: =CONCATENATE("Q2","-",RIGHT(AU5,4)) | AW5: =CONCATENATE("Q3","-",RIGHT(AV5,4)) | AX5: =CONCATENATE("Q4","-",RIGHT(AW5,4)) | AY5: =CONCATENATE("FY",RIGHT(AT5,4)+1) | AZ5: =CONCATENATE("Q1","-",RIGHT(AY5,4)+1) | BA5: =CONCATENATE("Q2","-",RIGHT(AZ5,4)) | BB5: =CONCATENATE("Q3","-",RIGHT(BA5,4)) | BC5: =CONCATENATE("Q4","-",RIGHT(BB5,4)) | BD5: =CONCATENATE("FY",RIGHT(AY5,4)+1) | BE5: =CONCATENATE("Q1","-",RIGHT(BD5,4)+1) | BF5: =CONCATENATE("Q2","-",RIGHT(BE5,4)) | BG5: =CONCATENATE("Q3","-",RIGHT(BF5,4)) | BH5: =CONCATENATE("Q4","-",RIGHT(BG5,4)) | BI5: =CONCATENATE("FY",RIGHT(BD5,4)+1) | BJ5: =CONCATENATE("Q1","-",RIGHT(BI5,4)+1) | BK5: =CONCATENATE("Q2","-",RIGHT(BJ5,4)) | BL5: =CONCATENATE("Q3","-",RIGHT(BK5,4)) | BM5: =CONCATENATE("Q4","-",RIGHT(BL5,4)) | BN5: =CONCATENATE("FY",RIGHT(BI5,4)+1) | BO5: =CONCATENATE("Q1","-",RIGHT(BN5,4)+1) | BP5: =CONCATENATE("Q2","-",RIGHT(BO5,4)) | BQ5: =CONCATENATE("Q3","-",RIGHT(BP5,4)) | BR5: =CONCATENATE("Q4","-",RIGHT(BQ5,4)) | BS5: =CONCATENATE("FY",RIGHT(BN5,4)+1) | BT5: =CONCATENATE("Q1","-",RIGHT(BS5,4)+1) | BU5: =CONCATENATE("Q2","-",RIGHT(BT5,4)) | BV5: =CONCATENATE("Q3","-",RIGHT(BU5,4)) | BW5: =CONCATENATE("Q4","-",RIGHT(BV5,4)) | BX5: =CONCATENATE("FY",RIGHT(BS5,4)+1) | BY5: =CONCATENATE("Q1","-",RIGHT(BX5,4)+1) | BZ5: =CONCATENATE("Q2","-",RIGHT(BY5,4)) | CA5: =CONCATENATE("Q3","-",RIGHT(BZ5,4)) | CB5: =CONCATENATE("Q4","-",RIGHT(CA5,4)) | CC5: =CONCATENATE("FY",RIGHT(BX5,4)+1) | CD5: =CONCATENATE("FY",RIGHT(CC5,4)+1) | CE5: =CONCATENATE("FY",RIGHT(CD5,4)+1) | CF5: =CONCATENATE("FY",RIGHT(CE5,4)+1)
A6: Revenue Build (FS/PR)
A7: Gaming Revenue, mm | P7: 1511 | Q7: 468 | R7: 417 | S7: 527 | T7: =U7-SUM(Q7,R7,S7) | U7: 2058 | V7: 587 | W7: 660 | X7: 761 | Y7: =Z7-SUM(V7,W7,X7) | Z7: 2818 | AA7: 687 | AB7: 781 | AC7: 1244 | AD7: =AE7-SUM(AA7,AB7,AC7) | AE7: 4060 | AF7: 1027 | AG7: 1186 | AH7: 1561 | AI7: =AJ7-SUM(AF7,AG7,AH7) | AJ7: 5513 | AK7: 1723 | AL7: 1805 | AM7: 1764 | AN7: 954 | AO7: =SUM(AK7,AL7,AM7,AN7) | AP7: 1055 | AQ7: 1313 | AR7: 1659 | AS7: 1491 | AT7: =SUM(AP7,AQ7,AR7,AS7) | AU7: 1339 | AV7: 1654 | AW7: 2271 | AX7: 2495 | AY7: =SUM(AU7,AV7,AW7,AX7) | AZ7: 2760 | BA7: 3061 | BB7: 3221 | BC7: 3420 | BD7: =SUM(AZ7,BA7,BB7,BC7) | BE7: 3620 | BF7: 2042 | BG7: 1574 | BH7: 1831 | BI7: =SUM(BE7,BF7,BG7,BH7) | BJ7: 2240 | BK7: 2486 | BL7: 2856 | BM7: 2865 | BN7: =SUM(BJ7,BK7,BL7,BM7) | BO7: 2647 | BP7: 2880 | BQ7: 3279 | BR7: 2544 | BS7: =SUM(BO7,BP7,BQ7,BR7) | BT7: 3763 | BU7: 4287 | BV7: 4265 | BW7: =+BR7*(1+BW9) | BX7: =SUM(BT7,BU7,BV7,BW7) | BY7: =+BT7*(1+BY9) | BZ7: =+BU7*(1+BZ9) | CA7: =+BV7*(1+CA9) | CB7: =+BW7*(1+CB9) | CC7: =SUM(BY7,BZ7,CA7,CB7) | CD7: =+CC7*(1+CD9) | CE7: =+CD7*(1+CE9) | CF7: =+CE7*(1+CF9)
A8: Q/Q Gaming Revenue growth, % | R8: =R7/Q7-1 | S8: =S7/R7-1 | T8: =T7/S7-1 | V8: =V7/T7-1 | W8: =W7/V7-1 | X8: =X7/W7-1 | Y8: =Y7/X7-1 | AA8: =AA7/Y7-1 | AB8: =AB7/AA7-1 | AC8: =AC7/AB7-1 | AD8: =AD7/AC7-1 | AF8: =AF7/AD7-1 | AG8: =AG7/AF7-1 | AH8: =AH7/AG7-1 | AI8: =AI7/AH7-1 | AK8: =AK7/AI7-1 | AL8: =AL7/AK7-1 | AM8: =AM7/AL7-1 | AN8: =AN7/AM7-1 | AP8: =AP7/AN7-1 | AQ8: =AQ7/AP7-1 | AR8: =AR7/AQ7-1 | AS8: =AS7/AR7-1 | AU8: =AU7/AS7-1 | AV8: =AV7/AU7-1 | AW8: =AW7/AV7-1 | AX8: =AX7/AW7-1 | AZ8: =AZ7/AX7-1 | BA8: =BA7/AZ7-1 | BB8: =BB7/BA7-1 | BC8: =BC7/BB7-1 | BE8: =BE7/BC7-1 | BF8: =BF7/BE7-1 | BG8: =BG7/BF7-1 | BH8: =BH7/BG7-1 | BJ8: =BJ7/BH7-1 | BK8: =BK7/BJ7-1 | BL8: =BL7/BK7-1 | BM8: =BM7/BL7-1 | BO8: =BO7/BM7-1 | BP8: =BP7/BO7-1 | BQ8: =BQ7/BP7-1 | BR8: =BR7/BQ7-1 | BT8: =BT7/BR7-1 | BU8: =BU7/BT7-1 | BV8: =BV7/BU7-1 | BW8: =BW7/BV7-1 | BY8: =BY7/BW7-1 | BZ8: =BZ7/BY7-1 | CA8: =CA7/BZ7-1 | CB8: =CB7/CA7-1
A9: Y/Y Gaming Revenue Growth, % | U9: =+U7/P7-1 | V9: =+V7/Q7-1 | W9: =+W7/R7-1 | X9: =+X7/S7-1 | Y9: =+Y7/T7-1 | Z9: =+Z7/U7-1 | AA9: =+AA7/V7-1 | AB9: =+AB7/W7-1 | ... BV9: =+BV7/BQ7-1 | BW9: 0.5 | BX9: =+BX7/BS7-1 | BY9: 0.5 | BZ9: 0.3 | CA9: 0.25 | CB9: 0.2 | CC9: =+CC7/BX7-1 | CD9: 0.1 | CE9: 0.1 | CF9: 0.1
A11: Professional Visualization Revenue, mm | P11: 789 | Q11: 191 | R11: 208 | S11: 206 | T11: =U11-SUM(Q11,R11,S11) | U11: 795 | V11: 181 | W11: 176 | X11: 190 | Y11: =Z11-SUM(V11,W11,X11) | Z11: 750 | AA11: 189 | AB11: 214 | AC11: 207 | AD11: =AE11-SUM(AA11,AB11,AC11) | AE11: 835 | AF11: 205 | AG11: 235 | AH11: 239 | AI11: =AJ11-SUM(AF11,AG11,AH11) | AJ11: 934 | AK11: 251 | AL11: 281 | AM11: 305 | AN11: 293 | AO11: =SUM(AK11,AL11,AM11,AN11) | AP11: 266 | AQ11: 291 | AR11: 324 | AS11: 331 | AT11: =SUM(AP11,AQ11,AR11,AS11) | AU11: 307 | AV11: 203 | AW11: 236 | AX11: 307 | AY11: =SUM(AU11,AV11,AW11,AX11) | AZ11: 372 | BA11: 519 | BB11: 577 | BC11: 643 | BD11: =SUM(AZ11,BA11,BB11,BC11) | BE11: 622 | BF11: 496 | BG11: 200 | BH11: 226 | BI11: =SUM(BE11,BF11,BG11,BH11) | BJ11: 295 | BK11: 379 | BL11: 416 | BM11: 463 | BN11: =SUM(BJ11,BK11,BL11,BM11) | BO11: 427 | BP11: 454 | BQ11: 486 | BR11: 511 | BS11: =SUM(BO11,BP11,BQ11,BR11) | BT11: 509 | BU11: 601 | BV11: 760 | BW11: =+BR11*(1+BW13) | BX11: =SUM(BT11,BU11,BV11,BW11) | BY11: =+BT11*(1+BY13) | BZ11: =+BU11*(1+BZ13) | CA11: =+BV11*(1+CA13) | CB11: =+BW11*(1+CB13) | CC11: =SUM(BY11,BZ11,CA11,CB11) | CD11: =+CC11*(1+CD13) | CE11: =+CD11*(1+CE13) | CF11: =+CE11*(1+CF13)
A12: Q/Q Professional Visualization Revenue growth, % | R12: =R11/Q11-1 | S12: =S11/R11-1 | T12: =T11/S11-1 | V12: =V11/T11-1 | W12: =W11/V11-1 | X12: =X11/W11-1 | Y12: =Y11/X11-1 | AA12: =AA11/Y11-1 | AB12: =AB11/AA11-1 | AC12: =AC11/AB11-1 | AD12: =AD11/AC11-1 | AF12: =AF11/AD11-1 | AG12: =AG11/AF11-1 | AH12: =AH11/AG11-1 | AI12: =AI11/AH11-1 | AK12: =AK11/AI11-1 | AL12: =AL11/AK11-1 | AM12: =AM11/AL11-1 | AN12: =AN11/AM11-1 | AP12: =AP11/AN11-1 | AQ12: =AQ11/AP11-1 | AR12: =AR11/AQ11-1 | AS12: =AS11/AR11-1 | AU12: =AU11/AS11-1 | AV12: =AV11/AU11-1 | AW12: =AW11/AV11-1 | AX12: =AX11/AW11-1 | AZ12: =AZ11/AX11-1 | BA12: =BA11/AZ11-1 | BB12: =BB11/BA11-1 | BC12: =BC11/BB11-1 | BE12: =BE11/BC11-1 | BF12: =BF11/BE11-1 | BG12: =BG11/BF11-1 | BH12: =BH11/BG11-1 | BJ12: =BJ11/BH11-1 | BK12: =BK11/BJ11-1 | BL12: =BL11/BK11-1 | BM12: =BM11/BL11-1 | BO12: =BO11/BM11-1 | BP12: =BP11/BO11-1 | BQ12: =BQ11/BP11-1 | BR12: =BR11/BQ11-1 | BT12: =BT11/BR11-1 | BU12: =BU11/BT11-1 | BV12: =BV11/BU11-1 | BW12: =BW11/BV11-1 | BY12: =BY11/BW11-1 | BZ12: =BZ11/BY11-1 | CA12: =CA11/BZ11-1 | CB12: =CB11/CA11-1
A13: Y/Y Professional Visualization Revenue Growth, % | U13: =+U11/P11-1 | V13: =+V11/Q11-1 | W13: =+W11/R11-1 | X13: =+X11/S11-1 | Y13: =+Y11/T11-1 | Z13: =+Z11/U11-1 | AA13: =+AA11/V11-1 | AB13: =+AB11/W11-1 | ... BV13: =+BV11/BQ11-1 | BW13: 0.3 | BX13: =+BX11/BS11-1 | BY13: 0.05 | BZ13: 0.05 | CA13: 0.05 | CB13: 0.05 | CC13: =+CC11/BX11-1 | CD13: 0.1 | CE13: 0.1 | CF13: 0.1
A15: Compute revenue, mm | BJ15: 3357 | BK15: 8612 | BL15: 11908 | BM15: 15073 | BN15: 38950 | BO15: 19392 | BP15: 22604 | BQ15: 27644 | BR15: =BS15-SUM(BO15,BP15,BQ15) | BS15: 102196 | BT15: 34155 | BU15: 33844 | BV15: 43028
A16: Q/Q Compute Revenue growth, % | BK16: =BK15/BJ15-1 | BL16: =BL15/BK15-1 | BM16: =BM15/BL15-1 | BO16: =BO15/BM15-1 | BP16: =BP15/BO15-1 | BQ16: =BQ15/BP15-1 | BR16: =BR15/BQ15-1 | BT16: =BT15/BR15-1 | BU16: =BU15/BT15-1 | BV16: =BV15/BU15-1
A17: Y/Y Compute Revenue Growth, % | BO17: =+BO15/BJ15-1 | BP17: =+BP15/BK15-1 | BQ17: =+BQ15/BL15-1 | BR17: =+BR15/BM15-1 | BS17: =+BS15/BN15-1 | BT17: =+BT15/BO15-1 | BU17: =+BU15/BP15-1 | BV17: =+BV15/BQ15-1
A19: Networking revenue, mm | BJ19: 927 | BK19: 1711 | BL19: 2606 | BM19: 3331 | BN19: 8575 | BO19: 3171 | BP19: 3668 | BQ19: 3127 | BR19: =BS19-SUM(BO19,BP19,BQ19) | BS19: 12990 | BT19: 4957 | BU19: 7252 | BV19: 8187
A20: Q/Q Networking Revenue growth, % | BK20: =BK19/BJ19-1 | BL20: =BL19/BK19-1 | BM20: =BM19/BL19-1 | BO20: =BO19/BM19-1 | BP20: =BP19/BO19-1 | BQ20: =BQ19/BP19-1 | BR20: =BR19/BQ19-1 | BT20: =BT19/BR19-1 | BU20: =BU19/BT19-1 | BV20: =BV19/BU19-1
A21: Y/Y Networking Revenue Growth, % | BO21: =+BO19/BJ19-1 | BP21: =+BP19/BK19-1 | BQ21: =+BQ19/BL19-1 | BR21: =+BR19/BM19-1 | BS21: =+BS19/BN19-1 | BT21: =+BT19/BO19-1 | BU21: =+BU19/BP19-1 | BV21: =+BV19/BQ19-1
A22: Datacenter Revenue, mm | P22: 199 | Q22: 57 | R22: 83 | S22: 89 | T22: =U22-SUM(Q22,R22,S22) | U22: 317 | V22: 88 | W22: 72 | X22: 82 | Y22: =Z22-SUM(V22,W22,X22) | Z22: 339 | AA22: 143 | AB22: 151 | AC22: 240 | AD22: =AE22-SUM(AA22,AB22,AC22) | AE22: 830 | AF22: 409 | AG22: 416 | AH22: 501 | AI22: =AJ22-SUM(AF22,AG22,AH22) | AJ22: 1932 | AK22: 701 | AL22: 760 | AM22: 792 | AN22: 679 | AO22: =SUM(AK22,AL22,AM22,AN22) | AP22: 634 | AQ22: 655 | AR22: 726 | AS22: 968 | AT22: =SUM(AP22,AQ22,AR22,AS22) | AU22: 1141 | AV22: 1752 | AW22: 1900 | AX22: 1903 | AY22: =SUM(AU22,AV22,AW22,AX22) | AZ22: 2048 | BA22: 2366 | BB22: 2936 | BC22: 3263 | BD22: =SUM(AZ22,BA22,BB22,BC22) | BE22: 3750 | BF22: 3806 | BG22: 3833 | BH22: 3616 | BI22: =SUM(BE22,BF22,BG22,BH22) | BJ22: 4284 | BK22: 10323 | BL22: 14514 | BM22: 18404 | BN22: =SUM(BJ22,BK22,BL22,BM22) | BO22: 22563 | BP22: 26272 | BQ22: 30771 | BR22: 35580 | BS22: =SUM(BO22,BP22,BQ22,BR22) | BT22: 39112 | BU22: 41096 | BV22: 51215 | BW22: =+BR22*(1+BW24) | BX22: =SUM(BT22,BU22,BV22,BW22) | BY22: =+BT22*(1+BY24) | BZ22: =+BU22*(1+BZ24) | CA22: =+BV22*(1+CA24) | CB22: =+BW22*(1+CB24) | CC22: =SUM(BY22,BZ22,CA22,CB22) | CD22: =+CC22*(1+CD24) | CE22: =+CD22*(1+CE24) | CF22: =+CE22*(1+CF24)
A23: Q/Q Datacenter Revenue growth, % | R23: =R22/Q22-1 | S23: =S22/R22-1 | T23: =T22/S22-1 | V23: =V22/T22-1 | W23: =W22/V22-1 | X23: =X22/W22-1 | Y23: =Y22/X22-1 | AA23: =AA22/Y22-1 | AB23: =AB22/AA22-1 | AC23: =AC22/AB22-1 | AD23: =AD22/AC22-1 | AF23: =AF22/AD22-1 | AG23: =AG22/AF22-1 | AH23: =AH22/AG22-1 | AI23: =AI22/AH22-1 | AK23: =AK22/AI22-1 | AL23: =AL22/AK22-1 | AM23: =AM22/AL22-1 | AN23: =AN22/AM22-1 | AP23: =AP22/AN22-1 | AQ23: =AQ22/AP22-1 | AR23: =AR22/AQ22-1 | AS23: =AS22/AR22-1 | AU23: =AU22/AS22-1 | AV23: =AV22/AU22-1 | AW23: =AW22/AV22-1 | AX23: =AX22/AW22-1 | AZ23: =AZ22/AX22-1 | BA23: =BA22/AZ22-1 | BB23: =BB22/BA22-1 | BC23: =BC22/BB22-1 | BE23: =BE22/BC22-1 | BF23: =BF22/BE22-1 | BG23: =BG22/BF22-1 | BH23: =BH22/BG22-1 | BJ23: =BJ22/BH22-1 | BK23: =BK22/BJ22-1 | BL23: =BL22/BK22-1 | BM23: =BM22/BL22-1 | BO23: =BO22/BM22-1 | BP23: =BP22/BO22-1 | BQ23: =BQ22/BP22-1 | BR23: =BR22/BQ22-1 | BT23: =BT22/BR22-1 | BU23: =BU22/BT22-1 | BV23: =BV22/BU22-1 | BW23: =BW22/BV22-1 | BY23: =BY22/BW22-1 | BZ23: =BZ22/BY22-1 | CA23: =CA22/BZ22-1 | CB23: =CB22/CA22-1
A24: Y/Y Datacenter Revenue Growth, % | U24: =+U22/P22-1 | V24: =+V22/Q22-1 | W24: =+W22/R22-1 | X24: =+X22/S22-1 | Y24: =+Y22/T22-1 | Z24: =+Z22/U22-1 | AA24: =+AA22/V22-1 | AB24: =+AB22/W22-1 | ... BV24: =+BV22/BQ22-1 | BW24: 0.67 | BX24: =+BX22/BS22-1 | BY24: 0.5 | BZ24: 0.5 | CA24: 0.35 | CB24: 0.3 | CC24: =+CC22/BX22-1 | CD24: 0.25 | CE24: 0.2 | CF24: 0.18
A26: Automotive Revenue, mm | P26: 99 | Q26: 35 | R26: 40 | S26: 52 | T26: =U26-SUM(Q26,R26,S26) | U26: 183 | V26: 77 | W26: 71 | X26: 79 | Y26: =Z26-SUM(V26,W26,X26) | Z26: 320 | AA26: 113 | AB26: 119 | AC26: 127 | AD26: =AE26-SUM(AA26,AB26,AC26) | AE26: 487 | AF26: 140 | AG26: 142 | AH26: 144 | AI26: =AJ26-SUM(AF26,AG26,AH26) | AJ26: 558 | AK26: 145 | AL26: 161 | AM26: 172 | AN26: 163 | AO26: =SUM(AK26,AL26,AM26,AN26) | AP26: 166 | AQ26: 209 | AR26: 162 | AS26: 163 | AT26: =SUM(AP26,AQ26,AR26,AS26) | AU26: 155 | AV26: 111 | AW26: 125 | AX26: 145 | AY26: =SUM(AU26,AV26,AW26,AX26) | AZ26: 154 | BA26: 152 | BB26: 135 | BC26: 125 | BD26: =SUM(AZ26,BA26,BB26,BC26) | BE26: 138 | BF26: 220 | BG26: 251 | BH26: 294 | BI26: =SUM(BE26,BF26,BG26,BH26) | BJ26: 296 | BK26: 253 | BL26: 261 | BM26: 281 | BN26: =SUM(BJ26,BK26,BL26,BM26) | BO26: 329 | BP26: 346 | BQ26: 449 | BR26: 570 | BS26: =SUM(BO26,BP26,BQ26,BR26) | BT26: 567 | BU26: 586 | BV26: 592 | BW26: =+BR26*(1+BW28) | BX26: =SUM(BT26,BU26,BV26,BW26) | BY26: =+BT26*(1+BY28) | BZ26: =+BU26*(1+BZ28) | CA26: =+BV26*(1+CA28) | CB26: =+BW26*(1+CB28) | CC26: =SUM(BY26,BZ26,CA26,CB26) | CD26: =+CC26*(1+CD28) | CE26: =+CD26*(1+CE28) | CF26: =+CE26*(1+CF28)
A27: Q/Q Automotive Revenue growth, % | R27: =R26/Q26-1 | S27: =S26/R26-1 | T27: =T26/S26-1 | V27: =V26/T26-1 | W27: =W26/V26-1 | X27: =X26/W26-1 | Y27: =Y26/X26-1 | AA27: =AA26/Y26-1 | AB27: =AB26/AA26-1 | AC27: =AC26/AB26-1 | AD27: =AD26/AC26-1 | AF27: =AF26/AD26-1 | AG27: =AG26/AF26-1 | AH27: =AH26/AG26-1 | AI27: =AI26/AH26-1 | AK27: =AK26/AI26-1 | AL27: =AL26/AK26-1 | AM27: =AM26/AL26-1 | AN27: =AN26/AM26-1 | AP27: =AP26/AN26-1 | AQ27: =AQ26/AP26-1 | AR27: =AR26/AQ26-1 | AS27: =AS26/AR26-1 | AU27: =AU26/AS26-1 | AV27: =AV26/AU26-1 | AW27: =AW26/AV26-1 | AX27: =AX26/AW26-1 | AZ27: =AZ26/AX26-1 | BA27: =BA26/AZ26-1 | BB27: =BB26/BA26-1 | BC27: =BC26/BB26-1 | BE27: =BE26/BC26-1 | BF27: =BF26/BE26-1 | BG27: =BG26/BF26-1 | BH27: =BH26/BG26-1 | BJ27: =BJ26/BH26-1 | BK27: =BK26/BJ26-1 | BL27: =BL26/BK26-1 | BM27: =BM26/BL26-1 | BO27: =BO26/BM26-1 | BP27: =BP26/BO26-1 | BQ27: =BQ26/BP26-1 | BR27: =BR26/BQ26-1 | BT27: =BT26/BR26-1 | BU27: =BU26/BT26-1 | BV27: =BV26/BU26-1 | BW27: =BW26/BV26-1 | BY27: =BY26/BW26-1 | BZ27: =BZ26/BY26-1 | CA27: =CA26/BZ26-1 | CB27: =CB26/CA26-1
A28: Y/Y Automotive Revenue Growth, % | U28: =+U26/P26-1 | V28: =+V26/Q26-1 | W28: =+W26/R26-1 | X28: =+X26/S26-1 | Y28: =+Y26/T26-1 | Z28: =+Z26/U26-1 | AA28: =+AA26/V26-1 | AB28: =+AB26/W26-1 | ... BV28: =+BV26/BQ26-1 | BW28: 0.1 | BX28: =+BX26/BS26-1 | BY28: 0.3 | BZ28: 0.2 | CA28: 0.2 | CB28: 0.2 | CC28: =+CC26/BX26-1 | CD28: 0.1 | CE28: 0.1 | CF28: 0.1
A30: OEM & IP Revenue, mm | P30: 1532 | Q30: 352 | R30: 355 | S30: 351 | T30: =U30-SUM(Q30,R30,S30) | U30: 1329 | V30: 218 | W30: 174 | X30: 193 | Y30: =Z30-SUM(V30,W30,X30) | Z30: 783 | AA30: 173 | AB30: 163 | AC30: 186 | AD30: =AE30-SUM(AA30,AB30,AC30) | AE30: 698 | AF30: 156 | AG30: 251 | AH30: 191 | AI30: =AJ30-SUM(AF30,AG30,AH30) | AJ30: 777 | AK30: 387 | AL30: 116 | AM30: 148 | AN30: 116 | AO30: =SUM(AK30,AL30,AM30,AN30) | AP30: 99 | AQ30: 111 | AR30: 143 | AS30: 152 | AT30: =SUM(AP30,AQ30,AR30,AS30) | AU30: 138 | AV30: 146 | AW30: 194 | AX30: 153 | AY30: =SUM(AU30,AV30,AW30,AX30) | AZ30: 327 | BA30: 409 | BB30: 234 | BC30: 192 | BD30: =SUM(AZ30,BA30,BB30,BC30) | BE30: 158 | BF30: 140 | BG30: 73 | BH30: 84 | BI30: =SUM(BE30,BF30,BG30,BH30) | BJ30: 77 | BK30: 66 | BL30: 73 | BM30: 90 | BN30: =SUM(BJ30,BK30,BL30,BM30) | BO30: 78 | BP30: 88 | BQ30: 97 | BR30: 126 | BS30: =SUM(BO30,BP30,BQ30,BR30) | BT30: 111 | BU30: 173 | BV30: 174 | BW30: =+BR30*(1+BW32) | BX30: =SUM(BT30,BU30,BV30,BW30) | BY30: =+BT30*(1+BY32) | BZ30: =+BU30*(1+BZ32) | CA30: =+BV30*(1+CA32) | CB30: =+BW30*(1+CB32) | CC30: =SUM(BY30,BZ30,CA30,CB30) | CD30: =+CC30*(1+CD32) | CE30: =+CD30*(1+CE32) | CF30: =+CE30*(1+CF32)
A31: Q/Q OEM & IP Revenue growth, % | R31: =R30/Q30-1 | S31: =S30/R30-1 | T31: =T30/S30-1 | V31: =V30/T30-1 | W31: =W30/V30-1 | X31: =X30/W30-1 | Y31: =Y30/X30-1 | AA31: =AA30/Y30-1 | AB31: =AB30/AA30-1 | AC31: =AC30/AB30-1 | AD31: =AD30/AC30-1 | AF31: =AF30/AD30-1 | AG31: =AG30/AF30-1 | AH31: =AH30/AG30-1 | AI31: =AI30/AH30-1 | AK31: =AK30/AI30-1 | AL31: =AL30/AK30-1 | AM31: =AM30/AL30-1 | AN31: =AN30/AM30-1 | AP31: =AP30/AN30-1 | AQ31: =AQ30/AP30-1 | AR31: =AR30/AQ30-1 | AS31: =AS30/AR30-1 | AU31: =AU30/AS30-1 | AV31: =AV30/AU30-1 | AW31: =AW30/AV30-1 | AX31: =AX30/AW30-1 | AZ31: =AZ30/AX30-1 | BA31: =BA30/AZ30-1 | BB31: =BB30/BA30-1 | BC31: =BC30/BB30-1 | BE31: =BE30/BC30-1 | BF31: =BF30/BE30-1 | BG31: =BG30/BF30-1 | BH31: =BH30/BG30-1 | BJ31: =BJ30/BH30-1 | BK31: =BK30/BJ30-1 | BL31: =BL30/BK30-1 | BM31: =BM30/BL30-1 | BO31: =BO30/BM30-1 | BP31: =BP30/BO30-1 | BQ31: =BQ30/BP30-1 | BR31: =BR30/BQ30-1 | BT31: =BT30/BR30-1 | BU31: =BU30/BT30-1 | BV31: =BV30/BU30-1 | BW31: =BW30/BV30-1 | BY31: =BY30/BW30-1 | BZ31: =BZ30/BY30-1 | CA31: =CA30/BZ30-1 | CB31: =CB30/CA30-1
A32: Y/Y OEM & IP Revenue Growth, % | U32: =+U30/P30-1 | V32: =+V30/Q30-1 | W32: =+W30/R30-1 | X32: =+X30/S30-1 | Y32: =+Y30/T30-1 | Z32: =+Z30/U30-1 | AA32: =+AA30/V30-1 | AB32: =+AB30/W30-1 | ... BV32: =+BV30/BQ30-1 | BW32: 0.5 | BX32: =+BX30/BS30-1 | BY32: 0.1 | BZ32: 0.1 | CA32: 0.1 | CB32: 0.1 | CC32: =+CC30/BX30-1 | CD32: 0.1 | CE32: 0.1 | CF32: 0.1
A34: Total Revenue, mm | C34: =C292 | D34: =D292 | E34: =E292 | F34: =F292 | G34: =G292 | H34: =H292 | I34: =I292 | J34: =J292 | ... O34: =O292 | P34: =P7+P11+P22+P26+P30 | Q34: =Q7+Q11+Q22+Q26+Q30 | R34: =R7+R11+R22+R26+R30 | S34: =S7+S11+S22+S26+S30 | T34: =T7+T11+T22+T26+T30 | U34: =U7+U11+U22+U26+U30 | V34: =V7+V11+V22+V26+V30 | W34: =W7+W11+W22+W26+W30 | ... CF34: =CF7+CF11+CF22+CF26+CF30
A35: =CONCATENATE("Consensus Estimates - ",IFERROR(LEFT(A34,FIND("(",A34)-1),A34)) | BW35: =BW363 | BX35: =BX363 | BY35: =BY363 | BZ35: =BZ363 | CA35: =CA363 | CB35: =CB363 | CC35: =CC363 | CD35: =CD363 | ... CF35: =CF363
A36: Guidance - Total Revenue, mm | BW36: =BW572 | BX36: =BX572 | BY36: =BY572 | BZ36: =BZ572 | CA36: =CA572 | CB36: =CB572 | CC36: =CC572 | CD36: =CD572 | ... CF36: =CF572
A37: Q/Q Total Revenue growth, % | H37: =H34/G34-1 | I37: =I34/H34-1 | J37: =J34/I34-1 | L37: =L34/J34-1 | M37: =M34/L34-1 | N37: =N34/M34-1 | O37: =O34/N34-1 | Q37: =Q34/O34-1 | R37: =R34/Q34-1 | S37: =S34/R34-1 | T37: =T34/S34-1 | V37: =V34/T34-1 | W37: =W34/V34-1 | X37: =X34/W34-1 | Y37: =Y34/X34-1 | AA37: =AA34/Y34-1 | AB37: =AB34/AA34-1 | AC37: =AC34/AB34-1 | AD37: =AD34/AC34-1 | AF37: =AF34/AD34-1 | AG37: =AG34/AF34-1 | AH37: =AH34/AG34-1 | AI37: =AI34/AH34-1 | AK37: =AK34/AI34-1 | AL37: =AL34/AK34-1 | AM37: =AM34/AL34-1 | AN37: =AN34/AM34-1 | AP37: =AP34/AN34-1 | AQ37: =AQ34/AP34-1 | AR37: =AR34/AQ34-1 | AS37: =AS34/AR34-1 | AU37: =AU34/AS34-1 | AV37: =AV34/AU34-1 | AW37: =AW34/AV34-1 | AX37: =AX34/AW34-1 | AZ37: =AZ34/AX34-1 | BA37: =BA34/AZ34-1 | BB37: =BB34/BA34-1 | BC37: =BC34/BB34-1 | BE37: =BE34/BC34-1 | BF37: =BF34/BE34-1 | BG37: =BG34/BF34-1 | BH37: =BH34/BG34-1 | BJ37: =BJ34/BH34-1 | BK37: =BK34/BJ34-1 | BL37: =BL34/BK34-1 | BM37: =BM34/BL34-1 | BO37: =BO34/BM34-1 | BP37: =BP34/BO34-1 | BQ37: =BQ34/BP34-1 | BR37: =BR34/BQ34-1 | BT37: =BT34/BR34-1 | BU37: =BU34/BT34-1 | BV37: =BV34/BU34-1 | BW37: =BW34/BV34-1 | BY37: =BY34/BW34-1 | BZ37: =BZ34/BY34-1 | CA37: =CA34/BZ34-1 | CB37: =CB34/CA34-1
A38: Y/Y Total Revenue Growth, % | D38: =D34/C34-1 | E38: =E34/D34-1 | F38: =F34/E34-1 | K38: =K34/F34-1 | L38: =L34/G34-1 | M38: =M34/H34-1 | N38: =N34/I34-1 | O38: =O34/J34-1 | P38: =P34/K34-1 | Q38: =Q34/L34-1 | R38: =R34/M34-1 | ... CC38: =CC34/BX34-1 | CD38: =CD34/CC34-1 | CE38: =CE34/CD34-1 | CF38: =CF34/CE34-1
A40: Blackwell Revenue, mm | BR40: 11000
A41: CMP Revenue, mm | AF41: 289 | AK41: 0 | AY41: 0 | AZ41: 155 | BA41: 266 | BB41: 105 | BC41: =BD41-SUM(AZ41,BA41,BB41) | BD41: 550 | BE41: 0 | BF41: 0 | BG41: 0 | BH41: =BI41-SUM(BE41,BF41,BG41) | BI41: 0 | BM41: =BN41-SUM(BJ41,BK41,BL41) | BR41: =BS41-SUM(BO41,BP41,BQ41)
A43: Operating Expense Forecasting
A44: Revenue, mm | C44: =C292 | D44: =D292 | E44: =E292 | F44: =F292 | G44: =G292 | H44: =H292 | I44: =I292 | J44: =J292 | ... O44: =O292 | P44: =P34 | Q44: =Q34 | R44: =R34 | S44: =S34 | T44: =T34 | U44: =U34 | V44: =V34 | W44: =W34 | ... CF44: =CF34
A45: Cost of revenue, mm | C45: =C293 | D45: =D293 | E45: =E293 | F45: =F293 | G45: =G293 | H45: =H293 | I45: =I293 | J45: =J293 | ... BV45: =BV293 | BW45: =BW44-BW46 | BX45: =BX44-BX46 | BY45: =BY44-BY46 | BZ45: =BZ44-BZ46 | CA45: =CA44-CA46 | CB45: =CB44-CB46 | CC45: =CC44-CC46 | CD45: =CD44-CD46 | ... CF45: =CF44-CF46
A46: GAAP Gross Profit, mm | C46: =C44-C45 | D46: =D44-D45 | E46: =E44-E45 | F46: =F44-F45 | G46: =G44-G45 | H46: =H44-H45 | I46: =I44-I45 | J46: =J44-J45 | ... BV46: =BV44-BV45 | BW46: =BW57-BW55-BW53-BW51 | BX46: =SUM(BT46,BU46,BV46,BW46) | BY46: =BY57-BY55-BY53-BY51 | BZ46: =BZ57-BZ55-BZ53-BZ51 | CA46: =CA57-CA55-CA53-CA51 | CB46: =CB57-CB55-CB53-CB51 | CC46: =SUM(BY46,BZ46,CA46,CB46) | CD46: =CD57-CD55-CD53-CD51 | CE46: =CE57-CE55-CE53-CE51 | CF46: =CF57-CF55-CF53-CF51
A47: Y/Y growth in Gross Profit, % | D47: =D46/C46-1 | E47: =E46/D46-1 | F47: =F46/E46-1 | K47: =K46/F46-1 | L47: =L46/G46-1 | M47: =M46/H46-1 | N47: =N46/I46-1 | O47: =O46/J46-1 | P47: =P46/K46-1 | Q47: =Q46/L46-1 | R47: =R46/M46-1 | ... CC47: =CC46/BX46-1 | CD47: =CD46/CC46-1 | CE47: =CE46/CD46-1 | CF47: =CF46/CE46-1
A48: GAAP Gross Margin, % | C48: =C46/C44 | D48: =D46/D44 | E48: =E46/E44 | F48: =F46/F44 | G48: =G46/G44 | H48: =H46/H44 | I48: =I46/I44 | J48: =J46/J44 | ... CF48: =CF46/CF44
...

Sheet Exec Comp
A1: =MO.CompanyName
A2: =MO.Ticker | C2: =Model!C2 | D2: =Model!D2 | E2: =Model!E2 | F2: =Model!F2 | G2: =Model!G2 | H2: =Model!H2 | I2: =Model!I2 | J2: =Model!J2 | ... CF2: =Model!CF2
A3: =MO.TradingCurrency | B3: =MO.LastPrice | C3: =INDEX(MO_Common_FPDays,0,MATCH(C$5,MO_Common_ColumnHeader,0)) | D3: =INDEX(MO_Common_FPDays,0,MATCH(D$5,MO_Common_ColumnHeader,0)) | E3: =INDEX(MO_Common_FPDays,0,MATCH(E$5,MO_Common_ColumnHeader,0)) | F3: =INDEX(MO_Common_FPDays,0,MATCH(F$5,MO_Common_ColumnHeader,0)) | G3: =INDEX(MO_Common_FPDays,0,MATCH(G$5,MO_Common_ColumnHeader,0)) | H3: =INDEX(MO_Common_FPDays,0,MATCH(H$5,MO_Common_ColumnHeader,0)) | I3: =INDEX(MO_Common_FPDays,0,MATCH(I$5,MO_Common_ColumnHeader,0)) | J3: =INDEX(MO_Common_FPDays,0,MATCH(J$5,MO_Common_ColumnHeader,0)) | ... CF3: =INDEX(MO_Common_FPDays,0,MATCH(CF$5,MO_Common_ColumnHeader,0))
A4: =MO.DataSourceName | B4: =MO.RealTime | C4: =INDEX(MO_Common_QEndDate,0,MATCH(C$5,MO_Common_ColumnHeader,0)) | D4: =INDEX(MO_Common_QEndDate,0,MATCH(D$5,MO_Common_ColumnHeader,0)) | E4: =INDEX(MO_Common_QEndDate,0,MATCH(E$5,MO_Common_ColumnHeader,0)) | F4: =INDEX(MO_Common_QEndDate,0,MATCH(F$5,MO_Common_ColumnHeader,0)) | G4: =INDEX(MO_Common_QEndDate,0,MATCH(G$5,MO_Common_ColumnHeader,0)) | H4: =INDEX(MO_Common_QEndDate,0,MATCH(H$5,MO_Common_ColumnHeader,0)) | I4: =INDEX(MO_Common_QEndDate,0,MATCH(I$5,MO_Common_ColumnHeader,0)) | J4: =INDEX(MO_Common_QEndDate,0,MATCH(J$5,MO_Common_ColumnHeader,0)) | ... CF4: =INDEX(MO_Common_QEndDate,0,MATCH(CF$5,MO_Common_ColumnHeader,0))
A5: =MO.ReportFX | C5: =Model!C5 | D5: =Model!D5 | E5: =Model!E5 | F5: =Model!F5 | G5: =Model!G5 | H5: =Model!H5 | I5: =Model!I5 | J5: =Model!J5 | ... CF5: =Model!CF5
A6: Executive Compensation
A7: CEO - Base Pay, 000s | AT7: 996.514 | AY7: 1017.355 | BD7: 996.216 | BI7: 996.832 | BN7: 996.514
A8: CEO - Stock Awards, 000s | AT8: 9676.92 | AY8: 15279.78 | BD8: 18660.407 | BI8: 19666.382 | BN8: 26676.415
A9: CEO - Non-equity incentive plans, 000s | AT9: 805.444 | AY9: 3000 | BD9: 4000 | BI9: 0 | BN9: 4000
A10: CEO - All other compensation, 000s | AT10: 13.402 | AY10: 19.266 | BD10: 81.038 | BI10: 693.71 | BN10: 2494.973
A11: CEO - Total Comp, 000s | AT11: =SUM(AT7:AT10) | AY11: =SUM(AY7:AY10) | BD11: =SUM(BD7:BD10) | BI11: =SUM(BI7:BI10) | BN11: =SUM(BN7:BN10)
A12: CEO - comp tied to equity, % | AT12: =SUM(AT8)/AT11 | AY12: =SUM(AY8)/AY11 | BD12: =SUM(BD8)/BD11 | BI12: =SUM(BI8)/BI11 | BN12: =SUM(BN8)/BN11
A13: Market Cap - EoP, mm | AT13: =Model!AT746 | AU13: =Model!AU746 | AV13: =Model!AV746 | AW13: =Model!AW746 | AX13: =Model!AX746 | AY13: =Model!AY746 | AZ13: =Model!AZ746 | BA13: =Model!BA746 | ... BV13: =Model!BV746
A15: CEO - Options 09/14/2020 # of unexercised exercisable options, 000s | AT15: 250
A16: CEO - Options 09/14/2020 exercise price, $ | AT16: 10.56
A18: CEO - Options 03/17/2021 # of unexercised exercisable options, 000s | AT18: 250 | AY18: 50
A19: CEO - Options 03/17/2021 exercise price, $ | AT19: 17.62 | AY19: 17.62
A21: CEO - Options 09/20/2021 # of unexercised exercisable options, 000s | AT21: 250 | AY21: 250
A22: CEO - Options 09/20/2021 exercise price, $ | AT22: 14.465 | AY22: 14.465
A24: CEO - Options 03/20/2022 # of unexercised exercisable options, 000s | AT24: 300 | AY24: 300 | BD24: 292.34
A25: CEO - Options 03/20/2022 exercise price, $ | AT25: 14.46 | AY25: 14.46 | BD25: 3.615
A27: CEO - Options 09/18/2022 # of unexercised exercisable options, 000s | AT27: 300 | AY27: 300 | BD27: 1200
A28: CEO - Options 09/18/2022 exercise price, $ | AT28: 13.71 | AY28: 13.71 | BD28: 3.4275
A30: CEO - Options 03/19/2023 # of unexercised exercisable options, 000s | AT30: 237.5 | AY30: 237.5 | BD30: 950
A31: CEO - Options 03/19/2023 exercise price, $ | AT31: 12.62 | AY31: 12.62 | BD31: 3.155
A33: CEO - Options 09/17/2023 # of unexercised excercisable options, 000s | AT33: 237.5 | AY33: 237.5 | BD33: 950 | BI33: 475
A34: CEO - Options 09/17/2023 exercise price, $ | AT34: 16 | AY34: 16 | BD34: 4 | BI34: 4
A36: CEO - EoP shares owned, 000s | AT36: =(21462.889*(10))*(4) | AY36: =(21375.455*(10))*(4) | BD36: =84421.722*(10) | BI36: =86403.193*(10) | BN36: =93463.791*(10)
A37: CEO - EoP Shares Issuable Within 60 days, 000s | AT37: =(1825*(10))*(4) | AY37: =(1325*(10))*(4) | BD37: =3100*(10) | BI37: =475*(10)
A38: CEO - EoP shares beneficially owned, 000s | AT38: =SUM(AT36:AT37) | AY38: =SUM(AY36:AY37) | BD38: =SUM(BD36:BD37) | BI38: =SUM(BI36:BI37) | BN38: =SUM(BN36:BN37)
A40: CFO - Base Pay, 000s | AT40: 896.863 | AY40: 915.62 | BD40: 896.595 | BI40: 897.149 | BN40: 896.863
A41: CFO - Stock Awards, 000s | AT41: 3307.188 | AY41: 6595.691 | BD41: 8269.02 | BI41: 10004.677 | BN41: 11756.027
A42: CFO - Non-equity incentive plans, 000s | AT42: 219.667 | AY42: 600 | BD42: 600 | BI42: 0 | BN42: 600
A43: CFO - All other compensation, 000s | AT43: 9.122 | AY43: 9.731 | BD43: 10.312 | BI43: 15.402 | BN43: 13.902
A44: CFO - Total Comp, 000s | AT44: =SUM(AT40:AT43) | AY44: =SUM(AY40:AY43) | BD44: =SUM(BD40:BD43) | BI44: =SUM(BI40:BI43) | BN44: =SUM(BN40:BN43)
A45: CFO - comp tied to equity, % | AT45: =SUM(AT41)/AT44 | AY45: =SUM(AY41)/AY44 | BD45: =SUM(BD41)/BD44 | BI45: =SUM(BI41)/BI44 | BN45: =SUM(BN41)/BN44
A47: CFO - EoP shares owned, 000s | AT47: 81.792 | AY47: 98.873 | BD47: 447.471 | BI47: 478.297 | BN47: 515.421
A48: CFO - EoP Shares Issuable Within 60 days, 000s
A49: CFO - EoP shares beneficially owned, 000s | AT49: =SUM(AT47:AT47) | AY49: =SUM(AY47:AY47) | BD49: =SUM(BD47:BD47) | BI49: =SUM(BI47:BI47) | BN49: =SUM(BN47:BN48)
A51: Board Diversity
...

Sheet Guidance
B1: =MO.CompanyName
B2: Most Recent Period: | F2: =UL.MRQ
I4: Guidance | M4: Model | P4: Difference vs. Mid | S4: Update Log
B5: Type | D5: Item | E5: Item Name | F5: Fiscal Period | G5: Base Period | I5: Low | J5: High | K5: Mid | M5: Type | N5: Output | P5: Absolute | Q5: Relative | S5: Date | T5: Link
A6: 388 | B6: =IF(INDEX(MO_SNA_IsHistoricalPeriod,,MATCH(F6,MO_Common_ColumnHeader,0)),"Historical","Forward") | D6: =INDEX(INDIRECT(E6),0,COLUMN(MO_Common_Column_A)) | E6: MO_RIS_REV | F6: Q4-2026 | I6: =65000*0.98 | J6: =65000*1.02 | K6: =AVERAGE(I6:J6) | M6: =IF(INDEX(MO_SNA_IsHistoricalPeriod,,MATCH(F6,MO_Common_ColumnHeader,0)),"Actual","Estimate") | N6: =IFERROR(INDEX(INDIRECT(E6),0,MATCH(F6,MO_Common_ColumnHeader,0)),"N/A") | P6: =IF(ISNUMBER(N6),N6-K6,"N/A") | Q6: =IFERROR(IF(ISNUMBER(N6),(N6-K6)/ABS(K6),"N/A"),"N/A") | S6: 45980 | T6: CFO Commentary
A7: 387 | B7: =IF(INDEX(MO_SNA_IsHistoricalPeriod,,MATCH(F7,MO_Common_ColumnHeader,0)),"Historical","Forward") | D7: =INDEX(INDIRECT(E7),0,COLUMN(MO_Common_Column_A)) | E7: MO_MA_GM | F7: Q4-2026 | I7: =74.8%-0.5% | J7: =74.8%+0.5% | K7: =AVERAGE(I7:J7) | M7: =IF(INDEX(MO_SNA_IsHistoricalPeriod,,MATCH(F7,MO_Common_ColumnHeader,0)),"Actual","Estimate") | N7: =IFERROR(INDEX(INDIRECT(E7),0,MATCH(F7,MO_Common_ColumnHeader,0)),"N/A") | P7: =IF(ISNUMBER(N7),N7-K7,"N/A") | Q7: =IFERROR(IF(ISNUMBER(N7),(N7-K7)/ABS(K7),"N/A"),"N/A") | S7: 45980 | T7: CFO Commentary
A8: 386 | B8: =IF(INDEX(MO_SNA_IsHistoricalPeriod,,MATCH(F8,MO_Common_ColumnHeader,0)),"Historical","Forward") | D8: =INDEX(INDIRECT(E8),0,COLUMN(MO_Common_Column_A)) | E8: MO_MA_GM_NONGAAP | F8: Q4-2026 | I8: =75%-0.5% | J8: =75%+0.5% | K8: =AVERAGE(I8:J8) | M8: =IF(INDEX(MO_SNA_IsHistoricalPeriod,,MATCH(F8,MO_Common_ColumnHeader,0)),"Actual","Estimate") | N8: =IFERROR(INDEX(INDIRECT(E8),0,MATCH(F8,MO_Common_ColumnHeader,0)),"N/A") | P8: =IF(ISNUMBER(N8),N8-K8,"N/A") | Q8: =IFERROR(IF(ISNUMBER(N8),(N8-K8)/ABS(K8),"N/A"),"N/A") | S8: 45980 | T8: CFO Commentary
A9: 385 | B9: =IF(INDEX(MO_SNA_IsHistoricalPeriod,,MATCH(F9,MO_Common_ColumnHeader,0)),"Historical","Forward") | D9: GAAP Operating Expenses | F9: Q4-2026 | I9: 6700 | J9: 6700 | K9: =AVERAGE(I9:J9) | M9: =IF(INDEX(MO_SNA_IsHistoricalPeriod,,MATCH(F9,MO_Common_ColumnHeader,0)),"Actual","Estimate") | N9: =INDEX(MO_RIS_RD,0,MATCH(F9,MO_Common_ColumnHeader,0))+INDEX(MO_RIS_SGA,0,MATCH(F9,MO_Common_ColumnHeader,0)) | P9: =IF(ISNUMBER(N9),N9-K9,"N/A") | Q9: =IFERROR(IF(ISNUMBER(N9),(N9-K9)/ABS(K9),"N/A"),"N/A") | S9: 45980 | T9: CFO Commentary
A10: 384 | B10: =IF(INDEX(MO_SNA_IsHistoricalPeriod,,MATCH(F10,MO_Common_ColumnHeader,0)),"Historical","Forward") | D10: =INDEX(INDIRECT(E10),0,COLUMN(MO_Common_Column_A)) | E10: MO_OS_OPEX | F10: Q4-2026 | I10: 5000 | J10: 5000 | K10: =AVERAGE(I10:J10) | M10: =IF(INDEX(MO_SNA_IsHistoricalPeriod,,MATCH(F10,MO_Common_ColumnHeader,0)),"Actual","Estimate") | N10: =IFERROR(INDEX(INDIRECT(E10),0,MATCH(F10,MO_Common_ColumnHeader,0)),"N/A") | P10: =IF(ISNUMBER(N10),N10-K10,"N/A") | Q10: =IFERROR(IF(ISNUMBER(N10),(N10-K10)/ABS(K10),"N/A"),"N/A") | S10: 45980 | T10: CFO Commentary
A11: 383 | B11: =IF(INDEX(MO_SNA_IsHistoricalPeriod,,MATCH(F11,MO_Common_ColumnHeader,0)),"Historical","Forward") | D11: GAAP Other Income | F11: Q4-2026 | I11: -500 | J11: -500 | K11: =AVERAGE(I11:J11) | M11: =IF(INDEX(MO_SNA_IsHistoricalPeriod,,MATCH(F11,MO_Common_ColumnHeader,0)),"Actual","Estimate") | N11: =IFERROR(INDEX(INDIRECT(E11),0,MATCH(F11,MO_Common_ColumnHeader,0)),"N/A") | P11: =IF(ISNUMBER(N11),N11-K11,"N/A") | Q11: =IFERROR(IF(ISNUMBER(N11),(N11-K11)/ABS(K11),"N/A"),"N/A") | S11: 45980 | T11: CFO Commentary
A12: 382 | B12: =IF(INDEX(MO_SNA_IsHistoricalPeriod,,MATCH(F12,MO_Common_ColumnHeader,0)),"Historical","Forward") | D12: Non-GAAP Other Income | F12: Q4-2026 | I12: -500 | J12: -500 | K12: =AVERAGE(I12:J12) | M12: =IF(INDEX(MO_SNA_IsHistoricalPeriod,,MATCH(F12,MO_Common_ColumnHeader,0)),"Actual","Estimate") | N12: =INDEX(MO_RIS_IE_Net_NONGAAP,0,MATCH(F12,MO_Common_ColumnHeader,0))+INDEX(MO_RIS_OI_NONGAAP,0,MATCH(F12,MO_Common_ColumnHeader,0)) | P12: =IF(ISNUMBER(N12),N12-K12,"N/A") | Q12: =IFERROR(IF(ISNUMBER(N12),(N12-K12)/ABS(K12),"N/A"),"N/A") | S12: 45980 | T12: CFO Commentary
A13: 381 | B13: =IF(INDEX(MO_SNA_IsHistoricalPeriod,,MATCH(F13,MO_Common_ColumnHeader,0)),"Historical","Forward") | D13: GAAP Tax Rate | E13: MO_RIS_TaxRate | F13: Q4-2026 | I13: 0.16 | J13: 0.18 | K13: =AVERAGE(I13:J13) | M13: =IF(INDEX(MO_SNA_IsHistoricalPeriod,,MATCH(F13,MO_Common_ColumnHeader,0)),"Actual","Estimate") | N13: =IFERROR(INDEX(INDIRECT(E13),0,MATCH(F13,MO_Common_ColumnHeader,0)),"N/A") | P13: =IF(ISNUMBER(N13),N13-K13,"N/A") | Q13: =IFERROR(IF(ISNUMBER(N13),(N13-K13)/ABS(K13),"N/A"),"N/A") | S13: 45980 | T13: CFO Commentary
A14: 380 | B14: =IF(INDEX(MO_SNA_IsHistoricalPeriod,,MATCH(F14,MO_Common_ColumnHeader,0)),"Historical","Forward") | D14: =INDEX(INDIRECT(E14),0,COLUMN(MO_Common_Column_A)) | E14: MO_RIS_TaxRate_NONGAAP | F14: Q4-2026 | I14: 0.16 | J14: 0.18 | K14: =AVERAGE(I14:J14) | M14: =IF(INDEX(MO_SNA_IsHistoricalPeriod,,MATCH(F14,MO_Common_ColumnHeader,0)),"Actual","Estimate") | N14: =IFERROR(INDEX(INDIRECT(E14),0,MATCH(F14,MO_Common_ColumnHeader,0)),"N/A") | P14: =IF(ISNUMBER(N14),N14-K14,"N/A") | Q14: =IFERROR(IF(ISNUMBER(N14),(N14-K14)/ABS(K14),"N/A"),"N/A") | S14: 45980 | T14: CFO Commentary
A15: 379
A16: 378 | B16: =IF(INDEX(MO_SNA_IsHistoricalPeriod,,MATCH(F16,MO_Common_ColumnHeader,0)),"Historical","Forward") | D16: =INDEX(INDIRECT(E16),0,COLUMN(MO_Common_Column_A)) | E16: MO_RIS_REV | F16: Q3-2026 | I16: =54000*0.98 | J16: =54000*1.02 | K16: =AVERAGE(I16:J16) | M16: =IF(INDEX(MO_SNA_IsHistoricalPeriod,,MATCH(F16,MO_Common_ColumnHeader,0)),"Actual","Estimate") | N16: =IFERROR(INDEX(INDIRECT(E16),0,MATCH(F16,MO_Common_ColumnHeader,0)),"N/A") | P16: =IF(ISNUMBER(N16),N16-K16,"N/A") | Q16: =IFERROR(IF(ISNUMBER(N16),(N16-K16)/ABS(K16),"N/A"),"N/A") | S16: 45896 | T16: CFO Commentary
A17: 377 | B17: =IF(INDEX(MO_SNA_IsHistoricalPeriod,,MATCH(F17,MO_Common_ColumnHeader,0)),"Historical","Forward") | D17: =INDEX(INDIRECT(E17),0,COLUMN(MO_Common_Column_A)) | E17: MO_MA_GM | F17: Q3-2026 | I17: =73.3%-0.5% | J17: =73.3%+0.5% | K17: =AVERAGE(I17:J17) | M17: =IF(INDEX(MO_SNA_IsHistoricalPeriod,,MATCH(F17,MO_Common_ColumnHeader,0)),"Actual","Estimate") | N17: =IFERROR(INDEX(INDIRECT(E17),0,MATCH(F17,MO_Common_ColumnHeader,0)),"N/A") | P17: =IF(ISNUMBER(N17),N17-K17,"N/A") | Q17: =IFERROR(IF(ISNUMBER(N17),(N17-K17)/ABS(K17),"N/A"),"N/A") | S17: 45896 | T17: CFO Commentary
A18: 376 | B18: =IF(INDEX(MO_SNA_IsHistoricalPeriod,,MATCH(F18,MO_Common_ColumnHeader,0)),"Historical","Forward") | D18: =INDEX(INDIRECT(E18),0,COLUMN(MO_Common_Column_A)) | E18: MO_MA_GM_NONGAAP | F18: Q3-2026 | I18: =73.5%-0.5% | J18: =73.5%+0.5% | K18: =AVERAGE(I18:J18) | M18: =IF(INDEX(MO_SNA_IsHistoricalPeriod,,MATCH(F18,MO_Common_ColumnHeader,0)),"Actual","Estimate") | N18: =IFERROR(INDEX(INDIRECT(E18),0,MATCH(F18,MO_Common_ColumnHeader,0)),"N/A") | P18: =IF(ISNUMBER(N18),N18-K18,"N/A") | Q18: =IFERROR(IF(ISNUMBER(N18),(N18-K18)/ABS(K18),"N/A"),"N/A") | S18: 45896 | T18: CFO Commentary
A19: 375 | B19: =IF(INDEX(MO_SNA_IsHistoricalPeriod,,MATCH(F19,MO_Common_ColumnHeader,0)),"Historical","Forward") | D19: GAAP Operating Expenses | F19: Q3-2026 | I19: 5900 | J19: 5900 | K19: =AVERAGE(I19:J19) | M19: =IF(INDEX(MO_SNA_IsHistoricalPeriod,,MATCH(F19,MO_Common_ColumnHeader,0)),"Actual","Estimate") | N19: =INDEX(MO_RIS_RD,0,MATCH(F19,MO_Common_ColumnHeader,0))+INDEX(MO_RIS_SGA,0,MATCH(F19,MO_Common_ColumnHeader,0)) | P19: =IF(ISNUMBER(N19),N19-K19,"N/A") | Q19: =IFERROR(IF(ISNUMBER(N19),(N19-K19)/ABS(K19),"N/A"),"N/A") | S19: 45896 | T19: CFO Commentary
A20: 374 | B20: =IF(INDEX(MO_SNA_IsHistoricalPeriod,,MATCH(F20,MO_Common_ColumnHeader,0)),"Historical","Forward") | D20: =INDEX(INDIRECT(E20),0,COLUMN(MO_Common_Column_A)) | E20: MO_OS_OPEX | F20: Q3-2026 | I20: 4200 | J20: 4200 | K20: =AVERAGE(I20:J20) | M20: =IF(INDEX(MO_SNA_IsHistoricalPeriod,,MATCH(F20,MO_Common_ColumnHeader,0)),"Actual","Estimate") | N20: =IFERROR(INDEX(INDIRECT(E20),0,MATCH(F20,MO_Common_ColumnHeader,0)),"N/A") | P20: =IF(ISNUMBER(N20),N20-K20,"N/A") | Q20: =IFERROR(IF(ISNUMBER(N20),(N20-K20)/ABS(K20),"N/A"),"N/A") | S20: 45896 | T20: CFO Commentary
A21: 373 | B21: =IF(INDEX(MO_SNA_IsHistoricalPeriod,,MATCH(F21,MO_Common_ColumnHeader,0)),"Historical","Forward") | D21: GAAP Other Income | F21: Q3-2026 | I21: -500 | J21: -500 | K21: =AVERAGE(I21:J21) | M21: =IF(INDEX(MO_SNA_IsHistoricalPeriod,,MATCH(F21,MO_Common_ColumnHeader,0)),"Actual","Estimate") | N21: =IFERROR(INDEX(INDIRECT(E21),0,MATCH(F21,MO_Common_ColumnHeader,0)),"N/A") | P21: =IF(ISNUMBER(N21),N21-K21,"N/A") | Q21: =IFERROR(IF(ISNUMBER(N21),(N21-K21)/ABS(K21),"N/A"),"N/A") | S21: 45896 | T21: CFO Commentary
A22: 372 | B22: =IF(INDEX(MO_SNA_IsHistoricalPeriod,,MATCH(F22,MO_Common_ColumnHeader,0)),"Historical","Forward") | D22: Non-GAAP Other Income | F22: Q3-2026 | I22: -500 | J22: -500 | K22: =AVERAGE(I22:J22) | M22: =IF(INDEX(MO_SNA_IsHistoricalPeriod,,MATCH(F22,MO_Common_ColumnHeader,0)),"Actual","Estimate") | N22: =INDEX(MO_RIS_IE_Net_NONGAAP,0,MATCH(F22,MO_Common_ColumnHeader,0))+INDEX(MO_RIS_OI_NONGAAP,0,MATCH(F22,MO_Common_ColumnHeader,0)) | P22: =IF(ISNUMBER(N22),N22-K22,"N/A") | Q22: =IFERROR(IF(ISNUMBER(N22),(N22-K22)/ABS(K22),"N/A"),"N/A") | S22: 45896 | T22: CFO Commentary
A23: 371 | B23: =IF(INDEX(MO_SNA_IsHistoricalPeriod,,MATCH(F23,MO_Common_ColumnHeader,0)),"Historical","Forward") | D23: GAAP Tax Rate | E23: MO_RIS_TaxRate | F23: Q3-2026 | I23: 0.155 | J23: 0.175 | K23: =AVERAGE(I23:J23) | M23: =IF(INDEX(MO_SNA_IsHistoricalPeriod,,MATCH(F23,MO_Common_ColumnHeader,0)),"Actual","Estimate") | N23: =IFERROR(INDEX(INDIRECT(E23),0,MATCH(F23,MO_Common_ColumnHeader,0)),"N/A") | P23: =IF(ISNUMBER(N23),N23-K23,"N/A") | Q23: =IFERROR(IF(ISNUMBER(N23),(N23-K23)/ABS(K23),"N/A"),"N/A") | S23: 45896 | T23: CFO Commentary
A24: 370 | B24: =IF(INDEX(MO_SNA_IsHistoricalPeriod,,MATCH(F24,MO_Common_ColumnHeader,0)),"Historical","Forward") | D24: =INDEX(INDIRECT(E24),0,COLUMN(MO_Common_Column_A)) | E24: MO_RIS_TaxRate_NONGAAP | F24: Q3-2026 | I24: 0.155 | J24: 0.175 | K24: =AVERAGE(I24:J24) | M24: =IF(INDEX(MO_SNA_IsHistoricalPeriod,,MATCH(F24,MO_Common_ColumnHeader,0)),"Actual","Estimate") | N24: =IFERROR(INDEX(INDIRECT(E24),0,MATCH(F24,MO_Common_ColumnHeader,0)),"N/A") | P24: =IF(ISNUMBER(N24),N24-K24,"N/A") | Q24: =IFERROR(IF(ISNUMBER(N24),(N24-K24)/ABS(K24),"N/A"),"N/A") | S24: 45896 | T24: CFO Commentary
A25: 369
A26: 368 | B26: =IF(INDEX(MO_SNA_IsHistoricalPeriod,,MATCH(F26,MO_Common_ColumnHeader,0)),"Historical","Forward") | D26: =INDEX(INDIRECT(E26),0,COLUMN(MO_Common_Column_A)) | E26: MO_RIS_REV | F26: Q2-2026 | I26: =45000*0.98 | J26: =45000*1.02 | K26: =AVERAGE(I26:J26) | M26: =IF(INDEX(MO_SNA_IsHistoricalPeriod,,MATCH(F26,MO_Common_ColumnHeader,0)),"Actual","Estimate") | N26: =IFERROR(INDEX(INDIRECT(E26),0,MATCH(F26,MO_Common_ColumnHeader,0)),"N/A") | P26: =IF(ISNUMBER(N26),N26-K26,"N/A") | Q26: =IFERROR(IF(ISNUMBER(N26),(N26-K26)/ABS(K26),"N/A"),"N/A") | S26: 45805 | T26: CFO Commentary
A27: 367 | B27: =IF(INDEX(MO_SNA_IsHistoricalPeriod,,MATCH(F27,MO_Common_ColumnHeader,0)),"Historical","Forward") | D27: =INDEX(INDIRECT(E27),0,COLUMN(MO_Common_Column_A)) | E27: MO_MA_GM | F27: Q2-2026 | I27: 0.713 | J27: 0.723 | K27: =AVERAGE(I27:J27) | M27: =IF(INDEX(MO_SNA_IsHistoricalPeriod,,MATCH(F27,MO_Common_ColumnHeader,0)),"Actual","Estimate") | N27: =IFERROR(INDEX(INDIRECT(E27),0,MATCH(F27,MO_Common_ColumnHeader,0)),"N/A") | P27: =IF(ISNUMBER(N27),N27-K27,"N/A") | Q27: =IFERROR(IF(ISNUMBER(N27),(N27-K27)/ABS(K27),"N/A"),"N/A") | S27: 45805 | T27: CFO Commentary
