Workbook
Name AA.AlternatePriceSourceStartPeriod: "Q1-2018"
Name AA.CIK: "1046179"
Name AA.CompareQuarters.LatestMRQ: "Q3-2024"
Name AA.CSIN: "M2B13B0184"
Name AA.CurationVersion: "2023.11.1.0"
Name AA.DBMacroVersion: "1.0.13.0"
Name AA.FreeCashFlow: "TRUE"
Name AA.HardcodeChecker.LatestMRQ: "Q3-2019"
Name AA.ModelChecks.LatestMRQ: "Q3-2021"
Name AA.ModelChecks.LatestVersionNumber: "2.38.27.0"
Name AA.ModelVersion: "FY2025.24"
Name AA.NonLibraryWideCurationVersion: "4"
Name AA.PartialUpdate.BsAvailable: "TRUE"
Name AA.PartialUpdate.CfsAvailable: "TRUE"
Name AA.PartialUpdate.IsAvailable: "TRUE"
Name AA.PeriodLayout: "QFY"
Name AA.PersonalMacro.VersionNumber: "1.5.1.5"
Name AA.RowNameEnforcerVersion: "2023.11.1.0"
Name AA.SessionToUploadId: ""
Name AA.StartWorkModelVersion: "FY2025.22"
Name AA.StartWorkType: ""
Name AA.SubyearType: "Q"
Name AA.TemplateUpgradeAttempted: "TRUE"
Name AA.TemplateVersion: "7.5.4.0"
Name AA.UpdateType: "Partial"
Name FP.DataSource: 'Front Page'!$H$16
Name FP.DataSourceName: 'Front Page'!$H$15
Name FP.Disclaimer: 'Front Page'!$C$22
Name FP.LastPrice: 'Front Page'!$H$20
Name FP.LastPriceDate: 'Front Page'!$F$20
Name FP.RealTimeToggle: 'Front Page'!$H$18
Name FP.UpdateDate: 'Front Page'!$H$11
Name FP.UpdateEvent: 'Front Page'!$H$13
Name FP_Comment: 'Front Page'!$M$13:$P$20
Name FP_StockPriceOverride: 'Front Page'!$C$20:$H$20
Name GD.CompanyName: Guidance!$B$1
Name GD.MRQ: Guidance!$F$2
Name GD_Difference_Mid_Absolute: Guidance!$P:$P
Name GD_Difference_Mid_Relative: Guidance!$Q:$Q
Name GD_Guidance_High: Guidance!$J:$J
Name GD_Guidance_Low: Guidance!$I:$I
Name GD_Guidance_Mid: Guidance!$K:$K
Name GD_Header_Column: Guidance!$5:$5
Name GD_Header_Section: Guidance!$4:$4
Name GD_Index: Guidance!$A:$A
Name GD_Item: Guidance!$D:$D
Name GD_Item_BasePeriod: Guidance!$G:$G
Name GD_Item_FiscalPeriod: Guidance!$F:$F
Name GD_Item_Name: Guidance!$E:$E
Name GD_Model_Output: Guidance!$N:$N
Name GD_Model_Type: Guidance!$M:$M
Name GD_Type: Guidance!$B:$B
Name GD_Update_Date: Guidance!$S:$S
Name GD_Update_Link: Guidance!$T:$T
Name HP.MRFX: Model!$B$1096
Name HP.ReportCurrency: Model!$B$1095
Name HP.Ticker: Model!$A$2
Name HP.TradeCurrency: Model!$B$1093
Name HP.TradeCurrency.HardCoded: Model!$B$1094
Name MO.ApplyTradeCurrencyScaling: Model!$B$1092

Sheet Front Page
M6: Please contact this email for any model-specific questions:
M7: modelsupport@alpha-sense.com | N7: mailto:support@canalyst.com?subject=Canalyst%20Support:%20Taiwan%20Semiconductor%20Manufacturing%20Company%20Ltd.%20TSM%20US&body=Model%20Version:%20Q2-2019.21 | O7: mailto:support@canalyst.com?subject=Canalyst%20Support:%20Taiwan%20Semiconductor%20Manufacturing%20Company%20Ltd.%20TSM%20US&body=Model%20Version:%20Q2-2019.21
C9: Company Model: | H9: =Model!A1
C11: Updated: | H11: =OFFSET('Update Log'!$C$10,1,0,1,1)
M12: Comments on Model:
C13: For: | H13: =OFFSET('Update Log'!$E$10,1,0,1,1) | M13: 1 ADR represents 5 shares. Partially updated with PR, to be fully updated with 20F
C15: Consensus Data and Real-Time Stock Price: | H15: Bloomberg
H16: =IF(FP.DataSourceName="Bloomberg",1,IF(FP.DataSourceName="Capital IQ",2,IF(FP.DataSourceName="FactSet",3,IF(FP.DataSourceName="Refinitiv",4))))
C18: Real-Time Stock Price: | H18: OFF
C20: Stock Price Override: | F20: 46051 | H20: 339.55
C22: DISCLAIMER Access to and use of this model, including the data contained herein (this "Model") is subject to Tegus, Inc.'s (a successor entity to Canalyst Financial Modeling Corporation) ("Company") Terms of Use that you accepted prior to accessing this Model, the applicable Service Agreement between the Company and you (or a corporate entity that has authorized you to access and use this Model on its behalf in accordance with the terms of such Service Agreement) or other similar agreement between you and the Company. BY CONTINUING TO ACCESS OR USE THIS MODEL, YOU EXPRESSLY AGREE TO THE TERMS AND CONDITIONS OF SUCH AGREEMENTS. The Company and certain of its licensors have exclusive proprietary rights in this Model. This Model is being provided for internal use only. Unless prior written consent by the Company and its licensors has been provided to you, you may not distribute or otherwise furnish this Model to any third party, nor use or permit anyone to use this Model for any unlawful or unauthorized purpose. IF YOU HAVE UNLAWFULLY OBTAINED, OR ARE NOT AUTHORIZED TO USE THIS MODEL, YOU ARE OBLIGATED TO PROMPTLY: (I) RETURN THIS MODEL (AND ANY DERIVATIVE WORKS ARISING FROM OR RELATING THERETO) TO THE AUTHORIZED USER OF THIS MODEL; (II) PROVIDE NOTICE TO THE COMPANY AT LEGAL@TEGUS.COM OF SUCH UNLAWFUL OR UNAUTHORIZED ACCESS AND USE; AND, (III) CERTIFY THAT YOU HAVE DESTROYED THIS MODEL (AND ANY DERIVATIVE WORKS ARISING FROM OR RELATING THERETO) AND ANY COPIES FROM YOUR SYSTEMS SO AS TO ENSURE THEY ARE INCAPABLE OF RETRIEVAL. A portion of the data contained in this Model may be powered by third party contributors and their respective licensors, or derived from data provided by such contributors, including (but not limited to): (i) QuoteMedia Inc.: A portion of the market data is powered by Quotemedia.com. All rights reserved. Data delayed 15 minutes unless otherwise indicated; (ii) S&P Global Market Intelligence LLC: Copyright (c) {{YEAR}} S&P Global Market Intelligence LLC (and its affiliates as applicable). All rights reserved. Reproduction of any information, opinions, views, data or material, including ratings ("Content") in any form is prohibited except with the prior written permission of the relevant party. Such party, its affiliates and suppliers ("Content Providers") do not guarantee the accuracy, adequacy, completeness, timeliness or availability of any Content and are not responsible for any errors or omissions (negligent or otherwise), regardless of the cause, or for the results obtained from the use of such Content. In no event shall Content Providers be liable for any damages, costs, expenses, legal fees, or losses (including lost income or lost profit and opportunity costs) in connection with any use of the Content. A reference to a particular investment or security, a rating or any observation concerning an investment that is part of the Content is not a recommendation to buy, sell or hold such investment or security, does not address the suitability of an investment or security and should not be relied on as investment advice. Credit ratings are statements of opinions and are not statements of fact; and, (iii) Refinitiv Canada Holdings Limited: A portion of the information may be provided by or derived from data provided by Refinitiv. By accessing or using this Model (including any portion of the data contained herein) you expressly represent that such access or use does not constitute a violation of any applicable law or regulation to which you or the securities are subject. This Model does not constitute investment advice by the Company or any of its licensors. Reference to a particular investment or security, credit rating or any observation concerning a security or investment in this Model is not a recommendation or solicitation to buy, sell or hold such investment or security or make any other investment decisions. For greater certainty, any forecasts or forward-looking information expressed herein are for illustrative purposes only and do not purport to express any view on what may transpire. Neither the Company nor any of its licensors have performed company-specific research on any projected information, as such, it is your responsibility to express your own views on projected results. This Model does not guarantee future performance and undue reliance should not be placed on such. You are solely responsible for evaluating the merits and risks of any investment based on your own business and financial expertise, the business and financial expertise of professional advisors with whom you have consulted, your financial situation and risk tolerance. Neither the Company, nor any of its licensors, undertake any liability with respect to your reliance on this Model. This Model is a quantitative tool with no investment views. The Company and its respective directors, officers, employees, agents, contractors, and affiliates may hold long or short positions in the security to which this Model relates, based on their personal views, and may initiate or close out any positions in such security at any time without any notice. THIS MODEL IS PROVIDED "AS IS" AND ON AN "AS AVAILABLE" BASIS ONLY, WITHOUT WARRANTIES OR CONDITIONS OF ANY KIND. NEITHER THE COMPANY NOR ANY OF ITS LICENSORS NOR THEIR RESPECTIVE AFFILIATES OR SUPPLIERS HAVE LIABILITY FOR THE ACCURACY, TIMELINESS OR COMPLETENESS OF THIS MODEL, OR FOR DELAYS, INTERRUPTIONS OR OMISSIONS HEREIN, NOR FOR ANY LOST PROFITS, INDIRECT, SPECIAL OR CONSEQUENTIAL DAMAGES. Access to data in this Model that is sourced from third party contributors is subject to termination in the event that any agreement between the Company and such third party contributors terminates for any reason. Copyright 2023 Tegus. All rights reserved.

Sheet DCF
A1: TSMC DCF Valuation Analysis
A4: Period | F4: FY2025 | G4: FY2026 | H4: FY2027 | I4: FY2028 | J4: FY2029
A6: REVENUE BUILD
A7: Smartphone Revenue | F7: =Model!L7 | G7: =Model!Q7 | H7: =Model!V7 | I7: =Model!AA7 | J7: =Model!AF7
A8: HPC Revenue | F8: =Model!L10 | G8: =Model!Q10 | H8: =Model!V10 | I8: =Model!AA10 | J8: =Model!AF10
A9: IoT Revenue | F9: =Model!L13 | G9: =Model!Q13 | H9: =Model!V13 | I9: =Model!AA13 | J9: =Model!AF13
A10: Automotive Revenue | F10: =Model!L16 | G10: =Model!Q16 | H10: =Model!V16 | I10: =Model!AA16 | J10: =Model!AF16
A11: Digital Consumer Revenue | F11: =Model!L19 | G11: =Model!Q19 | H11: =Model!V19 | I11: =Model!AA19 | J11: =Model!AF19
A12: Other Revenue | F12: =Model!L22 | G12: =Model!Q22 | H12: =Model!V22 | I12: =Model!AA22 | J12: =Model!AF22
A13: Total Revenue | F13: =SUM(F7:F12) | G13: =SUM(G7:G12) | H13: =SUM(H7:H12) | I13: =SUM(I7:I12) | J13: =SUM(J7:J12)
A14: Y/Y Growth % | G14: =G13/F13 - 1 | H14: =H13/G13 - 1 | I14: =I13/H13 - 1 | J14: =J13/I13 - 1
A16: OPERATING MARGINS
A17: Gross Margin % | F17: =Model!L38 | G17: =Model!Q38 | H17: =Model!V38 | I17: =Model!AA38 | J17: =Model!AF38
A18: Operating Margin % | F18: =Model!L59 / Model!L25 | G18: =Model!Q59 / Model!Q25 | H18: =Model!V59 / Model!V25 | I18: =Model!AA59 / Model!AA25 | J18: =Model!AF59 / Model!AF25
A27: UFCF BUILD
A28: Revenue | F28: =F13 | G28: =G13 | H28: =H13 | I28: =I13 | J28: =J13
A29: Gross Margin % | F29: =F17 | G29: =G17 | H29: =H17 | I29: =I17 | J29: =J17
A30: Gross Profit | F30: =F28 * F29 | G30: =G28 * G29 | H30: =H28 * H29 | I30: =I28 * I29 | J30: =J28 * J29
A31: Operating Margin % | F31: =F18 | G31: =G18 | H31: =H18 | I31: =I18 | J31: =J18
A32: EBIT | F32: =F28 * F31 | G32: =G28 * G31 | H32: =H28 * H31 | I32: =I28 * I31 | J32: =J28 * J31
A33: Tax Rate % | F33: 0.15 | G33: 0.15 | H33: 0.15 | I33: 0.15 | J33: 0.15
A34: NOPAT (EBIT × (1-tax)) | F34: =F32 * (1 - F33) | G34: =G32 * (1 - G33) | H34: =H32 * (1 - H33) | I34: =I32 * (1 - I33) | J34: =J32 * (1 - J33)
A35: D&A | F35: =Model!L72 + Model!L76 | G35: =Model!Q72 + Model!Q76 | H35: =Model!V72 + Model!V76 | I35: =Model!AA72 + Model!AA76 | J35: =Model!AF72 + Model!AF76
A36: CapEx | F36: =Model!L86 * 1000 | G36: =Model!Q86 * 1000 | H36: =Model!V86 * 1000 | I36: =Model!AA86 * 1000 | J36: =Model!AF86 * 1000
A37: Change in Working Capital | F37: =F28 * 0.10 | G37: =G28 * 0.10 | H37: =H28 * 0.10 | I37: =I28 * 0.10 | J37: =J28 * 0.10
A38: Unlevered FCF | F38: =F34 + F35 - F36 - F37 | G38: =G34 + G35 - G36 - G37 | H38: =H34 + H35 - H36 - H37 | I38: =I34 + I35 - I36 - I37 | J38: =J34 + J35 - J36 - J37
A40: DISCOUNTING
A41: WACC % | F41: 0.09 | G41: 0.09 | H41: 0.09 | I41: 0.09 | J41: 0.09
A42: Discount Factor | F42: =1 / (1 + F41)^1 | G42: =1 / (1 + G41)^2 | H42: =1 / (1 + H41)^3 | I42: =1 / (1 + I41)^4 | J42: =1 / (1 + J41)^5
A43: PV of UFCF | F43: =F38 * F42 | G43: =G38 * G42 | H43: =H38 * H42 | I43: =I38 * I42 | J43: =J38 * J42
A45: TERMINAL VALUE
A46: Terminal Growth % | F46: 0.025
A47: Terminal Value | F47: =F38 * (1 + F46) / (F41 - F46)
A48: PV of TV | F48: =F47 * F42
A50: VALUATION
A51: Sum PV UFCF | F51: =SUM(F43:J43)
A52: PV Terminal Value | F52: =F48
A53: Enterprise Value | F53: =F51 + F52
A54: Less: Net Debt | F54: =Model!L84 - Model!L80
A55: Equity Value | F55: =F53 - F54
...

Sheet Model
A1: Taiwan Semiconductor Manufacturing Company Ltd.
A2: =CHOOSE(MO.DataSourceIndex,MO.Ticker.Bloomberg,MO.Ticker.CapIQ,MO.Ticker.FactSet,MO.Ticker.Thomson) | C2: =EOMONTH(C4,-12) | BN2: Partial | BO2: Partial
A3: =HP.TradeCurrency | B3: =IF(MO.RealTime="OFF",MO.LastPriceHardcoded,MO.LastPriceFormula) | C3: =C4-C2 | D3: =D4-C4 | E3: =E4-D4 | F3: =F4-E4 | G3: =G4-F4 | H3: =H4-G4 | I3: =I4-H4 | J3: =J4-I4 | K3: =K4-J4 | L3: =L4-G4 | M3: =M4-L4 | N3: =N4-M4 | O3: =O4-N4 | P3: =P4-O4 | Q3: =Q4-L4 | R3: =R4-Q4 | S3: =S4-R4 | T3: =T4-S4 | U3: =U4-T4 | V3: =V4-Q4 | W3: =W4-V4 | X3: =X4-W4 | Y3: =Y4-X4 | Z3: =Z4-Y4 | AA3: =AA4-V4 | AB3: =AB4-AA4 | AC3: =AC4-AB4 | AD3: =AD4-AC4 | AE3: =AE4-AD4 | AF3: =AF4-AA4 | AG3: =AG4-AF4 | AH3: =AH4-AG4 | AI3: =AI4-AH4 | AJ3: =AJ4-AI4 | AK3: =AK4-AF4 | AL3: =AL4-AK4 | AM3: =AM4-AL4 | AN3: =AN4-AM4 | AO3: =AO4-AN4 | AP3: =AP4-AK4 | AQ3: =AQ4-AP4 | AR3: =AR4-AQ4 | AS3: =AS4-AR4 | AT3: =AT4-AS4 | AU3: =AU4-AP4 | AV3: =AV4-AU4 | AW3: =AW4-AV4 | AX3: =AX4-AW4 | AY3: =AY4-AX4 | AZ3: =AZ4-AU4 | BA3: =BA4-AZ4 | BB3: =BB4-BA4 | BC3: =BC4-BB4 | BD3: =BD4-BC4 | BE3: =BE4-AZ4 | BF3: =BF4-BE4 | BG3: =BG4-BF4 | BH3: =BH4-BG4 | BI3: =BI4-BH4 | BJ3: =BJ4-BE4 | BK3: =BK4-BJ4 | BL3: =BL4-BK4 | BM3: =BM4-BL4 | BN3: =BN4-BM4 | BO3: =BO4-BJ4 | BP3: =BP4-BO4 | BQ3: =BQ4-BP4 | BR3: =BR4-BQ4 | BS3: =BS4-BR4 | BT3: =BT4-BO4 | BU3: =BU4-BT4 | BV3: =BV4-BU4 | BW3: =BW4-BV4 | BX3: =BX4-BW4 | BY3: =BY4-BT4 | BZ3: =BZ4-BY4 | CA3: =CA4-BZ4 | CB3: =CB4-CA4
A4: =FP.DataSourceName | B4: =IF(AND(MO.RealTimeStockPriceToggle,MO.LastPriceFormula<>"N/A"),"ON","OFF") | C4: 40178 | D4: =EOMONTH(C4,12) | E4: =EOMONTH(D4,12) | F4: =EOMONTH(E4,12) | G4: =EOMONTH(F4,12) | H4: =EOMONTH(G4,3) | I4: =EOMONTH(H4,3) | J4: =EOMONTH(I4,3) | K4: =EOMONTH(J4,3) | L4: =K4 | M4: =EOMONTH(L4,3) | N4: =EOMONTH(M4,3) | O4: =EOMONTH(N4,3) | P4: =EOMONTH(O4,3) | Q4: =P4 | R4: =EOMONTH(Q4,3) | S4: =EOMONTH(R4,3) | T4: =EOMONTH(S4,3) | U4: =EOMONTH(T4,3) | V4: =U4 | W4: =EOMONTH(V4,3) | X4: =EOMONTH(W4,3) | Y4: =EOMONTH(X4,3) | Z4: =EOMONTH(Y4,3) | AA4: =Z4 | AB4: =EOMONTH(AA4,3) | AC4: =EOMONTH(AB4,3) | AD4: =EOMONTH(AC4,3) | AE4: =EOMONTH(AD4,3) | AF4: =AE4 | AG4: =EOMONTH(AF4,3) | AH4: =EOMONTH(AG4,3) | AI4: =EOMONTH(AH4,3) | AJ4: =EOMONTH(AI4,3) | AK4: =AJ4 | AL4: =EOMONTH(AK4,3) | AM4: =EOMONTH(AL4,3) | AN4: =EOMONTH(AM4,3) | AO4: =EOMONTH(AN4,3) | AP4: =AO4 | AQ4: =EOMONTH(AP4,3) | AR4: =EOMONTH(AQ4,3) | AS4: =EOMONTH(AR4,3) | AT4: =EOMONTH(AS4,3) | AU4: =AT4 | AV4: =EOMONTH(AU4,3) | AW4: =EOMONTH(AV4,3) | AX4: =EOMONTH(AW4,3) | AY4: =EOMONTH(AX4,3) | AZ4: =AY4 | BA4: =EOMONTH(AZ4,3) | BB4: =EOMONTH(BA4,3) | BC4: =EOMONTH(BB4,3) | BD4: =EOMONTH(BC4,3) | BE4: =BD4 | BF4: =EOMONTH(BE4,3) | BG4: =EOMONTH(BF4,3) | BH4: =EOMONTH(BG4,3) | BI4: =EOMONTH(BH4,3) | BJ4: =BI4 | BK4: =EOMONTH(BJ4,3) | BL4: =EOMONTH(BK4,3) | BM4: =EOMONTH(BL4,3) | BN4: =EOMONTH(BM4,3) | BO4: =BN4 | BP4: =EOMONTH(BO4,3) | BQ4: =EOMONTH(BP4,3) | BR4: =EOMONTH(BQ4,3) | BS4: =EOMONTH(BR4,3) | BT4: =BS4 | BU4: =EOMONTH(BT4,3) | BV4: =EOMONTH(BU4,3) | BW4: =EOMONTH(BV4,3) | BX4: =EOMONTH(BW4,3) | BY4: =BX4 | BZ4: =EOMONTH(BY4,12) | CA4: =EOMONTH(BZ4,12) | CB4: =EOMONTH(CA4,12)
A5: =MO.ReportCurrency | C5: FY2009 | D5: =CONCATENATE("FY",RIGHT(C5,4)+1) | E5: =CONCATENATE("FY",RIGHT(D5,4)+1) | F5: =CONCATENATE("FY",RIGHT(E5,4)+1) | G5: =CONCATENATE("FY",RIGHT(F5,4)+1) | H5: =CONCATENATE("Q1","-",RIGHT(G5,4)+1) | I5: =CONCATENATE("Q2","-",RIGHT(H5,4)) | J5: =CONCATENATE("Q3","-",RIGHT(I5,4)) | K5: =CONCATENATE("Q4","-",RIGHT(J5,4)) | L5: =CONCATENATE("FY",RIGHT(G5,4)+1) | M5: =CONCATENATE("Q1","-",RIGHT(L5,4)+1) | N5: =CONCATENATE("Q2","-",RIGHT(M5,4)) | O5: =CONCATENATE("Q3","-",RIGHT(N5,4)) | P5: =CONCATENATE("Q4","-",RIGHT(O5,4)) | Q5: =CONCATENATE("FY",RIGHT(L5,4)+1) | R5: =CONCATENATE("Q1","-",RIGHT(Q5,4)+1) | S5: =CONCATENATE("Q2","-",RIGHT(R5,4)) | T5: =CONCATENATE("Q3","-",RIGHT(S5,4)) | U5: =CONCATENATE("Q4","-",RIGHT(T5,4)) | V5: =CONCATENATE("FY",RIGHT(Q5,4)+1) | W5: =CONCATENATE("Q1","-",RIGHT(V5,4)+1) | X5: =CONCATENATE("Q2","-",RIGHT(W5,4)) | Y5: =CONCATENATE("Q3","-",RIGHT(X5,4)) | Z5: =CONCATENATE("Q4","-",RIGHT(Y5,4)) | AA5: =CONCATENATE("FY",RIGHT(V5,4)+1) | AB5: =CONCATENATE("Q1","-",RIGHT(AA5,4)+1) | AC5: =CONCATENATE("Q2","-",RIGHT(AB5,4)) | AD5: =CONCATENATE("Q3","-",RIGHT(AC5,4)) | AE5: =CONCATENATE("Q4","-",RIGHT(AD5,4)) | AF5: =CONCATENATE("FY",RIGHT(AA5,4)+1) | AG5: =CONCATENATE("Q1","-",RIGHT(AF5,4)+1) | AH5: =CONCATENATE("Q2","-",RIGHT(AG5,4)) | AI5: =CONCATENATE("Q3","-",RIGHT(AH5,4)) | AJ5: =CONCATENATE("Q4","-",RIGHT(AI5,4)) | AK5: =CONCATENATE("FY",RIGHT(AF5,4)+1) | AL5: =CONCATENATE("Q1","-",RIGHT(AK5,4)+1) | AM5: =CONCATENATE("Q2","-",RIGHT(AL5,4)) | AN5: =CONCATENATE("Q3","-",RIGHT(AM5,4)) | AO5: =CONCATENATE("Q4","-",RIGHT(AN5,4)) | AP5: =CONCATENATE("FY",RIGHT(AK5,4)+1) | AQ5: =CONCATENATE("Q1","-",RIGHT(AP5,4)+1) | AR5: =CONCATENATE("Q2","-",RIGHT(AQ5,4)) | AS5: =CONCATENATE("Q3","-",RIGHT(AR5,4)) | AT5: =CONCATENATE("Q4","-",RIGHT(AS5,4)) | AU5: =CONCATENATE("FY",RIGHT(AP5,4)+1) | AV5: =CONCATENATE("Q1","-",RIGHT(AU5,4)+1) | AW5: =CONCATENATE("Q2","-",RIGHT(AV5,4)) | AX5: =CONCATENATE("Q3","-",RIGHT(AW5,4)) | AY5: =CONCATENATE("Q4","-",RIGHT(AX5,4)) | AZ5: =CONCATENATE("FY",RIGHT(AU5,4)+1) | BA5: =CONCATENATE("Q1","-",RIGHT(AZ5,4)+1) | BB5: =CONCATENATE("Q2","-",RIGHT(BA5,4)) | BC5: =CONCATENATE("Q3","-",RIGHT(BB5,4)) | BD5: =CONCATENATE("Q4","-",RIGHT(BC5,4)) | BE5: =CONCATENATE("FY",RIGHT(AZ5,4)+1) | BF5: =CONCATENATE("Q1","-",RIGHT(BE5,4)+1) | BG5: =CONCATENATE("Q2","-",RIGHT(BF5,4)) | BH5: =CONCATENATE("Q3","-",RIGHT(BG5,4)) | BI5: =CONCATENATE("Q4","-",RIGHT(BH5,4)) | BJ5: =CONCATENATE("FY",RIGHT(BE5,4)+1) | BK5: =CONCATENATE("Q1","-",RIGHT(BJ5,4)+1) | BL5: =CONCATENATE("Q2","-",RIGHT(BK5,4)) | BM5: =CONCATENATE("Q3","-",RIGHT(BL5,4)) | BN5: =CONCATENATE("Q4","-",RIGHT(BM5,4)) | BO5: =CONCATENATE("FY",RIGHT(BJ5,4)+1) | BP5: =CONCATENATE("Q1","-",RIGHT(BO5,4)+1) | BQ5: =CONCATENATE("Q2","-",RIGHT(BP5,4)) | BR5: =CONCATENATE("Q3","-",RIGHT(BQ5,4)) | BS5: =CONCATENATE("Q4","-",RIGHT(BR5,4)) | BT5: =CONCATENATE("FY",RIGHT(BO5,4)+1) | BU5: =CONCATENATE("Q1","-",RIGHT(BT5,4)+1) | BV5: =CONCATENATE("Q2","-",RIGHT(BU5,4)) | BW5: =CONCATENATE("Q3","-",RIGHT(BV5,4)) | BX5: =CONCATENATE("Q4","-",RIGHT(BW5,4)) | BY5: =CONCATENATE("FY",RIGHT(BT5,4)+1) | BZ5: =CONCATENATE("FY",RIGHT(BY5,4)+1) | CA5: =CONCATENATE("FY",RIGHT(BZ5,4)+1) | CB5: =CONCATENATE("FY",RIGHT(CA5,4)+1)
A6: Revenue Build
A7: Smartphone revenue , mm | AB7: 113267.91 | AC7: 82753.245 | AD7: 117666.46 | AE7: =AF7-SUM(AB7,AC7,AD7) | AF7: 466452.28 | AG7: 103210.27 | AH7: 108860.87 | AI7: 144301.2 | AJ7: =AK7-SUM(AG7,AH7,AI7) | AK7: 523612.86 | AL7: 151931.28 | AM7: 145843.88 | AN7: 163491.24 | AO7: =AP7-SUM(AL7,AM7,AN7) | AP7: 645303.61 | AQ7: 163207.8 | AR7: 157744.89 | AS7: 180649.83 | AT7: =AU7-SUM(AQ7,AR7,AS7) | AU7: 695091.19 | AV7: 195999.89 | AW7: 201555.76 | AX7: 251069.57 | AY7: =AZ7-SUM(AV7,AW7,AX7) | AZ7: 888879.25 | BA7: 174372.27 | BB7: 159366.87 | BC7: 212001.18 | BD7: =BE7-SUM(BA7,BB7,BC7) | BE7: 814914.29 | BF7: 225032.14 | BG7: 222543.37 | BH7: 257495.61 | BI7: =BJ7-SUM(BF7,BG7,BH7) | BJ7: 1005130.5 | BK7: 233611.39 | BL7: 249959.55 | BM7: 296745.65 | BN7: =BN25*0.32 | BO7: =SUM(BK7,BL7,BM7,BN7) | BP7: =BK7*(1+BP9) | BQ7: =BL7*(1+BQ9) | BR7: =BM7*(1+BR9) | BS7: =BN7*(1+BS9) | BT7: =SUM(BP7,BQ7,BR7,BS7) | BU7: =BP7*(1+BU9) | BV7: =BQ7*(1+BV9) | BW7: =BR7*(1+BW9) | BX7: =BS7*(1+BX9) | BY7: =SUM(BU7,BV7,BW7,BX7) | BZ7: =BY7*(1+BZ9) | CA7: =BZ7*(1+CA9) | CB7: =CA7*(1+CB9)
A8: Q/Q Smartphone revenue growth, % | AC8: =AC7/AB7-1 | AD8: =AD7/AC7-1 | AE8: =AE7/AD7-1 | AG8: =AG7/AE7-1 | AH8: =AH7/AG7-1 | AI8: =AI7/AH7-1 | AJ8: =AJ7/AI7-1 | AL8: =AL7/AJ7-1 | AM8: =AM7/AL7-1 | AN8: =AN7/AM7-1 | AO8: =AO7/AN7-1 | AQ8: =AQ7/AO7-1 | AR8: =AR7/AQ7-1 | AS8: =AS7/AR7-1 | AT8: =AT7/AS7-1 | AV8: =AV7/AT7-1 | AW8: =AW7/AV7-1 | AX8: =AX7/AW7-1 | AY8: =AY7/AX7-1 | BA8: =BA7/AY7-1 | BB8: =BB7/BA7-1 | BC8: =BC7/BB7-1 | BD8: =BD7/BC7-1 | BF8: =BF7/BD7-1 | BG8: =BG7/BF7-1 | BH8: =BH7/BG7-1 | BI8: =BI7/BH7-1 | BK8: =BK7/BI7-1 | BL8: =BL7/BK7-1 | BM8: =BM7/BL7-1 | BN8: =BN7/BM7-1 | BP8: =BP7/BN7-1 | BQ8: =BQ7/BP7-1 | BR8: =BR7/BQ7-1 | BS8: =BS7/BR7-1 | BU8: =BU7/BS7-1 | BV8: =BV7/BU7-1 | BW8: =BW7/BV7-1 | BX8: =BX7/BW7-1
A9: Y/Y Smartphone revenue growth, % | AG9: =AG7/AB7-1 | AH9: =AH7/AC7-1 | AI9: =AI7/AD7-1 | AJ9: =AJ7/AE7-1 | AK9: =AK7/AF7-1 | AL9: =AL7/AG7-1 | AM9: =AM7/AH7-1 | AN9: =AN7/AI7-1 | ... BO9: =BO7/BJ7-1 | BP9: 0.15 | BQ9: 0.05 | BR9: 0.191 | BS9: 0.2 | BT9: =BT7/BO7-1 | BU9: 0.1 | BV9: 0.05 | BW9: 0.191 | BX9: 0.2 | BY9: =BY7/BT7-1 | BZ9: 0.2 | CA9: 0.1 | CB9: 0.1
A10: High performance computing revenue , mm | AB10: 78988.359 | AC10: 93089.339 | AD10: 84945.146 | AE10: =AF10-SUM(AB10,AC10,AD10) | AF10: 341910.2 | AG10: 62824.973 | AH10: 77376.963 | AI10: 85300.705 | AJ10: =AK10-SUM(AG10,AH10,AI10) | AK10: 315822.31 | AL10: 92993.61 | AM10: 104115.54 | AN10: 130404.09 | AO10: =AP10-SUM(AL10,AM10,AN10) | AP10: 439809.98 | AQ10: 127843.39 | AR10: 143391.01 | AS10: 155629.73 | AT10: =AU10-SUM(AQ10,AR10,AS10) | AU10: 587780.14 | AV10: 202245.16 | AW10: 228940.67 | AX10: 238237.29 | AY10: =AZ10-SUM(AV10,AW10,AX10) | AZ10: 932383.73 | BA10: 225532.03 | BB10: 214359.34 | BC10: 227816.59 | BD10: =BE10-SUM(BA10,BB10,BC10) | BE10: 934768.62 | BF10: 274772.97 | BG10: 351392.53 | BH10: 389309.41 | BI10: =BJ10-SUM(BF10,BG10,BH10) | BJ10: 1476890.6 | BK10: 493223.15 | BL10: 561155.35 | BM10: 558592.35 | BN10: =BN25*0.55 | BO10: =SUM(BK10,BL10,BM10,BN10) | BP10: =BK10*(1+BP12) | BQ10: =BL10*(1+BQ12) | BR10: =BM10*(1+BR12) | BS10: =BN10*(1+BS12) | BT10: =SUM(BP10,BQ10,BR10,BS10) | BU10: =BP10*(1+BU12) | BV10: =BQ10*(1+BV12) | BW10: =BR10*(1+BW12) | BX10: =BS10*(1+BX12) | BY10: =SUM(BU10,BV10,BW10,BX10) | BZ10: =BY10*(1+BZ12) | CA10: =BZ10*(1+CA12) | CB10: =CA10*(1+CB12)
A11: Q/Q High performance computing revenue growth, % | AC11: =AC10/AB10-1 | AD11: =AD10/AC10-1 | AE11: =AE10/AD10-1 | AG11: =AG10/AE10-1 | AH11: =AH10/AG10-1 | AI11: =AI10/AH10-1 | AJ11: =AJ10/AI10-1 | AL11: =AL10/AJ10-1 | AM11: =AM10/AL10-1 | AN11: =AN10/AM10-1 | AO11: =AO10/AN10-1 | AQ11: =AQ10/AO10-1 | AR11: =AR10/AQ10-1 | AS11: =AS10/AR10-1 | AT11: =AT10/AS10-1 | AV11: =AV10/AT10-1 | AW11: =AW10/AV10-1 | AX11: =AX10/AW10-1 | AY11: =AY10/AX10-1 | BA11: =BA10/AY10-1 | BB11: =BB10/BA10-1 | BC11: =BC10/BB10-1 | BD11: =BD10/BC10-1 | BF11: =BF10/BD10-1 | BG11: =BG10/BF10-1 | BH11: =BH10/BG10-1 | BI11: =BI10/BH10-1 | BK11: =BK10/BI10-1 | BL11: =BL10/BK10-1 | BM11: =BM10/BL10-1 | BN11: =BN10/BM10-1 | BP11: =BP10/BN10-1 | BQ11: =BQ10/BP10-1 | BR11: =BR10/BQ10-1 | BS11: =BS10/BR10-1 | BU11: =BU10/BS10-1 | BV11: =BV10/BU10-1 | BW11: =BW10/BV10-1 | BX11: =BX10/BW10-1
A12: Y/Y High performance computing revenue growth, % | AG12: =AG10/AB10-1 | AH12: =AH10/AC10-1 | AI12: =AI10/AD10-1 | AJ12: =AJ10/AE10-1 | AK12: =AK10/AF10-1 | AL12: =AL10/AG10-1 | AM12: =AM10/AH10-1 | AN12: =AN10/AI10-1 | ... BO12: =BO10/BJ10-1 | BP12: 0.4 | BQ12: 0.05 | BR12: 0.23 | BS12: 0.26 | BT12: =BT10/BO10-1 | BU12: 0.1 | BV12: 0.05 | BW12: 0.23 | BX12: 0.26 | BY12: =BY10/BT10-1 | BZ12: 0.05 | CA12: 0.12 | CB12: 0.12
A13: Internet of things revenue , mm | AB13: 15379.027 | AC13: 15747.791 | AD13: 17015.261 | AE13: =AF13-SUM(AB13,AC13,AD13) | AF13: 65091.314 | AG13: 16717.625 | AH13: 19150.847 | AI13: 25790.65 | AJ13: =AK13-SUM(AG13,AH13,AI13) | AK13: 86342.707 | AL13: 26595.813 | AM13: 25265.823 | AN13: 31201.283 | AO13: =AP13-SUM(AL13,AM13,AN13) | AP13: 110355.19 | AQ13: 30122.731 | AR13: 29391.787 | AS13: 36282.241 | AT13: =AU13-SUM(AQ13,AR13,AS13) | AU13: 133005.98 | AV13: 39045.775 | AW13: 44648.551 | AX13: 59410.567 | AY13: =AZ13-SUM(AV13,AW13,AX13) | AZ13: 196114.99 | BA13: 42720.43 | BB13: 38168.913 | BC13: 47409.811 | BD13: =BE13-SUM(BA13,BB13,BC13) | BE13: 161916.54 | BF13: 35320.95 | BG13: 37346.267 | BH13: 50255.327 | BI13: =BJ13-SUM(BF13,BG13,BH13) | BJ13: 165516.21 | BK13: 38723.19 | BL13: 44298.398 | BM13: 53250.285 | BN13: =BN25*0.05 | BO13: =SUM(BK13,BL13,BM13,BN13) | BP13: =BK13*(1+BP15) | BQ13: =BL13*(1+BQ15) | BR13: =BM13*(1+BR15) | BS13: =BN13*(1+BS15) | BT13: =SUM(BP13,BQ13,BR13,BS13) | BU13: =BP13*(1+BU15) | BV13: =BQ13*(1+BV15) | BW13: =BR13*(1+BW15) | BX13: =BS13*(1+BX15) | BY13: =SUM(BU13,BV13,BW13,BX13) | BZ13: =BY13*(1+BZ15) | CA13: =BZ13*(1+CA15) | CB13: =CA13*(1+CB15)
A14: Q/Q Internet of things revenue growth, % | AC14: =AC13/AB13-1 | AD14: =AD13/AC13-1 | AE14: =AE13/AD13-1 | AG14: =AG13/AE13-1 | AH14: =AH13/AG13-1 | AI14: =AI13/AH13-1 | AJ14: =AJ13/AI13-1 | AL14: =AL13/AJ13-1 | AM14: =AM13/AL13-1 | AN14: =AN13/AM13-1 | AO14: =AO13/AN13-1 | AQ14: =AQ13/AO13-1 | AR14: =AR13/AQ13-1 | AS14: =AS13/AR13-1 | AT14: =AT13/AS13-1 | AV14: =AV13/AT13-1 | AW14: =AW13/AV13-1 | AX14: =AX13/AW13-1 | AY14: =AY13/AX13-1 | BA14: =BA13/AY13-1 | BB14: =BB13/BA13-1 | BC14: =BC13/BB13-1 | BD14: =BD13/BC13-1 | BF14: =BF13/BD13-1 | BG14: =BG13/BF13-1 | BH14: =BH13/BG13-1 | BI14: =BI13/BH13-1 | BK14: =BK13/BI13-1 | BL14: =BL13/BK13-1 | BM14: =BM13/BL13-1 | BN14: =BN13/BM13-1 | BP14: =BP13/BN13-1 | BQ14: =BQ13/BP13-1 | BR14: =BR13/BQ13-1 | BS14: =BS13/BR13-1 | BU14: =BU13/BS13-1 | BV14: =BV13/BU13-1 | BW14: =BW13/BV13-1 | BX14: =BX13/BW13-1
A15: Y/Y Internet of things revenue growth, % | AG15: =AG13/AB13-1 | AH15: =AH13/AC13-1 | AI15: =AI13/AD13-1 | AJ15: =AJ13/AE13-1 | AK15: =AK13/AF13-1 | AL15: =AL13/AG13-1 | AM15: =AM13/AH13-1 | AN15: =AN13/AI13-1 | ... BO15: =BO13/BJ13-1 | BP15: 0.25 | BQ15: 0.3 | BR15: 0.3 | BS15: 0.35 | BT15: =BT13/BO13-1 | BU15: 0.15 | BV15: 0.3 | BW15: 0.3 | BX15: 0.35 | BY15: =BY13/BT13-1 | BZ15: 0.05 | CA15: 0.1 | CB15: 0.1
A16: Automotive revenue , mm | AB16: 12907.788 | AC16: 13285.974 | AD16: 13288.092 | AE16: =AF16-SUM(AB16,AC16,AD16) | AF16: 51709.787 | AG16: 10626.515 | AH16: 10960.006 | AI16: 13143.575 | AJ16: =AK16-SUM(AG16,AH16,AI16) | AK16: 47914.518 | AL16: 13061.727 | AM16: 11392.379 | AN16: 8791.105 | AO16: =AP16-SUM(AL16,AM16,AN16) | AP16: 44367.562 | AQ16: 14605.54 | AR16: 16395.914 | AS16: 17186.114 | AT16: =AU16-SUM(AQ16,AR16,AS16) | AU16: 67076.353 | AV16: 23731.218 | AW16: 27041.397 | AX16: 31203.686 | AY16: =AZ16-SUM(AV16,AW16,AX16) | AZ16: 116380.99 | BA16: 36022.65 | BB16: 37275.507 | BC16: 28338.188 | BD16: =BE16-SUM(BA16,BB16,BC16) | BE16: 133654.28 | BF16: 32136.633 | BG16: 33747.863 | BH16: 35671.522 | BI16: =BJ16-SUM(BF16,BG16,BH16) | BJ16: 139323.1 | BK16: 43028.245 | BL16: 43029.218 | BM16: 50586.157 | BN16: =BN25*0.05 | BO16: =SUM(BK16,BL16,BM16,BN16) | BP16: =BK16*(1+BP18) | BQ16: =BL16*(1+BQ18) | BR16: =BM16*(1+BR18) | BS16: =BN16*(1+BS18) | BT16: =SUM(BP16,BQ16,BR16,BS16) | BU16: =BP16*(1+BU18) | BV16: =BQ16*(1+BV18) | BW16: =BR16*(1+BW18) | BX16: =BS16*(1+BX18) | BY16: =SUM(BU16,BV16,BW16,BX16) | BZ16: =BY16*(1+BZ18) | CA16: =BZ16*(1+CA18) | CB16: =CA16*(1+CB18)
A17: Q/Q Automotive revenue growth, % | AC17: =AC16/AB16-1 | AD17: =AD16/AC16-1 | AE17: =AE16/AD16-1 | AG17: =AG16/AE16-1 | AH17: =AH16/AG16-1 | AI17: =AI16/AH16-1 | AJ17: =AJ16/AI16-1 | AL17: =AL16/AJ16-1 | AM17: =AM16/AL16-1 | AN17: =AN16/AM16-1 | AO17: =AO16/AN16-1 | AQ17: =AQ16/AO16-1 | AR17: =AR16/AQ16-1 | AS17: =AS16/AR16-1 | AT17: =AT16/AS16-1 | AV17: =AV16/AT16-1 | AW17: =AW16/AV16-1 | AX17: =AX16/AW16-1 | AY17: =AY16/AX16-1 | BA17: =BA16/AY16-1 | BB17: =BB16/BA16-1 | BC17: =BC16/BB16-1 | BD17: =BD16/BC16-1 | BF17: =BF16/BD16-1 | BG17: =BG16/BF16-1 | BH17: =BH16/BG16-1 | BI17: =BI16/BH16-1 | BK17: =BK16/BI16-1 | BL17: =BL16/BK16-1 | BM17: =BM16/BL16-1 | BN17: =BN16/BM16-1 | BP17: =BP16/BN16-1 | BQ17: =BQ16/BP16-1 | BR17: =BR16/BQ16-1 | BS17: =BS16/BR16-1 | BU17: =BU16/BS16-1 | BV17: =BV16/BU16-1 | BW17: =BW16/BV16-1 | BX17: =BX16/BW16-1
A18: Y/Y Automotive revenue growth, % | AG18: =AG16/AB16-1 | AH18: =AH16/AC16-1 | AI18: =AI16/AD16-1 | AJ18: =AJ16/AE16-1 | AK18: =AK16/AF16-1 | AL18: =AL16/AG16-1 | AM18: =AM16/AH16-1 | AN18: =AN16/AI16-1 | ... BO18: =BO16/BJ16-1 | BP18: 0.4 | BQ18: 0.3 | BR18: 0.3 | BS18: 0.3 | BT18: =BT16/BO16-1 | BU18: 0.15 | BV18: 0.3 | BW18: 0.3 | BX18: 0.3 | BY18: =BY16/BT16-1 | BZ18: 0.05 | CA18: 0.1 | CB18: 0.1
A19: Digital consumer electronics revenue , mm | AB19: 15723.792 | AC19: 15511.894 | AD19: 14829.678 | AE19: =AF19-SUM(AB19,AC19,AD19) | AF19: 58470.179 | AG19: 14627.749 | AH19: 14183.705 | AI19: 14078.762 | AJ19: =AK19-SUM(AG19,AH19,AI19) | AK19: 53733.395 | AL19: 15577.838 | AM19: 14213.141 | AN19: 10820.057 | AO19: =AP19-SUM(AL19,AM19,AN19) | AP19: 54555.665 | AQ19: 15414.085 | AR19: 13540.616 | AS19: 13204.541 | AT19: =AU19-SUM(AQ19,AR19,AS19) | AU19: 55577.223 | AV19: 14478.836 | AW19: 15245.696 | AX19: 14900.562 | AY19: =AZ19-SUM(AV19,AW19,AX19) | AZ19: 56158.772 | BA19: 10929.154 | BB19: 13657.809 | BC19: 13570.337 | BD19: =BE19-SUM(BA19,BB19,BC19) | BE19: 46999.803 | BF19: 11737.785 | BG19: 14119.376 | BH19: 11404.721 | BI19: =BJ19-SUM(BF19,BG19,BH19) | BJ19: 47960.415 | BK19: 11552.466 | BL19: 14997.583 | BM19: 12023.942 | BN19: =BN25*0.01 | BO19: =SUM(BK19,BL19,BM19,BN19) | BP19: =BK19*(1+BP21) | BQ19: =BL19*(1+BQ21) | BR19: =BM19*(1+BR21) | BS19: =BN19*(1+BS21) | BT19: =SUM(BP19,BQ19,BR19,BS19) | BU19: =BP19*(1+BU21) | BV19: =BQ19*(1+BV21) | BW19: =BR19*(1+BW21) | BX19: =BS19*(1+BX21) | BY19: =SUM(BU19,BV19,BW19,BX19) | BZ19: =BY19*(1+BZ21) | CA19: =BZ19*(1+CA21) | CB19: =CA19*(1+CB21)
A20: Q/Q Digital consumer electronics revenue growth, % | AC20: =AC19/AB19-1 | AD20: =AD19/AC19-1 | AE20: =AE19/AD19-1 | AG20: =AG19/AE19-1 | AH20: =AH19/AG19-1 | AI20: =AI19/AH19-1 | AJ20: =AJ19/AI19-1 | AL20: =AL19/AJ19-1 | AM20: =AM19/AL19-1 | AN20: =AN19/AM19-1 | AO20: =AO19/AN19-1 | AQ20: =AQ19/AO19-1 | AR20: =AR19/AQ19-1 | AS20: =AS19/AR19-1 | AT20: =AT19/AS19-1 | AV20: =AV19/AT19-1 | AW20: =AW19/AV19-1 | AX20: =AX19/AW19-1 | AY20: =AY19/AX19-1 | BA20: =BA19/AY19-1 | BB20: =BB19/BA19-1 | BC20: =BC19/BB19-1 | BD20: =BD19/BC19-1 | BF20: =BF19/BD19-1 | BG20: =BG19/BF19-1 | BH20: =BH19/BG19-1 | BI20: =BI19/BH19-1 | BK20: =BK19/BI19-1 | BL20: =BL19/BK19-1 | BM20: =BM19/BL19-1 | BN20: =BN19/BM19-1 | BP20: =BP19/BN19-1 | BQ20: =BQ19/BP19-1 | BR20: =BR19/BQ19-1 | BS20: =BS19/BR19-1 | BU20: =BU19/BS19-1 | BV20: =BV19/BU19-1 | BW20: =BW19/BV19-1 | BX20: =BX19/BW19-1
A21: Y/Y Digital consumer electronics revenue growth, % | AG21: =AG19/AB19-1 | AH21: =AH19/AC19-1 | AI21: =AI19/AD19-1 | AJ21: =AJ19/AE19-1 | AK21: =AK19/AF19-1 | AL21: =AL19/AG19-1 | AM21: =AM19/AH19-1 | AN21: =AN19/AI19-1 | ... BO21: =BO19/BJ19-1 | BP21: 0.25 | BQ21: 0.2 | BR21: 0.2 | BS21: 0.2 | BT21: =BT19/BO19-1 | BU21: 0.2 | BV21: 0.2 | BW21: 0.2 | BX21: 0.2 | BY21: =BY19/BT19-1 | BZ21: 0.05 | CA21: 0.1 | CB21: 0.1
A22: Other revenue , mm | AB22: 11811.79 | AC22: 12888.568 | AD22: 12603.243 | AE22: =AF22-SUM(AB22,AC22,AD22) | AF22: 47839.802 | AG22: 10697.338 | AH22: 10466.088 | AI22: 10430.547 | AJ22: =AK22-SUM(AG22,AH22,AI22) | AK22: 42559.654 | AL22: 10436.918 | AM22: 9867.604 | AN22: 11718.428 | AO22: =AP22-SUM(AL22,AM22,AN22) | AP22: 44862.799 | AQ22: 11216.69 | AR22: 11680.896 | AS22: 11717.914 | AT22: =AU22-SUM(AQ22,AR22,AS22) | AU22: 48884.147 | AV22: 15574.988 | AW22: 16708.735 | AX22: 18321.07 | AY22: =AZ22-SUM(AV22,AW22,AX22) | AZ22: 73973.567 | BA22: 19056.43 | BB22: 18012.813 | BC22: 17596.658 | BD22: =BE22-SUM(BA22,BB22,BC22) | BE22: 69482.307 | BF22: 13643.72 | BG22: 14360.771 | BH22: 15555.553 | BI22: =BJ22-SUM(BF22,BG22,BH22) | BJ22: 59486.924 | BK22: 19115.229 | BL22: 20351.771 | BM22: 18719.934 | BN22: =BN25*0.02 | BO22: =SUM(BK22,BL22,BM22,BN22) | BP22: =BK22*(1+BP24) | BQ22: =BL22*(1+BQ24) | BR22: =BM22*(1+BR24) | BS22: =BN22*(1+BS24) | BT22: =SUM(BP22,BQ22,BR22,BS22) | BU22: =BP22*(1+BU24) | BV22: =BQ22*(1+BV24) | BW22: =BR22*(1+BW24) | BX22: =BS22*(1+BX24) | BY22: =SUM(BU22,BV22,BW22,BX22) | BZ22: =BY22*(1+BZ24) | CA22: =BZ22*(1+CA24) | CB22: =CA22*(1+CB24)
A23: Q/Q Other revenue growth, % | AC23: =AC22/AB22-1 | AD23: =AD22/AC22-1 | AE23: =AE22/AD22-1 | AG23: =AG22/AE22-1 | AH23: =AH22/AG22-1 | AI23: =AI22/AH22-1 | AJ23: =AJ22/AI22-1 | AL23: =AL22/AJ22-1 | AM23: =AM22/AL22-1 | AN23: =AN22/AM22-1 | AO23: =AO22/AN22-1 | AQ23: =AQ22/AO22-1 | AR23: =AR22/AQ22-1 | AS23: =AS22/AR22-1 | AT23: =AT22/AS22-1 | AV23: =AV22/AT22-1 | AW23: =AW22/AV22-1 | AX23: =AX22/AW22-1 | AY23: =AY22/AX22-1 | BA23: =BA22/AY22-1 | BB23: =BB22/BA22-1 | BC23: =BC22/BB22-1 | BD23: =BD22/BC22-1 | BF23: =BF22/BD22-1 | BG23: =BG22/BF22-1 | BH23: =BH22/BG22-1 | BI23: =BI22/BH22-1 | BK23: =BK22/BI22-1 | BL23: =BL22/BK22-1 | BM23: =BM22/BL22-1 | BN23: =BN22/BM22-1 | BP23: =BP22/BN22-1 | BQ23: =BQ22/BP22-1 | BR23: =BR22/BQ22-1 | BS23: =BS22/BR22-1 | BU23: =BU22/BS22-1 | BV23: =BV22/BU22-1 | BW23: =BW22/BV22-1 | BX23: =BX22/BW22-1
A24: Y/Y Other revenue growth, % | AG24: =AG22/AB22-1 | AH24: =AH22/AC22-1 | AI24: =AI22/AD22-1 | AJ24: =AJ22/AE22-1 | AK24: =AK22/AF22-1 | AL24: =AL22/AG22-1 | AM24: =AM22/AH22-1 | AN24: =AN22/AI22-1 | ... BO24: =BO22/BJ22-1 | BP24: 0.3 | BQ24: 0.1 | BR24: 0.1 | BS24: 0.1 | BT24: =BT22/BO22-1 | BU24: 0.1 | BV24: 0.1 | BW24: 0.1 | BX24: 0.1 | BY24: =BY22/BT22-1 | BZ24: 0.05 | CA24: 0.05 | CB24: 0.05
A25: Total Revenue, mm | AB25: =AB7+AB10+AB13+AB16+AB19+AB22 | AC25: =AC7+AC10+AC13+AC16+AC19+AC22 | AD25: =AD7+AD10+AD13+AD16+AD19+AD22 | AE25: =AE7+AE10+AE13+AE16+AE19+AE22 | AF25: =AF7+AF10+AF13+AF16+AF19+AF22 | AG25: =AG7+AG10+AG13+AG16+AG19+AG22 | AH25: =AH7+AH10+AH13+AH16+AH19+AH22 | AI25: =AI7+AI10+AI13+AI16+AI19+AI22 | ... BL25: =BL7+BL10+BL13+BL16+BL19+BL22 | BM25: =BM369 | BN25: =BN322 | BO25: =BO322 | BP25: =BP7+BP10+BP13+BP16+BP19+BP22 | BQ25: =BQ7+BQ10+BQ13+BQ16+BQ19+BQ22 | BR25: =BR7+BR10+BR13+BR16+BR19+BR22 | BS25: =BS7+BS10+BS13+BS16+BS19+BS22 | BT25: =BT7+BT10+BT13+BT16+BT19+BT22 | BU25: =BU7+BU10+BU13+BU16+BU19+BU22 | BV25: =BV7+BV10+BV13+BV16+BV19+BV22 | BW25: =BW7+BW10+BW13+BW16+BW19+BW22 | ... CB25: =CB7+CB10+CB13+CB16+CB19+CB22
A26: =A370 | BP26: =BP370 | BQ26: =BQ370 | BR26: =BR370 | BS26: =BS370 | BT26: =BT370 | BU26: =BU370 | BV26: =BV370 | BW26: =BW370 | ... CB26: =CB370
A27: Q/Q Total revenue growth, % | AC27: =AC25/AB25-1 | AD27: =AD25/AC25-1 | AE27: =AE25/AD25-1 | AG27: =AG25/AE25-1 | AH27: =AH25/AG25-1 | AI27: =AI25/AH25-1 | AJ27: =AJ25/AI25-1 | AL27: =AL25/AJ25-1 | AM27: =AM25/AL25-1 | AN27: =AN25/AM25-1 | AO27: =AO25/AN25-1 | AQ27: =AQ25/AO25-1 | AR27: =AR25/AQ25-1 | AS27: =AS25/AR25-1 | AT27: =AT25/AS25-1 | AV27: =AV25/AT25-1 | AW27: =AW25/AV25-1 | AX27: =AX25/AW25-1 | AY27: =AY25/AX25-1 | BA27: =BA25/AY25-1 | BB27: =BB25/BA25-1 | BC27: =BC25/BB25-1 | BD27: =BD25/BC25-1 | BF27: =BF25/BD25-1 | BG27: =BG25/BF25-1 | BH27: =BH25/BG25-1 | BI27: =BI25/BH25-1 | BK27: =BK25/BI25-1 | BL27: =BL25/BK25-1 | BM27: =BM25/BL25-1 | BN27: =BN25/BM25-1 | BP27: =BP25/BN25-1 | BQ27: =BQ25/BP25-1 | BR27: =BR25/BQ25-1 | BS27: =BS25/BR25-1 | BU27: =BU25/BS25-1 | BV27: =BV25/BU25-1 | BW27: =BW25/BV25-1 | BX27: =BX25/BW25-1
A28: Y/Y Total Revenue Growth, % | C28: =C$369/333158-1 | D28: =D369/C369-1 | E28: =E369/D369-1 | F28: =F369/E369-1 | G28: =G369/F369-1 | H28: =H$369/132755-1 | I28: =I$369/155886-1 | J28: =J$369/162577-1 | K28: =K$369/145806-1 | L28: =L369/G369-1 | M28: =M369/H369-1 | N28: =N369/I369-1 | O28: =O369/J369-1 | P28: =P369/K369-1 | Q28: =Q369/L369-1 | R28: =R369/M369-1 | S28: =S369/N369-1 | ... BY28: =BY369/BT369-1 | BZ28: =BZ369/BY369-1 | CA28: =CA369/BZ369-1 | CB28: =CB369/CA369-1
A30: Consolidated revenue in USD (Calculated), mm USD | C30: =C322/C257 | D30: =D322/D257 | E30: =E322/E257 | F30: =F322/F257 | G30: =G322/G257 | H30: =H322/H257 | I30: =I322/I257 | J30: =J322/J257 | K30: =K322/K257 | L30: =SUM(H30,I30,J30,K30) | M30: =M322/M257 | N30: =N322/N257 | O30: =O322/O257 | P30: =P322/P257 | Q30: =SUM(M30,N30,O30,P30) | R30: =R322/R257 | S30: =S322/S257 | T30: =T322/T257 | U30: =U322/U257 | V30: =SUM(R30,S30,T30,U30) | W30: =W322/W257 | X30: =X322/X257 | Y30: =Y322/Y257 | Z30: =Z322/Z257 | AA30: =SUM(W30,X30,Y30,Z30) | AB30: =AB322/AB257 | AC30: =AC322/AC257 | AD30: =AD322/AD257 | AE30: =AE322/AE257 | AF30: =SUM(AB30,AC30,AD30,AE30) | AG30: =AG322/AG257 | AH30: =AH322/AH257 | AI30: =AI322/AI257 | AJ30: =AJ322/AJ257 | AK30: =SUM(AG30,AH30,AI30,AJ30) | AL30: =AL322/AL257 | AM30: =AM322/AM257 | AN30: =AN322/AN257 | AO30: =AO322/AO257 | AP30: =SUM(AL30,AM30,AN30,AO30) | AQ30: =AQ322/AQ257 | AR30: =AR322/AR257 | AS30: =AS322/AS257 | AT30: =AT322/AT257 | AU30: =SUM(AQ30,AR30,AS30,AT30) | AV30: =AV322/AV257 | AW30: =AW322/AW257 | AX30: =AX322/AX257 | AY30: =AY322/AY257 | AZ30: =SUM(AV30,AW30,AX30,AY30) | BA30: =BA322/BA257 | BB30: =BB322/BB257 | BC30: =BC322/BC257 | BD30: =BD322/BD257 | BE30: =SUM(BA30,BB30,BC30,BD30) | BF30: =BF322/BF257 | BG30: =BG322/BG257 | BH30: =BH322/BH257 | BI30: =BI322/BI257 | BJ30: =SUM(BF30,BG30,BH30,BI30) | BK30: =BK322/BK257 | BL30: =BL322/BL257 | BM30: =BM322/BM257 | BN30: =BN322/BN257 | BO30: =SUM(BK30,BL30,BM30,BN30)
A31: Consolidated revenue in USD (Reported), mm USD | C31: 8998 | D31: 13322 | E31: 14543 | F31: 17116 | G31: 20111 | H31: 4900 | I31: 6076 | J31: 6968 | K31: 7228 | L31: 25173 | M31: 7041 | N31: 6661 | O31: 6665 | P31: 6238 | Q31: 26606 | R31: 6141 | S31: 6843 | T31: 8197 | U31: 8253 | V31: =SUM(R31,S31,T31,U31) | W31: 7507 | X31: 7061 | Y31: 8324 | Z31: 9213 | AA31: =SUM(W31,X31,Y31,Z31) | AB31: 8459 | AC31: 7853 | AD31: 8486 | AE31: 9398 | AF31: =SUM(AB31,AC31,AD31,AE31) | AG31: 7096 | AH31: 7746 | AI31: 9396 | AJ31: 10394 | AK31: =SUM(AG31,AH31,AI31,AJ31) | AL31: 10306 | AM31: 10385 | AN31: 12138 | AO31: 12676 | AP31: =SUM(AL31,AM31,AN31,AO31) | AQ31: 12919 | AR31: 13289 | AS31: 14878 | AT31: 15736 | AU31: =SUM(AQ31,AR31,AS31,AT31) | AV31: 17567 | AW31: 18158 | AX31: 20225 | AY31: 19931 | AZ31: =SUM(AV31,AW31,AX31,AY31) | BA31: 16719 | BB31: 15677 | BC31: 17278 | BD31: 19624 | BE31: =SUM(BA31,BB31,BC31,BD31) | BF31: 18873 | BG31: 20822 | BH31: 23504 | BI31: 26884 | BJ31: =SUM(BF31,BG31,BH31,BI31) | BK31: 25526 | BL31: 30070 | BM31: 33097 | BN31: 33731 | BO31: =SUM(BK31,BL31,BM31,BN31)
A33: Operating Expense Forecasting
A34: Revenue, mm | C34: =C369 | D34: =D369 | E34: =E369 | F34: =F369 | G34: =G369 | H34: =H369 | I34: =I369 | J34: =J369 | ... BO34: =BO369 | BP34: =BP25 | BQ34: =BQ25 | BR34: =BR25 | BS34: =BS25 | BT34: =BT25 | BU34: =BU25 | BV34: =BV25 | BW34: =BW25 | ... CB34: =CB25
A35: COGS, mm | C35: =C34-C36 | D35: =D34-D36 | E35: =E34-E36 | F35: =F34-F36 | G35: =G34-G36 | H35: =H34-H36 | I35: =I34-I36 | J35: =J34-J36 | ... CB35: =CB34-CB36
A36: Gross Profit, mm | C36: =C373 | D36: =D373 | E36: =E373 | F36: =F373 | G36: =G373 | H36: =H373 | I36: =I373 | J36: =J373 | ... BO36: =BO373 | BP36: =BP34*BP38 | BQ36: =BQ34*BQ38 | BR36: =BR34*BR38 | BS36: =BS34*BS38 | BT36: =BS36+BR36+BQ36+BP36 | BU36: =BU34*BU38 | BV36: =BV34*BV38 | BW36: =BW34*BW38 | BX36: =BX34*BX38 | BY36: =BX36+BW36+BV36+BU36 | BZ36: =BZ34*BZ38 | CA36: =CA34*CA38 | CB36: =CB34*CB38
A37: Y/Y growth in Gross profit, % | D37: =D36/C36-1 | E37: =E36/D36-1 | F37: =F36/E36-1 | G37: =G36/F36-1 | L37: =L36/G36-1 | M37: =M36/H36-1 | N37: =N36/I36-1 | O37: =O36/J36-1 | P37: =P36/K36-1 | Q37: =Q36/L36-1 | R37: =R36/M36-1 | S37: =S36/N36-1 | ... BY37: =BY36/BT36-1 | BZ37: =BZ36/BY36-1 | CA37: =CA36/BZ36-1 | CB37: =CB36/CA36-1
A38: Gross Margin, % | C38: =C36/C34 | D38: =D36/D34 | E38: =E36/E34 | F38: =F36/F34 | G38: =G36/G34 | H38: =H36/H34 | I38: =I36/I34 | J38: =J36/J34 | ... BO38: =BO36/BO34 | BP38: =BK38+BP40/10000 | BQ38: =BL38+BQ40/10000 | BR38: =BM38+BR40/10000 | BS38: =BN38+BS40/10000 | BT38: =BT36/BT34 | BU38: =BP38+BU40/10000 | BV38: =BQ38+BV40/10000 | BW38: =BR38+BW40/10000 | BX38: =BS38+BX40/10000 | BY38: =BY36/BY34 | BZ38: =BY38+BZ40/10000 | CA38: =BZ38+CA40/10000 | CB38: =CA38+CB40/10000
A39: Consensus Estimates - Gross Margin, % | BP39: =BP304 | BQ39: =BQ304 | BR39: =BR304 | BS39: =BS304 | BT39: =BT304 | BU39: =BU304 | BV39: =BV304 | BW39: =BW304 | ... CB39: =CB304
A40: Y/Y improvement in Gross Margin, bps | D40: =(D38-C38)*10000 | E40: =(E38-D38)*10000 | F40: =(F38-E38)*10000 | G40: =(G38-F38)*10000 | L40: =(L38-G38)*10000 | M40: =(M38-H38)*10000 | N40: =(N38-I38)*10000 | O40: =(O38-J38)*10000 | P40: =(P38-K38)*10000 | Q40: =(Q38-L38)*10000 | R40: =(R38-M38)*10000 | S40: =(S38-N38)*10000 | ... BO40: =(BO38-BJ38)*10000 | BP40: 520 | BQ40: 0 | BR40: 0 | BS40: 0 | BT40: =(BT38-BO38)*10000 | BU40: 0 | BV40: 0 | BW40: 0 | BX40: 0 | BY40: =(BY38-BT38)*10000 | BZ40: 0 | CA40: 0 | CB40: 0
A42: R&D Expense, mm | C42: =C375 | D42: =D375 | E42: =E375 | F42: =F375 | G42: =G375 | H42: =H375 | I42: =I375 | J42: =J375 | ... BO42: =BO375 | BP42: =BP34*BP44 | BQ42: =BQ34*BQ44 | BR42: =BR34*BR44 | BS42: =BS34*BS44 | BT42: =BS42+BR42+BQ42+BP42 | BU42: =BU34*BU44 | BV42: =BV34*BV44 | BW42: =BW34*BW44 | BX42: =BX34*BX44 | BY42: =BX42+BW42+BV42+BU42 | BZ42: =BZ34*BZ44 | CA42: =CA34*CA44 | CB42: =CB34*CB44
A43: Y/Y growth in R&D expense, % | D43: =D42/C42-1 | E43: =E42/D42-1 | F43: =F42/E42-1 | G43: =G42/F42-1 | H43: =H42/C42-1 | I43: =I42/D42-1 | J43: =J42/E42-1 | K43: =K42/F42-1 | L43: =L42/G42-1 | M43: =M42/H42-1 | N43: =N42/I42-1 | O43: =O42/J42-1 | ... BY43: =BY42/BT42-1 | BZ43: =BZ42/BY42-1 | CA43: =CA42/BZ42-1 | CB43: =CB42/CA42-1
...

Sheet Guidance
B1: =MO.CompanyName
B2: Most Recent Period: | F2: =UL.MRQ
I4: Guidance | M4: Model | P4: Difference vs. Mid | S4: Update Log
B5: Type | D5: Item | E5: Item Name | F5: Fiscal Period | G5: Base Period | I5: Low | J5: High | K5: Mid | M5: Type | N5: Output | P5: Absolute | Q5: Relative | S5: Date | T5: Link
A6: 250 | B6: =IF(INDEX(MO_SNA_IsHistoricalPeriod,,MATCH(F6,MO_Common_ColumnHeader,0)),"Historical","Forward") | D6: =INDEX(INDIRECT(E6),0,COLUMN(MO_Common_Column_A)) | E6: MO_CFSum_Capex | F6: FY2026 | I6: -56000 | J6: -52000 | K6: =AVERAGE(I6:J6) | M6: =IF(INDEX(MO_SNA_IsHistoricalPeriod,,MATCH(F6,MO_Common_ColumnHeader,0)),"Actual","Estimate") | N6: =IFERROR(INDEX(INDIRECT(E6),0,MATCH(F6,MO_Common_ColumnHeader,0)),"N/A")*INDEX(MO_VA_FX_Average,0,MATCH(F6,MO_Common_ColumnHeader,0)) | P6: =IF(ISNUMBER(N6),N6-K6,"N/A") | Q6: =IFERROR(IF(ISNUMBER(N6),(N6-K6)/ABS(K6),"N/A"),"N/A") | S6: 46037 | T6: Transcript
A7: 249
A8: 248 | B8: =IF(INDEX(MO_SNA_IsHistoricalPeriod,,MATCH(F8,MO_Common_ColumnHeader,0)),"Historical","Forward") | D8: =INDEX(INDIRECT(E8),0,COLUMN(MO_Common_Column_A)) | E8: MO_RIS_REV | F8: Q1-2026 | I8: 34600 | J8: 35800 | K8: =AVERAGE(I8:J8) | M8: =IF(INDEX(MO_SNA_IsHistoricalPeriod,,MATCH(F8,MO_Common_ColumnHeader,0)),"Actual","Estimate") | N8: =IFERROR(INDEX(INDIRECT(E8),0,MATCH(F8,MO_Common_ColumnHeader,0)),"N/A")/INDEX(z_M2B13B0184_MO_OS_Weightedaverageforeignexchangedratereported,0,MATCH(F8,MO_Common_ColumnHeader,0)) | P8: =IF(ISNUMBER(N8),N8-K8,"N/A") | Q8: =IFERROR(IF(ISNUMBER(N8),(N8-K8)/ABS(K8),"N/A"),"N/A") | S8: 46037 | T8: Investor Presentation
A9: 247 | B9: =IF(INDEX(MO_SNA_IsHistoricalPeriod,,MATCH(F9,MO_Common_ColumnHeader,0)),"Historical","Forward") | D9: =INDEX(INDIRECT(E9),0,COLUMN(MO_Common_Column_A)) | E9: z_M2B13B0184_MO_OS_Weightedaverageforeignexchangedratereported | F9: Q1-2026 | I9: 31.6 | J9: 31.6 | K9: =AVERAGE(I9:J9) | M9: =IF(INDEX(MO_SNA_IsHistoricalPeriod,,MATCH(F9,MO_Common_ColumnHeader,0)),"Actual","Estimate") | N9: =IFERROR(INDEX(INDIRECT(E9),0,MATCH(F9,MO_Common_ColumnHeader,0)),"N/A") | P9: =IF(ISNUMBER(N9),N9-K9,"N/A") | Q9: =IFERROR(IF(ISNUMBER(N9),(N9-K9)/ABS(K9),"N/A"),"N/A") | S9: 46037 | T9: Investor Presentation
A10: 246 | B10: =IF(INDEX(MO_SNA_IsHistoricalPeriod,,MATCH(F10,MO_Common_ColumnHeader,0)),"Historical","Forward") | D10: =INDEX(INDIRECT(E10),0,COLUMN(MO_Common_Column_A)) | E10: MO_MA_GM | F10: Q1-2026 | I10: 0.63 | J10: 0.65 | K10: =AVERAGE(I10:J10) | M10: =IF(INDEX(MO_SNA_IsHistoricalPeriod,,MATCH(F10,MO_Common_ColumnHeader,0)),"Actual","Estimate") | N10: =IFERROR(INDEX(INDIRECT(E10),0,MATCH(F10,MO_Common_ColumnHeader,0)),"N/A") | P10: =IF(ISNUMBER(N10),N10-K10,"N/A") | Q10: =IFERROR(IF(ISNUMBER(N10),(N10-K10)/ABS(K10),"N/A"),"N/A") | S10: 46037 | T10: Investor Presentation
A11: 245 | B11: =IF(INDEX(MO_SNA_IsHistoricalPeriod,,MATCH(F11,MO_Common_ColumnHeader,0)),"Historical","Forward") | D11: Operating Profit Margin | F11: Q1-2026 | I11: 0.54 | J11: 0.56 | K11: =AVERAGE(I11:J11) | M11: =IF(INDEX(MO_SNA_IsHistoricalPeriod,,MATCH(F11,MO_Common_ColumnHeader,0)),"Actual","Estimate") | N11: =INDEX(MO_RIS_EBIT,0,MATCH(F11,MO_Common_ColumnHeader,0))/INDEX(MO_RIS_REV,0,MATCH(F11,MO_Common_ColumnHeader,0)) | P11: =IF(ISNUMBER(N11),N11-K11,"N/A") | Q11: =IFERROR(IF(ISNUMBER(N11),(N11-K11)/ABS(K11),"N/A"),"N/A") | S11: 46037 | T11: Investor Presentation
A12: 244
A13: 243 | B13: =IF(INDEX(MO_SNA_IsHistoricalPeriod,,MATCH(F13,MO_Common_ColumnHeader,0)),"Historical","Forward") | D13: =INDEX(INDIRECT(E13),0,COLUMN(MO_Common_Column_A)) | E13: MO_CFSum_Capex | F13: FY2025 | I13: -42000 | J13: -40000 | K13: =AVERAGE(I13:J13) | M13: =IF(INDEX(MO_SNA_IsHistoricalPeriod,,MATCH(F13,MO_Common_ColumnHeader,0)),"Actual","Estimate") | N13: =IFERROR(INDEX(INDIRECT(E13),0,MATCH(F13,MO_Common_ColumnHeader,0)),"N/A")*INDEX(MO_VA_FX_Average,0,MATCH(F13,MO_Common_ColumnHeader,0)) | P13: =IF(ISNUMBER(N13),N13-K13,"N/A") | Q13: =IFERROR(IF(ISNUMBER(N13),(N13-K13)/ABS(K13),"N/A"),"N/A") | S13: 45946 | T13: Transcript
A14: 242
A15: 241 | B15: =IF(INDEX(MO_SNA_IsHistoricalPeriod,,MATCH(F15,MO_Common_ColumnHeader,0)),"Historical","Forward") | D15: =INDEX(INDIRECT(E15),0,COLUMN(MO_Common_Column_A)) | E15: MO_RIS_REV | F15: Q4-2025 | I15: 32200 | J15: 33400 | K15: =AVERAGE(I15:J15) | M15: =IF(INDEX(MO_SNA_IsHistoricalPeriod,,MATCH(F15,MO_Common_ColumnHeader,0)),"Actual","Estimate") | N15: =IFERROR(INDEX(INDIRECT(E15),0,MATCH(F15,MO_Common_ColumnHeader,0)),"N/A")/INDEX(z_M2B13B0184_MO_OS_Weightedaverageforeignexchangedratereported,0,MATCH(F15,MO_Common_ColumnHeader,0)) | P15: =IF(ISNUMBER(N15),N15-K15,"N/A") | Q15: =IFERROR(IF(ISNUMBER(N15),(N15-K15)/ABS(K15),"N/A"),"N/A") | S15: 45946 | T15: Investor Presentation
A16: 240 | B16: =IF(INDEX(MO_SNA_IsHistoricalPeriod,,MATCH(F16,MO_Common_ColumnHeader,0)),"Historical","Forward") | D16: =INDEX(INDIRECT(E16),0,COLUMN(MO_Common_Column_A)) | E16: z_M2B13B0184_MO_OS_Weightedaverageforeignexchangedratereported | F16: Q4-2025 | I16: 30.6 | J16: 30.6 | K16: =AVERAGE(I16:J16) | M16: =IF(INDEX(MO_SNA_IsHistoricalPeriod,,MATCH(F16,MO_Common_ColumnHeader,0)),"Actual","Estimate") | N16: =IFERROR(INDEX(INDIRECT(E16),0,MATCH(F16,MO_Common_ColumnHeader,0)),"N/A") | P16: =IF(ISNUMBER(N16),N16-K16,"N/A") | Q16: =IFERROR(IF(ISNUMBER(N16),(N16-K16)/ABS(K16),"N/A"),"N/A") | S16: 45946 | T16: Investor Presentation
A17: 239 | B17: =IF(INDEX(MO_SNA_IsHistoricalPeriod,,MATCH(F17,MO_Common_ColumnHeader,0)),"Historical","Forward") | D17: =INDEX(INDIRECT(E17),0,COLUMN(MO_Common_Column_A)) | E17: MO_MA_GM | F17: Q4-2025 | I17: 0.59 | J17: 0.61 | K17: =AVERAGE(I17:J17) | M17: =IF(INDEX(MO_SNA_IsHistoricalPeriod,,MATCH(F17,MO_Common_ColumnHeader,0)),"Actual","Estimate") | N17: =IFERROR(INDEX(INDIRECT(E17),0,MATCH(F17,MO_Common_ColumnHeader,0)),"N/A") | P17: =IF(ISNUMBER(N17),N17-K17,"N/A") | Q17: =IFERROR(IF(ISNUMBER(N17),(N17-K17)/ABS(K17),"N/A"),"N/A") | S17: 45946 | T17: Investor Presentation
A18: 238 | B18: =IF(INDEX(MO_SNA_IsHistoricalPeriod,,MATCH(F18,MO_Common_ColumnHeader,0)),"Historical","Forward") | D18: Operating Profit Margin | F18: Q4-2025 | I18: 0.49 | J18: 0.51 | K18: =AVERAGE(I18:J18) | M18: =IF(INDEX(MO_SNA_IsHistoricalPeriod,,MATCH(F18,MO_Common_ColumnHeader,0)),"Actual","Estimate") | N18: =INDEX(MO_RIS_EBIT,0,MATCH(F18,MO_Common_ColumnHeader,0))/INDEX(MO_RIS_REV,0,MATCH(F18,MO_Common_ColumnHeader,0)) | P18: =IF(ISNUMBER(N18),N18-K18,"N/A") | Q18: =IFERROR(IF(ISNUMBER(N18),(N18-K18)/ABS(K18),"N/A"),"N/A") | S18: 45946 | T18: Investor Presentation
A19: 237
A20: 236 | B20: =IF(INDEX(MO_SNA_IsHistoricalPeriod,,MATCH(F20,MO_Common_ColumnHeader,0)),"Historical","Forward") | D20: Revenue growth in USD | E20: MO_RIS_REV | F20: FY2025 | G20: FY2024 | I20: 0.3 | J20: 0.3 | K20: =AVERAGE(I20:J20) | M20: =IF(INDEX(MO_SNA_IsHistoricalPeriod,,MATCH(F20,MO_Common_ColumnHeader,0)),"Actual","Estimate") | N20: =IFERROR(INDEX(INDIRECT(E20),0,MATCH(F20,MO_Common_ColumnHeader,0)),"N/A")/INDEX(z_M2B13B0184_MO_OS_Weightedaverageforeignexchangedratereported,0,MATCH(F20,MO_Common_ColumnHeader,0))/(IFERROR(INDEX(INDIRECT(E20),0,MATCH(G20,MO_Common_ColumnHeader,0)),"N/A")/INDEX(z_M2B13B0184_MO_OS_Weightedaverageforeignexchangedratereported,0,MATCH(G20,MO_Common_ColumnHeader,0)))-1 | P20: =IF(ISNUMBER(N20),N20-K20,"N/A") | Q20: =IFERROR(IF(ISNUMBER(N20),(N20-K20)/ABS(K20),"N/A"),"N/A") | S20: 45855 | T20: Investor Presentation
A21: 235 | B21: =IF(INDEX(MO_SNA_IsHistoricalPeriod,,MATCH(F21,MO_Common_ColumnHeader,0)),"Historical","Forward") | D21: =INDEX(INDIRECT(E21),0,COLUMN(MO_Common_Column_A)) | E21: MO_CFSum_Capex | F21: FY2025 | I21: -42000 | J21: -38000 | K21: =AVERAGE(I21:J21) | M21: =IF(INDEX(MO_SNA_IsHistoricalPeriod,,MATCH(F21,MO_Common_ColumnHeader,0)),"Actual","Estimate") | N21: =IFERROR(INDEX(INDIRECT(E21),0,MATCH(F21,MO_Common_ColumnHeader,0)),"N/A")*INDEX(MO_VA_FX_Average,0,MATCH(F21,MO_Common_ColumnHeader,0)) | P21: =IF(ISNUMBER(N21),N21-K21,"N/A") | Q21: =IFERROR(IF(ISNUMBER(N21),(N21-K21)/ABS(K21),"N/A"),"N/A") | S21: 45855 | T21: Transcript
A22: 234
A23: 233 | B23: =IF(INDEX(MO_SNA_IsHistoricalPeriod,,MATCH(F23,MO_Common_ColumnHeader,0)),"Historical","Forward") | D23: =INDEX(INDIRECT(E23),0,COLUMN(MO_Common_Column_A)) | E23: MO_RIS_REV | F23: Q3-2025 | I23: 31800 | J23: 33000 | K23: =AVERAGE(I23:J23) | M23: =IF(INDEX(MO_SNA_IsHistoricalPeriod,,MATCH(F23,MO_Common_ColumnHeader,0)),"Actual","Estimate") | N23: =IFERROR(INDEX(INDIRECT(E23),0,MATCH(F23,MO_Common_ColumnHeader,0)),"N/A")/INDEX(z_M2B13B0184_MO_OS_Weightedaverageforeignexchangedratereported,0,MATCH(F23,MO_Common_ColumnHeader,0)) | P23: =IF(ISNUMBER(N23),N23-K23,"N/A") | Q23: =IFERROR(IF(ISNUMBER(N23),(N23-K23)/ABS(K23),"N/A"),"N/A") | S23: 45855 | T23: Investor Presentation
A24: 232 | B24: =IF(INDEX(MO_SNA_IsHistoricalPeriod,,MATCH(F24,MO_Common_ColumnHeader,0)),"Historical","Forward") | D24: =INDEX(INDIRECT(E24),0,COLUMN(MO_Common_Column_A)) | E24: z_M2B13B0184_MO_OS_Weightedaverageforeignexchangedratereported | F24: Q3-2025 | I24: 29 | J24: 29 | K24: =AVERAGE(I24:J24) | M24: =IF(INDEX(MO_SNA_IsHistoricalPeriod,,MATCH(F24,MO_Common_ColumnHeader,0)),"Actual","Estimate") | N24: =IFERROR(INDEX(INDIRECT(E24),0,MATCH(F24,MO_Common_ColumnHeader,0)),"N/A") | P24: =IF(ISNUMBER(N24),N24-K24,"N/A") | Q24: =IFERROR(IF(ISNUMBER(N24),(N24-K24)/ABS(K24),"N/A"),"N/A") | S24: 45855 | T24: Investor Presentation
A25: 231 | B25: =IF(INDEX(MO_SNA_IsHistoricalPeriod,,MATCH(F25,MO_Common_ColumnHeader,0)),"Historical","Forward") | D25: =INDEX(INDIRECT(E25),0,COLUMN(MO_Common_Column_A)) | E25: MO_MA_GM | F25: Q3-2025 | I25: 0.555 | J25: 0.575 | K25: =AVERAGE(I25:J25) | M25: =IF(INDEX(MO_SNA_IsHistoricalPeriod,,MATCH(F25,MO_Common_ColumnHeader,0)),"Actual","Estimate") | N25: =IFERROR(INDEX(INDIRECT(E25),0,MATCH(F25,MO_Common_ColumnHeader,0)),"N/A") | P25: =IF(ISNUMBER(N25),N25-K25,"N/A") | Q25: =IFERROR(IF(ISNUMBER(N25),(N25-K25)/ABS(K25),"N/A"),"N/A") | S25: 45855 | T25: Investor Presentation
A26: 230 | B26: =IF(INDEX(MO_SNA_IsHistoricalPeriod,,MATCH(F26,MO_Common_ColumnHeader,0)),"Historical","Forward") | D26: Operating Profit Margin | F26: Q3-2025 | I26: 0.455 | J26: 0.475 | K26: =AVERAGE(I26:J26) | M26: =IF(INDEX(MO_SNA_IsHistoricalPeriod,,MATCH(F26,MO_Common_ColumnHeader,0)),"Actual","Estimate") | N26: =INDEX(MO_RIS_EBIT,0,MATCH(F26,MO_Common_ColumnHeader,0))/INDEX(MO_RIS_REV,0,MATCH(F26,MO_Common_ColumnHeader,0)) | P26: =IF(ISNUMBER(N26),N26-K26,"N/A") | Q26: =IFERROR(IF(ISNUMBER(N26),(N26-K26)/ABS(K26),"N/A"),"N/A") | S26: 45855 | T26: Investor Presentation
A27: 229
A28: 228 | B28: =IF(INDEX(MO_SNA_IsHistoricalPeriod,,MATCH(F28,MO_Common_ColumnHeader,0)),"Historical","Forward") | D28: Revenue growth in USD | E28: MO_RIS_REV | F28: FY2025 | G28: FY2024 | I28: 0.24 | J28: 0.26 | K28: =AVERAGE(I28:J28) | M28: =IF(INDEX(MO_SNA_IsHistoricalPeriod,,MATCH(F28,MO_Common_ColumnHeader,0)),"Actual","Estimate") | N28: =IFERROR(INDEX(INDIRECT(E28),0,MATCH(F28,MO_Common_ColumnHeader,0)),"N/A")/INDEX(z_M2B13B0184_MO_OS_Weightedaverageforeignexchangedratereported,0,MATCH(F28,MO_Common_ColumnHeader,0))/(IFERROR(INDEX(INDIRECT(E28),0,MATCH(G28,MO_Common_ColumnHeader,0)),"N/A")/INDEX(z_M2B13B0184_MO_OS_Weightedaverageforeignexchangedratereported,0,MATCH(G28,MO_Common_ColumnHeader,0)))-1 | P28: =IF(ISNUMBER(N28),N28-K28,"N/A") | Q28: =IFERROR(IF(ISNUMBER(N28),(N28-K28)/ABS(K28),"N/A"),"N/A") | S28: 45764 | T28: Investor Presentation
A29: 227 | B29: =IF(INDEX(MO_SNA_IsHistoricalPeriod,,MATCH(F29,MO_Common_ColumnHeader,0)),"Historical","Forward") | D29: =INDEX(INDIRECT(E29),0,COLUMN(MO_Common_Column_A)) | E29: MO_CFSum_Capex | F29: FY2025 | I29: -42000 | J29: -38000 | K29: =AVERAGE(I29:J29) | M29: =IF(INDEX(MO_SNA_IsHistoricalPeriod,,MATCH(F29,MO_Common_ColumnHeader,0)),"Actual","Estimate") | N29: =IFERROR(INDEX(INDIRECT(E29),0,MATCH(F29,MO_Common_ColumnHeader,0)),"N/A")*INDEX(MO_VA_FX_Average,0,MATCH(F29,MO_Common_ColumnHeader,0)) | P29: =IF(ISNUMBER(N29),N29-K29,"N/A") | Q29: =IFERROR(IF(ISNUMBER(N29),(N29-K29)/ABS(K29),"N/A"),"N/A") | S29: 45764 | T29: Transcript
A30: 226 | B30: =IF(INDEX(MO_SNA_IsHistoricalPeriod,,MATCH(F30,MO_Common_ColumnHeader,0)),"Historical","Forward") | D30: =INDEX(INDIRECT(E30),0,COLUMN(MO_Common_Column_A)) | E30: MO_RIS_TaxRate_Current | F30: FY2025 | I30: 0.16 | J30: 0.17 | K30: =AVERAGE(I30:J30) | M30: =IF(INDEX(MO_SNA_IsHistoricalPeriod,,MATCH(F30,MO_Common_ColumnHeader,0)),"Actual","Estimate") | N30: =IFERROR(INDEX(INDIRECT(E30),0,MATCH(F30,MO_Common_ColumnHeader,0)),"N/A") | P30: =IF(ISNUMBER(N30),N30-K30,"N/A") | Q30: =IFERROR(IF(ISNUMBER(N30),(N30-K30)/ABS(K30),"N/A"),"N/A") | S30: 45764 | T30: Transcript
A31: 225
A32: 224 | B32: =IF(INDEX(MO_SNA_IsHistoricalPeriod,,MATCH(F32,MO_Common_ColumnHeader,0)),"Historical","Forward") | D32: =INDEX(INDIRECT(E32),0,COLUMN(MO_Common_Column_A)) | E32: MO_RIS_REV | F32: Q2-2025 | I32: 28400 | J32: 29200 | K32: =AVERAGE(I32:J32) | M32: =IF(INDEX(MO_SNA_IsHistoricalPeriod,,MATCH(F32,MO_Common_ColumnHeader,0)),"Actual","Estimate") | N32: =IFERROR(INDEX(INDIRECT(E32),0,MATCH(F32,MO_Common_ColumnHeader,0)),"N/A")/INDEX(z_M2B13B0184_MO_OS_Weightedaverageforeignexchangedratereported,0,MATCH(F32,MO_Common_ColumnHeader,0)) | P32: =IF(ISNUMBER(N32),N32-K32,"N/A") | Q32: =IFERROR(IF(ISNUMBER(N32),(N32-K32)/ABS(K32),"N/A"),"N/A") | S32: 45764 | T32: Investor Presentation
A33: 223 | B33: =IF(INDEX(MO_SNA_IsHistoricalPeriod,,MATCH(F33,MO_Common_ColumnHeader,0)),"Historical","Forward") | D33: =INDEX(INDIRECT(E33),0,COLUMN(MO_Common_Column_A)) | E33: z_M2B13B0184_MO_OS_Weightedaverageforeignexchangedratereported | F33: Q2-2025 | I33: 32.5 | J33: 32.5 | K33: =AVERAGE(I33:J33) | M33: =IF(INDEX(MO_SNA_IsHistoricalPeriod,,MATCH(F33,MO_Common_ColumnHeader,0)),"Actual","Estimate") | N33: =IFERROR(INDEX(INDIRECT(E33),0,MATCH(F33,MO_Common_ColumnHeader,0)),"N/A") | P33: =IF(ISNUMBER(N33),N33-K33,"N/A") | Q33: =IFERROR(IF(ISNUMBER(N33),(N33-K33)/ABS(K33),"N/A"),"N/A") | S33: 45764 | T33: Investor Presentation
A34: 222 | B34: =IF(INDEX(MO_SNA_IsHistoricalPeriod,,MATCH(F34,MO_Common_ColumnHeader,0)),"Historical","Forward") | D34: =INDEX(INDIRECT(E34),0,COLUMN(MO_Common_Column_A)) | E34: MO_MA_GM | F34: Q2-2025 | I34: 0.57 | J34: 0.59 | K34: =AVERAGE(I34:J34) | M34: =IF(INDEX(MO_SNA_IsHistoricalPeriod,,MATCH(F34,MO_Common_ColumnHeader,0)),"Actual","Estimate") | N34: =IFERROR(INDEX(INDIRECT(E34),0,MATCH(F34,MO_Common_ColumnHeader,0)),"N/A") | P34: =IF(ISNUMBER(N34),N34-K34,"N/A") | Q34: =IFERROR(IF(ISNUMBER(N34),(N34-K34)/ABS(K34),"N/A"),"N/A") | S34: 45764 | T34: Investor Presentation
A35: 221 | B35: =IF(INDEX(MO_SNA_IsHistoricalPeriod,,MATCH(F35,MO_Common_ColumnHeader,0)),"Historical","Forward") | D35: Operating Profit Margin | F35: Q2-2025 | I35: 0.47 | J35: 0.49 | K35: =AVERAGE(I35:J35) | M35: =IF(INDEX(MO_SNA_IsHistoricalPeriod,,MATCH(F35,MO_Common_ColumnHeader,0)),"Actual","Estimate") | N35: =INDEX(MO_RIS_EBIT,0,MATCH(F35,MO_Common_ColumnHeader,0))/INDEX(MO_RIS_REV,0,MATCH(F35,MO_Common_ColumnHeader,0)) | P35: =IF(ISNUMBER(N35),N35-K35,"N/A") | Q35: =IFERROR(IF(ISNUMBER(N35),(N35-K35)/ABS(K35),"N/A"),"N/A") | S35: 45764 | T35: Investor Presentation
A36: 220 | B36: =IF(INDEX(MO_SNA_IsHistoricalPeriod,,MATCH(F36,MO_Common_ColumnHeader,0)),"Historical","Forward") | D36: =INDEX(INDIRECT(E36),0,COLUMN(MO_Common_Column_A)) | E36: MO_RIS_TaxRate_Current | F36: Q2-2025 | I36: 0.2 | J36: 0.2 | K36: =AVERAGE(I36:J36) | M36: =IF(INDEX(MO_SNA_IsHistoricalPeriod,,MATCH(F36,MO_Common_ColumnHeader,0)),"Actual","Estimate") | N36: =IFERROR(INDEX(INDIRECT(E36),0,MATCH(F36,MO_Common_ColumnHeader,0)),"N/A") | P36: =IF(ISNUMBER(N36),N36-K36,"N/A") | Q36: =IFERROR(IF(ISNUMBER(N36),(N36-K36)/ABS(K36),"N/A"),"N/A") | S36: 45764 | T36: Transcript
A37: 219
A38: 218 | B38: =IF(INDEX(MO_SNA_IsHistoricalPeriod,,MATCH(F38,MO_Common_ColumnHeader,0)),"Historical","Forward") | D38: =INDEX(INDIRECT(E38),0,COLUMN(MO_Common_Column_A)) | E38: MO_CFSum_Capex | F38: FY2025 | I38: -42000 | J38: -38000 | K38: =AVERAGE(I38:J38) | M38: =IF(INDEX(MO_SNA_IsHistoricalPeriod,,MATCH(F38,MO_Common_ColumnHeader,0)),"Actual","Estimate") | N38: =IFERROR(INDEX(INDIRECT(E38),0,MATCH(F38,MO_Common_ColumnHeader,0)),"N/A")*INDEX(MO_VA_FX_Average,0,MATCH(F38,MO_Common_ColumnHeader,0)) | P38: =IF(ISNUMBER(N38),N38-K38,"N/A") | Q38: =IFERROR(IF(ISNUMBER(N38),(N38-K38)/ABS(K38),"N/A"),"N/A") | S38: 45673 | T38: Transcript
A39: 217 | B39: =IF(INDEX(MO_SNA_IsHistoricalPeriod,,MATCH(F39,MO_Common_ColumnHeader,0)),"Historical","Forward") | D39: =INDEX(INDIRECT(E39),0,COLUMN(MO_Common_Column_A)) | E39: MO_RIS_TaxRate_Current | F39: FY2025 | I39: 0.16 | J39: 0.17 | K39: =AVERAGE(I39:J39) | M39: =IF(INDEX(MO_SNA_IsHistoricalPeriod,,MATCH(F39,MO_Common_ColumnHeader,0)),"Actual","Estimate") | N39: =IFERROR(INDEX(INDIRECT(E39),0,MATCH(F39,MO_Common_ColumnHeader,0)),"N/A") | P39: =IF(ISNUMBER(N39),N39-K39,"N/A") | Q39: =IFERROR(IF(ISNUMBER(N39),(N39-K39)/ABS(K39),"N/A"),"N/A") | S39: 45673 | T39: Transcript
A40: 216
A41: 215 | B41: =IF(INDEX(MO_SNA_IsHistoricalPeriod,,MATCH(F41,MO_Common_ColumnHeader,0)),"Historical","Forward") | D41: =INDEX(INDIRECT(E41),0,COLUMN(MO_Common_Column_A)) | E41: MO_RIS_REV | F41: Q1-2025 | I41: 25000 | J41: 25800 | K41: =AVERAGE(I41:J41) | M41: =IF(INDEX(MO_SNA_IsHistoricalPeriod,,MATCH(F41,MO_Common_ColumnHeader,0)),"Actual","Estimate") | N41: =IFERROR(INDEX(INDIRECT(E41),0,MATCH(F41,MO_Common_ColumnHeader,0)),"N/A")/INDEX(z_M2B13B0184_MO_OS_Weightedaverageforeignexchangedratereported,0,MATCH(F41,MO_Common_ColumnHeader,0)) | P41: =IF(ISNUMBER(N41),N41-K41,"N/A") | Q41: =IFERROR(IF(ISNUMBER(N41),(N41-K41)/ABS(K41),"N/A"),"N/A") | S41: 45673 | T41: Investor Presentation
...

Sheet Summary Page
A1: =MO.CompanyName | C1: =INDEX(MO_Common_QEndDate,0,COLUMN()) | D1: =INDEX(MO_Common_QEndDate,0,COLUMN()) | E1: =INDEX(MO_Common_QEndDate,0,COLUMN()) | F1: =INDEX(MO_Common_QEndDate,0,COLUMN()) | G1: =INDEX(MO_Common_QEndDate,0,COLUMN()) | H1: =INDEX(MO_Common_QEndDate,0,COLUMN()) | I1: =INDEX(MO_Common_QEndDate,0,COLUMN()) | J1: =INDEX(MO_Common_QEndDate,0,COLUMN()) | ... CB1: =INDEX(MO_Common_QEndDate,0,COLUMN())
